Workbook

Sheet Übersicht
A1: bestanden – Übersicht der drei Szenarien
A2: CHF, ohne MWST und Steuern. Alle Werte sind Formeln auf die Modellblätter.
A4: Vorsichtig | C4: 2027 | D4: 2028 | E4: 2029 | F4: 2030 | G4: 2031
A5: Lernende abgedeckt | C5: ='Modell Vorsichtig'!C5 | D5: ='Modell Vorsichtig'!D5 | E5: ='Modell Vorsichtig'!E5 | F5: ='Modell Vorsichtig'!F5 | G5: ='Modell Vorsichtig'!G5
A6: Lernende mit Betriebslizenz | C6: ='Modell Vorsichtig'!C7 | D6: ='Modell Vorsichtig'!D7 | E6: ='Modell Vorsichtig'!E7 | F6: ='Modell Vorsichtig'!F7 | G6: ='Modell Vorsichtig'!G7
A7: Lehrbetriebe | C7: ='Modell Vorsichtig'!C8 | D7: ='Modell Vorsichtig'!D8 | E7: ='Modell Vorsichtig'!E8 | F7: ='Modell Vorsichtig'!F8 | G7: ='Modell Vorsichtig'!G8
A8: B2C-Käufer/innen | C8: ='Modell Vorsichtig'!C11 | D8: ='Modell Vorsichtig'!D11 | E8: ='Modell Vorsichtig'!E11 | F8: ='Modell Vorsichtig'!F11 | G8: ='Modell Vorsichtig'!G11
A9: Umsatz | C9: ='Modell Vorsichtig'!C18 | D9: ='Modell Vorsichtig'!D18 | E9: ='Modell Vorsichtig'!E18 | F9: ='Modell Vorsichtig'!F18 | G9: ='Modell Vorsichtig'!G18
A10: Anteil B2B | C10: ='Modell Vorsichtig'!C19 | D10: ='Modell Vorsichtig'!D19 | E10: ='Modell Vorsichtig'!E19 | F10: ='Modell Vorsichtig'!F19 | G10: ='Modell Vorsichtig'!G19
A11: Deckungsbeitrag | C11: ='Modell Vorsichtig'!C25 | D11: ='Modell Vorsichtig'!D25 | E11: ='Modell Vorsichtig'!E25 | F11: ='Modell Vorsichtig'!F25 | G11: ='Modell Vorsichtig'!G25
A12: Personal | C12: ='Modell Vorsichtig'!C28 | D12: ='Modell Vorsichtig'!D28 | E12: ='Modell Vorsichtig'!E28 | F12: ='Modell Vorsichtig'!F28 | G12: ='Modell Vorsichtig'!G28
A13: Marketing und Vertrieb | C13: ='Modell Vorsichtig'!C31 | D13: ='Modell Vorsichtig'!D31 | E13: ='Modell Vorsichtig'!E31 | F13: ='Modell Vorsichtig'!F31 | G13: ='Modell Vorsichtig'!G31
A14: Operatives Ergebnis | C14: ='Modell Vorsichtig'!C34 | D14: ='Modell Vorsichtig'!D34 | E14: ='Modell Vorsichtig'!E34 | F14: ='Modell Vorsichtig'!F34 | G14: ='Modell Vorsichtig'!G34
A15: Kasse Ende Jahr | C15: ='Modell Vorsichtig'!C37 | D15: ='Modell Vorsichtig'!D37 | E15: ='Modell Vorsichtig'!E37 | F15: ='Modell Vorsichtig'!F37 | G15: ='Modell Vorsichtig'!G37
A16: Finanzierungsbedarf (kumuliert) | C16: ='Modell Vorsichtig'!C38 | D16: ='Modell Vorsichtig'!D38 | E16: ='Modell Vorsichtig'!E38 | F16: ='Modell Vorsichtig'!F38 | G16: ='Modell Vorsichtig'!G38
A17: Marktanteil Lernende CH | C17: ='Modell Vorsichtig'!C40 | D17: ='Modell Vorsichtig'!D40 | E17: ='Modell Vorsichtig'!E40 | F17: ='Modell Vorsichtig'!F40 | G17: ='Modell Vorsichtig'!G40
A18: Dauerhaft positives Ergebnis ab | C18: =IF('Modell Vorsichtig'!G34>0,IF('Modell Vorsichtig'!F34>0,IF('Modell Vorsichtig'!E34>0,IF('Modell Vorsichtig'!D34>0,IF('Modell Vorsichtig'!C34>0,2027,2028),2029),2030),2031),"nach 2031")
A20: Basis | C20: 2027 | D20: 2028 | E20: 2029 | F20: 2030 | G20: 2031
A21: Lernende abgedeckt | C21: ='Modell Basis'!C5 | D21: ='Modell Basis'!D5 | E21: ='Modell Basis'!E5 | F21: ='Modell Basis'!F5 | G21: ='Modell Basis'!G5
A22: Lernende mit Betriebslizenz | C22: ='Modell Basis'!C7 | D22: ='Modell Basis'!D7 | E22: ='Modell Basis'!E7 | F22: ='Modell Basis'!F7 | G22: ='Modell Basis'!G7
A23: Lehrbetriebe | C23: ='Modell Basis'!C8 | D23: ='Modell Basis'!D8 | E23: ='Modell Basis'!E8 | F23: ='Modell Basis'!F8 | G23: ='Modell Basis'!G8
A24: B2C-Käufer/innen | C24: ='Modell Basis'!C11 | D24: ='Modell Basis'!D11 | E24: ='Modell Basis'!E11 | F24: ='Modell Basis'!F11 | G24: ='Modell Basis'!G11
A25: Umsatz | C25: ='Modell Basis'!C18 | D25: ='Modell Basis'!D18 | E25: ='Modell Basis'!E18 | F25: ='Modell Basis'!F18 | G25: ='Modell Basis'!G18
A26: Anteil B2B | C26: ='Modell Basis'!C19 | D26: ='Modell Basis'!D19 | E26: ='Modell Basis'!E19 | F26: ='Modell Basis'!F19 | G26: ='Modell Basis'!G19
A27: Deckungsbeitrag | C27: ='Modell Basis'!C25 | D27: ='Modell Basis'!D25 | E27: ='Modell Basis'!E25 | F27: ='Modell Basis'!F25 | G27: ='Modell Basis'!G25
A28: Personal | C28: ='Modell Basis'!C28 | D28: ='Modell Basis'!D28 | E28: ='Modell Basis'!E28 | F28: ='Modell Basis'!F28 | G28: ='Modell Basis'!G28
A29: Marketing und Vertrieb | C29: ='Modell Basis'!C31 | D29: ='Modell Basis'!D31 | E29: ='Modell Basis'!E31 | F29: ='Modell Basis'!F31 | G29: ='Modell Basis'!G31
A30: Operatives Ergebnis | C30: ='Modell Basis'!C34 | D30: ='Modell Basis'!D34 | E30: ='Modell Basis'!E34 | F30: ='Modell Basis'!F34 | G30: ='Modell Basis'!G34
A31: Kasse Ende Jahr | C31: ='Modell Basis'!C37 | D31: ='Modell Basis'!D37 | E31: ='Modell Basis'!E37 | F31: ='Modell Basis'!F37 | G31: ='Modell Basis'!G37
A32: Finanzierungsbedarf (kumuliert) | C32: ='Modell Basis'!C38 | D32: ='Modell Basis'!D38 | E32: ='Modell Basis'!E38 | F32: ='Modell Basis'!F38 | G32: ='Modell Basis'!G38
A33: Marktanteil Lernende CH | C33: ='Modell Basis'!C40 | D33: ='Modell Basis'!D40 | E33: ='Modell Basis'!E40 | F33: ='Modell Basis'!F40 | G33: ='Modell Basis'!G40
A34: Dauerhaft positives Ergebnis ab | C34: =IF('Modell Basis'!G34>0,IF('Modell Basis'!F34>0,IF('Modell Basis'!E34>0,IF('Modell Basis'!D34>0,IF('Modell Basis'!C34>0,2027,2028),2029),2030),2031),"nach 2031")
A36: Wachstum | C36: 2027 | D36: 2028 | E36: 2029 | F36: 2030 | G36: 2031
A37: Lernende abgedeckt | C37: ='Modell Wachstum'!C5 | D37: ='Modell Wachstum'!D5 | E37: ='Modell Wachstum'!E5 | F37: ='Modell Wachstum'!F5 | G37: ='Modell Wachstum'!G5
A38: Lernende mit Betriebslizenz | C38: ='Modell Wachstum'!C7 | D38: ='Modell Wachstum'!D7 | E38: ='Modell Wachstum'!E7 | F38: ='Modell Wachstum'!F7 | G38: ='Modell Wachstum'!G7
A39: Lehrbetriebe | C39: ='Modell Wachstum'!C8 | D39: ='Modell Wachstum'!D8 | E39: ='Modell Wachstum'!E8 | F39: ='Modell Wachstum'!F8 | G39: ='Modell Wachstum'!G8
A40: B2C-Käufer/innen | C40: ='Modell Wachstum'!C11 | D40: ='Modell Wachstum'!D11 | E40: ='Modell Wachstum'!E11 | F40: ='Modell Wachstum'!F11 | G40: ='Modell Wachstum'!G11
A41: Umsatz | C41: ='Modell Wachstum'!C18 | D41: ='Modell Wachstum'!D18 | E41: ='Modell Wachstum'!E18 | F41: ='Modell Wachstum'!F18 | G41: ='Modell Wachstum'!G18
A42: Anteil B2B | C42: ='Modell Wachstum'!C19 | D42: ='Modell Wachstum'!D19 | E42: ='Modell Wachstum'!E19 | F42: ='Modell Wachstum'!F19 | G42: ='Modell Wachstum'!G19
A43: Deckungsbeitrag | C43: ='Modell Wachstum'!C25 | D43: ='Modell Wachstum'!D25 | E43: ='Modell Wachstum'!E25 | F43: ='Modell Wachstum'!F25 | G43: ='Modell Wachstum'!G25
...

Sheet Annahmen
A1: bestanden – Finanzmodell · Annahmen
A2: Blaue Werte sind Eingaben, alles andere ist berechnet. Einzelwerte stehen im ersten Jahr des Szenarios und gelten für alle Jahre. CHF ohne MWST. Hypothesen sind in Spalte U so bezeichnet.
C4: Vorsichtig | I4: Basis | O4: Wachstum
C5: 2027 | D5: 2028 | E5: 2029 | F5: 2030 | G5: 2031 | I5: 2027 | J5: 2028 | K5: 2029 | L5: 2030 | M5: 2031 | O5: 2027 | P5: 2028 | Q5: 2029 | R5: 2030 | S5: 2031 | U5: Quelle / Begründung
A6: Markt
A7: Lernende in den abgedeckten Berufen | B7: Personen | C7: 2000 | D7: 5000 | E7: 10000 | F7: 18000 | G7: 28000 | I7: 2500 | J7: 9000 | K7: 22000 | L7: 40000 | M7: 60000 | O7: 4000 | P7: 15000 | Q7: 35000 | R7: 65000 | S7: 100000 | U7: Start Sanitär (rund 600 QV-Antritte/Jahr, EHB 2024), danach Heizung (rund 280). Danach weitere Berufe. Obergrenze Schweiz: 215'052 Lernende (BFS 2025). Wachstum 2031 = 46 % aller Lernenden: nur erreichbar, wenn auch grosse Berufe mit bestehender Konkurrenz dazukommen.
A8: Berufe live (kumuliert) | B8: Anzahl | C8: 1 | D8: 2 | E8: 4 | F8: 6 | G8: 8 | I8: 1 | J8: 3 | K8: 6 | L8: 10 | M8: 14 | O8: 2 | P8: 5 | Q8: 11 | R8: 17 | S8: 24 | U8: Pro Beruf eine Fachperson für die Prüfung der Inhalte.
A9: QV-Kandidaten je Lernende | B9: Anteil | C9: 0.32 | I9: 0.32 | O9: 0.32 | U9: 70'000 Antritte (EHB 2024) ÷ 215'052 Lernende (BFS 2025) = 0,33. Gerundet 0,32.
A10: Lehrbetriebe (B2B)
A11: Anteil Lernende mit Betriebslizenz | B11: % | C11: 0.03 | D11: 0.05 | E11: 0.07 | F11: 0.09 | G11: 0.1 | I11: 0.04 | J11: 0.07 | K11: 0.11 | L11: 0.15 | M11: 0.18 | O11: 0.05 | P11: 0.1 | Q11: 0.15 | R11: 0.21 | S11: 0.26 | U11: Hypothese, im Pilot zu messen. time2learn nennt >5'000 Betriebe (Selbstangabe) – Betriebe zahlen für Ausbildungssoftware.
A12: Lizenzierte Lernende je Lehrbetrieb | B12: Personen | C12: 2 | I12: 2.5 | O12: 3 | U12: Annahme. Gebäudetechnik-Betriebe sind oft klein (1–3 Lernende).
A13: Kündigungsrate Lehrbetriebe | B13: %/Jahr | C13: 0.25 | I13: 0.18 | O13: 0.12 | U13: Annahme. Betriebe ohne Lernende im nächsten Jahrgang kündigen.
A14: Ø erzielter Preis je lizenzierte/r Lernende/r | B14: CHF/Jahr | C14: 90 | D14: 95 | E14: 100 | F14: 100 | G14: 100 | I14: 100 | J14: 105 | K14: 110 | L14: 110 | M14: 110 | O14: 100 | P14: 110 | Q14: 115 | R14: 115 | S14: 115 | U14: Liste CHF 120 (= CHF 10/Monat), abzüglich Staffel- und Verbandsrabatte. Preisanker der Konkurrenz: LernStrom Sanitär CHF 80 einmalig. Der Aufpreis muss durch Berufsbildner-Ansicht und Fachgespräch-Training begründet sein.
A15: Akquisekosten je neuer Lehrbetrieb | B15: CHF | C15: 80 | D15: 350 | E15: 350 | F15: 350 | G15: 350 | I15: 60 | J15: 250 | K15: 250 | L15: 220 | M15: 200 | O15: 60 | P15: 200 | Q15: 180 | R15: 160 | S15: 150 | U15: Annahme. 2027 verkauft der Gründer selbst (nur Spesen). Danach Anrufe, Besuche, Verbandsanlässe; über Verbandskanal sinkend. Im Pilot messen.
A16: Lernende direkt (B2C)
A17: Kaufquote QV-Kandidaten ohne Betriebslizenz | B17: % | C17: 0.015 | D17: 0.02 | E17: 0.025 | F17: 0.03 | G17: 0.03 | I17: 0.02 | J17: 0.03 | K17: 0.04 | L17: 0.045 | M17: 0.05 | O17: 0.03 | P17: 0.04 | Q17: 0.05 | R17: 0.06 | S17: 0.07 | U17: Hypothese. Freemium-Apps wandeln typischerweise wenige Prozent um; Gratis-Konkurrenz in grossen Berufen (FaGefit).
A18: Preis QV-Pass (Januar bis QV) | B18: CHF | C18: 59 | I18: 59 | O18: 59 | U18: Vergleich: LernStrom QV Sanitär CHF 80 einmalig (5 Jahre Zugriff), «I got this» (KV) CHF 89/365 Tage. B2C ist im Modell nur ein Nebenkanal.
A19: Akquisekosten je bezahlte/r B2C-Käufer/in | B19: CHF | C19: 20 | I19: 15 | O19: 12 | U19: Annahme für Social Ads (TikTok/Instagram) an 17–20-Jährige. Im Pilot messen.
A20: Anteil B2C-Käufe ohne Werbung (Empfehlung, Schule) | B20: % | C20: 0.3 | I20: 0.4 | O20: 0.5 | U20: Annahme.
A21: Verbände (OdA-Lizenz)
A22: Verbandslizenzen (Branchenlizenz, eigenes Branding) | B22: Anzahl | C22: 0 | D22: 0 | E22: 0 | F22: 1 | G22: 1 | I22: 0 | J22: 0 | K22: 1 | L22: 2 | M22: 3 | O22: 0 | P22: 1 | Q22: 2 | R22: 4 | S22: 6 | U22: Hypothese. Verbände investieren bereits in QV-Erfolg (suissetec: Bildungscoachs seit 2024).
A23: Preis Verbandslizenz | B23: CHF/Jahr | C23: 25000 | I23: 25000 | O23: 25000 | U23: Annahme: Plattform, Branding, Auswertungen; Inhalte bleiben beim Verband oder werden geteilt.
A24: Variable Kosten
A25: Anteil aktive Nutzer/innen unter den Lizenzierten | B25: % | C25: 0.6 | I25: 0.6 | O25: 0.6 | U25: Annahme.
A26: KI-Kosten je aktive/r Nutzer/in | B26: CHF/Jahr | C26: 3 | I26: 3 | O26: 3 | U26: 150 Bewertungen offener Antworten/Jahr × ~2'000 Eingabe- und 400 Ausgabe-Tokens. Claude Opus 5 ($5/$25 je Mio. Tokens): USD 0.02 je Bewertung = USD 3.00/Jahr; Sonnet 5 ($2/$10): USD 1.20. Ohne Rabatt durch Caching. Siehe 05-ki-konzept.md.
A27: Hosting und Speicher je aktive/r Nutzer/in | B27: CHF/Jahr | C27: 1.5 | I27: 1.5 | O27: 1.5 | U27: Annahme, Schweizer Hosting.
A28: Zahlungsgebühren B2C (Karte, TWINT) | B28: % Umsatz | C28: 0.035 | I28: 0.035 | O28: 0.035 | U28: Annahme rund 3–3,5 %.
A29: Zahlungs- und Mahnkosten B2B | B29: % Umsatz | C29: 0.01 | I29: 0.01 | O29: 0.01 | U29: Rechnung per QR-Rechnung.
A30: Fixkosten
A31: Angestellte (Vollzeitstellen, Gründer ab Lohn) | B31: FTE | C31: 0 | D31: 0 | E31: 0.3 | F31: 0.8 | G31: 1.5 | I31: 0 | J31: 0 | K31: 1 | L31: 3 | M31: 5.5 | O31: 0 | P31: 0.5 | Q31: 3 | R31: 7 | S31: 11 | U31: 2027 arbeitet der Gründer abends ohne Lohn. Stellen erst, wenn Umsatz sie trägt (siehe Gates).
A32: Vollkosten je FTE | B32: CHF/Jahr | C32: 110000 | I32: 110000 | O32: 110000 | U32: Lohn ~CHF 90k + Sozialabgaben/BVG ~18 %. Mischwert Entwicklung, Vertrieb, Inhalte.
A33: Inhalte je neuer Beruf (Fachprüfung, Bilder) | B33: CHF | C33: 4000 | D33: 15000 | E33: 20000 | F33: 20000 | G33: 20000 | I33: 4000 | J33: 15000 | K33: 18000 | L33: 18000 | M33: 18000 | O33: 4000 | P33: 15000 | Q33: 18000 | R33: 18000 | S33: 18000 | U33: 2027: KI-Entwurf durch Gründer, Fachperson prüft ~50 h à CHF 80. Später ~180 h plus Grafiken.
A34: Inhaltspflege je Beruf live | B34: CHF/Jahr | C34: 4000 | I34: 4000 | O34: 4000 | U34: Ab dem Jahr nach dem Start: Durchsicht, Korrekturen, Änderungen im Bildungsplan.
A35: Technik fix (Werkzeuge, Monitoring, App-Stores) | B35: CHF/Jahr | C35: 600 | D35: 2400 | E35: 6000 | F35: 10000 | G35: 15000 | I35: 600 | J35: 3000 | K35: 8000 | L35: 15000 | M35: 25000 | O35: 800 | P35: 5000 | Q35: 15000 | R35: 30000 | S35: 50000 | U35: Annahme.
A36: Marketing fix (Messen, Material, Inhalte Social Media) | B36: CHF/Jahr | C36: 300 | D36: 3000 | E36: 10000 | F36: 20000 | G36: 30000 | I36: 500 | J36: 8000 | K36: 20000 | L36: 40000 | M36: 60000 | O36: 800 | P36: 15000 | Q36: 40000 | R36: 70000 | S36: 100000 | U36: Annahme.
A37: Administration (Treuhand, Versicherung, Recht, Datenschutzprüfung) | B37: CHF/Jahr | C37: 1200 | D37: 5000 | E37: 10000 | F37: 20000 | G37: 30000 | I37: 1500 | J37: 6000 | K37: 15000 | L37: 30000 | M37: 50000 | O37: 1500 | P37: 10000 | Q37: 25000 | R37: 50000 | S37: 80000 | U37: 2027: Einzelfirma, Versicherung, einmalige Rechtsprüfung AGB/Datenschutz (Offerte einholen).
A38: Eigenmittel zu Beginn | B38: CHF | C38: 1000 | I38: 1000 | O38: 1000 | U38: Vorgabe: CHF 100–1'000.

Sheet Modell Vorsichtig
A1: bestanden – Modell · Szenario Vorsichtig
A2: Berechnet aus «Annahmen». Nicht von Hand ändern.
A4: Mengen | C4: 2027 | D4: 2028 | E4: 2029 | F4: 2030 | G4: 2031
A5: Lernende in abgedeckten Berufen | C5: =Annahmen!$C$7 | D5: =Annahmen!$D$7 | E5: =Annahmen!$E$7 | F5: =Annahmen!$F$7 | G5: =Annahmen!$G$7
A6: QV-Kandidaten pro Jahr | C6: =C5*Annahmen!$C$9 | D6: =D5*Annahmen!$C$9 | E6: =E5*Annahmen!$C$9 | F6: =F5*Annahmen!$C$9 | G6: =G5*Annahmen!$C$9
A7: Lernende mit Betriebslizenz | C7: =C5*Annahmen!$C$11 | D7: =D5*Annahmen!$D$11 | E7: =E5*Annahmen!$E$11 | F7: =F5*Annahmen!$F$11 | G7: =G5*Annahmen!$G$11
A8: Lehrbetriebe mit Lizenz | C8: =C7/Annahmen!$C$12 | D8: =D7/Annahmen!$C$12 | E8: =E7/Annahmen!$C$12 | F8: =F7/Annahmen!$C$12 | G8: =G7/Annahmen!$C$12
A9: davon neu gewonnen | C9: =C8 | D9: =MAX(0,D8-C8*(1-Annahmen!$C$13)) | E9: =MAX(0,E8-D8*(1-Annahmen!$C$13)) | F9: =MAX(0,F8-E8*(1-Annahmen!$C$13)) | G9: =MAX(0,G8-F8*(1-Annahmen!$C$13))
A10: QV-Kandidaten ohne Betriebslizenz | C10: =C6*(1-Annahmen!$C$11) | D10: =D6*(1-Annahmen!$D$11) | E10: =E6*(1-Annahmen!$E$11) | F10: =F6*(1-Annahmen!$F$11) | G10: =G6*(1-Annahmen!$G$11)
A11: B2C-Käufer/innen QV-Pass | C11: =C10*Annahmen!$C$17 | D11: =D10*Annahmen!$D$17 | E11: =E10*Annahmen!$E$17 | F11: =F10*Annahmen!$F$17 | G11: =G10*Annahmen!$G$17
A12: Verbandslizenzen | C12: =Annahmen!$C$22 | D12: =Annahmen!$D$22 | E12: =Annahmen!$E$22 | F12: =Annahmen!$F$22 | G12: =Annahmen!$G$22
A13: Aktive Nutzer/innen (bezahlt) | C13: =C7*Annahmen!$C$25+C11 | D13: =D7*Annahmen!$C$25+D11 | E13: =E7*Annahmen!$C$25+E11 | F13: =F7*Annahmen!$C$25+F11 | G13: =G7*Annahmen!$C$25+G11
A14: Umsatz | C14: 2027 | D14: 2028 | E14: 2029 | F14: 2030 | G14: 2031
A15: Betriebslizenzen (B2B) | C15: =C7*Annahmen!$C$14 | D15: =D7*Annahmen!$D$14 | E15: =E7*Annahmen!$E$14 | F15: =F7*Annahmen!$F$14 | G15: =G7*Annahmen!$G$14
A16: QV-Pass (B2C) | C16: =C11*Annahmen!$C$18 | D16: =D11*Annahmen!$C$18 | E16: =E11*Annahmen!$C$18 | F16: =F11*Annahmen!$C$18 | G16: =G11*Annahmen!$C$18
A17: Verbandslizenzen (B2B2C) | C17: =C12*Annahmen!$C$23 | D17: =D12*Annahmen!$C$23 | E17: =E12*Annahmen!$C$23 | F17: =F12*Annahmen!$C$23 | G17: =G12*Annahmen!$C$23
A18: Umsatz total | C18: =C15+C16+C17 | D18: =D15+D16+D17 | E18: =E15+E16+E17 | F18: =F15+F16+F17 | G18: =G15+G16+G17
A19: Anteil B2B inkl. Verbände | C19: =IF(C18=0,0,(C15+C17)/C18) | D19: =IF(D18=0,0,(D15+D17)/D18) | E19: =IF(E18=0,0,(E15+E17)/E18) | F19: =IF(F18=0,0,(F15+F17)/F18) | G19: =IF(G18=0,0,(G15+G17)/G18)
A20: Variable Kosten und Deckungsbeitrag | C20: 2027 | D20: 2028 | E20: 2029 | F20: 2030 | G20: 2031
A21: Zahlungsgebühren | C21: =C16*Annahmen!$C$28+(C15+C17)*Annahmen!$C$29 | D21: =D16*Annahmen!$C$28+(D15+D17)*Annahmen!$C$29 | E21: =E16*Annahmen!$C$28+(E15+E17)*Annahmen!$C$29 | F21: =F16*Annahmen!$C$28+(F15+F17)*Annahmen!$C$29 | G21: =G16*Annahmen!$C$28+(G15+G17)*Annahmen!$C$29
A22: KI-Kosten | C22: =C13*Annahmen!$C$26 | D22: =D13*Annahmen!$C$26 | E22: =E13*Annahmen!$C$26 | F22: =F13*Annahmen!$C$26 | G22: =G13*Annahmen!$C$26
A23: Hosting variabel | C23: =C13*Annahmen!$C$27 | D23: =D13*Annahmen!$C$27 | E23: =E13*Annahmen!$C$27 | F23: =F13*Annahmen!$C$27 | G23: =G13*Annahmen!$C$27
A24: Variable Kosten total | C24: =C21+C22+C23 | D24: =D21+D22+D23 | E24: =E21+E22+E23 | F24: =F21+F22+F23 | G24: =G21+G22+G23
A25: Deckungsbeitrag | C25: =C18-C24 | D25: =D18-D24 | E25: =E18-E24 | F25: =F18-F24 | G25: =G18-G24
A26: Deckungsbeitrag in % des Umsatzes | C26: =IF(C18=0,0,C25/C18) | D26: =IF(D18=0,0,D25/D18) | E26: =IF(E18=0,0,E25/E18) | F26: =IF(F18=0,0,F25/F18) | G26: =IF(G18=0,0,G25/G18)
A27: Fixkosten | C27: 2027 | D27: 2028 | E27: 2029 | F27: 2030 | G27: 2031
A28: Personal | C28: =Annahmen!$C$31*Annahmen!$C$32 | D28: =Annahmen!$D$31*Annahmen!$C$32 | E28: =Annahmen!$E$31*Annahmen!$C$32 | F28: =Annahmen!$F$31*Annahmen!$C$32 | G28: =Annahmen!$G$31*Annahmen!$C$32
A29: Inhalte (neue Berufe + Pflege) | C29: =Annahmen!$C$8*Annahmen!$C$33 | D29: =MAX(0,Annahmen!$D$8-Annahmen!$C$8)*Annahmen!$D$33+Annahmen!$C$8*Annahmen!$C$34 | E29: =MAX(0,Annahmen!$E$8-Annahmen!$D$8)*Annahmen!$E$33+Annahmen!$D$8*Annahmen!$C$34 | F29: =MAX(0,Annahmen!$F$8-Annahmen!$E$8)*Annahmen!$F$33+Annahmen!$E$8*Annahmen!$C$34 | G29: =MAX(0,Annahmen!$G$8-Annahmen!$F$8)*Annahmen!$G$33+Annahmen!$F$8*Annahmen!$C$34
A30: Technologie fix | C30: =Annahmen!$C$35 | D30: =Annahmen!$D$35 | E30: =Annahmen!$E$35 | F30: =Annahmen!$F$35 | G30: =Annahmen!$G$35
A31: Marketing und Vertrieb | C31: =C11*(1-Annahmen!$C$20)*Annahmen!$C$19+C9*Annahmen!$C$15+Annahmen!$C$36 | D31: =D11*(1-Annahmen!$C$20)*Annahmen!$C$19+D9*Annahmen!$D$15+Annahmen!$D$36 | E31: =E11*(1-Annahmen!$C$20)*Annahmen!$C$19+E9*Annahmen!$E$15+Annahmen!$E$36 | F31: =F11*(1-Annahmen!$C$20)*Annahmen!$C$19+F9*Annahmen!$F$15+Annahmen!$F$36 | G31: =G11*(1-Annahmen!$C$20)*Annahmen!$C$19+G9*Annahmen!$G$15+Annahmen!$G$36
A32: Administration | C32: =Annahmen!$C$37 | D32: =Annahmen!$D$37 | E32: =Annahmen!$E$37 | F32: =Annahmen!$F$37 | G32: =Annahmen!$G$37
A33: Fixkosten total | C33: =C28+C29+C30+C31+C32 | D33: =D28+D29+D30+D31+D32 | E33: =E28+E29+E30+E31+E32 | F33: =F28+F29+F30+F31+F32 | G33: =G28+G29+G30+G31+G32
A34: Operatives Ergebnis | C34: =C25-C33 | D34: =D25-D33 | E34: =E25-E33 | F34: =F25-F33 | G34: =G25-G33
A35: Operative Marge | C35: =IF(C18=0,0,C34/C18) | D35: =IF(D18=0,0,D34/D18) | E35: =IF(E18=0,0,E34/E18) | F35: =IF(F18=0,0,F34/F18) | G35: =IF(G18=0,0,G34/G18)
A36: Kasse (ohne Steuern, ohne Fremdkapital) | C36: 2027 | D36: 2028 | E36: 2029 | F36: 2030 | G36: 2031
A37: Kasse Ende Jahr | C37: =Annahmen!$C$38+C34 | D37: =C37+D34 | E37: =D37+E34 | F37: =E37+F34 | G37: =F37+G34
A38: Finanzierungsbedarf bis hier (tiefster Kassenstand) | C38: =MAX(0,-C37) | D38: =MAX(C38,-D37) | E38: =MAX(D38,-E37) | F38: =MAX(E38,-F37) | G38: =MAX(F38,-G37)
A39: Kennzahlen | C39: 2027 | D39: 2028 | E39: 2029 | F39: 2030 | G39: 2031
A40: Marktanteil an allen Lernenden CH (Betriebslizenz) | C40: =C7/215052 | D40: =D7/215052 | E40: =E7/215052 | F40: =F7/215052 | G40: =G7/215052
A41: LTV je Lehrbetrieb (Deckungsbeitrag über Lebensdauer) | C41: =Annahmen!$C$12*Annahmen!$C$14*(1-Annahmen!$C$29)/Annahmen!$C$13-Annahmen!$C$12*Annahmen!$C$25*(Annahmen!$C$26+Annahmen!$C$27)/Annahmen!$C$13 | D41: =Annahmen!$C$12*Annahmen!$D$14*(1-Annahmen!$C$29)/Annahmen!$C$13-Annahmen!$C$12*Annahmen!$C$25*(Annahmen!$C$26+Annahmen!$C$27)/Annahmen!$C$13 | E41: =Annahmen!$C$12*Annahmen!$E$14*(1-Annahmen!$C$29)/Annahmen!$C$13-Annahmen!$C$12*Annahmen!$C$25*(Annahmen!$C$26+Annahmen!$C$27)/Annahmen!$C$13 | F41: =Annahmen!$C$12*Annahmen!$F$14*(1-Annahmen!$C$29)/Annahmen!$C$13-Annahmen!$C$12*Annahmen!$C$25*(Annahmen!$C$26+Annahmen!$C$27)/Annahmen!$C$13 | G41: =Annahmen!$C$12*Annahmen!$G$14*(1-Annahmen!$C$29)/Annahmen!$C$13-Annahmen!$C$12*Annahmen!$C$25*(Annahmen!$C$26+Annahmen!$C$27)/Annahmen!$C$13
...

Sheet Modell Basis
A1: bestanden – Modell · Szenario Basis
A2: Berechnet aus «Annahmen». Nicht von Hand ändern.
A4: Mengen | C4: 2027 | D4: 2028 | E4: 2029 | F4: 2030 | G4: 2031
A5: Lernende in abgedeckten Berufen | C5: =Annahmen!$I$7 | D5: =Annahmen!$J$7 | E5: =Annahmen!$K$7 | F5: =Annahmen!$L$7 | G5: =Annahmen!$M$7
A6: QV-Kandidaten pro Jahr | C6: =C5*Annahmen!$I$9 | D6: =D5*Annahmen!$I$9 | E6: =E5*Annahmen!$I$9 | F6: =F5*Annahmen!$I$9 | G6: =G5*Annahmen!$I$9
A7: Lernende mit Betriebslizenz | C7: =C5*Annahmen!$I$11 | D7: =D5*Annahmen!$J$11 | E7: =E5*Annahmen!$K$11 | F7: =F5*Annahmen!$L$11 | G7: =G5*Annahmen!$M$11
A8: Lehrbetriebe mit Lizenz | C8: =C7/Annahmen!$I$12 | D8: =D7/Annahmen!$I$12 | E8: =E7/Annahmen!$I$12 | F8: =F7/Annahmen!$I$12 | G8: =G7/Annahmen!$I$12
A9: davon neu gewonnen | C9: =C8 | D9: =MAX(0,D8-C8*(1-Annahmen!$I$13)) | E9: =MAX(0,E8-D8*(1-Annahmen!$I$13)) | F9: =MAX(0,F8-E8*(1-Annahmen!$I$13)) | G9: =MAX(0,G8-F8*(1-Annahmen!$I$13))
A10: QV-Kandidaten ohne Betriebslizenz | C10: =C6*(1-Annahmen!$I$11) | D10: =D6*(1-Annahmen!$J$11) | E10: =E6*(1-Annahmen!$K$11) | F10: =F6*(1-Annahmen!$L$11) | G10: =G6*(1-Annahmen!$M$11)
A11: B2C-Käufer/innen QV-Pass | C11: =C10*Annahmen!$I$17 | D11: =D10*Annahmen!$J$17 | E11: =E10*Annahmen!$K$17 | F11: =F10*Annahmen!$L$17 | G11: =G10*Annahmen!$M$17
A12: Verbandslizenzen | C12: =Annahmen!$I$22 | D12: =Annahmen!$J$22 | E12: =Annahmen!$K$22 | F12: =Annahmen!$L$22 | G12: =Annahmen!$M$22
A13: Aktive Nutzer/innen (bezahlt) | C13: =C7*Annahmen!$I$25+C11 | D13: =D7*Annahmen!$I$25+D11 | E13: =E7*Annahmen!$I$25+E11 | F13: =F7*Annahmen!$I$25+F11 | G13: =G7*Annahmen!$I$25+G11
A14: Umsatz | C14: 2027 | D14: 2028 | E14: 2029 | F14: 2030 | G14: 2031
A15: Betriebslizenzen (B2B) | C15: =C7*Annahmen!$I$14 | D15: =D7*Annahmen!$J$14 | E15: =E7*Annahmen!$K$14 | F15: =F7*Annahmen!$L$14 | G15: =G7*Annahmen!$M$14
A16: QV-Pass (B2C) | C16: =C11*Annahmen!$I$18 | D16: =D11*Annahmen!$I$18 | E16: =E11*Annahmen!$I$18 | F16: =F11*Annahmen!$I$18 | G16: =G11*Annahmen!$I$18
A17: Verbandslizenzen (B2B2C) | C17: =C12*Annahmen!$I$23 | D17: =D12*Annahmen!$I$23 | E17: =E12*Annahmen!$I$23 | F17: =F12*Annahmen!$I$23 | G17: =G12*Annahmen!$I$23
A18: Umsatz total | C18: =C15+C16+C17 | D18: =D15+D16+D17 | E18: =E15+E16+E17 | F18: =F15+F16+F17 | G18: =G15+G16+G17
A19: Anteil B2B inkl. Verbände | C19: =IF(C18=0,0,(C15+C17)/C18) | D19: =IF(D18=0,0,(D15+D17)/D18) | E19: =IF(E18=0,0,(E15+E17)/E18) | F19: =IF(F18=0,0,(F15+F17)/F18) | G19: =IF(G18=0,0,(G15+G17)/G18)
A20: Variable Kosten und Deckungsbeitrag | C20: 2027 | D20: 2028 | E20: 2029 | F20: 2030 | G20: 2031
A21: Zahlungsgebühren | C21: =C16*Annahmen!$I$28+(C15+C17)*Annahmen!$I$29 | D21: =D16*Annahmen!$I$28+(D15+D17)*Annahmen!$I$29 | E21: =E16*Annahmen!$I$28+(E15+E17)*Annahmen!$I$29 | F21: =F16*Annahmen!$I$28+(F15+F17)*Annahmen!$I$29 | G21: =G16*Annahmen!$I$28+(G15+G17)*Annahmen!$I$29
A22: KI-Kosten | C22: =C13*Annahmen!$I$26 | D22: =D13*Annahmen!$I$26 | E22: =E13*Annahmen!$I$26 | F22: =F13*Annahmen!$I$26 | G22: =G13*Annahmen!$I$26
A23: Hosting variabel | C23: =C13*Annahmen!$I$27 | D23: =D13*Annahmen!$I$27 | E23: =E13*Annahmen!$I$27 | F23: =F13*Annahmen!$I$27 | G23: =G13*Annahmen!$I$27
A24: Variable Kosten total | C24: =C21+C22+C23 | D24: =D21+D22+D23 | E24: =E21+E22+E23 | F24: =F21+F22+F23 | G24: =G21+G22+G23
A25: Deckungsbeitrag | C25: =C18-C24 | D25: =D18-D24 | E25: =E18-E24 | F25: =F18-F24 | G25: =G18-G24
A26: Deckungsbeitrag in % des Umsatzes | C26: =IF(C18=0,0,C25/C18) | D26: =IF(D18=0,0,D25/D18) | E26: =IF(E18=0,0,E25/E18) | F26: =IF(F18=0,0,F25/F18) | G26: =IF(G18=0,0,G25/G18)
A27: Fixkosten | C27: 2027 | D27: 2028 | E27: 2029 | F27: 2030 | G27: 2031
A28: Personal | C28: =Annahmen!$I$31*Annahmen!$I$32 | D28: =Annahmen!$J$31*Annahmen!$I$32 | E28: =Annahmen!$K$31*Annahmen!$I$32 | F28: =Annahmen!$L$31*Annahmen!$I$32 | G28: =Annahmen!$M$31*Annahmen!$I$32
A29: Inhalte (neue Berufe + Pflege) | C29: =Annahmen!$I$8*Annahmen!$I$33 | D29: =MAX(0,Annahmen!$J$8-Annahmen!$I$8)*Annahmen!$J$33+Annahmen!$I$8*Annahmen!$I$34 | E29: =MAX(0,Annahmen!$K$8-Annahmen!$J$8)*Annahmen!$K$33+Annahmen!$J$8*Annahmen!$I$34 | F29: =MAX(0,Annahmen!$L$8-Annahmen!$K$8)*Annahmen!$L$33+Annahmen!$K$8*Annahmen!$I$34 | G29: =MAX(0,Annahmen!$M$8-Annahmen!$L$8)*Annahmen!$M$33+Annahmen!$L$8*Annahmen!$I$34
A30: Technologie fix | C30: =Annahmen!$I$35 | D30: =Annahmen!$J$35 | E30: =Annahmen!$K$35 | F30: =Annahmen!$L$35 | G30: =Annahmen!$M$35
A31: Marketing und Vertrieb | C31: =C11*(1-Annahmen!$I$20)*Annahmen!$I$19+C9*Annahmen!$I$15+Annahmen!$I$36 | D31: =D11*(1-Annahmen!$I$20)*Annahmen!$I$19+D9*Annahmen!$J$15+Annahmen!$J$36 | E31: =E11*(1-Annahmen!$I$20)*Annahmen!$I$19+E9*Annahmen!$K$15+Annahmen!$K$36 | F31: =F11*(1-Annahmen!$I$20)*Annahmen!$I$19+F9*Annahmen!$L$15+Annahmen!$L$36 | G31: =G11*(1-Annahmen!$I$20)*Annahmen!$I$19+G9*Annahmen!$M$15+Annahmen!$M$36
A32: Administration | C32: =Annahmen!$I$37 | D32: =Annahmen!$J$37 | E32: =Annahmen!$K$37 | F32: =Annahmen!$L$37 | G32: =Annahmen!$M$37
A33: Fixkosten total | C33: =C28+C29+C30+C31+C32 | D33: =D28+D29+D30+D31+D32 | E33: =E28+E29+E30+E31+E32 | F33: =F28+F29+F30+F31+F32 | G33: =G28+G29+G30+G31+G32
A34: Operatives Ergebnis | C34: =C25-C33 | D34: =D25-D33 | E34: =E25-E33 | F34: =F25-F33 | G34: =G25-G33
A35: Operative Marge | C35: =IF(C18=0,0,C34/C18) | D35: =IF(D18=0,0,D34/D18) | E35: =IF(E18=0,0,E34/E18) | F35: =IF(F18=0,0,F34/F18) | G35: =IF(G18=0,0,G34/G18)
A36: Kasse (ohne Steuern, ohne Fremdkapital) | C36: 2027 | D36: 2028 | E36: 2029 | F36: 2030 | G36: 2031
A37: Kasse Ende Jahr | C37: =Annahmen!$I$38+C34 | D37: =C37+D34 | E37: =D37+E34 | F37: =E37+F34 | G37: =F37+G34
A38: Finanzierungsbedarf bis hier (tiefster Kassenstand) | C38: =MAX(0,-C37) | D38: =MAX(C38,-D37) | E38: =MAX(D38,-E37) | F38: =MAX(E38,-F37) | G38: =MAX(F38,-G37)
A39: Kennzahlen | C39: 2027 | D39: 2028 | E39: 2029 | F39: 2030 | G39: 2031
A40: Marktanteil an allen Lernenden CH (Betriebslizenz) | C40: =C7/215052 | D40: =D7/215052 | E40: =E7/215052 | F40: =F7/215052 | G40: =G7/215052
A41: LTV je Lehrbetrieb (Deckungsbeitrag über Lebensdauer) | C41: =Annahmen!$I$12*Annahmen!$I$14*(1-Annahmen!$I$29)/Annahmen!$I$13-Annahmen!$I$12*Annahmen!$I$25*(Annahmen!$I$26+Annahmen!$I$27)/Annahmen!$I$13 | D41: =Annahmen!$I$12*Annahmen!$J$14*(1-Annahmen!$I$29)/Annahmen!$I$13-Annahmen!$I$12*Annahmen!$I$25*(Annahmen!$I$26+Annahmen!$I$27)/Annahmen!$I$13 | E41: =Annahmen!$I$12*Annahmen!$K$14*(1-Annahmen!$I$29)/Annahmen!$I$13-Annahmen!$I$12*Annahmen!$I$25*(Annahmen!$I$26+Annahmen!$I$27)/Annahmen!$I$13 | F41: =Annahmen!$I$12*Annahmen!$L$14*(1-Annahmen!$I$29)/Annahmen!$I$13-Annahmen!$I$12*Annahmen!$I$25*(Annahmen!$I$26+Annahmen!$I$27)/Annahmen!$I$13 | G41: =Annahmen!$I$12*Annahmen!$M$14*(1-Annahmen!$I$29)/Annahmen!$I$13-Annahmen!$I$12*Annahmen!$I$25*(Annahmen!$I$26+Annahmen!$I$27)/Annahmen!$I$13
...

Sheet Modell Wachstum
A1: bestanden – Modell · Szenario Wachstum
A2: Berechnet aus «Annahmen». Nicht von Hand ändern.
A4: Mengen | C4: 2027 | D4: 2028 | E4: 2029 | F4: 2030 | G4: 2031
A5: Lernende in abgedeckten Berufen | C5: =Annahmen!$O$7 | D5: =Annahmen!$P$7 | E5: =Annahmen!$Q$7 | F5: =Annahmen!$R$7 | G5: =Annahmen!$S$7
A6: QV-Kandidaten pro Jahr | C6: =C5*Annahmen!$O$9 | D6: =D5*Annahmen!$O$9 | E6: =E5*Annahmen!$O$9 | F6: =F5*Annahmen!$O$9 | G6: =G5*Annahmen!$O$9
A7: Lernende mit Betriebslizenz | C7: =C5*Annahmen!$O$11 | D7: =D5*Annahmen!$P$11 | E7: =E5*Annahmen!$Q$11 | F7: =F5*Annahmen!$R$11 | G7: =G5*Annahmen!$S$11
A8: Lehrbetriebe mit Lizenz | C8: =C7/Annahmen!$O$12 | D8: =D7/Annahmen!$O$12 | E8: =E7/Annahmen!$O$12 | F8: =F7/Annahmen!$O$12 | G8: =G7/Annahmen!$O$12
A9: davon neu gewonnen | C9: =C8 | D9: =MAX(0,D8-C8*(1-Annahmen!$O$13)) | E9: =MAX(0,E8-D8*(1-Annahmen!$O$13)) | F9: =MAX(0,F8-E8*(1-Annahmen!$O$13)) | G9: =MAX(0,G8-F8*(1-Annahmen!$O$13))
A10: QV-Kandidaten ohne Betriebslizenz | C10: =C6*(1-Annahmen!$O$11) | D10: =D6*(1-Annahmen!$P$11) | E10: =E6*(1-Annahmen!$Q$11) | F10: =F6*(1-Annahmen!$R$11) | G10: =G6*(1-Annahmen!$S$11)
A11: B2C-Käufer/innen QV-Pass | C11: =C10*Annahmen!$O$17 | D11: =D10*Annahmen!$P$17 | E11: =E10*Annahmen!$Q$17 | F11: =F10*Annahmen!$R$17 | G11: =G10*Annahmen!$S$17
A12: Verbandslizenzen | C12: =Annahmen!$O$22 | D12: =Annahmen!$P$22 | E12: =Annahmen!$Q$22 | F12: =Annahmen!$R$22 | G12: =Annahmen!$S$22
A13: Aktive Nutzer/innen (bezahlt) | C13: =C7*Annahmen!$O$25+C11 | D13: =D7*Annahmen!$O$25+D11 | E13: =E7*Annahmen!$O$25+E11 | F13: =F7*Annahmen!$O$25+F11 | G13: =G7*Annahmen!$O$25+G11
A14: Umsatz | C14: 2027 | D14: 2028 | E14: 2029 | F14: 2030 | G14: 2031
A15: Betriebslizenzen (B2B) | C15: =C7*Annahmen!$O$14 | D15: =D7*Annahmen!$P$14 | E15: =E7*Annahmen!$Q$14 | F15: =F7*Annahmen!$R$14 | G15: =G7*Annahmen!$S$14
A16: QV-Pass (B2C) | C16: =C11*Annahmen!$O$18 | D16: =D11*Annahmen!$O$18 | E16: =E11*Annahmen!$O$18 | F16: =F11*Annahmen!$O$18 | G16: =G11*Annahmen!$O$18
A17: Verbandslizenzen (B2B2C) | C17: =C12*Annahmen!$O$23 | D17: =D12*Annahmen!$O$23 | E17: =E12*Annahmen!$O$23 | F17: =F12*Annahmen!$O$23 | G17: =G12*Annahmen!$O$23
A18: Umsatz total | C18: =C15+C16+C17 | D18: =D15+D16+D17 | E18: =E15+E16+E17 | F18: =F15+F16+F17 | G18: =G15+G16+G17
A19: Anteil B2B inkl. Verbände | C19: =IF(C18=0,0,(C15+C17)/C18) | D19: =IF(D18=0,0,(D15+D17)/D18) | E19: =IF(E18=0,0,(E15+E17)/E18) | F19: =IF(F18=0,0,(F15+F17)/F18) | G19: =IF(G18=0,0,(G15+G17)/G18)
A20: Variable Kosten und Deckungsbeitrag | C20: 2027 | D20: 2028 | E20: 2029 | F20: 2030 | G20: 2031
A21: Zahlungsgebühren | C21: =C16*Annahmen!$O$28+(C15+C17)*Annahmen!$O$29 | D21: =D16*Annahmen!$O$28+(D15+D17)*Annahmen!$O$29 | E21: =E16*Annahmen!$O$28+(E15+E17)*Annahmen!$O$29 | F21: =F16*Annahmen!$O$28+(F15+F17)*Annahmen!$O$29 | G21: =G16*Annahmen!$O$28+(G15+G17)*Annahmen!$O$29
A22: KI-Kosten | C22: =C13*Annahmen!$O$26 | D22: =D13*Annahmen!$O$26 | E22: =E13*Annahmen!$O$26 | F22: =F13*Annahmen!$O$26 | G22: =G13*Annahmen!$O$26
A23: Hosting variabel | C23: =C13*Annahmen!$O$27 | D23: =D13*Annahmen!$O$27 | E23: =E13*Annahmen!$O$27 | F23: =F13*Annahmen!$O$27 | G23: =G13*Annahmen!$O$27
A24: Variable Kosten total | C24: =C21+C22+C23 | D24: =D21+D22+D23 | E24: =E21+E22+E23 | F24: =F21+F22+F23 | G24: =G21+G22+G23
A25: Deckungsbeitrag | C25: =C18-C24 | D25: =D18-D24 | E25: =E18-E24 | F25: =F18-F24 | G25: =G18-G24
A26: Deckungsbeitrag in % des Umsatzes | C26: =IF(C18=0,0,C25/C18) | D26: =IF(D18=0,0,D25/D18) | E26: =IF(E18=0,0,E25/E18) | F26: =IF(F18=0,0,F25/F18) | G26: =IF(G18=0,0,G25/G18)
A27: Fixkosten | C27: 2027 | D27: 2028 | E27: 2029 | F27: 2030 | G27: 2031
A28: Personal | C28: =Annahmen!$O$31*Annahmen!$O$32 | D28: =Annahmen!$P$31*Annahmen!$O$32 | E28: =Annahmen!$Q$31*Annahmen!$O$32 | F28: =Annahmen!$R$31*Annahmen!$O$32 | G28: =Annahmen!$S$31*Annahmen!$O$32
A29: Inhalte (neue Berufe + Pflege) | C29: =Annahmen!$O$8*Annahmen!$O$33 | D29: =MAX(0,Annahmen!$P$8-Annahmen!$O$8)*Annahmen!$P$33+Annahmen!$O$8*Annahmen!$O$34 | E29: =MAX(0,Annahmen!$Q$8-Annahmen!$P$8)*Annahmen!$Q$33+Annahmen!$P$8*Annahmen!$O$34 | F29: =MAX(0,Annahmen!$R$8-Annahmen!$Q$8)*Annahmen!$R$33+Annahmen!$Q$8*Annahmen!$O$34 | G29: =MAX(0,Annahmen!$S$8-Annahmen!$R$8)*Annahmen!$S$33+Annahmen!$R$8*Annahmen!$O$34
A30: Technologie fix | C30: =Annahmen!$O$35 | D30: =Annahmen!$P$35 | E30: =Annahmen!$Q$35 | F30: =Annahmen!$R$35 | G30: =Annahmen!$S$35
A31: Marketing und Vertrieb | C31: =C11*(1-Annahmen!$O$20)*Annahmen!$O$19+C9*Annahmen!$O$15+Annahmen!$O$36 | D31: =D11*(1-Annahmen!$O$20)*Annahmen!$O$19+D9*Annahmen!$P$15+Annahmen!$P$36 | E31: =E11*(1-Annahmen!$O$20)*Annahmen!$O$19+E9*Annahmen!$Q$15+Annahmen!$Q$36 | F31: =F11*(1-Annahmen!$O$20)*Annahmen!$O$19+F9*Annahmen!$R$15+Annahmen!$R$36 | G31: =G11*(1-Annahmen!$O$20)*Annahmen!$O$19+G9*Annahmen!$S$15+Annahmen!$S$36
A32: Administration | C32: =Annahmen!$O$37 | D32: =Annahmen!$P$37 | E32: =Annahmen!$Q$37 | F32: =Annahmen!$R$37 | G32: =Annahmen!$S$37
A33: Fixkosten total | C33: =C28+C29+C30+C31+C32 | D33: =D28+D29+D30+D31+D32 | E33: =E28+E29+E30+E31+E32 | F33: =F28+F29+F30+F31+F32 | G33: =G28+G29+G30+G31+G32
A34: Operatives Ergebnis | C34: =C25-C33 | D34: =D25-D33 | E34: =E25-E33 | F34: =F25-F33 | G34: =G25-G33
A35: Operative Marge | C35: =IF(C18=0,0,C34/C18) | D35: =IF(D18=0,0,D34/D18) | E35: =IF(E18=0,0,E34/E18) | F35: =IF(F18=0,0,F34/F18) | G35: =IF(G18=0,0,G34/G18)
A36: Kasse (ohne Steuern, ohne Fremdkapital) | C36: 2027 | D36: 2028 | E36: 2029 | F36: 2030 | G36: 2031
A37: Kasse Ende Jahr | C37: =Annahmen!$O$38+C34 | D37: =C37+D34 | E37: =D37+E34 | F37: =E37+F34 | G37: =F37+G34
A38: Finanzierungsbedarf bis hier (tiefster Kassenstand) | C38: =MAX(0,-C37) | D38: =MAX(C38,-D37) | E38: =MAX(D38,-E37) | F38: =MAX(E38,-F37) | G38: =MAX(F38,-G37)
A39: Kennzahlen | C39: 2027 | D39: 2028 | E39: 2029 | F39: 2030 | G39: 2031
A40: Marktanteil an allen Lernenden CH (Betriebslizenz) | C40: =C7/215052 | D40: =D7/215052 | E40: =E7/215052 | F40: =F7/215052 | G40: =G7/215052
A41: LTV je Lehrbetrieb (Deckungsbeitrag über Lebensdauer) | C41: =Annahmen!$O$12*Annahmen!$O$14*(1-Annahmen!$O$29)/Annahmen!$O$13-Annahmen!$O$12*Annahmen!$O$25*(Annahmen!$O$26+Annahmen!$O$27)/Annahmen!$O$13 | D41: =Annahmen!$O$12*Annahmen!$P$14*(1-Annahmen!$O$29)/Annahmen!$O$13-Annahmen!$O$12*Annahmen!$O$25*(Annahmen!$O$26+Annahmen!$O$27)/Annahmen!$O$13 | E41: =Annahmen!$O$12*Annahmen!$Q$14*(1-Annahmen!$O$29)/Annahmen!$O$13-Annahmen!$O$12*Annahmen!$O$25*(Annahmen!$O$26+Annahmen!$O$27)/Annahmen!$O$13 | F41: =Annahmen!$O$12*Annahmen!$R$14*(1-Annahmen!$O$29)/Annahmen!$O$13-Annahmen!$O$12*Annahmen!$O$25*(Annahmen!$O$26+Annahmen!$O$27)/Annahmen!$O$13 | G41: =Annahmen!$O$12*Annahmen!$S$14*(1-Annahmen!$O$29)/Annahmen!$O$13-Annahmen!$O$12*Annahmen!$O$25*(Annahmen!$O$26+Annahmen!$O$27)/Annahmen!$O$13
...

Sheet Zielrechnung CHF 7–10 Mio.
A1: Was braucht es für CHF 7,5 Mio. oder CHF 10 Mio. Umsatz – nur Schweiz?
B3: CHF 7,5 Mio. | C3: CHF 10 Mio.
A4: Umsatzziel | B4: 7500000 | C4: 10000000
A5: Lernende in der Schweiz (alle Berufe) | B5: 215052 | C5: 215052 | D5: BFS, Lehrverhältnisse 2025
A6: QV-Kandidaten pro Jahr (alle Berufe) | B6: 70000 | C6: 70000 | D6: EHB Trendbericht 6, 2024
A7: Ø Preis Betriebslizenz je Lernende/r und Jahr | B7: 110 | C7: 110
A8: Preis QV-Pass | B8: 59 | C8: 59
A10: Nur Betriebslizenzen: nötige lizenzierte Lernende | B10: =B4/B7 | C10: =C4/C7
A11: … in % aller Lernenden der Schweiz | B11: =B10/B5 | C11: =C10/C5
A12: Nur QV-Pass: nötige Käufer/innen pro Jahr | B12: =B4/B8 | C12: =C4/C8
A13: … in % aller QV-Kandidaten (über 100 % = unmöglich) | B13: =B12/B6 | C13: =C12/C6
A15: Obere plausible Grenze mit heutigem Modell (Annahmen blau, Hypothesen)
A16: Anteil aller Lernenden mit Betriebslizenz | B16: 0.25 | C16: 0.25 | D16: Hypothese: jede/r vierte Lernende der Schweiz
A17: Kaufquote QV-Pass unter den übrigen Kandidaten | B17: 0.08 | C17: 0.08 | D17: Hypothese
A18: Verbandslizenzen × CHF 40'000 | B18: 20 | C18: 20 | D18: Hypothese: 20 Verbände
A19: Umsatz Betriebslizenzen | B19: =B5*B16*B7 | C19: =C5*C16*C7
A20: Umsatz QV-Pass | B20: =B6*(1-B16)*B17*B8 | C20: =C6*(1-C16)*C17*C8
A21: Umsatz Verbände | B21: =B18*40000 | C21: =C18*40000
A22: Umsatz total bei oberer Grenze | B22: =B19+B20+B21 | C22: =C19+C20+C21
A23: Lücke zum Ziel (muss aus neuen Segmenten kommen) | B23: =MAX(0,B4-B22) | C23: =MAX(0,C4-C22)
A25: Mögliche Segmente für die Lücke (nur Schweiz, alle zu prüfen): Erwachsene mit Berufsabschluss (Art. 32 BBV), Berufsprüfungen und höhere Fachprüfungen, üK-Zentren und Berufsfachschulen als Kunden, Prüfungs- und Aufgabenplattform für Verbände (eQV).
