Workbook
Name Bewirtschafterliste: Stammdaten!$A$5:$A$24

Sheet Anleitung
A1: Leerstandsliste – Kurzanleitung
A4: Wozu diese Datei da ist
A5: Sie stellt sicher, dass keine Kündigung, keine Abnahme und keine Schlussabrechnung vergessen geht.
A6: Mieter-, Objekt- und Eigentümerdaten bleiben in Garaio REM, Dokumente im Dossier, Inserate in der VMZ.
A7: Ein Eintrag hier hält nur fest, dass der Schritt im zuständigen System erledigt wurde.
A9: Die Blätter
A10: Leerstände – hier wird gearbeitet. Eine Zeile je Mieterwechsel. Beim Start leer.
A11: Beispiele – zehn ausgefüllte Fälle zum Nachschlagen. Ändert keine Kennzahl.
A12: Kennzahlen – rechnet sich selbst aus den Leerständen. Nur lesen.
A13: Prozessschritte – Nachschlagewerk: wo ein Schritt auszuführen ist.
A14: Stammdaten – Bewirtschafter und Teams. Hier neue Personen erfassen.
A16: So wird ein Schritt erfasst
... A49: Erstellt am 22.09.2026 · Fachliche Grundlage: Prozessbeschreibung Mieterwechsel

Sheet Stammdaten
A1: Stammdaten
A2: Bewirtschafter und Teamzuordnung. Wird von der Spalte «Team» und den Auswahllisten gelesen.
A4: Bewirtschafter | B4: Team | D4: Teams
A5: Moren | B5: BS 02 | D5: BS 01
A6: Ryser | B6: BS 02 | D6: BS 02
A7: Scherb | B7: BS 02
A8: Ademi | B8: BS 02 | D8: Weitere Bewirtschafter einfach in Spalte A und B ergänzen (bis Zeile 24).
A9: Fazliu | B9: BS 02
A10: Brandenburger | B10: BS 01
A11: Breitmeier | B11: BS 01
A12: Loa | B12: BS 01
A13: Sivanesan | B13: BS 01

Sheet Leerstände
A1: Leerstandsliste – Pendenzen zu Mieterwechseln
A2: Datenführung bleibt in Garaio REM. Hier wird nur festgehalten, dass ein Schritt erledigt ist. Graue Spalten rechnen selbst – bitte nicht überschreiben.
A3: Schrittspalten: Erledigungsdatum eintragen, oder «n.e.» wenn der Schritt entfällt. Leer bedeutet offen. | Das Blatt ist leer und einsatzbereit – zehn ausgefüllte Beispielfälle stehen im Blatt «Beispiele».
A4: Fall-Nr. | B4: Obj.-Nr. | C4: Liegenschaft | D4: Stock | E4: ex-Mieter | F4: Bewirtschafter | G4: Team | H4: Status | I4: Nächster Schritt | J4: Leerstandstage | K4: Prüfhinweis | L4: gekündigt per | M4: Haftungsdatum | N4: Leerstandsbeginn | O4: Vorlauftage | P4: Berichtsmonat | Q4: Mieter seit | R4: neuer Mieter | S4: Vermietet per | T4: Arbeitsbereich | U4: Phase | V4: Ort | W4: Anz. Zimmer | X4: Eigentümer | Y4: Dossier | Z4: WA-Termin | AA4: Sollfrist Abnahmetermin | AB4: Sollfrist Handwerker | AC4: Vertrag retour bis | AD4: Schlüsselübergabe-Termin | AE4: Kündigung bestätigt / G-Rem | AF4: Meldung Werke / EGT | AG4: Vorbesichtigung | AH4: VMZ aktualisiert | AI4: Inserat online | AJ4: Wohnungsabnahme durchgeführt | AK4: Handwerker aufgeboten | AL4: Zustimmungserklärung | AM4: Instandstellungen beauftragt | AN4: Vertrag versendet | AO4: Vertrag retour | AP4: Info Werke / EGT | AQ4: Schlüsselübergabe erfolgt | AR4: Reinigung veranlasst | AS4: Namensschilder | AT4: Kaution / G-Rem mutiert | AU4: Instandstellungs-RG | AV4: Schlussabrechnung | AW4: Zahlungseingang | AX4: zurückgestellt bis | AY4: Fall abgeschlossen | AZ4: Notiz
G5: =IF(F5="","",IFERROR(INDEX(Stammdaten!$B$5:$B$24,MATCH(F5,Stammdaten!$A$5:$A$24,0)),"unbekannt")) | H5: =IF($B5="","",IF(AY5<>"","abgeschlossen",IF(AND(ISNUMBER(AX5),AX5>=TODAY()),"zurückgestellt",IF(OR(AND(ISNUMBER(AA5),AA5<TODAY(),Z5="",AJ5=""),AND(ISNUMBER(Z5),Z5<TODAY(),AJ5=""),AND(ISNUMBER(AB5),AB5<TODAY(),AK5=""),AND(ISNUMBER(AC5),AC5<TODAY(),AO5=""),AND(ISNUMBER(AD5),AD5<TODAY(),AQ5="")),"überfällig","offen")))) | I5: =IF($B5="","",IF(AY5<>"","—",IF(AND(ISNUMBER(AA5),AA5<TODAY(),Z5="",AJ5=""),"Abnahmetermin vereinbaren – Sollfrist verstrichen",IF(AND(ISNUMBER(Z5),Z5<TODAY(),AJ5=""),"Wohnungsabnahme nachtragen – Termin war fällig",IF(AND(ISNUMBER(AB5),AB5<TODAY(),AK5=""),"Handwerker aufbieten – Frist verstrichen",IF(AND(ISNUMBER(AC5),AC5<TODAY(),AO5=""),"Vertrag retour mahnen – Frist verstrichen",IF(AND(ISNUMBER(AD5),AD5<TODAY(),AQ5=""),"Schlüsselübergabe nachtragen – Termin war fällig",IF(M5="","Haftungsdatum erfassen",IF(E5="","ex-Mieter erfassen",IF(AE5="","Kündigung bestätigen / G-Rem",IF(AF5="","Werke / EGT melden",IF(AG5="","Vorbesichtigung (oder n.e.)",IF(AH5="","VMZ aktualisieren",IF(AI5="","Inserat aufschalten",IF(AND(Z5="",AJ5=""),"Abnahmetermin vereinbaren",IF(AJ5="","Wohnungsabnahme durchführen",IF(AK5="","Handwerker aufbieten",IF(AL5="","Zustimmungserklärung einholen",IF(AM5="","Instandstellungen beauftragen",IF(R5="","Nachmieter erfassen",IF(AN5="","Vertrag versenden",IF(AO5="","Vertrag retour erfassen",IF(S5="","Vermietet per erfassen",IF(AP5="","Werke / EGT über Einzug informieren",IF(AND(AD5="",AQ5=""),"Schlüsselübergabe terminieren",IF(AQ5="","Schlüsselübergabe durchführen",IF(AR5="","Reinigung veranlassen",IF(AS5="","Namensschilder bestellen",IF(AT5="","Kaution prüfen / G-Rem mutieren",IF(AU5="","Instandstellungs-Rechnung erfassen",IF(AV5="","Schlussabrechnung erstellen",IF(AW5="","Zahlungseingang kontrollieren","Fall abschliessen")))))))))))))))))))))))))))))))) | J5: =IF(M5="","",IF(S5<>"",MAX(0,S5-M5-1),MAX(0,TODAY()-M5))) | K5: =IF($B5="","",TRIM(IF(AND(L5<>"",M5<>"",M5<L5),"Haftungsdatum vor Kündigung. ","")&IF(AND(S5<>"",M5<>"",S5<M5),"Vermietung vor Leerstandsbeginn. ","")&IF(AND(Z5<>"",L5<>"",Z5<L5),"WA-Termin vor Kündigung. ","")&IF(COUNTIFS($B$5:$B$404,$B5,$AY$5:$AY$404,"")>1,"Zweiter offener Fall zum selben Objekt. ","")&IF(AND($A5<>"",COUNTIFS($A$5:$A$404,$A5)>1),"Fall-Nr. doppelt vergeben. ","")&IF(E5="","ex-Mieter fehlt. ","")&IF(M5="","Haftungsdatum fehlt. ","")&IF(F5="","Bewirtschafter fehlt. ","")&IF(AND(AY5<>"",AW5=""),"Abgeschlossen trotz offener Schlussabrechnung. ","")&IF(AND(AY5="",S5="",ISNUMBER(J5),J5>60),"Langläufer über 60 Tage. ",""))) | N5: =IF(M5="","",M5+1) | O5: =IF(OR(L5="",M5=""),"",M5-L5) | P5: =IF(M5="","",YEAR(M5+1)&"-"&TEXT(MONTH(M5+1),"00")) | T5: =IF(U5="","",IF(LEFT(U5,1)="6","abgeschlossen",IF(OR(LEFT(U5,1)="1",LEFT(U5,1)="2"),"Kündigung & Abnahme",IF(OR(LEFT(U5,1)="3",LEFT(U5,1)="4"),"Wiedervermietung","Schlussabrechnung")))) | U5: =IF($B5="","",IF(AY5<>"","6 · abgeschlossen",IF(AW5<>"","5 · bereit zum Abschluss",IF(AT5<>"","5 · Schlussabrechnung",IF(AO5<>"","4 · Übergabe",IF(AM5<>"","3 · Neuvermietung",IF(M5<>"","2 · Abnahme & Vermarktung","1 · Erfassung"))))))) | AA5: =IF(M5="","",M5-30) | AB5: =IF(ISNUMBER(AJ5),AJ5+3,"")
G6: =IF(F6="","",IFERROR(INDEX(Stammdaten!$B$5:$B$24,MATCH(F6,Stammdaten!$A$5:$A$24,0)),"unbekannt")) | H6: =IF($B6="","",IF(AY6<>"","abgeschlossen",IF(AND(ISNUMBER(AX6),AX6>=TODAY()),"zurückgestellt",IF(OR(AND(ISNUMBER(AA6),AA6<TODAY(),Z6="",AJ6=""),AND(ISNUMBER(Z6),Z6<TODAY(),AJ6=""),AND(ISNUMBER(AB6),AB6<TODAY(),AK6=""),AND(ISNUMBER(AC6),AC6<TODAY(),AO6=""),AND(ISNUMBER(AD6),AD6<TODAY(),AQ6="")),"überfällig","offen")))) | I6: =IF($B6="","",IF(AY6<>"","—",IF(AND(ISNUMBER(AA6),AA6<TODAY(),Z6="",AJ6=""),"Abnahmetermin vereinbaren – Sollfrist verstrichen",IF(AND(ISNUMBER(Z6),Z6<TODAY(),AJ6=""),"Wohnungsabnahme nachtragen – Termin war fällig",IF(AND(ISNUMBER(AB6),AB6<TODAY(),AK6=""),"Handwerker aufbieten – Frist verstrichen",IF(AND(ISNUMBER(AC6),AC6<TODAY(),AO6=""),"Vertrag retour mahnen – Frist verstrichen",IF(AND(ISNUMBER(AD6),AD6<TODAY(),AQ6=""),"Schlüsselübergabe nachtragen – Termin war fällig",IF(M6="","Haftungsdatum erfassen",IF(E6="","ex-Mieter erfassen",IF(AE6="","Kündigung bestätigen / G-Rem",IF(AF6="","Werke / EGT melden",IF(AG6="","Vorbesichtigung (oder n.e.)",IF(AH6="","VMZ aktualisieren",IF(AI6="","Inserat aufschalten",IF(AND(Z6="",AJ6=""),"Abnahmetermin vereinbaren",IF(AJ6="","Wohnungsabnahme durchführen",IF(AK6="","Handwerker aufbieten",IF(AL6="","Zustimmungserklärung einholen",IF(AM6="","Instandstellungen beauftragen",IF(R6="","Nachmieter erfassen",IF(AN6="","Vertrag versenden",IF(AO6="","Vertrag retour erfassen",IF(S6="","Vermietet per erfassen",IF(AP6="","Werke / EGT über Einzug informieren",IF(AND(AD6="",AQ6=""),"Schlüsselübergabe terminieren",IF(AQ6="","Schlüsselübergabe durchführen",IF(AR6="","Reinigung veranlassen",IF(AS6="","Namensschilder bestellen",IF(AT6="","Kaution prüfen / G-Rem mutieren",IF(AU6="","Instandstellungs-Rechnung erfassen",IF(AV6="","Schlussabrechnung erstellen",IF(AW6="","Zahlungseingang kontrollieren","Fall abschliessen")))))))))))))))))))))))))))))))) | J6: =IF(M6="","",IF(S6<>"",MAX(0,S6-M6-1),MAX(0,TODAY()-M6))) | K6: =IF($B6="","",TRIM(IF(AND(L6<>"",M6<>"",M6<L6),"Haftungsdatum vor Kündigung. ","")&IF(AND(S6<>"",M6<>"",S6<M6),"Vermietung vor Leerstandsbeginn. ","")&IF(AND(Z6<>"",L6<>"",Z6<L6),"WA-Termin vor Kündigung. ","")&IF(COUNTIFS($B$5:$B$404,$B6,$AY$5:$AY$404,"")>1,"Zweiter offener Fall zum selben Objekt. ","")&IF(AND($A6<>"",COUNTIFS($A$5:$A$404,$A6)>1),"Fall-Nr. doppelt vergeben. ","")&IF(E6="","ex-Mieter fehlt. ","")&IF(M6="","Haftungsdatum fehlt. ","")&IF(F6="","Bewirtschafter fehlt. ","")&IF(AND(AY6<>"",AW6=""),"Abgeschlossen trotz offener Schlussabrechnung. ","")&IF(AND(AY6="",S6="",ISNUMBER(J6),J6>60),"Langläufer über 60 Tage. ",""))) | N6: =IF(M6="","",M6+1) | O6: =IF(OR(L6="",M6=""),"",M6-L6) | P6: =IF(M6="","",YEAR(M6+1)&"-"&TEXT(MONTH(M6+1),"00")) | T6: =IF(U6="","",IF(LEFT(U6,1)="6","abgeschlossen",IF(OR(LEFT(U6,1)="1",LEFT(U6,1)="2"),"Kündigung & Abnahme",IF(OR(LEFT(U6,1)="3",LEFT(U6,1)="4"),"Wiedervermietung","Schlussabrechnung")))) | U6: =IF($B6="","",IF(AY6<>"","6 · abgeschlossen",IF(AW6<>"","5 · bereit zum Abschluss",IF(AT6<>"","5 · Schlussabrechnung",IF(AO6<>"","4 · Übergabe",IF(AM6<>"","3 · Neuvermietung",IF(M6<>"","2 · Abnahme & Vermarktung","1 · Erfassung"))))))) | AA6: =IF(M6="","",M6-30) | AB6: =IF(ISNUMBER(AJ6),AJ6+3,"")
G7: =IF(F7="","",IFERROR(INDEX(Stammdaten!$B$5:$B$24,MATCH(F7,Stammdaten!$A$5:$A$24,0)),"unbekannt")) | H7: =IF($B7="","",IF(AY7<>"","abgeschlossen",IF(AND(ISNUMBER(AX7),AX7>=TODAY()),"zurückgestellt",IF(OR(AND(ISNUMBER(AA7),AA7<TODAY(),Z7="",AJ7=""),AND(ISNUMBER(Z7),Z7<TODAY(),AJ7=""),AND(ISNUMBER(AB7),AB7<TODAY(),AK7=""),AND(ISNUMBER(AC7),AC7<TODAY(),AO7=""),AND(ISNUMBER(AD7),AD7<TODAY(),AQ7="")),"überfällig","offen")))) | I7: =IF($B7="","",IF(AY7<>"","—",IF(AND(ISNUMBER(AA7),AA7<TODAY(),Z7="",AJ7=""),"Abnahmetermin vereinbaren – Sollfrist verstrichen",IF(AND(ISNUMBER(Z7),Z7<TODAY(),AJ7=""),"Wohnungsabnahme nachtragen – Termin war fällig",IF(AND(ISNUMBER(AB7),AB7<TODAY(),AK7=""),"Handwerker aufbieten – Frist verstrichen",IF(AND(ISNUMBER(AC7),AC7<TODAY(),AO7=""),"Vertrag retour mahnen – Frist verstrichen",IF(AND(ISNUMBER(AD7),AD7<TODAY(),AQ7=""),"Schlüsselübergabe nachtragen – Termin war fällig",IF(M7="","Haftungsdatum erfassen",IF(E7="","ex-Mieter erfassen",IF(AE7="","Kündigung bestätigen / G-Rem",IF(AF7="","Werke / EGT melden",IF(AG7="","Vorbesichtigung (oder n.e.)",IF(AH7="","VMZ aktualisieren",IF(AI7="","Inserat aufschalten",IF(AND(Z7="",AJ7=""),"Abnahmetermin vereinbaren",IF(AJ7="","Wohnungsabnahme durchführen",IF(AK7="","Handwerker aufbieten",IF(AL7="","Zustimmungserklärung einholen",IF(AM7="","Instandstellungen beauftragen",IF(R7="","Nachmieter erfassen",IF(AN7="","Vertrag versenden",IF(AO7="","Vertrag retour erfassen",IF(S7="","Vermietet per erfassen",IF(AP7="","Werke / EGT über Einzug informieren",IF(AND(AD7="",AQ7=""),"Schlüsselübergabe terminieren",IF(AQ7="","Schlüsselübergabe durchführen",IF(AR7="","Reinigung veranlassen",IF(AS7="","Namensschilder bestellen",IF(AT7="","Kaution prüfen / G-Rem mutieren",IF(AU7="","Instandstellungs-Rechnung erfassen",IF(AV7="","Schlussabrechnung erstellen",IF(AW7="","Zahlungseingang kontrollieren","Fall abschliessen")))))))))))))))))))))))))))))))) | J7: =IF(M7="","",IF(S7<>"",MAX(0,S7-M7-1),MAX(0,TODAY()-M7))) | K7: =IF($B7="","",TRIM(IF(AND(L7<>"",M7<>"",M7<L7),"Haftungsdatum vor Kündigung. ","")&IF(AND(S7<>"",M7<>"",S7<M7),"Vermietung vor Leerstandsbeginn. ","")&IF(AND(Z7<>"",L7<>"",Z7<L7),"WA-Termin vor Kündigung. ","")&IF(COUNTIFS($B$5:$B$404,$B7,$AY$5:$AY$404,"")>1,"Zweiter offener Fall zum selben Objekt. ","")&IF(AND($A7<>"",COUNTIFS($A$5:$A$404,$A7)>1),"Fall-Nr. doppelt vergeben. ","")&IF(E7="","ex-Mieter fehlt. ","")&IF(M7="","Haftungsdatum fehlt. ","")&IF(F7="","Bewirtschafter fehlt. ","")&IF(AND(AY7<>"",AW7=""),"Abgeschlossen trotz offener Schlussabrechnung. ","")&IF(AND(AY7="",S7="",ISNUMBER(J7),J7>60),"Langläufer über 60 Tage. ",""))) | N7: =IF(M7="","",M7+1) | O7: =IF(OR(L7="",M7=""),"",M7-L7) | P7: =IF(M7="","",YEAR(M7+1)&"-"&TEXT(MONTH(M7+1),"00")) | T7: =IF(U7="","",IF(LEFT(U7,1)="6","abgeschlossen",IF(OR(LEFT(U7,1)="1",LEFT(U7,1)="2"),"Kündigung & Abnahme",IF(OR(LEFT(U7,1)="3",LEFT(U7,1)="4"),"Wiedervermietung","Schlussabrechnung")))) | U7: =IF($B7="","",IF(AY7<>"","6 · abgeschlossen",IF(AW7<>"","5 · bereit zum Abschluss",IF(AT7<>"","5 · Schlussabrechnung",IF(AO7<>"","4 · Übergabe",IF(AM7<>"","3 · Neuvermietung",IF(M7<>"","2 · Abnahme & Vermarktung","1 · Erfassung"))))))) | AA7: =IF(M7="","",M7-30) | AB7: =IF(ISNUMBER(AJ7),AJ7+3,"")
G8: =IF(F8="","",IFERROR(INDEX(Stammdaten!$B$5:$B$24,MATCH(F8,Stammdaten!$A$5:$A$24,0)),"unbekannt")) | H8: =IF($B8="","",IF(AY8<>"","abgeschlossen",IF(AND(ISNUMBER(AX8),AX8>=TODAY()),"zurückgestellt",IF(OR(AND(ISNUMBER(AA8),AA8<TODAY(),Z8="",AJ8=""),AND(ISNUMBER(Z8),Z8<TODAY(),AJ8=""),AND(ISNUMBER(AB8),AB8<TODAY(),AK8=""),AND(ISNUMBER(AC8),AC8<TODAY(),AO8=""),AND(ISNUMBER(AD8),AD8<TODAY(),AQ8="")),"überfällig","offen")))) | I8: =IF($B8="","",IF(AY8<>"","—",IF(AND(ISNUMBER(AA8),AA8<TODAY(),Z8="",AJ8=""),"Abnahmetermin vereinbaren – Sollfrist verstrichen",IF(AND(ISNUMBER(Z8),Z8<TODAY(),AJ8=""),"Wohnungsabnahme nachtragen – Termin war fällig",IF(AND(ISNUMBER(AB8),AB8<TODAY(),AK8=""),"Handwerker aufbieten – Frist verstrichen",IF(AND(ISNUMBER(AC8),AC8<TODAY(),AO8=""),"Vertrag retour mahnen – Frist verstrichen",IF(AND(ISNUMBER(AD8),AD8<TODAY(),AQ8=""),"Schlüsselübergabe nachtragen – Termin war fällig",IF(M8="","Haftungsdatum erfassen",IF(E8="","ex-Mieter erfassen",IF(AE8="","Kündigung bestätigen / G-Rem",IF(AF8="","Werke / EGT melden",IF(AG8="","Vorbesichtigung (oder n.e.)",IF(AH8="","VMZ aktualisieren",IF(AI8="","Inserat aufschalten",IF(AND(Z8="",AJ8=""),"Abnahmetermin vereinbaren",IF(AJ8="","Wohnungsabnahme durchführen",IF(AK8="","Handwerker aufbieten",IF(AL8="","Zustimmungserklärung einholen",IF(AM8="","Instandstellungen beauftragen",IF(R8="","Nachmieter erfassen",IF(AN8="","Vertrag versenden",IF(AO8="","Vertrag retour erfassen",IF(S8="","Vermietet per erfassen",IF(AP8="","Werke / EGT über Einzug informieren",IF(AND(AD8="",AQ8=""),"Schlüsselübergabe terminieren",IF(AQ8="","Schlüsselübergabe durchführen",IF(AR8="","Reinigung veranlassen",IF(AS8="","Namensschilder bestellen",IF(AT8="","Kaution prüfen / G-Rem mutieren",IF(AU8="","Instandstellungs-Rechnung erfassen",IF(AV8="","Schlussabrechnung erstellen",IF(AW8="","Zahlungseingang kontrollieren","Fall abschliessen")))))))))))))))))))))))))))))))) | J8: =IF(M8="","",IF(S8<>"",MAX(0,S8-M8-1),MAX(0,TODAY()-M8))) | K8: =IF($B8="","",TRIM(IF(AND(L8<>"",M8<>"",M8<L8),"Haftungsdatum vor Kündigung. ","")&IF(AND(S8<>"",M8<>"",S8<M8),"Vermietung vor Leerstandsbeginn. ","")&IF(AND(Z8<>"",L8<>"",Z8<L8),"WA-Termin vor Kündigung. ","")&IF(COUNTIFS($B$5:$B$404,$B8,$AY$5:$AY$404,"")>1,"Zweiter offener Fall zum selben Objekt. ","")&IF(AND($A8<>"",COUNTIFS($A$5:$A$404,$A8)>1),"Fall-Nr. doppelt vergeben. ","")&IF(E8="","ex-Mieter fehlt. ","")&IF(M8="","Haftungsdatum fehlt. ","")&IF(F8="","Bewirtschafter fehlt. ","")&IF(AND(AY8<>"",AW8=""),"Abgeschlossen trotz offener Schlussabrechnung. ","")&IF(AND(AY8="",S8="",ISNUMBER(J8),J8>60),"Langläufer über 60 Tage. ",""))) | N8: =IF(M8="","",M8+1) | O8: =IF(OR(L8="",M8=""),"",M8-L8) | P8: =IF(M8="","",YEAR(M8+1)&"-"&TEXT(MONTH(M8+1),"00")) | T8: =IF(U8="","",IF(LEFT(U8,1)="6","abgeschlossen",IF(OR(LEFT(U8,1)="1",LEFT(U8,1)="2"),"Kündigung & Abnahme",IF(OR(LEFT(U8,1)="3",LEFT(U8,1)="4"),"Wiedervermietung","Schlussabrechnung")))) | U8: =IF($B8="","",IF(AY8<>"","6 · abgeschlossen",IF(AW8<>"","5 · bereit zum Abschluss",IF(AT8<>"","5 · Schlussabrechnung",IF(AO8<>"","4 · Übergabe",IF(AM8<>"","3 · Neuvermietung",IF(M8<>"","2 · Abnahme & Vermarktung","1 · Erfassung"))))))) | AA8: =IF(M8="","",M8-30) | AB8: =IF(ISNUMBER(AJ8),AJ8+3,"")
G9: =IF(F9="","",IFERROR(INDEX(Stammdaten!$B$5:$B$24,MATCH(F9,Stammdaten!$A$5:$A$24,0)),"unbekannt")) | H9: =IF($B9="","",IF(AY9<>"","abgeschlossen",IF(AND(ISNUMBER(AX9),AX9>=TODAY()),"zurückgestellt",IF(OR(AND(ISNUMBER(AA9),AA9<TODAY(),Z9="",AJ9=""),AND(ISNUMBER(Z9),Z9<TODAY(),AJ9=""),AND(ISNUMBER(AB9),AB9<TODAY(),AK9=""),AND(ISNUMBER(AC9),AC9<TODAY(),AO9=""),AND(ISNUMBER(AD9),AD9<TODAY(),AQ9="")),"überfällig","offen")))) | I9: =IF($B9="","",IF(AY9<>"","—",IF(AND(ISNUMBER(AA9),AA9<TODAY(),Z9="",AJ9=""),"Abnahmetermin vereinbaren – Sollfrist verstrichen",IF(AND(ISNUMBER(Z9),Z9<TODAY(),AJ9=""),"Wohnungsabnahme nachtragen – Termin war fällig",IF(AND(ISNUMBER(AB9),AB9<TODAY(),AK9=""),"Handwerker aufbieten – Frist verstrichen",IF(AND(ISNUMBER(AC9),AC9<TODAY(),AO9=""),"Vertrag retour mahnen – Frist verstrichen",IF(AND(ISNUMBER(AD9),AD9<TODAY(),AQ9=""),"Schlüsselübergabe nachtragen – Termin war fällig",IF(M9="","Haftungsdatum erfassen",IF(E9="","ex-Mieter erfassen",IF(AE9="","Kündigung bestätigen / G-Rem",IF(AF9="","Werke / EGT melden",IF(AG9="","Vorbesichtigung (oder n.e.)",IF(AH9="","VMZ aktualisieren",IF(AI9="","Inserat aufschalten",IF(AND(Z9="",AJ9=""),"Abnahmetermin vereinbaren",IF(AJ9="","Wohnungsabnahme durchführen",IF(AK9="","Handwerker aufbieten",IF(AL9="","Zustimmungserklärung einholen",IF(AM9="","Instandstellungen beauftragen",IF(R9="","Nachmieter erfassen",IF(AN9="","Vertrag versenden",IF(AO9="","Vertrag retour erfassen",IF(S9="","Vermietet per erfassen",IF(AP9="","Werke / EGT über Einzug informieren",IF(AND(AD9="",AQ9=""),"Schlüsselübergabe terminieren",IF(AQ9="","Schlüsselübergabe durchführen",IF(AR9="","Reinigung veranlassen",IF(AS9="","Namensschilder bestellen",IF(AT9="","Kaution prüfen / G-Rem mutieren",IF(AU9="","Instandstellungs-Rechnung erfassen",IF(AV9="","Schlussabrechnung erstellen",IF(AW9="","Zahlungseingang kontrollieren","Fall abschliessen")))))))))))))))))))))))))))))))) | J9: =IF(M9="","",IF(S9<>"",MAX(0,S9-M9-1),MAX(0,TODAY()-M9))) | K9: =IF($B9="","",TRIM(IF(AND(L9<>"",M9<>"",M9<L9),"Haftungsdatum vor Kündigung. ","")&IF(AND(S9<>"",M9<>"",S9<M9),"Vermietung vor Leerstandsbeginn. ","")&IF(AND(Z9<>"",L9<>"",Z9<L9),"WA-Termin vor Kündigung. ","")&IF(COUNTIFS($B$5:$B$404,$B9,$AY$5:$AY$404,"")>1,"Zweiter offener Fall zum selben Objekt. ","")&IF(AND($A9<>"",COUNTIFS($A$5:$A$404,$A9)>1),"Fall-Nr. doppelt vergeben. ","")&IF(E9="","ex-Mieter fehlt. ","")&IF(M9="","Haftungsdatum fehlt. ","")&IF(F9="","Bewirtschafter fehlt. ","")&IF(AND(AY9<>"",AW9=""),"Abgeschlossen trotz offener Schlussabrechnung. ","")&IF(AND(AY9="",S9="",ISNUMBER(J9),J9>60),"Langläufer über 60 Tage. ",""))) | N9: =IF(M9="","",M9+1) | O9: =IF(OR(L9="",M9=""),"",M9-L9) | P9: =IF(M9="","",YEAR(M9+1)&"-"&TEXT(MONTH(M9+1),"00")) | T9: =IF(U9="","",IF(LEFT(U9,1)="6","abgeschlossen",IF(OR(LEFT(U9,1)="1",LEFT(U9,1)="2"),"Kündigung & Abnahme",IF(OR(LEFT(U9,1)="3",LEFT(U9,1)="4"),"Wiedervermietung","Schlussabrechnung")))) | U9: =IF($B9="","",IF(AY9<>"","6 · abgeschlossen",IF(AW9<>"","5 · bereit zum Abschluss",IF(AT9<>"","5 · Schlussabrechnung",IF(AO9<>"","4 · Übergabe",IF(AM9<>"","3 · Neuvermietung",IF(M9<>"","2 · Abnahme & Vermarktung","1 · Erfassung"))))))) | AA9: =IF(M9="","",M9-30) | AB9: =IF(ISNUMBER(AJ9),AJ9+3,"")
G10: =IF(F10="","",IFERROR(INDEX(Stammdaten!$B$5:$B$24,MATCH(F10,Stammdaten!$A$5:$A$24,0)),"unbekannt")) | H10: =IF($B10="","",IF(AY10<>"","abgeschlossen",IF(AND(ISNUMBER(AX10),AX10>=TODAY()),"zurückgestellt",IF(OR(AND(ISNUMBER(AA10),AA10<TODAY(),Z10="",AJ10=""),AND(ISNUMBER(Z10),Z10<TODAY(),AJ10=""),AND(ISNUMBER(AB10),AB10<TODAY(),AK10=""),AND(ISNUMBER(AC10),AC10<TODAY(),AO10=""),AND(ISNUMBER(AD10),AD10<TODAY(),AQ10="")),"überfällig","offen")))) | I10: =IF($B10="","",IF(AY10<>"","—",IF(AND(ISNUMBER(AA10),AA10<TODAY(),Z10="",AJ10=""),"Abnahmetermin vereinbaren – Sollfrist verstrichen",IF(AND(ISNUMBER(Z10),Z10<TODAY(),AJ10=""),"Wohnungsabnahme nachtragen – Termin war fällig",IF(AND(ISNUMBER(AB10),AB10<TODAY(),AK10=""),"Handwerker aufbieten – Frist verstrichen",IF(AND(ISNUMBER(AC10),AC10<TODAY(),AO10=""),"Vertrag retour mahnen – Frist verstrichen",IF(AND(ISNUMBER(AD10),AD10<TODAY(),AQ10=""),"Schlüsselübergabe nachtragen – Termin war fällig",IF(M10="","Haftungsdatum erfassen",IF(E10="","ex-Mieter erfassen",IF(AE10="","Kündigung bestätigen / G-Rem",IF(AF10="","Werke / EGT melden",IF(AG10="","Vorbesichtigung (oder n.e.)",IF(AH10="","VMZ aktualisieren",IF(AI10="","Inserat aufschalten",IF(AND(Z10="",AJ10=""),"Abnahmetermin vereinbaren",IF(AJ10="","Wohnungsabnahme durchführen",IF(AK10="","Handwerker aufbieten",IF(AL10="","Zustimmungserklärung einholen",IF(AM10="","Instandstellungen beauftragen",IF(R10="","Nachmieter erfassen",IF(AN10="","Vertrag versenden",IF(AO10="","Vertrag retour erfassen",IF(S10="","Vermietet per erfassen",IF(AP10="","Werke / EGT über Einzug informieren",IF(AND(AD10="",AQ10=""),"Schlüsselübergabe terminieren",IF(AQ10="","Schlüsselübergabe durchführen",IF(AR10="","Reinigung veranlassen",IF(AS10="","Namensschilder bestellen",IF(AT10="","Kaution prüfen / G-Rem mutieren",IF(AU10="","Instandstellungs-Rechnung erfassen",IF(AV10="","Schlussabrechnung erstellen",IF(AW10="","Zahlungseingang kontrollieren","Fall abschliessen")))))))))))))))))))))))))))))))) | J10: =IF(M10="","",IF(S10<>"",MAX(0,S10-M10-1),MAX(0,TODAY()-M10))) | K10: =IF($B10="","",TRIM(IF(AND(L10<>"",M10<>"",M10<L10),"Haftungsdatum vor Kündigung. ","")&IF(AND(S10<>"",M10<>"",S10<M10),"Vermietung vor Leerstandsbeginn. ","")&IF(AND(Z10<>"",L10<>"",Z10<L10),"WA-Termin vor Kündigung. ","")&IF(COUNTIFS($B$5:$B$404,$B10,$AY$5:$AY$404,"")>1,"Zweiter offener Fall zum selben Objekt. ","")&IF(AND($A10<>"",COUNTIFS($A$5:$A$404,$A10)>1),"Fall-Nr. doppelt vergeben. ","")&IF(E10="","ex-Mieter fehlt. ","")&IF(M10="","Haftungsdatum fehlt. ","")&IF(F10="","Bewirtschafter fehlt. ","")&IF(AND(AY10<>"",AW10=""),"Abgeschlossen trotz offener Schlussabrechnung. ","")&IF(AND(AY10="",S10="",ISNUMBER(J10),J10>60),"Langläufer über 60 Tage. ",""))) | N10: =IF(M10="","",M10+1) | O10: =IF(OR(L10="",M10=""),"",M10-L10) | P10: =IF(M10="","",YEAR(M10+1)&"-"&TEXT(MONTH(M10+1),"00")) | T10: =IF(U10="","",IF(LEFT(U10,1)="6","abgeschlossen",IF(OR(LEFT(U10,1)="1",LEFT(U10,1)="2"),"Kündigung & Abnahme",IF(OR(LEFT(U10,1)="3",LEFT(U10,1)="4"),"Wiedervermietung","Schlussabrechnung")))) | U10: =IF($B10="","",IF(AY10<>"","6 · abgeschlossen",IF(AW10<>"","5 · bereit zum Abschluss",IF(AT10<>"","5 · Schlussabrechnung",IF(AO10<>"","4 · Übergabe",IF(AM10<>"","3 · Neuvermietung",IF(M10<>"","2 · Abnahme & Vermarktung","1 · Erfassung"))))))) | AA10: =IF(M10="","",M10-30) | AB10: =IF(ISNUMBER(AJ10),AJ10+3,"")
G11: =IF(F11="","",IFERROR(INDEX(Stammdaten!$B$5:$B$24,MATCH(F11,Stammdaten!$A$5:$A$24,0)),"unbekannt")) | H11: =IF($B11="","",IF(AY11<>"","abgeschlossen",IF(AND(ISNUMBER(AX11),AX11>=TODAY()),"zurückgestellt",IF(OR(AND(ISNUMBER(AA11),AA11<TODAY(),Z11="",AJ11=""),AND(ISNUMBER(Z11),Z11<TODAY(),AJ11=""),AND(ISNUMBER(AB11),AB11<TODAY(),AK11=""),AND(ISNUMBER(AC11),AC11<TODAY(),AO11=""),AND(ISNUMBER(AD11),AD11<TODAY(),AQ11="")),"überfällig","offen")))) | I11: =IF($B11="","",IF(AY11<>"","—",IF(AND(ISNUMBER(AA11),AA11<TODAY(),Z11="",AJ11=""),"Abnahmetermin vereinbaren – Sollfrist verstrichen",IF(AND(ISNUMBER(Z11),Z11<TODAY(),AJ11=""),"Wohnungsabnahme nachtragen – Termin war fällig",IF(AND(ISNUMBER(AB11),AB11<TODAY(),AK11=""),"Handwerker aufbieten – Frist verstrichen",IF(AND(ISNUMBER(AC11),AC11<TODAY(),AO11=""),"Vertrag retour mahnen – Frist verstrichen",IF(AND(ISNUMBER(AD11),AD11<TODAY(),AQ11=""),"Schlüsselübergabe nachtragen – Termin war fällig",IF(M11="","Haftungsdatum erfassen",IF(E11="","ex-Mieter erfassen",IF(AE11="","Kündigung bestätigen / G-Rem",IF(AF11="","Werke / EGT melden",IF(AG11="","Vorbesichtigung (oder n.e.)",IF(AH11="","VMZ aktualisieren",IF(AI11="","Inserat aufschalten",IF(AND(Z11="",AJ11=""),"Abnahmetermin vereinbaren",IF(AJ11="","Wohnungsabnahme durchführen",IF(AK11="","Handwerker aufbieten",IF(AL11="","Zustimmungserklärung einholen",IF(AM11="","Instandstellungen beauftragen",IF(R11="","Nachmieter erfassen",IF(AN11="","Vertrag versenden",IF(AO11="","Vertrag retour erfassen",IF(S11="","Vermietet per erfassen",IF(AP11="","Werke / EGT über Einzug informieren",IF(AND(AD11="",AQ11=""),"Schlüsselübergabe terminieren",IF(AQ11="","Schlüsselübergabe durchführen",IF(AR11="","Reinigung veranlassen",IF(AS11="","Namensschilder bestellen",IF(AT11="","Kaution prüfen / G-Rem mutieren",IF(AU11="","Instandstellungs-Rechnung erfassen",IF(AV11="","Schlussabrechnung erstellen",IF(AW11="","Zahlungseingang kontrollieren","Fall abschliessen")))))))))))))))))))))))))))))))) | J11: =IF(M11="","",IF(S11<>"",MAX(0,S11-M11-1),MAX(0,TODAY()-M11))) | K11: =IF($B11="","",TRIM(IF(AND(L11<>"",M11<>"",M11<L11),"Haftungsdatum vor Kündigung. ","")&IF(AND(S11<>"",M11<>"",S11<M11),"Vermietung vor Leerstandsbeginn. ","")&IF(AND(Z11<>"",L11<>"",Z11<L11),"WA-Termin vor Kündigung. ","")&IF(COUNTIFS($B$5:$B$404,$B11,$AY$5:$AY$404,"")>1,"Zweiter offener Fall zum selben Objekt. ","")&IF(AND($A11<>"",COUNTIFS($A$5:$A$404,$A11)>1),"Fall-Nr. doppelt vergeben. ","")&IF(E11="","ex-Mieter fehlt. ","")&IF(M11="","Haftungsdatum fehlt. ","")&IF(F11="","Bewirtschafter fehlt. ","")&IF(AND(AY11<>"",AW11=""),"Abgeschlossen trotz offener Schlussabrechnung. ","")&IF(AND(AY11="",S11="",ISNUMBER(J11),J11>60),"Langläufer über 60 Tage. ",""))) | N11: =IF(M11="","",M11+1) | O11: =IF(OR(L11="",M11=""),"",M11-L11) | P11: =IF(M11="","",YEAR(M11+1)&"-"&TEXT(MONTH(M11+1),"00")) | T11: =IF(U11="","",IF(LEFT(U11,1)="6","abgeschlossen",IF(OR(LEFT(U11,1)="1",LEFT(U11,1)="2"),"Kündigung & Abnahme",IF(OR(LEFT(U11,1)="3",LEFT(U11,1)="4"),"Wiedervermietung","Schlussabrechnung")))) | U11: =IF($B11="","",IF(AY11<>"","6 · abgeschlossen",IF(AW11<>"","5 · bereit zum Abschluss",IF(AT11<>"","5 · Schlussabrechnung",IF(AO11<>"","4 · Übergabe",IF(AM11<>"","3 · Neuvermietung",IF(M11<>"","2 · Abnahme & Vermarktung","1 · Erfassung"))))))) | AA11: =IF(M11="","",M11-30) | AB11: =IF(ISNUMBER(AJ11),AJ11+3,"")
G12: =IF(F12="","",IFERROR(INDEX(Stammdaten!$B$5:$B$24,MATCH(F12,Stammdaten!$A$5:$A$24,0)),"unbekannt")) | H12: =IF($B12="","",IF(AY12<>"","abgeschlossen",IF(AND(ISNUMBER(AX12),AX12>=TODAY()),"zurückgestellt",IF(OR(AND(ISNUMBER(AA12),AA12<TODAY(),Z12="",AJ12=""),AND(ISNUMBER(Z12),Z12<TODAY(),AJ12=""),AND(ISNUMBER(AB12),AB12<TODAY(),AK12=""),AND(ISNUMBER(AC12),AC12<TODAY(),AO12=""),AND(ISNUMBER(AD12),AD12<TODAY(),AQ12="")),"überfällig","offen")))) | I12: =IF($B12="","",IF(AY12<>"","—",IF(AND(ISNUMBER(AA12),AA12<TODAY(),Z12="",AJ12=""),"Abnahmetermin vereinbaren – Sollfrist verstrichen",IF(AND(ISNUMBER(Z12),Z12<TODAY(),AJ12=""),"Wohnungsabnahme nachtragen – Termin war fällig",IF(AND(ISNUMBER(AB12),AB12<TODAY(),AK12=""),"Handwerker aufbieten – Frist verstrichen",IF(AND(ISNUMBER(AC12),AC12<TODAY(),AO12=""),"Vertrag retour mahnen – Frist verstrichen",IF(AND(ISNUMBER(AD12),AD12<TODAY(),AQ12=""),"Schlüsselübergabe nachtragen – Termin war fällig",IF(M12="","Haftungsdatum erfassen",IF(E12="","ex-Mieter erfassen",IF(AE12="","Kündigung bestätigen / G-Rem",IF(AF12="","Werke / EGT melden",IF(AG12="","Vorbesichtigung (oder n.e.)",IF(AH12="","VMZ aktualisieren",IF(AI12="","Inserat aufschalten",IF(AND(Z12="",AJ12=""),"Abnahmetermin vereinbaren",IF(AJ12="","Wohnungsabnahme durchführen",IF(AK12="","Handwerker aufbieten",IF(AL12="","Zustimmungserklärung einholen",IF(AM12="","Instandstellungen beauftragen",IF(R12="","Nachmieter erfassen",IF(AN12="","Vertrag versenden",IF(AO12="","Vertrag retour erfassen",IF(S12="","Vermietet per erfassen",IF(AP12="","Werke / EGT über Einzug informieren",IF(AND(AD12="",AQ12=""),"Schlüsselübergabe terminieren",IF(AQ12="","Schlüsselübergabe durchführen",IF(AR12="","Reinigung veranlassen",IF(AS12="","Namensschilder bestellen",IF(AT12="","Kaution prüfen / G-Rem mutieren",IF(AU12="","Instandstellungs-Rechnung erfassen",IF(AV12="","Schlussabrechnung erstellen",IF(AW12="","Zahlungseingang kontrollieren","Fall abschliessen")))))))))))))))))))))))))))))))) | J12: =IF(M12="","",IF(S12<>"",MAX(0,S12-M12-1),MAX(0,TODAY()-M12))) | K12: =IF($B12="","",TRIM(IF(AND(L12<>"",M12<>"",M12<L12),"Haftungsdatum vor Kündigung. ","")&IF(AND(S12<>"",M12<>"",S12<M12),"Vermietung vor Leerstandsbeginn. ","")&IF(AND(Z12<>"",L12<>"",Z12<L12),"WA-Termin vor Kündigung. ","")&IF(COUNTIFS($B$5:$B$404,$B12,$AY$5:$AY$404,"")>1,"Zweiter offener Fall zum selben Objekt. ","")&IF(AND($A12<>"",COUNTIFS($A$5:$A$404,$A12)>1),"Fall-Nr. doppelt vergeben. ","")&IF(E12="","ex-Mieter fehlt. ","")&IF(M12="","Haftungsdatum fehlt. ","")&IF(F12="","Bewirtschafter fehlt. ","")&IF(AND(AY12<>"",AW12=""),"Abgeschlossen trotz offener Schlussabrechnung. ","")&IF(AND(AY12="",S12="",ISNUMBER(J12),J12>60),"Langläufer über 60 Tage. ",""))) | N12: =IF(M12="","",M12+1) | O12: =IF(OR(L12="",M12=""),"",M12-L12) | P12: =IF(M12="","",YEAR(M12+1)&"-"&TEXT(MONTH(M12+1),"00")) | T12: =IF(U12="","",IF(LEFT(U12,1)="6","abgeschlossen",IF(OR(LEFT(U12,1)="1",LEFT(U12,1)="2"),"Kündigung & Abnahme",IF(OR(LEFT(U12,1)="3",LEFT(U12,1)="4"),"Wiedervermietung","Schlussabrechnung")))) | U12: =IF($B12="","",IF(AY12<>"","6 · abgeschlossen",IF(AW12<>"","5 · bereit zum Abschluss",IF(AT12<>"","5 · Schlussabrechnung",IF(AO12<>"","4 · Übergabe",IF(AM12<>"","3 · Neuvermietung",IF(M12<>"","2 · Abnahme & Vermarktung","1 · Erfassung"))))))) | AA12: =IF(M12="","",M12-30) | AB12: =IF(ISNUMBER(AJ12),AJ12+3,"")
G13: =IF(F13="","",IFERROR(INDEX(Stammdaten!$B$5:$B$24,MATCH(F13,Stammdaten!$A$5:$A$24,0)),"unbekannt")) | H13: =IF($B13="","",IF(AY13<>"","abgeschlossen",IF(AND(ISNUMBER(AX13),AX13>=TODAY()),"zurückgestellt",IF(OR(AND(ISNUMBER(AA13),AA13<TODAY(),Z13="",AJ13=""),AND(ISNUMBER(Z13),Z13<TODAY(),AJ13=""),AND(ISNUMBER(AB13),AB13<TODAY(),AK13=""),AND(ISNUMBER(AC13),AC13<TODAY(),AO13=""),AND(ISNUMBER(AD13),AD13<TODAY(),AQ13="")),"überfällig","offen")))) | I13: =IF($B13="","",IF(AY13<>"","—",IF(AND(ISNUMBER(AA13),AA13<TODAY(),Z13="",AJ13=""),"Abnahmetermin vereinbaren – Sollfrist verstrichen",IF(AND(ISNUMBER(Z13),Z13<TODAY(),AJ13=""),"Wohnungsabnahme nachtragen – Termin war fällig",IF(AND(ISNUMBER(AB13),AB13<TODAY(),AK13=""),"Handwerker aufbieten – Frist verstrichen",IF(AND(ISNUMBER(AC13),AC13<TODAY(),AO13=""),"Vertrag retour mahnen – Frist verstrichen",IF(AND(ISNUMBER(AD13),AD13<TODAY(),AQ13=""),"Schlüsselübergabe nachtragen – Termin war fällig",IF(M13="","Haftungsdatum erfassen",IF(E13="","ex-Mieter erfassen",IF(AE13="","Kündigung bestätigen / G-Rem",IF(AF13="","Werke / EGT melden",IF(AG13="","Vorbesichtigung (oder n.e.)",IF(AH13="","VMZ aktualisieren",IF(AI13="","Inserat aufschalten",IF(AND(Z13="",AJ13=""),"Abnahmetermin vereinbaren",IF(AJ13="","Wohnungsabnahme durchführen",IF(AK13="","Handwerker aufbieten",IF(AL13="","Zustimmungserklärung einholen",IF(AM13="","Instandstellungen beauftragen",IF(R13="","Nachmieter erfassen",IF(AN13="","Vertrag versenden",IF(AO13="","Vertrag retour erfassen",IF(S13="","Vermietet per erfassen",IF(AP13="","Werke / EGT über Einzug informieren",IF(AND(AD13="",AQ13=""),"Schlüsselübergabe terminieren",IF(AQ13="","Schlüsselübergabe durchführen",IF(AR13="","Reinigung veranlassen",IF(AS13="","Namensschilder bestellen",IF(AT13="","Kaution prüfen / G-Rem mutieren",IF(AU13="","Instandstellungs-Rechnung erfassen",IF(AV13="","Schlussabrechnung erstellen",IF(AW13="","Zahlungseingang kontrollieren","Fall abschliessen")))))))))))))))))))))))))))))))) | J13: =IF(M13="","",IF(S13<>"",MAX(0,S13-M13-1),MAX(0,TODAY()-M13))) | K13: =IF($B13="","",TRIM(IF(AND(L13<>"",M13<>"",M13<L13),"Haftungsdatum vor Kündigung. ","")&IF(AND(S13<>"",M13<>"",S13<M13),"Vermietung vor Leerstandsbeginn. ","")&IF(AND(Z13<>"",L13<>"",Z13<L13),"WA-Termin vor Kündigung. ","")&IF(COUNTIFS($B$5:$B$404,$B13,$AY$5:$AY$404,"")>1,"Zweiter offener Fall zum selben Objekt. ","")&IF(AND($A13<>"",COUNTIFS($A$5:$A$404,$A13)>1),"Fall-Nr. doppelt vergeben. ","")&IF(E13="","ex-Mieter fehlt. ","")&IF(M13="","Haftungsdatum fehlt. ","")&IF(F13="","Bewirtschafter fehlt. ","")&IF(AND(AY13<>"",AW13=""),"Abgeschlossen trotz offener Schlussabrechnung. ","")&IF(AND(AY13="",S13="",ISNUMBER(J13),J13>60),"Langläufer über 60 Tage. ",""))) | N13: =IF(M13="","",M13+1) | O13: =IF(OR(L13="",M13=""),"",M13-L13) | P13: =IF(M13="","",YEAR(M13+1)&"-"&TEXT(MONTH(M13+1),"00")) | T13: =IF(U13="","",IF(LEFT(U13,1)="6","abgeschlossen",IF(OR(LEFT(U13,1)="1",LEFT(U13,1)="2"),"Kündigung & Abnahme",IF(OR(LEFT(U13,1)="3",LEFT(U13,1)="4"),"Wiedervermietung","Schlussabrechnung")))) | U13: =IF($B13="","",IF(AY13<>"","6 · abgeschlossen",IF(AW13<>"","5 · bereit zum Abschluss",IF(AT13<>"","5 · Schlussabrechnung",IF(AO13<>"","4 · Übergabe",IF(AM13<>"","3 · Neuvermietung",IF(M13<>"","2 · Abnahme & Vermarktung","1 · Erfassung"))))))) | AA13: =IF(M13="","",M13-30) | AB13: =IF(ISNUMBER(AJ13),AJ13+3,"")
G14: =IF(F14="","",IFERROR(INDEX(Stammdaten!$B$5:$B$24,MATCH(F14,Stammdaten!$A$5:$A$24,0)),"unbekannt")) | H14: =IF($B14="","",IF(AY14<>"","abgeschlossen",IF(AND(ISNUMBER(AX14),AX14>=TODAY()),"zurückgestellt",IF(OR(AND(ISNUMBER(AA14),AA14<TODAY(),Z14="",AJ14=""),AND(ISNUMBER(Z14),Z14<TODAY(),AJ14=""),AND(ISNUMBER(AB14),AB14<TODAY(),AK14=""),AND(ISNUMBER(AC14),AC14<TODAY(),AO14=""),AND(ISNUMBER(AD14),AD14<TODAY(),AQ14="")),"überfällig","offen")))) | I14: =IF($B14="","",IF(AY14<>"","—",IF(AND(ISNUMBER(AA14),AA14<TODAY(),Z14="",AJ14=""),"Abnahmetermin vereinbaren – Sollfrist verstrichen",IF(AND(ISNUMBER(Z14),Z14<TODAY(),AJ14=""),"Wohnungsabnahme nachtragen – Termin war fällig",IF(AND(ISNUMBER(AB14),AB14<TODAY(),AK14=""),"Handwerker aufbieten – Frist verstrichen",IF(AND(ISNUMBER(AC14),AC14<TODAY(),AO14=""),"Vertrag retour mahnen – Frist verstrichen",IF(AND(ISNUMBER(AD14),AD14<TODAY(),AQ14=""),"Schlüsselübergabe nachtragen – Termin war fällig",IF(M14="","Haftungsdatum erfassen",IF(E14="","ex-Mieter erfassen",IF(AE14="","Kündigung bestätigen / G-Rem",IF(AF14="","Werke / EGT melden",IF(AG14="","Vorbesichtigung (oder n.e.)",IF(AH14="","VMZ aktualisieren",IF(AI14="","Inserat aufschalten",IF(AND(Z14="",AJ14=""),"Abnahmetermin vereinbaren",IF(AJ14="","Wohnungsabnahme durchführen",IF(AK14="","Handwerker aufbieten",IF(AL14="","Zustimmungserklärung einholen",IF(AM14="","Instandstellungen beauftragen",IF(R14="","Nachmieter erfassen",IF(AN14="","Vertrag versenden",IF(AO14="","Vertrag retour erfassen",IF(S14="","Vermietet per erfassen",IF(AP14="","Werke / EGT über Einzug informieren",IF(AND(AD14="",AQ14=""),"Schlüsselübergabe terminieren",IF(AQ14="","Schlüsselübergabe durchführen",IF(AR14="","Reinigung veranlassen",IF(AS14="","Namensschilder bestellen",IF(AT14="","Kaution prüfen / G-Rem mutieren",IF(AU14="","Instandstellungs-Rechnung erfassen",IF(AV14="","Schlussabrechnung erstellen",IF(AW14="","Zahlungseingang kontrollieren","Fall abschliessen")))))))))))))))))))))))))))))))) | J14: =IF(M14="","",IF(S14<>"",MAX(0,S14-M14-1),MAX(0,TODAY()-M14))) | K14: =IF($B14="","",TRIM(IF(AND(L14<>"",M14<>"",M14<L14),"Haftungsdatum vor Kündigung. ","")&IF(AND(S14<>"",M14<>"",S14<M14),"Vermietung vor Leerstandsbeginn. ","")&IF(AND(Z14<>"",L14<>"",Z14<L14),"WA-Termin vor Kündigung. ","")&IF(COUNTIFS($B$5:$B$404,$B14,$AY$5:$AY$404,"")>1,"Zweiter offener Fall zum selben Objekt. ","")&IF(AND($A14<>"",COUNTIFS($A$5:$A$404,$A14)>1),"Fall-Nr. doppelt vergeben. ","")&IF(E14="","ex-Mieter fehlt. ","")&IF(M14="","Haftungsdatum fehlt. ","")&IF(F14="","Bewirtschafter fehlt. ","")&IF(AND(AY14<>"",AW14=""),"Abgeschlossen trotz offener Schlussabrechnung. ","")&IF(AND(AY14="",S14="",ISNUMBER(J14),J14>60),"Langläufer über 60 Tage. ",""))) | N14: =IF(M14="","",M14+1) | O14: =IF(OR(L14="",M14=""),"",M14-L14) | P14: =IF(M14="","",YEAR(M14+1)&"-"&TEXT(MONTH(M14+1),"00")) | T14: =IF(U14="","",IF(LEFT(U14,1)="6","abgeschlossen",IF(OR(LEFT(U14,1)="1",LEFT(U14,1)="2"),"Kündigung & Abnahme",IF(OR(LEFT(U14,1)="3",LEFT(U14,1)="4"),"Wiedervermietung","Schlussabrechnung")))) | U14: =IF($B14="","",IF(AY14<>"","6 · abgeschlossen",IF(AW14<>"","5 · bereit zum Abschluss",IF(AT14<>"","5 · Schlussabrechnung",IF(AO14<>"","4 · Übergabe",IF(AM14<>"","3 · Neuvermietung",IF(M14<>"","2 · Abnahme & Vermarktung","1 · Erfassung"))))))) | AA14: =IF(M14="","",M14-30) | AB14: =IF(ISNUMBER(AJ14),AJ14+3,"")
G15: =IF(F15="","",IFERROR(INDEX(Stammdaten!$B$5:$B$24,MATCH(F15,Stammdaten!$A$5:$A$24,0)),"unbekannt")) | H15: =IF($B15="","",IF(AY15<>"","abgeschlossen",IF(AND(ISNUMBER(AX15),AX15>=TODAY()),"zurückgestellt",IF(OR(AND(ISNUMBER(AA15),AA15<TODAY(),Z15="",AJ15=""),AND(ISNUMBER(Z15),Z15<TODAY(),AJ15=""),AND(ISNUMBER(AB15),AB15<TODAY(),AK15=""),AND(ISNUMBER(AC15),AC15<TODAY(),AO15=""),AND(ISNUMBER(AD15),AD15<TODAY(),AQ15="")),"überfällig","offen")))) | I15: =IF($B15="","",IF(AY15<>"","—",IF(AND(ISNUMBER(AA15),AA15<TODAY(),Z15="",AJ15=""),"Abnahmetermin vereinbaren – Sollfrist verstrichen",IF(AND(ISNUMBER(Z15),Z15<TODAY(),AJ15=""),"Wohnungsabnahme nachtragen – Termin war fällig",IF(AND(ISNUMBER(AB15),AB15<TODAY(),AK15=""),"Handwerker aufbieten – Frist verstrichen",IF(AND(ISNUMBER(AC15),AC15<TODAY(),AO15=""),"Vertrag retour mahnen – Frist verstrichen",IF(AND(ISNUMBER(AD15),AD15<TODAY(),AQ15=""),"Schlüsselübergabe nachtragen – Termin war fällig",IF(M15="","Haftungsdatum erfassen",IF(E15="","ex-Mieter erfassen",IF(AE15="","Kündigung bestätigen / G-Rem",IF(AF15="","Werke / EGT melden",IF(AG15="","Vorbesichtigung (oder n.e.)",IF(AH15="","VMZ aktualisieren",IF(AI15="","Inserat aufschalten",IF(AND(Z15="",AJ15=""),"Abnahmetermin vereinbaren",IF(AJ15="","Wohnungsabnahme durchführen",IF(AK15="","Handwerker aufbieten",IF(AL15="","Zustimmungserklärung einholen",IF(AM15="","Instandstellungen beauftragen",IF(R15="","Nachmieter erfassen",IF(AN15="","Vertrag versenden",IF(AO15="","Vertrag retour erfassen",IF(S15="","Vermietet per erfassen",IF(AP15="","Werke / EGT über Einzug informieren",IF(AND(AD15="",AQ15=""),"Schlüsselübergabe terminieren",IF(AQ15="","Schlüsselübergabe durchführen",IF(AR15="","Reinigung veranlassen",IF(AS15="","Namensschilder bestellen",IF(AT15="","Kaution prüfen / G-Rem mutieren",IF(AU15="","Instandstellungs-Rechnung erfassen",IF(AV15="","Schlussabrechnung erstellen",IF(AW15="","Zahlungseingang kontrollieren","Fall abschliessen")))))))))))))))))))))))))))))))) | J15: =IF(M15="","",IF(S15<>"",MAX(0,S15-M15-1),MAX(0,TODAY()-M15))) | K15: =IF($B15="","",TRIM(IF(AND(L15<>"",M15<>"",M15<L15),"Haftungsdatum vor Kündigung. ","")&IF(AND(S15<>"",M15<>"",S15<M15),"Vermietung vor Leerstandsbeginn. ","")&IF(AND(Z15<>"",L15<>"",Z15<L15),"WA-Termin vor Kündigung. ","")&IF(COUNTIFS($B$5:$B$404,$B15,$AY$5:$AY$404,"")>1,"Zweiter offener Fall zum selben Objekt. ","")&IF(AND($A15<>"",COUNTIFS($A$5:$A$404,$A15)>1),"Fall-Nr. doppelt vergeben. ","")&IF(E15="","ex-Mieter fehlt. ","")&IF(M15="","Haftungsdatum fehlt. ","")&IF(F15="","Bewirtschafter fehlt. ","")&IF(AND(AY15<>"",AW15=""),"Abgeschlossen trotz offener Schlussabrechnung. ","")&IF(AND(AY15="",S15="",ISNUMBER(J15),J15>60),"Langläufer über 60 Tage. ",""))) | N15: =IF(M15="","",M15+1) | O15: =IF(OR(L15="",M15=""),"",M15-L15) | P15: =IF(M15="","",YEAR(M15+1)&"-"&TEXT(MONTH(M15+1),"00")) | T15: =IF(U15="","",IF(LEFT(U15,1)="6","abgeschlossen",IF(OR(LEFT(U15,1)="1",LEFT(U15,1)="2"),"Kündigung & Abnahme",IF(OR(LEFT(U15,1)="3",LEFT(U15,1)="4"),"Wiedervermietung","Schlussabrechnung")))) | U15: =IF($B15="","",IF(AY15<>"","6 · abgeschlossen",IF(AW15<>"","5 · bereit zum Abschluss",IF(AT15<>"","5 · Schlussabrechnung",IF(AO15<>"","4 · Übergabe",IF(AM15<>"","3 · Neuvermietung",IF(M15<>"","2 · Abnahme & Vermarktung","1 · Erfassung"))))))) | AA15: =IF(M15="","",M15-30) | AB15: =IF(ISNUMBER(AJ15),AJ15+3,"")
G16: =IF(F16="","",IFERROR(INDEX(Stammdaten!$B$5:$B$24,MATCH(F16,Stammdaten!$A$5:$A$24,0)),"unbekannt")) | H16: =IF($B16="","",IF(AY16<>"","abgeschlossen",IF(AND(ISNUMBER(AX16),AX16>=TODAY()),"zurückgestellt",IF(OR(AND(ISNUMBER(AA16),AA16<TODAY(),Z16="",AJ16=""),AND(ISNUMBER(Z16),Z16<TODAY(),AJ16=""),AND(ISNUMBER(AB16),AB16<TODAY(),AK16=""),AND(ISNUMBER(AC16),AC16<TODAY(),AO16=""),AND(ISNUMBER(AD16),AD16<TODAY(),AQ16="")),"überfällig","offen")))) | I16: =IF($B16="","",IF(AY16<>"","—",IF(AND(ISNUMBER(AA16),AA16<TODAY(),Z16="",AJ16=""),"Abnahmetermin vereinbaren – Sollfrist verstrichen",IF(AND(ISNUMBER(Z16),Z16<TODAY(),AJ16=""),"Wohnungsabnahme nachtragen – Termin war fällig",IF(AND(ISNUMBER(AB16),AB16<TODAY(),AK16=""),"Handwerker aufbieten – Frist verstrichen",IF(AND(ISNUMBER(AC16),AC16<TODAY(),AO16=""),"Vertrag retour mahnen – Frist verstrichen",IF(AND(ISNUMBER(AD16),AD16<TODAY(),AQ16=""),"Schlüsselübergabe nachtragen – Termin war fällig",IF(M16="","Haftungsdatum erfassen",IF(E16="","ex-Mieter erfassen",IF(AE16="","Kündigung bestätigen / G-Rem",IF(AF16="","Werke / EGT melden",IF(AG16="","Vorbesichtigung (oder n.e.)",IF(AH16="","VMZ aktualisieren",IF(AI16="","Inserat aufschalten",IF(AND(Z16="",AJ16=""),"Abnahmetermin vereinbaren",IF(AJ16="","Wohnungsabnahme durchführen",IF(AK16="","Handwerker aufbieten",IF(AL16="","Zustimmungserklärung einholen",IF(AM16="","Instandstellungen beauftragen",IF(R16="","Nachmieter erfassen",IF(AN16="","Vertrag versenden",IF(AO16="","Vertrag retour erfassen",IF(S16="","Vermietet per erfassen",IF(AP16="","Werke / EGT über Einzug informieren",IF(AND(AD16="",AQ16=""),"Schlüsselübergabe terminieren",IF(AQ16="","Schlüsselübergabe durchführen",IF(AR16="","Reinigung veranlassen",IF(AS16="","Namensschilder bestellen",IF(AT16="","Kaution prüfen / G-Rem mutieren",IF(AU16="","Instandstellungs-Rechnung erfassen",IF(AV16="","Schlussabrechnung erstellen",IF(AW16="","Zahlungseingang kontrollieren","Fall abschliessen")))))))))))))))))))))))))))))))) | J16: =IF(M16="","",IF(S16<>"",MAX(0,S16-M16-1),MAX(0,TODAY()-M16))) | K16: =IF($B16="","",TRIM(IF(AND(L16<>"",M16<>"",M16<L16),"Haftungsdatum vor Kündigung. ","")&IF(AND(S16<>"",M16<>"",S16<M16),"Vermietung vor Leerstandsbeginn. ","")&IF(AND(Z16<>"",L16<>"",Z16<L16),"WA-Termin vor Kündigung. ","")&IF(COUNTIFS($B$5:$B$404,$B16,$AY$5:$AY$404,"")>1,"Zweiter offener Fall zum selben Objekt. ","")&IF(AND($A16<>"",COUNTIFS($A$5:$A$404,$A16)>1),"Fall-Nr. doppelt vergeben. ","")&IF(E16="","ex-Mieter fehlt. ","")&IF(M16="","Haftungsdatum fehlt. ","")&IF(F16="","Bewirtschafter fehlt. ","")&IF(AND(AY16<>"",AW16=""),"Abgeschlossen trotz offener Schlussabrechnung. ","")&IF(AND(AY16="",S16="",ISNUMBER(J16),J16>60),"Langläufer über 60 Tage. ",""))) | N16: =IF(M16="","",M16+1) | O16: =IF(OR(L16="",M16=""),"",M16-L16) | P16: =IF(M16="","",YEAR(M16+1)&"-"&TEXT(MONTH(M16+1),"00")) | T16: =IF(U16="","",IF(LEFT(U16,1)="6","abgeschlossen",IF(OR(LEFT(U16,1)="1",LEFT(U16,1)="2"),"Kündigung & Abnahme",IF(OR(LEFT(U16,1)="3",LEFT(U16,1)="4"),"Wiedervermietung","Schlussabrechnung")))) | U16: =IF($B16="","",IF(AY16<>"","6 · abgeschlossen",IF(AW16<>"","5 · bereit zum Abschluss",IF(AT16<>"","5 · Schlussabrechnung",IF(AO16<>"","4 · Übergabe",IF(AM16<>"","3 · Neuvermietung",IF(M16<>"","2 · Abnahme & Vermarktung","1 · Erfassung"))))))) | AA16: =IF(M16="","",M16-30) | AB16: =IF(ISNUMBER(AJ16),AJ16+3,"")
... G404: =IF(F404="","",IFERROR(INDEX(Stammdaten!$B$5:$B$24,MATCH(F404,Stammdaten!$A$5:$A$24,0)),"unbekannt")) | H404: =IF($B404="","",IF(AY404<>"","abgeschlossen",IF(AND(ISNUMBER(AX404),AX404>=TODAY()),"zurückgestellt",IF(OR(AND(ISNUMBER(AA404),AA404<TODAY(),Z404="",AJ404=""),AND(ISNUMBER(Z404),Z404<TODAY(),AJ404=""),AND(ISNUMBER(AB404),AB404<TODAY(),AK404=""),AND(ISNUMBER(AC404),AC404<TODAY(),AO404=""),AND(ISNUMBER(AD404),AD404<TODAY(),AQ404="")),"überfällig","offen")))) | I404: =IF($B404="","",IF(AY404<>"","—",IF(AND(ISNUMBER(AA404),AA404<TODAY(),Z404="",AJ404=""),"Abnahmetermin vereinbaren – Sollfrist verstrichen",IF(AND(ISNUMBER(Z404),Z404<TODAY(),AJ404=""),"Wohnungsabnahme nachtragen – Termin war fällig",IF(AND(ISNUMBER(AB404),AB404<TODAY(),AK404=""),"Handwerker aufbieten – Frist verstrichen",IF(AND(ISNUMBER(AC404),AC404<TODAY(),AO404=""),"Vertrag retour mahnen – Frist verstrichen",IF(AND(ISNUMBER(AD404),AD404<TODAY(),AQ404=""),"Schlüsselübergabe nachtragen – Termin war fällig",IF(M404="","Haftungsdatum erfassen",IF(E404="","ex-Mieter erfassen",IF(AE404="","Kündigung bestätigen / G-Rem",IF(AF404="","Werke / EGT melden",IF(AG404="","Vorbesichtigung (oder n.e.)",IF(AH404="","VMZ aktualisieren",IF(AI404="","Inserat aufschalten",IF(AND(Z404="",AJ404=""),"Abnahmetermin vereinbaren",IF(AJ404="","Wohnungsabnahme durchführen",IF(AK404="","Handwerker aufbieten",IF(AL404="","Zustimmungserklärung einholen",IF(AM404="","Instandstellungen beauftragen",IF(R404="","Nachmieter erfassen",IF(AN404="","Vertrag versenden",IF(AO404="","Vertrag retour erfassen",IF(S404="","Vermietet per erfassen",IF(AP404="","Werke / EGT über Einzug informieren",IF(AND(AD404="",AQ404=""),"Schlüsselübergabe terminieren",IF(AQ404="","Schlüsselübergabe durchführen",IF(AR404="","Reinigung veranlassen",IF(AS404="","Namensschilder bestellen",IF(AT404="","Kaution prüfen / G-Rem mutieren",IF(AU404="","Instandstellungs-Rechnung erfassen",IF(AV404="","Schlussabrechnung erstellen",IF(AW404="","Zahlungseingang kontrollieren","Fall abschliessen")))))))))))))))))))))))))))))))) | J404: =IF(M404="","",IF(S404<>"",MAX(0,S404-M404-1),MAX(0,TODAY()-M404))) | K404: =IF($B404="","",TRIM(IF(AND(L404<>"",M404<>"",M404<L404),"Haftungsdatum vor Kündigung. ","")&IF(AND(S404<>"",M404<>"",S404<M404),"Vermietung vor Leerstandsbeginn. ","")&IF(AND(Z404<>"",L404<>"",Z404<L404),"WA-Termin vor Kündigung. ","")&IF(COUNTIFS($B$5:$B$404,$B404,$AY$5:$AY$404,"")>1,"Zweiter offener Fall zum selben Objekt. ","")&IF(AND($A404<>"",COUNTIFS($A$5:$A$404,$A404)>1),"Fall-Nr. doppelt vergeben. ","")&IF(E404="","ex-Mieter fehlt. ","")&IF(M404="","Haftungsdatum fehlt. ","")&IF(F404="","Bewirtschafter fehlt. ","")&IF(AND(AY404<>"",AW404=""),"Abgeschlossen trotz offener Schlussabrechnung. ","")&IF(AND(AY404="",S404="",ISNUMBER(J404),J404>60),"Langläufer über 60 Tage. ",""))) | N404: =IF(M404="","",M404+1) | O404: =IF(OR(L404="",M404=""),"",M404-L404) | P404: =IF(M404="","",YEAR(M404+1)&"-"&TEXT(MONTH(M404+1),"00")) | T404: =IF(U404="","",IF(LEFT(U404,1)="6","abgeschlossen",IF(OR(LEFT(U404,1)="1",LEFT(U404,1)="2"),"Kündigung & Abnahme",IF(OR(LEFT(U404,1)="3",LEFT(U404,1)="4"),"Wiedervermietung","Schlussabrechnung")))) | U404: =IF($B404="","",IF(AY404<>"","6 · abgeschlossen",IF(AW404<>"","5 · bereit zum Abschluss",IF(AT404<>"","5 · Schlussabrechnung",IF(AO404<>"","4 · Übergabe",IF(AM404<>"","3 · Neuvermietung",IF(M404<>"","2 · Abnahme & Vermarktung","1 · Erfassung"))))))) | AA404: =IF(M404="","",M404-30) | AB404: =IF(ISNUMBER(AJ404),AJ404+3,"")

Sheet Beispiele
A1: Beispiele – zehn typische Fälle
A2: Nur zum Nachschlagen. Dieses Blatt rechnet gleich wie «Leerstände», wirkt sich aber auf keine Kennzahl aus. Hier darf gefahrlos ausprobiert werden.
A3: Jede Zeile zeigt eine andere Lage – auch fehlerhafte Erfassungen, damit sichtbar wird, was die Spalte «Prüfhinweis» meldet. Die Notiz rechts aussen erklärt den Fall.
A4: Fall-Nr. | B4: Obj.-Nr. | C4: Liegenschaft | D4: Stock | E4: ex-Mieter | F4: Bewirtschafter | G4: Team | H4: Status | I4: Nächster Schritt | J4: Leerstandstage | K4: Prüfhinweis | L4: gekündigt per | M4: Haftungsdatum | N4: Leerstandsbeginn | O4: Vorlauftage | P4: Berichtsmonat | Q4: Mieter seit | R4: neuer Mieter | S4: Vermietet per | T4: Arbeitsbereich | U4: Phase | V4: Ort | W4: Anz. Zimmer | X4: Eigentümer | Y4: Dossier | Z4: WA-Termin | AA4: Sollfrist Abnahmetermin | AB4: Sollfrist Handwerker | AC4: Vertrag retour bis | AD4: Schlüsselübergabe-Termin | AE4: Kündigung bestätigt / G-Rem | AF4: Meldung Werke / EGT | AG4: Vorbesichtigung | AH4: VMZ aktualisiert | AI4: Inserat online | AJ4: Wohnungsabnahme durchgeführt | AK4: Handwerker aufgeboten | AL4: Zustimmungserklärung | AM4: Instandstellungen beauftragt | AN4: Vertrag versendet | AO4: Vertrag retour | AP4: Info Werke / EGT | AQ4: Schlüsselübergabe erfolgt | AR4: Reinigung veranlasst | AS4: Namensschilder | AT4: Kaution / G-Rem mutiert | AU4: Instandstellungs-RG | AV4: Schlussabrechnung | AW4: Zahlungseingang | AX4: zurückgestellt bis | AY4: Fall abgeschlossen | AZ4: Notiz
A5: BSP-001 | B5: 0112.03.004 | C5: Seestrasse 118 | D5: 3. OG | E5: Familie Brunner | F5: Moren | G5: =IF(F5="","",IFERROR(INDEX(Stammdaten!$B$5:$B$24,MATCH(F5,Stammdaten!$A$5:$A$24,0)),"unbekannt")) | H5: =IF($B5="","",IF(AY5<>"","abgeschlossen",IF(AND(ISNUMBER(AX5),AX5>=TODAY()),"zurückgestellt",IF(OR(AND(ISNUMBER(AA5),AA5<TODAY(),Z5="",AJ5=""),AND(ISNUMBER(Z5),Z5<TODAY(),AJ5=""),AND(ISNUMBER(AB5),AB5<TODAY(),AK5=""),AND(ISNUMBER(AC5),AC5<TODAY(),AO5=""),AND(ISNUMBER(AD5),AD5<TODAY(),AQ5="")),"überfällig","offen")))) | I5: =IF($B5="","",IF(AY5<>"","—",IF(AND(ISNUMBER(AA5),AA5<TODAY(),Z5="",AJ5=""),"Abnahmetermin vereinbaren – Sollfrist verstrichen",IF(AND(ISNUMBER(Z5),Z5<TODAY(),AJ5=""),"Wohnungsabnahme nachtragen – Termin war fällig",IF(AND(ISNUMBER(AB5),AB5<TODAY(),AK5=""),"Handwerker aufbieten – Frist verstrichen",IF(AND(ISNUMBER(AC5),AC5<TODAY(),AO5=""),"Vertrag retour mahnen – Frist verstrichen",IF(AND(ISNUMBER(AD5),AD5<TODAY(),AQ5=""),"Schlüsselübergabe nachtragen – Termin war fällig",IF(M5="","Haftungsdatum erfassen",IF(E5="","ex-Mieter erfassen",IF(AE5="","Kündigung bestätigen / G-Rem",IF(AF5="","Werke / EGT melden",IF(AG5="","Vorbesichtigung (oder n.e.)",IF(AH5="","VMZ aktualisieren",IF(AI5="","Inserat aufschalten",IF(AND(Z5="",AJ5=""),"Abnahmetermin vereinbaren",IF(AJ5="","Wohnungsabnahme durchführen",IF(AK5="","Handwerker aufbieten",IF(AL5="","Zustimmungserklärung einholen",IF(AM5="","Instandstellungen beauftragen",IF(R5="","Nachmieter erfassen",IF(AN5="","Vertrag versenden",IF(AO5="","Vertrag retour erfassen",IF(S5="","Vermietet per erfassen",IF(AP5="","Werke / EGT über Einzug informieren",IF(AND(AD5="",AQ5=""),"Schlüsselübergabe terminieren",IF(AQ5="","Schlüsselübergabe durchführen",IF(AR5="","Reinigung veranlassen",IF(AS5="","Namensschilder bestellen",IF(AT5="","Kaution prüfen / G-Rem mutieren",IF(AU5="","Instandstellungs-Rechnung erfassen",IF(AV5="","Schlussabrechnung erstellen",IF(AW5="","Zahlungseingang kontrollieren","Fall abschliessen")))))))))))))))))))))))))))))))) | J5: =IF(M5="","",IF(S5<>"",MAX(0,S5-M5-1),MAX(0,TODAY()-M5))) | K5: =IF($B5="","",TRIM(IF(AND(L5<>"",M5<>"",M5<L5),"Haftungsdatum vor Kündigung. ","")&IF(AND(S5<>"",M5<>"",S5<M5),"Vermietung vor Leerstandsbeginn. ","")&IF(AND(Z5<>"",L5<>"",Z5<L5),"WA-Termin vor Kündigung. ","")&IF(COUNTIFS($B$5:$B$404,$B5,$AY$5:$AY$404,"")>1,"Zweiter offener Fall zum selben Objekt. ","")&IF(AND($A5<>"",COUNTIFS($A$5:$A$404,$A5)>1),"Fall-Nr. doppelt vergeben. ","")&IF(E5="","ex-Mieter fehlt. ","")&IF(M5="","Haftungsdatum fehlt. ","")&IF(F5="","Bewirtschafter fehlt. ","")&IF(AND(AY5<>"",AW5=""),"Abgeschlossen trotz offener Schlussabrechnung. ","")&IF(AND(AY5="",S5="",ISNUMBER(J5),J5>60),"Langläufer über 60 Tage. ",""))) | L5: 46229 | M5: 46263 | N5: =IF(M5="","",M5+1) | O5: =IF(OR(L5="",M5=""),"",M5-L5) | P5: =IF(M5="","",YEAR(M5+1)&"-"&TEXT(MONTH(M5+1),"00")) | T5: =IF(U5="","",IF(LEFT(U5,1)="6","abgeschlossen",IF(OR(LEFT(U5,1)="1",LEFT(U5,1)="2"),"Kündigung & Abnahme",IF(OR(LEFT(U5,1)="3",LEFT(U5,1)="4"),"Wiedervermietung","Schlussabrechnung")))) | U5: =IF($B5="","",IF(AY5<>"","6 · abgeschlossen",IF(AW5<>"","5 · bereit zum Abschluss",IF(AT5<>"","5 · Schlussabrechnung",IF(AO5<>"","4 · Übergabe",IF(AM5<>"","3 · Neuvermietung",IF(M5<>"","2 · Abnahme & Vermarktung","1 · Erfassung"))))))) | V5: 8002 Zürich | W5: 3.5 | X5: PK Helvetia Immobilien | Y5: https://schaeppi.sharepoint.com/objekte/0112-03-004 | Z5: 46281 | AA5: =IF(M5="","",M5-30) | AB5: =IF(ISNUMBER(AJ5),AJ5+3,"") | AE5: 46232 | AF5: 46233 | AH5: 46237 | AI5: 46240 | AK5: 46267 | AZ5: Abnahme kurzfristig verschoben, Mieter war krank.
A6: BSP-002 | B6: 0774.06.021 | C6: Hardturmstrasse 205 | D6: 6. OG | E6: S. Kaufmann | F6: Moren | G6: =IF(F6="","",IFERROR(INDEX(Stammdaten!$B$5:$B$24,MATCH(F6,Stammdaten!$A$5:$A$24,0)),"unbekannt")) | H6: =IF($B6="","",IF(AY6<>"","abgeschlossen",IF(AND(ISNUMBER(AX6),AX6>=TODAY()),"zurückgestellt",IF(OR(AND(ISNUMBER(AA6),AA6<TODAY(),Z6="",AJ6=""),AND(ISNUMBER(Z6),Z6<TODAY(),AJ6=""),AND(ISNUMBER(AB6),AB6<TODAY(),AK6=""),AND(ISNUMBER(AC6),AC6<TODAY(),AO6=""),AND(ISNUMBER(AD6),AD6<TODAY(),AQ6="")),"überfällig","offen")))) | I6: =IF($B6="","",IF(AY6<>"","—",IF(AND(ISNUMBER(AA6),AA6<TODAY(),Z6="",AJ6=""),"Abnahmetermin vereinbaren – Sollfrist verstrichen",IF(AND(ISNUMBER(Z6),Z6<TODAY(),AJ6=""),"Wohnungsabnahme nachtragen – Termin war fällig",IF(AND(ISNUMBER(AB6),AB6<TODAY(),AK6=""),"Handwerker aufbieten – Frist verstrichen",IF(AND(ISNUMBER(AC6),AC6<TODAY(),AO6=""),"Vertrag retour mahnen – Frist verstrichen",IF(AND(ISNUMBER(AD6),AD6<TODAY(),AQ6=""),"Schlüsselübergabe nachtragen – Termin war fällig",IF(M6="","Haftungsdatum erfassen",IF(E6="","ex-Mieter erfassen",IF(AE6="","Kündigung bestätigen / G-Rem",IF(AF6="","Werke / EGT melden",IF(AG6="","Vorbesichtigung (oder n.e.)",IF(AH6="","VMZ aktualisieren",IF(AI6="","Inserat aufschalten",IF(AND(Z6="",AJ6=""),"Abnahmetermin vereinbaren",IF(AJ6="","Wohnungsabnahme durchführen",IF(AK6="","Handwerker aufbieten",IF(AL6="","Zustimmungserklärung einholen",IF(AM6="","Instandstellungen beauftragen",IF(R6="","Nachmieter erfassen",IF(AN6="","Vertrag versenden",IF(AO6="","Vertrag retour erfassen",IF(S6="","Vermietet per erfassen",IF(AP6="","Werke / EGT über Einzug informieren",IF(AND(AD6="",AQ6=""),"Schlüsselübergabe terminieren",IF(AQ6="","Schlüsselübergabe durchführen",IF(AR6="","Reinigung veranlassen",IF(AS6="","Namensschilder bestellen",IF(AT6="","Kaution prüfen / G-Rem mutieren",IF(AU6="","Instandstellungs-Rechnung erfassen",IF(AV6="","Schlussabrechnung erstellen",IF(AW6="","Zahlungseingang kontrollieren","Fall abschliessen")))))))))))))))))))))))))))))))) | J6: =IF(M6="","",IF(S6<>"",MAX(0,S6-M6-1),MAX(0,TODAY()-M6))) | K6: =IF($B6="","",TRIM(IF(AND(L6<>"",M6<>"",M6<L6),"Haftungsdatum vor Kündigung. ","")&IF(AND(S6<>"",M6<>"",S6<M6),"Vermietung vor Leerstandsbeginn. ","")&IF(AND(Z6<>"",L6<>"",Z6<L6),"WA-Termin vor Kündigung. ","")&IF(COUNTIFS($B$5:$B$404,$B6,$AY$5:$AY$404,"")>1,"Zweiter offener Fall zum selben Objekt. ","")&IF(AND($A6<>"",COUNTIFS($A$5:$A$404,$A6)>1),"Fall-Nr. doppelt vergeben. ","")&IF(E6="","ex-Mieter fehlt. ","")&IF(M6="","Haftungsdatum fehlt. ","")&IF(F6="","Bewirtschafter fehlt. ","")&IF(AND(AY6<>"",AW6=""),"Abgeschlossen trotz offener Schlussabrechnung. ","")&IF(AND(AY6="",S6="",ISNUMBER(J6),J6>60),"Langläufer über 60 Tage. ",""))) | L6: 46201 | M6: 46253 | N6: =IF(M6="","",M6+1) | O6: =IF(OR(L6="",M6=""),"",M6-L6) | P6: =IF(M6="","",YEAR(M6+1)&"-"&TEXT(MONTH(M6+1),"00")) | R6: L. Iseli & P. Frei | S6: 46301 | T6: =IF(U6="","",IF(LEFT(U6,1)="6","abgeschlossen",IF(OR(LEFT(U6,1)="1",LEFT(U6,1)="2"),"Kündigung & Abnahme",IF(OR(LEFT(U6,1)="3",LEFT(U6,1)="4"),"Wiedervermietung","Schlussabrechnung")))) | U6: =IF($B6="","",IF(AY6<>"","6 · abgeschlossen",IF(AW6<>"","5 · bereit zum Abschluss",IF(AT6<>"","5 · Schlussabrechnung",IF(AO6<>"","4 · Übergabe",IF(AM6<>"","3 · Neuvermietung",IF(M6<>"","2 · Abnahme & Vermarktung","1 · Erfassung"))))))) | V6: 8005 Zürich | W6: 5.5 | X6: PK Helvetia Immobilien | Y6: https://schaeppi.sharepoint.com/objekte/0774-06-021 | AA6: =IF(M6="","",M6-30) | AB6: =IF(ISNUMBER(AJ6),AJ6+3,"") | AD6: 46291 | AE6: 46203 | AF6: 46204 | AG6: n.e. | AH6: 46208 | AI6: 46211 | AJ6: 46254 | AK6: 46255 | AL6: 46254 | AM6: 46256 | AN6: 46268 | AO6: 46275 | AP6: 46277 | AR6: 46281
A7: BSP-003 | B7: 0903.00.002 | C7: Rebbergstrasse 4 | D7: EG | E7: M. Odermatt | F7: Moren | G7: =IF(F7="","",IFERROR(INDEX(Stammdaten!$B$5:$B$24,MATCH(F7,Stammdaten!$A$5:$A$24,0)),"unbekannt")) | H7: =IF($B7="","",IF(AY7<>"","abgeschlossen",IF(AND(ISNUMBER(AX7),AX7>=TODAY()),"zurückgestellt",IF(OR(AND(ISNUMBER(AA7),AA7<TODAY(),Z7="",AJ7=""),AND(ISNUMBER(Z7),Z7<TODAY(),AJ7=""),AND(ISNUMBER(AB7),AB7<TODAY(),AK7=""),AND(ISNUMBER(AC7),AC7<TODAY(),AO7=""),AND(ISNUMBER(AD7),AD7<TODAY(),AQ7="")),"überfällig","offen")))) | I7: =IF($B7="","",IF(AY7<>"","—",IF(AND(ISNUMBER(AA7),AA7<TODAY(),Z7="",AJ7=""),"Abnahmetermin vereinbaren – Sollfrist verstrichen",IF(AND(ISNUMBER(Z7),Z7<TODAY(),AJ7=""),"Wohnungsabnahme nachtragen – Termin war fällig",IF(AND(ISNUMBER(AB7),AB7<TODAY(),AK7=""),"Handwerker aufbieten – Frist verstrichen",IF(AND(ISNUMBER(AC7),AC7<TODAY(),AO7=""),"Vertrag retour mahnen – Frist verstrichen",IF(AND(ISNUMBER(AD7),AD7<TODAY(),AQ7=""),"Schlüsselübergabe nachtragen – Termin war fällig",IF(M7="","Haftungsdatum erfassen",IF(E7="","ex-Mieter erfassen",IF(AE7="","Kündigung bestätigen / G-Rem",IF(AF7="","Werke / EGT melden",IF(AG7="","Vorbesichtigung (oder n.e.)",IF(AH7="","VMZ aktualisieren",IF(AI7="","Inserat aufschalten",IF(AND(Z7="",AJ7=""),"Abnahmetermin vereinbaren",IF(AJ7="","Wohnungsabnahme durchführen",IF(AK7="","Handwerker aufbieten",IF(AL7="","Zustimmungserklärung einholen",IF(AM7="","Instandstellungen beauftragen",IF(R7="","Nachmieter erfassen",IF(AN7="","Vertrag versenden",IF(AO7="","Vertrag retour erfassen",IF(S7="","Vermietet per erfassen",IF(AP7="","Werke / EGT über Einzug informieren",IF(AND(AD7="",AQ7=""),"Schlüsselübergabe terminieren",IF(AQ7="","Schlüsselübergabe durchführen",IF(AR7="","Reinigung veranlassen",IF(AS7="","Namensschilder bestellen",IF(AT7="","Kaution prüfen / G-Rem mutieren",IF(AU7="","Instandstellungs-Rechnung erfassen",IF(AV7="","Schlussabrechnung erstellen",IF(AW7="","Zahlungseingang kontrollieren","Fall abschliessen")))))))))))))))))))))))))))))))) | J7: =IF(M7="","",IF(S7<>"",MAX(0,S7-M7-1),MAX(0,TODAY()-M7))) | K7: =IF($B7="","",TRIM(IF(AND(L7<>"",M7<>"",M7<L7),"Haftungsdatum vor Kündigung. ","")&IF(AND(S7<>"",M7<>"",S7<M7),"Vermietung vor Leerstandsbeginn. ","")&IF(AND(Z7<>"",L7<>"",Z7<L7),"WA-Termin vor Kündigung. ","")&IF(COUNTIFS($B$5:$B$404,$B7,$AY$5:$AY$404,"")>1,"Zweiter offener Fall zum selben Objekt. ","")&IF(AND($A7<>"",COUNTIFS($A$5:$A$404,$A7)>1),"Fall-Nr. doppelt vergeben. ","")&IF(E7="","ex-Mieter fehlt. ","")&IF(M7="","Haftungsdatum fehlt. ","")&IF(F7="","Bewirtschafter fehlt. ","")&IF(AND(AY7<>"",AW7=""),"Abgeschlossen trotz offener Schlussabrechnung. ","")&IF(AND(AY7="",S7="",ISNUMBER(J7),J7>60),"Langläufer über 60 Tage. ",""))) | L7: 46154 | M7: 46216 | N7: =IF(M7="","",M7+1) | O7: =IF(OR(L7="",M7=""),"",M7-L7) | P7: =IF(M7="","",YEAR(M7+1)&"-"&TEXT(MONTH(M7+1),"00")) | R7: A. Schuler | S7: 46231 | T7: =IF(U7="","",IF(LEFT(U7,1)="6","abgeschlossen",IF(OR(LEFT(U7,1)="1",LEFT(U7,1)="2"),"Kündigung & Abnahme",IF(OR(LEFT(U7,1)="3",LEFT(U7,1)="4"),"Wiedervermietung","Schlussabrechnung")))) | U7: =IF($B7="","",IF(AY7<>"","6 · abgeschlossen",IF(AW7<>"","5 · bereit zum Abschluss",IF(AT7<>"","5 · Schlussabrechnung",IF(AO7<>"","4 · Übergabe",IF(AM7<>"","3 · Neuvermietung",IF(M7<>"","2 · Abnahme & Vermarktung","1 · Erfassung"))))))) | V7: 8610 Uster | W7: 2.5 | X7: Erbengemeinschaft Vogt | Y7: https://schaeppi.sharepoint.com/objekte/0903-00-002 | AA7: =IF(M7="","",M7-30) | AB7: =IF(ISNUMBER(AJ7),AJ7+3,"") | AE7: 46156 | AF7: 46157 | AG7: 46161 | AH7: 46163 | AI7: 46166 | AJ7: 46217 | AK7: 46218 | AL7: 46217 | AM7: 46220 | AN7: 46224 | AO7: 46229 | AP7: 46230 | AQ7: 46231 | AR7: 46229 | AS7: 46230 | AT7: 46228 | AU7: 46247 | AV7: 46261
