Workbook

Sheet Start
B2: Vermieter-Toolkit Schweiz
B3: Nebenkosten · Mietzinsanpassung · Mieterwechsel · Wohnungsabnahme
B5: So gehen Sie vor
B6: 1. «Liegenschaft»: Abrechnungsperiode, Wohnungen und Verteilschlüssel erfassen (gelbe Felder).
B7: 2. «Mieter»: alle Mietverhältnisse der Periode erfassen – auch Mieterwechsel unterjährig. Leere Daten = ganze Periode.
B8: 3. «Kosten»: Rechnungsbeträge erfassen, Art und Schlüssel wählen. Nur im Mietvertrag ausgeschiedene Nebenkosten werden belastet.
B9: 4. «Abrechnung»: Mieter-Nr. wählen, prüfen, drucken oder als PDF speichern. Leerstandskosten trägt automatisch der Vermieter.
B10: 5. «Mietzins»: Anpassung nach Referenzzinssatz, Teuerung und Kostensteigerung berechnen – inkl. spätestem Zustelltermin.
B11: 6. «Mieterwechsel» und «Abnahme»: Checkliste mit Terminen und druckbares Abnahmeprotokoll.
B13: Was dieses Toolkit automatisch berücksichtigt
B14: • Heiz- und Warmwasserkosten nach Heizgradtagen gewichtet (Mieterwechsel im Sommer ≠ im Winter). Skala anpassbar.
B15: • Andere Nebenkosten zeitanteilig nach Tagen.
... B27: Version 1.0 · Stand Oktober 2026

Sheet Liegenschaft
B2: Liegenschaft & Abrechnungsperiode
B3: Gelbe Felder ausfüllen. Die Periode muss 12 Monate umfassen und am Monatsersten beginnen.
B4: Liegenschaft
B5: Ort
B6: Vermieter/in
B7: Periode von
B8: Periode bis | D8: =IF(OR(C7="",C8=""),"",IF(AND(DAY(C7)=1,C8=DATE(YEAR(C7),MONTH(C7)+12,0)),"✓ 12 Monate","⚠ Periode muss 12 volle Monate ab Monatserstem umfassen"))
B9: Tage in Periode | C9: =IF(OR(C7="",C8=""),"",C8-C7+1)
B10: Verwaltungshonorar in % der Nebenkosten | C10: 0.03
B11: Honorar im Mietvertrag vereinbart? | C11: Nein
L12: Hilfstabelle (nicht bearbeiten)
B13: Wohnung / Einheit | C13: Fläche m² | D13: Zimmer | E13: Wertquote ‰ | F13: Volumen m³ | G13: Einheiten gleich | I13: Monat | J13: Heizgradtage % | L13: Nr | M13: Beginn | N13: Ende | O13: Gewicht
G14: =IF(B14="",0,1) | I14: Januar | J14: 18 | L14: 1 | M14: =IF($C$7="","",DATE(YEAR($C$7),MONTH($C$7)+0,1)) | N14: =IF($C$7="","",DATE(YEAR($C$7),MONTH($C$7)+1,0)) | O14: =IF($C$7="",0,INDEX($J$14:$J$25,MONTH(M14)))
G15: =IF(B15="",0,1) | I15: Februar | J15: 15 | L15: 2 | M15: =IF($C$7="","",DATE(YEAR($C$7),MONTH($C$7)+1,1)) | N15: =IF($C$7="","",DATE(YEAR($C$7),MONTH($C$7)+2,0)) | O15: =IF($C$7="",0,INDEX($J$14:$J$25,MONTH(M15)))
G16: =IF(B16="",0,1) | I16: März | J16: 13 | L16: 3 | M16: =IF($C$7="","",DATE(YEAR($C$7),MONTH($C$7)+2,1)) | N16: =IF($C$7="","",DATE(YEAR($C$7),MONTH($C$7)+3,0)) | O16: =IF($C$7="",0,INDEX($J$14:$J$25,MONTH(M16)))
G17: =IF(B17="",0,1) | I17: April | J17: 9 | L17: 4 | M17: =IF($C$7="","",DATE(YEAR($C$7),MONTH($C$7)+3,1)) | N17: =IF($C$7="","",DATE(YEAR($C$7),MONTH($C$7)+4,0)) | O17: =IF($C$7="",0,INDEX($J$14:$J$25,MONTH(M17)))
G18: =IF(B18="",0,1) | I18: Mai | J18: 4 | L18: 5 | M18: =IF($C$7="","",DATE(YEAR($C$7),MONTH($C$7)+4,1)) | N18: =IF($C$7="","",DATE(YEAR($C$7),MONTH($C$7)+5,0)) | O18: =IF($C$7="",0,INDEX($J$14:$J$25,MONTH(M18)))
G19: =IF(B19="",0,1) | I19: Juni | J19: 0 | L19: 6 | M19: =IF($C$7="","",DATE(YEAR($C$7),MONTH($C$7)+5,1)) | N19: =IF($C$7="","",DATE(YEAR($C$7),MONTH($C$7)+6,0)) | O19: =IF($C$7="",0,INDEX($J$14:$J$25,MONTH(M19)))
G20: =IF(B20="",0,1) | I20: Juli | J20: 0 | L20: 7 | M20: =IF($C$7="","",DATE(YEAR($C$7),MONTH($C$7)+6,1)) | N20: =IF($C$7="","",DATE(YEAR($C$7),MONTH($C$7)+7,0)) | O20: =IF($C$7="",0,INDEX($J$14:$J$25,MONTH(M20)))
G21: =IF(B21="",0,1) | I21: August | J21: 0 | L21: 8 | M21: =IF($C$7="","",DATE(YEAR($C$7),MONTH($C$7)+7,1)) | N21: =IF($C$7="","",DATE(YEAR($C$7),MONTH($C$7)+8,0)) | O21: =IF($C$7="",0,INDEX($J$14:$J$25,MONTH(M21)))
G22: =IF(B22="",0,1) | I22: September | J22: 3 | L22: 9 | M22: =IF($C$7="","",DATE(YEAR($C$7),MONTH($C$7)+8,1)) | N22: =IF($C$7="","",DATE(YEAR($C$7),MONTH($C$7)+9,0)) | O22: =IF($C$7="",0,INDEX($J$14:$J$25,MONTH(M22)))
G23: =IF(B23="",0,1) | I23: Oktober | J23: 8 | L23: 10 | M23: =IF($C$7="","",DATE(YEAR($C$7),MONTH($C$7)+9,1)) | N23: =IF($C$7="","",DATE(YEAR($C$7),MONTH($C$7)+10,0)) | O23: =IF($C$7="",0,INDEX($J$14:$J$25,MONTH(M23)))
G24: =IF(B24="",0,1) | I24: November | J24: 13 | L24: 11 | M24: =IF($C$7="","",DATE(YEAR($C$7),MONTH($C$7)+10,1)) | N24: =IF($C$7="","",DATE(YEAR($C$7),MONTH($C$7)+11,0)) | O24: =IF($C$7="",0,INDEX($J$14:$J$25,MONTH(M24)))
G25: =IF(B25="",0,1) | I25: Dezember | J25: 17 | L25: 12 | M25: =IF($C$7="","",DATE(YEAR($C$7),MONTH($C$7)+11,1)) | N25: =IF($C$7="","",DATE(YEAR($C$7),MONTH($C$7)+12,0)) | O25: =IF($C$7="",0,INDEX($J$14:$J$25,MONTH(M25)))
B26: Total | C26: =SUM(C14:C25) | D26: =SUM(D14:D25) | E26: =SUM(E14:E25) | F26: =SUM(F14:F25) | G26: =SUM(G14:G25) | I26: Summe | J26: =SUM(J14:J25)
I27: =IF(ABS(J26-100)<0.01,"✓","⚠ Summe ≠ 100")

Sheet Mieter
B2: Mietverhältnisse in der Periode
B3: Eine Zeile pro Mietverhältnis. Mietbeginn/-ende leer lassen, wenn vor bzw. nach der Periode.
B5: Nr | C5: Wohnung | D5: Mieter/in | E5: Mietbeginn | F5: Mietende | G5: Akonto bezahlt | H5: von (eff.) | I5: bis (eff.) | J5: Tage | K5: Zeitanteil | L5: Heizanteil | M5: Prüfung | O5: Hilfsspalten Heizgewichtung (nicht bearbeiten)
B6: 1 | H6: =IF(D6="","",MAX(E6,Liegenschaft!$C$7)) | I6: =IF(D6="","",IF(F6="",Liegenschaft!$C$8,MIN(F6,Liegenschaft!$C$8))) | J6: =IF(D6="",0,MAX(0,I6-H6+1)) | K6: =IF(OR(D6="",Liegenschaft!$C$9=""),0,J6/Liegenschaft!$C$9) | L6: =IF(OR(D6="",Liegenschaft!$J$26=0),0,SUM(O6:Z6)/Liegenschaft!$J$26) | M6: =IF(D6="","",IF(ISNA(MATCH(C6,Liegenschaft!$B$14:$B$25,0)),"⚠ Wohnung unbekannt",IF(J6=0,"⚠ nicht in Periode",IF(SUMPRODUCT(($C$6:$C$35=C6)*($D$6:$D$35<>"")*($J$6:$J$35>0)*($H$6:$H$35<=I6)*($I$6:$I$35>=H6))>1,"⚠ Überschneidung mit anderem Mieter","✓")))) | O6: =IF(OR(D6="",Liegenschaft!$C$7=""),0,MAX(0,MIN(I6,Liegenschaft!$N$14)-MAX(H6,Liegenschaft!$M$14)+1)/DAY(Liegenschaft!$N$14)*Liegenschaft!$O$14) | P6: =IF(OR(D6="",Liegenschaft!$C$7=""),0,MAX(0,MIN(I6,Liegenschaft!$N$15)-MAX(H6,Liegenschaft!$M$15)+1)/DAY(Liegenschaft!$N$15)*Liegenschaft!$O$15) | Q6: =IF(OR(D6="",Liegenschaft!$C$7=""),0,MAX(0,MIN(I6,Liegenschaft!$N$16)-MAX(H6,Liegenschaft!$M$16)+1)/DAY(Liegenschaft!$N$16)*Liegenschaft!$O$16) | R6: =IF(OR(D6="",Liegenschaft!$C$7=""),0,MAX(0,MIN(I6,Liegenschaft!$N$17)-MAX(H6,Liegenschaft!$M$17)+1)/DAY(Liegenschaft!$N$17)*Liegenschaft!$O$17) | S6: =IF(OR(D6="",Liegenschaft!$C$7=""),0,MAX(0,MIN(I6,Liegenschaft!$N$18)-MAX(H6,Liegenschaft!$M$18)+1)/DAY(Liegenschaft!$N$18)*Liegenschaft!$O$18) | T6: =IF(OR(D6="",Liegenschaft!$C$7=""),0,MAX(0,MIN(I6,Liegenschaft!$N$19)-MAX(H6,Liegenschaft!$M$19)+1)/DAY(Liegenschaft!$N$19)*Liegenschaft!$O$19) | U6: =IF(OR(D6="",Liegenschaft!$C$7=""),0,MAX(0,MIN(I6,Liegenschaft!$N$20)-MAX(H6,Liegenschaft!$M$20)+1)/DAY(Liegenschaft!$N$20)*Liegenschaft!$O$20) | V6: =IF(OR(D6="",Liegenschaft!$C$7=""),0,MAX(0,MIN(I6,Liegenschaft!$N$21)-MAX(H6,Liegenschaft!$M$21)+1)/DAY(Liegenschaft!$N$21)*Liegenschaft!$O$21) | W6: =IF(OR(D6="",Liegenschaft!$C$7=""),0,MAX(0,MIN(I6,Liegenschaft!$N$22)-MAX(H6,Liegenschaft!$M$22)+1)/DAY(Liegenschaft!$N$22)*Liegenschaft!$O$22) | X6: =IF(OR(D6="",Liegenschaft!$C$7=""),0,MAX(0,MIN(I6,Liegenschaft!$N$23)-MAX(H6,Liegenschaft!$M$23)+1)/DAY(Liegenschaft!$N$23)*Liegenschaft!$O$23) | Y6: =IF(OR(D6="",Liegenschaft!$C$7=""),0,MAX(0,MIN(I6,Liegenschaft!$N$24)-MAX(H6,Liegenschaft!$M$24)+1)/DAY(Liegenschaft!$N$24)*Liegenschaft!$O$24) | Z6: =IF(OR(D6="",Liegenschaft!$C$7=""),0,MAX(0,MIN(I6,Liegenschaft!$N$25)-MAX(H6,Liegenschaft!$M$25)+1)/DAY(Liegenschaft!$N$25)*Liegenschaft!$O$25)
B7: 2 | H7: =IF(D7="","",MAX(E7,Liegenschaft!$C$7)) | I7: =IF(D7="","",IF(F7="",Liegenschaft!$C$8,MIN(F7,Liegenschaft!$C$8))) | J7: =IF(D7="",0,MAX(0,I7-H7+1)) | K7: =IF(OR(D7="",Liegenschaft!$C$9=""),0,J7/Liegenschaft!$C$9) | L7: =IF(OR(D7="",Liegenschaft!$J$26=0),0,SUM(O7:Z7)/Liegenschaft!$J$26) | M7: =IF(D7="","",IF(ISNA(MATCH(C7,Liegenschaft!$B$14:$B$25,0)),"⚠ Wohnung unbekannt",IF(J7=0,"⚠ nicht in Periode",IF(SUMPRODUCT(($C$6:$C$35=C7)*($D$6:$D$35<>"")*($J$6:$J$35>0)*($H$6:$H$35<=I7)*($I$6:$I$35>=H7))>1,"⚠ Überschneidung mit anderem Mieter","✓")))) | O7: =IF(OR(D7="",Liegenschaft!$C$7=""),0,MAX(0,MIN(I7,Liegenschaft!$N$14)-MAX(H7,Liegenschaft!$M$14)+1)/DAY(Liegenschaft!$N$14)*Liegenschaft!$O$14) | P7: =IF(OR(D7="",Liegenschaft!$C$7=""),0,MAX(0,MIN(I7,Liegenschaft!$N$15)-MAX(H7,Liegenschaft!$M$15)+1)/DAY(Liegenschaft!$N$15)*Liegenschaft!$O$15) | Q7: =IF(OR(D7="",Liegenschaft!$C$7=""),0,MAX(0,MIN(I7,Liegenschaft!$N$16)-MAX(H7,Liegenschaft!$M$16)+1)/DAY(Liegenschaft!$N$16)*Liegenschaft!$O$16) | R7: =IF(OR(D7="",Liegenschaft!$C$7=""),0,MAX(0,MIN(I7,Liegenschaft!$N$17)-MAX(H7,Liegenschaft!$M$17)+1)/DAY(Liegenschaft!$N$17)*Liegenschaft!$O$17) | S7: =IF(OR(D7="",Liegenschaft!$C$7=""),0,MAX(0,MIN(I7,Liegenschaft!$N$18)-MAX(H7,Liegenschaft!$M$18)+1)/DAY(Liegenschaft!$N$18)*Liegenschaft!$O$18) | T7: =IF(OR(D7="",Liegenschaft!$C$7=""),0,MAX(0,MIN(I7,Liegenschaft!$N$19)-MAX(H7,Liegenschaft!$M$19)+1)/DAY(Liegenschaft!$N$19)*Liegenschaft!$O$19) | U7: =IF(OR(D7="",Liegenschaft!$C$7=""),0,MAX(0,MIN(I7,Liegenschaft!$N$20)-MAX(H7,Liegenschaft!$M$20)+1)/DAY(Liegenschaft!$N$20)*Liegenschaft!$O$20) | V7: =IF(OR(D7="",Liegenschaft!$C$7=""),0,MAX(0,MIN(I7,Liegenschaft!$N$21)-MAX(H7,Liegenschaft!$M$21)+1)/DAY(Liegenschaft!$N$21)*Liegenschaft!$O$21) | W7: =IF(OR(D7="",Liegenschaft!$C$7=""),0,MAX(0,MIN(I7,Liegenschaft!$N$22)-MAX(H7,Liegenschaft!$M$22)+1)/DAY(Liegenschaft!$N$22)*Liegenschaft!$O$22) | X7: =IF(OR(D7="",Liegenschaft!$C$7=""),0,MAX(0,MIN(I7,Liegenschaft!$N$23)-MAX(H7,Liegenschaft!$M$23)+1)/DAY(Liegenschaft!$N$23)*Liegenschaft!$O$23) | Y7: =IF(OR(D7="",Liegenschaft!$C$7=""),0,MAX(0,MIN(I7,Liegenschaft!$N$24)-MAX(H7,Liegenschaft!$M$24)+1)/DAY(Liegenschaft!$N$24)*Liegenschaft!$O$24) | Z7: =IF(OR(D7="",Liegenschaft!$C$7=""),0,MAX(0,MIN(I7,Liegenschaft!$N$25)-MAX(H7,Liegenschaft!$M$25)+1)/DAY(Liegenschaft!$N$25)*Liegenschaft!$O$25)
B8: 3 | H8: =IF(D8="","",MAX(E8,Liegenschaft!$C$7)) | I8: =IF(D8="","",IF(F8="",Liegenschaft!$C$8,MIN(F8,Liegenschaft!$C$8))) | J8: =IF(D8="",0,MAX(0,I8-H8+1)) | K8: =IF(OR(D8="",Liegenschaft!$C$9=""),0,J8/Liegenschaft!$C$9) | L8: =IF(OR(D8="",Liegenschaft!$J$26=0),0,SUM(O8:Z8)/Liegenschaft!$J$26) | M8: =IF(D8="","",IF(ISNA(MATCH(C8,Liegenschaft!$B$14:$B$25,0)),"⚠ Wohnung unbekannt",IF(J8=0,"⚠ nicht in Periode",IF(SUMPRODUCT(($C$6:$C$35=C8)*($D$6:$D$35<>"")*($J$6:$J$35>0)*($H$6:$H$35<=I8)*($I$6:$I$35>=H8))>1,"⚠ Überschneidung mit anderem Mieter","✓")))) | O8: =IF(OR(D8="",Liegenschaft!$C$7=""),0,MAX(0,MIN(I8,Liegenschaft!$N$14)-MAX(H8,Liegenschaft!$M$14)+1)/DAY(Liegenschaft!$N$14)*Liegenschaft!$O$14) | P8: =IF(OR(D8="",Liegenschaft!$C$7=""),0,MAX(0,MIN(I8,Liegenschaft!$N$15)-MAX(H8,Liegenschaft!$M$15)+1)/DAY(Liegenschaft!$N$15)*Liegenschaft!$O$15) | Q8: =IF(OR(D8="",Liegenschaft!$C$7=""),0,MAX(0,MIN(I8,Liegenschaft!$N$16)-MAX(H8,Liegenschaft!$M$16)+1)/DAY(Liegenschaft!$N$16)*Liegenschaft!$O$16) | R8: =IF(OR(D8="",Liegenschaft!$C$7=""),0,MAX(0,MIN(I8,Liegenschaft!$N$17)-MAX(H8,Liegenschaft!$M$17)+1)/DAY(Liegenschaft!$N$17)*Liegenschaft!$O$17) | S8: =IF(OR(D8="",Liegenschaft!$C$7=""),0,MAX(0,MIN(I8,Liegenschaft!$N$18)-MAX(H8,Liegenschaft!$M$18)+1)/DAY(Liegenschaft!$N$18)*Liegenschaft!$O$18) | T8: =IF(OR(D8="",Liegenschaft!$C$7=""),0,MAX(0,MIN(I8,Liegenschaft!$N$19)-MAX(H8,Liegenschaft!$M$19)+1)/DAY(Liegenschaft!$N$19)*Liegenschaft!$O$19) | U8: =IF(OR(D8="",Liegenschaft!$C$7=""),0,MAX(0,MIN(I8,Liegenschaft!$N$20)-MAX(H8,Liegenschaft!$M$20)+1)/DAY(Liegenschaft!$N$20)*Liegenschaft!$O$20) | V8: =IF(OR(D8="",Liegenschaft!$C$7=""),0,MAX(0,MIN(I8,Liegenschaft!$N$21)-MAX(H8,Liegenschaft!$M$21)+1)/DAY(Liegenschaft!$N$21)*Liegenschaft!$O$21) | W8: =IF(OR(D8="",Liegenschaft!$C$7=""),0,MAX(0,MIN(I8,Liegenschaft!$N$22)-MAX(H8,Liegenschaft!$M$22)+1)/DAY(Liegenschaft!$N$22)*Liegenschaft!$O$22) | X8: =IF(OR(D8="",Liegenschaft!$C$7=""),0,MAX(0,MIN(I8,Liegenschaft!$N$23)-MAX(H8,Liegenschaft!$M$23)+1)/DAY(Liegenschaft!$N$23)*Liegenschaft!$O$23) | Y8: =IF(OR(D8="",Liegenschaft!$C$7=""),0,MAX(0,MIN(I8,Liegenschaft!$N$24)-MAX(H8,Liegenschaft!$M$24)+1)/DAY(Liegenschaft!$N$24)*Liegenschaft!$O$24) | Z8: =IF(OR(D8="",Liegenschaft!$C$7=""),0,MAX(0,MIN(I8,Liegenschaft!$N$25)-MAX(H8,Liegenschaft!$M$25)+1)/DAY(Liegenschaft!$N$25)*Liegenschaft!$O$25)
B9: 4 | H9: =IF(D9="","",MAX(E9,Liegenschaft!$C$7)) | I9: =IF(D9="","",IF(F9="",Liegenschaft!$C$8,MIN(F9,Liegenschaft!$C$8))) | J9: =IF(D9="",0,MAX(0,I9-H9+1)) | K9: =IF(OR(D9="",Liegenschaft!$C$9=""),0,J9/Liegenschaft!$C$9) | L9: =IF(OR(D9="",Liegenschaft!$J$26=0),0,SUM(O9:Z9)/Liegenschaft!$J$26) | M9: =IF(D9="","",IF(ISNA(MATCH(C9,Liegenschaft!$B$14:$B$25,0)),"⚠ Wohnung unbekannt",IF(J9=0,"⚠ nicht in Periode",IF(SUMPRODUCT(($C$6:$C$35=C9)*($D$6:$D$35<>"")*($J$6:$J$35>0)*($H$6:$H$35<=I9)*($I$6:$I$35>=H9))>1,"⚠ Überschneidung mit anderem Mieter","✓")))) | O9: =IF(OR(D9="",Liegenschaft!$C$7=""),0,MAX(0,MIN(I9,Liegenschaft!$N$14)-MAX(H9,Liegenschaft!$M$14)+1)/DAY(Liegenschaft!$N$14)*Liegenschaft!$O$14) | P9: =IF(OR(D9="",Liegenschaft!$C$7=""),0,MAX(0,MIN(I9,Liegenschaft!$N$15)-MAX(H9,Liegenschaft!$M$15)+1)/DAY(Liegenschaft!$N$15)*Liegenschaft!$O$15) | Q9: =IF(OR(D9="",Liegenschaft!$C$7=""),0,MAX(0,MIN(I9,Liegenschaft!$N$16)-MAX(H9,Liegenschaft!$M$16)+1)/DAY(Liegenschaft!$N$16)*Liegenschaft!$O$16) | R9: =IF(OR(D9="",Liegenschaft!$C$7=""),0,MAX(0,MIN(I9,Liegenschaft!$N$17)-MAX(H9,Liegenschaft!$M$17)+1)/DAY(Liegenschaft!$N$17)*Liegenschaft!$O$17) | S9: =IF(OR(D9="",Liegenschaft!$C$7=""),0,MAX(0,MIN(I9,Liegenschaft!$N$18)-MAX(H9,Liegenschaft!$M$18)+1)/DAY(Liegenschaft!$N$18)*Liegenschaft!$O$18) | T9: =IF(OR(D9="",Liegenschaft!$C$7=""),0,MAX(0,MIN(I9,Liegenschaft!$N$19)-MAX(H9,Liegenschaft!$M$19)+1)/DAY(Liegenschaft!$N$19)*Liegenschaft!$O$19) | U9: =IF(OR(D9="",Liegenschaft!$C$7=""),0,MAX(0,MIN(I9,Liegenschaft!$N$20)-MAX(H9,Liegenschaft!$M$20)+1)/DAY(Liegenschaft!$N$20)*Liegenschaft!$O$20) | V9: =IF(OR(D9="",Liegenschaft!$C$7=""),0,MAX(0,MIN(I9,Liegenschaft!$N$21)-MAX(H9,Liegenschaft!$M$21)+1)/DAY(Liegenschaft!$N$21)*Liegenschaft!$O$21) | W9: =IF(OR(D9="",Liegenschaft!$C$7=""),0,MAX(0,MIN(I9,Liegenschaft!$N$22)-MAX(H9,Liegenschaft!$M$22)+1)/DAY(Liegenschaft!$N$22)*Liegenschaft!$O$22) | X9: =IF(OR(D9="",Liegenschaft!$C$7=""),0,MAX(0,MIN(I9,Liegenschaft!$N$23)-MAX(H9,Liegenschaft!$M$23)+1)/DAY(Liegenschaft!$N$23)*Liegenschaft!$O$23) | Y9: =IF(OR(D9="",Liegenschaft!$C$7=""),0,MAX(0,MIN(I9,Liegenschaft!$N$24)-MAX(H9,Liegenschaft!$M$24)+1)/DAY(Liegenschaft!$N$24)*Liegenschaft!$O$24) | Z9: =IF(OR(D9="",Liegenschaft!$C$7=""),0,MAX(0,MIN(I9,Liegenschaft!$N$25)-MAX(H9,Liegenschaft!$M$25)+1)/DAY(Liegenschaft!$N$25)*Liegenschaft!$O$25)
B10: 5 | H10: =IF(D10="","",MAX(E10,Liegenschaft!$C$7)) | I10: =IF(D10="","",IF(F10="",Liegenschaft!$C$8,MIN(F10,Liegenschaft!$C$8))) | J10: =IF(D10="",0,MAX(0,I10-H10+1)) | K10: =IF(OR(D10="",Liegenschaft!$C$9=""),0,J10/Liegenschaft!$C$9) | L10: =IF(OR(D10="",Liegenschaft!$J$26=0),0,SUM(O10:Z10)/Liegenschaft!$J$26) | M10: =IF(D10="","",IF(ISNA(MATCH(C10,Liegenschaft!$B$14:$B$25,0)),"⚠ Wohnung unbekannt",IF(J10=0,"⚠ nicht in Periode",IF(SUMPRODUCT(($C$6:$C$35=C10)*($D$6:$D$35<>"")*($J$6:$J$35>0)*($H$6:$H$35<=I10)*($I$6:$I$35>=H10))>1,"⚠ Überschneidung mit anderem Mieter","✓")))) | O10: =IF(OR(D10="",Liegenschaft!$C$7=""),0,MAX(0,MIN(I10,Liegenschaft!$N$14)-MAX(H10,Liegenschaft!$M$14)+1)/DAY(Liegenschaft!$N$14)*Liegenschaft!$O$14) | P10: =IF(OR(D10="",Liegenschaft!$C$7=""),0,MAX(0,MIN(I10,Liegenschaft!$N$15)-MAX(H10,Liegenschaft!$M$15)+1)/DAY(Liegenschaft!$N$15)*Liegenschaft!$O$15) | Q10: =IF(OR(D10="",Liegenschaft!$C$7=""),0,MAX(0,MIN(I10,Liegenschaft!$N$16)-MAX(H10,Liegenschaft!$M$16)+1)/DAY(Liegenschaft!$N$16)*Liegenschaft!$O$16) | R10: =IF(OR(D10="",Liegenschaft!$C$7=""),0,MAX(0,MIN(I10,Liegenschaft!$N$17)-MAX(H10,Liegenschaft!$M$17)+1)/DAY(Liegenschaft!$N$17)*Liegenschaft!$O$17) | S10: =IF(OR(D10="",Liegenschaft!$C$7=""),0,MAX(0,MIN(I10,Liegenschaft!$N$18)-MAX(H10,Liegenschaft!$M$18)+1)/DAY(Liegenschaft!$N$18)*Liegenschaft!$O$18) | T10: =IF(OR(D10="",Liegenschaft!$C$7=""),0,MAX(0,MIN(I10,Liegenschaft!$N$19)-MAX(H10,Liegenschaft!$M$19)+1)/DAY(Liegenschaft!$N$19)*Liegenschaft!$O$19) | U10: =IF(OR(D10="",Liegenschaft!$C$7=""),0,MAX(0,MIN(I10,Liegenschaft!$N$20)-MAX(H10,Liegenschaft!$M$20)+1)/DAY(Liegenschaft!$N$20)*Liegenschaft!$O$20) | V10: =IF(OR(D10="",Liegenschaft!$C$7=""),0,MAX(0,MIN(I10,Liegenschaft!$N$21)-MAX(H10,Liegenschaft!$M$21)+1)/DAY(Liegenschaft!$N$21)*Liegenschaft!$O$21) | W10: =IF(OR(D10="",Liegenschaft!$C$7=""),0,MAX(0,MIN(I10,Liegenschaft!$N$22)-MAX(H10,Liegenschaft!$M$22)+1)/DAY(Liegenschaft!$N$22)*Liegenschaft!$O$22) | X10: =IF(OR(D10="",Liegenschaft!$C$7=""),0,MAX(0,MIN(I10,Liegenschaft!$N$23)-MAX(H10,Liegenschaft!$M$23)+1)/DAY(Liegenschaft!$N$23)*Liegenschaft!$O$23) | Y10: =IF(OR(D10="",Liegenschaft!$C$7=""),0,MAX(0,MIN(I10,Liegenschaft!$N$24)-MAX(H10,Liegenschaft!$M$24)+1)/DAY(Liegenschaft!$N$24)*Liegenschaft!$O$24) | Z10: =IF(OR(D10="",Liegenschaft!$C$7=""),0,MAX(0,MIN(I10,Liegenschaft!$N$25)-MAX(H10,Liegenschaft!$M$25)+1)/DAY(Liegenschaft!$N$25)*Liegenschaft!$O$25)
B11: 6 | H11: =IF(D11="","",MAX(E11,Liegenschaft!$C$7)) | I11: =IF(D11="","",IF(F11="",Liegenschaft!$C$8,MIN(F11,Liegenschaft!$C$8))) | J11: =IF(D11="",0,MAX(0,I11-H11+1)) | K11: =IF(OR(D11="",Liegenschaft!$C$9=""),0,J11/Liegenschaft!$C$9) | L11: =IF(OR(D11="",Liegenschaft!$J$26=0),0,SUM(O11:Z11)/Liegenschaft!$J$26) | M11: =IF(D11="","",IF(ISNA(MATCH(C11,Liegenschaft!$B$14:$B$25,0)),"⚠ Wohnung unbekannt",IF(J11=0,"⚠ nicht in Periode",IF(SUMPRODUCT(($C$6:$C$35=C11)*($D$6:$D$35<>"")*($J$6:$J$35>0)*($H$6:$H$35<=I11)*($I$6:$I$35>=H11))>1,"⚠ Überschneidung mit anderem Mieter","✓")))) | O11: =IF(OR(D11="",Liegenschaft!$C$7=""),0,MAX(0,MIN(I11,Liegenschaft!$N$14)-MAX(H11,Liegenschaft!$M$14)+1)/DAY(Liegenschaft!$N$14)*Liegenschaft!$O$14) | P11: =IF(OR(D11="",Liegenschaft!$C$7=""),0,MAX(0,MIN(I11,Liegenschaft!$N$15)-MAX(H11,Liegenschaft!$M$15)+1)/DAY(Liegenschaft!$N$15)*Liegenschaft!$O$15) | Q11: =IF(OR(D11="",Liegenschaft!$C$7=""),0,MAX(0,MIN(I11,Liegenschaft!$N$16)-MAX(H11,Liegenschaft!$M$16)+1)/DAY(Liegenschaft!$N$16)*Liegenschaft!$O$16) | R11: =IF(OR(D11="",Liegenschaft!$C$7=""),0,MAX(0,MIN(I11,Liegenschaft!$N$17)-MAX(H11,Liegenschaft!$M$17)+1)/DAY(Liegenschaft!$N$17)*Liegenschaft!$O$17) | S11: =IF(OR(D11="",Liegenschaft!$C$7=""),0,MAX(0,MIN(I11,Liegenschaft!$N$18)-MAX(H11,Liegenschaft!$M$18)+1)/DAY(Liegenschaft!$N$18)*Liegenschaft!$O$18) | T11: =IF(OR(D11="",Liegenschaft!$C$7=""),0,MAX(0,MIN(I11,Liegenschaft!$N$19)-MAX(H11,Liegenschaft!$M$19)+1)/DAY(Liegenschaft!$N$19)*Liegenschaft!$O$19) | U11: =IF(OR(D11="",Liegenschaft!$C$7=""),0,MAX(0,MIN(I11,Liegenschaft!$N$20)-MAX(H11,Liegenschaft!$M$20)+1)/DAY(Liegenschaft!$N$20)*Liegenschaft!$O$20) | V11: =IF(OR(D11="",Liegenschaft!$C$7=""),0,MAX(0,MIN(I11,Liegenschaft!$N$21)-MAX(H11,Liegenschaft!$M$21)+1)/DAY(Liegenschaft!$N$21)*Liegenschaft!$O$21) | W11: =IF(OR(D11="",Liegenschaft!$C$7=""),0,MAX(0,MIN(I11,Liegenschaft!$N$22)-MAX(H11,Liegenschaft!$M$22)+1)/DAY(Liegenschaft!$N$22)*Liegenschaft!$O$22) | X11: =IF(OR(D11="",Liegenschaft!$C$7=""),0,MAX(0,MIN(I11,Liegenschaft!$N$23)-MAX(H11,Liegenschaft!$M$23)+1)/DAY(Liegenschaft!$N$23)*Liegenschaft!$O$23) | Y11: =IF(OR(D11="",Liegenschaft!$C$7=""),0,MAX(0,MIN(I11,Liegenschaft!$N$24)-MAX(H11,Liegenschaft!$M$24)+1)/DAY(Liegenschaft!$N$24)*Liegenschaft!$O$24) | Z11: =IF(OR(D11="",Liegenschaft!$C$7=""),0,MAX(0,MIN(I11,Liegenschaft!$N$25)-MAX(H11,Liegenschaft!$M$25)+1)/DAY(Liegenschaft!$N$25)*Liegenschaft!$O$25)
B12: 7 | H12: =IF(D12="","",MAX(E12,Liegenschaft!$C$7)) | I12: =IF(D12="","",IF(F12="",Liegenschaft!$C$8,MIN(F12,Liegenschaft!$C$8))) | J12: =IF(D12="",0,MAX(0,I12-H12+1)) | K12: =IF(OR(D12="",Liegenschaft!$C$9=""),0,J12/Liegenschaft!$C$9) | L12: =IF(OR(D12="",Liegenschaft!$J$26=0),0,SUM(O12:Z12)/Liegenschaft!$J$26) | M12: =IF(D12="","",IF(ISNA(MATCH(C12,Liegenschaft!$B$14:$B$25,0)),"⚠ Wohnung unbekannt",IF(J12=0,"⚠ nicht in Periode",IF(SUMPRODUCT(($C$6:$C$35=C12)*($D$6:$D$35<>"")*($J$6:$J$35>0)*($H$6:$H$35<=I12)*($I$6:$I$35>=H12))>1,"⚠ Überschneidung mit anderem Mieter","✓")))) | O12: =IF(OR(D12="",Liegenschaft!$C$7=""),0,MAX(0,MIN(I12,Liegenschaft!$N$14)-MAX(H12,Liegenschaft!$M$14)+1)/DAY(Liegenschaft!$N$14)*Liegenschaft!$O$14) | P12: =IF(OR(D12="",Liegenschaft!$C$7=""),0,MAX(0,MIN(I12,Liegenschaft!$N$15)-MAX(H12,Liegenschaft!$M$15)+1)/DAY(Liegenschaft!$N$15)*Liegenschaft!$O$15) | Q12: =IF(OR(D12="",Liegenschaft!$C$7=""),0,MAX(0,MIN(I12,Liegenschaft!$N$16)-MAX(H12,Liegenschaft!$M$16)+1)/DAY(Liegenschaft!$N$16)*Liegenschaft!$O$16) | R12: =IF(OR(D12="",Liegenschaft!$C$7=""),0,MAX(0,MIN(I12,Liegenschaft!$N$17)-MAX(H12,Liegenschaft!$M$17)+1)/DAY(Liegenschaft!$N$17)*Liegenschaft!$O$17) | S12: =IF(OR(D12="",Liegenschaft!$C$7=""),0,MAX(0,MIN(I12,Liegenschaft!$N$18)-MAX(H12,Liegenschaft!$M$18)+1)/DAY(Liegenschaft!$N$18)*Liegenschaft!$O$18) | T12: =IF(OR(D12="",Liegenschaft!$C$7=""),0,MAX(0,MIN(I12,Liegenschaft!$N$19)-MAX(H12,Liegenschaft!$M$19)+1)/DAY(Liegenschaft!$N$19)*Liegenschaft!$O$19) | U12: =IF(OR(D12="",Liegenschaft!$C$7=""),0,MAX(0,MIN(I12,Liegenschaft!$N$20)-MAX(H12,Liegenschaft!$M$20)+1)/DAY(Liegenschaft!$N$20)*Liegenschaft!$O$20) | V12: =IF(OR(D12="",Liegenschaft!$C$7=""),0,MAX(0,MIN(I12,Liegenschaft!$N$21)-MAX(H12,Liegenschaft!$M$21)+1)/DAY(Liegenschaft!$N$21)*Liegenschaft!$O$21) | W12: =IF(OR(D12="",Liegenschaft!$C$7=""),0,MAX(0,MIN(I12,Liegenschaft!$N$22)-MAX(H12,Liegenschaft!$M$22)+1)/DAY(Liegenschaft!$N$22)*Liegenschaft!$O$22) | X12: =IF(OR(D12="",Liegenschaft!$C$7=""),0,MAX(0,MIN(I12,Liegenschaft!$N$23)-MAX(H12,Liegenschaft!$M$23)+1)/DAY(Liegenschaft!$N$23)*Liegenschaft!$O$23) | Y12: =IF(OR(D12="",Liegenschaft!$C$7=""),0,MAX(0,MIN(I12,Liegenschaft!$N$24)-MAX(H12,Liegenschaft!$M$24)+1)/DAY(Liegenschaft!$N$24)*Liegenschaft!$O$24) | Z12: =IF(OR(D12="",Liegenschaft!$C$7=""),0,MAX(0,MIN(I12,Liegenschaft!$N$25)-MAX(H12,Liegenschaft!$M$25)+1)/DAY(Liegenschaft!$N$25)*Liegenschaft!$O$25)
B13: 8 | H13: =IF(D13="","",MAX(E13,Liegenschaft!$C$7)) | I13: =IF(D13="","",IF(F13="",Liegenschaft!$C$8,MIN(F13,Liegenschaft!$C$8))) | J13: =IF(D13="",0,MAX(0,I13-H13+1)) | K13: =IF(OR(D13="",Liegenschaft!$C$9=""),0,J13/Liegenschaft!$C$9) | L13: =IF(OR(D13="",Liegenschaft!$J$26=0),0,SUM(O13:Z13)/Liegenschaft!$J$26) | M13: =IF(D13="","",IF(ISNA(MATCH(C13,Liegenschaft!$B$14:$B$25,0)),"⚠ Wohnung unbekannt",IF(J13=0,"⚠ nicht in Periode",IF(SUMPRODUCT(($C$6:$C$35=C13)*($D$6:$D$35<>"")*($J$6:$J$35>0)*($H$6:$H$35<=I13)*($I$6:$I$35>=H13))>1,"⚠ Überschneidung mit anderem Mieter","✓")))) | O13: =IF(OR(D13="",Liegenschaft!$C$7=""),0,MAX(0,MIN(I13,Liegenschaft!$N$14)-MAX(H13,Liegenschaft!$M$14)+1)/DAY(Liegenschaft!$N$14)*Liegenschaft!$O$14) | P13: =IF(OR(D13="",Liegenschaft!$C$7=""),0,MAX(0,MIN(I13,Liegenschaft!$N$15)-MAX(H13,Liegenschaft!$M$15)+1)/DAY(Liegenschaft!$N$15)*Liegenschaft!$O$15) | Q13: =IF(OR(D13="",Liegenschaft!$C$7=""),0,MAX(0,MIN(I13,Liegenschaft!$N$16)-MAX(H13,Liegenschaft!$M$16)+1)/DAY(Liegenschaft!$N$16)*Liegenschaft!$O$16) | R13: =IF(OR(D13="",Liegenschaft!$C$7=""),0,MAX(0,MIN(I13,Liegenschaft!$N$17)-MAX(H13,Liegenschaft!$M$17)+1)/DAY(Liegenschaft!$N$17)*Liegenschaft!$O$17) | S13: =IF(OR(D13="",Liegenschaft!$C$7=""),0,MAX(0,MIN(I13,Liegenschaft!$N$18)-MAX(H13,Liegenschaft!$M$18)+1)/DAY(Liegenschaft!$N$18)*Liegenschaft!$O$18) | T13: =IF(OR(D13="",Liegenschaft!$C$7=""),0,MAX(0,MIN(I13,Liegenschaft!$N$19)-MAX(H13,Liegenschaft!$M$19)+1)/DAY(Liegenschaft!$N$19)*Liegenschaft!$O$19) | U13: =IF(OR(D13="",Liegenschaft!$C$7=""),0,MAX(0,MIN(I13,Liegenschaft!$N$20)-MAX(H13,Liegenschaft!$M$20)+1)/DAY(Liegenschaft!$N$20)*Liegenschaft!$O$20) | V13: =IF(OR(D13="",Liegenschaft!$C$7=""),0,MAX(0,MIN(I13,Liegenschaft!$N$21)-MAX(H13,Liegenschaft!$M$21)+1)/DAY(Liegenschaft!$N$21)*Liegenschaft!$O$21) | W13: =IF(OR(D13="",Liegenschaft!$C$7=""),0,MAX(0,MIN(I13,Liegenschaft!$N$22)-MAX(H13,Liegenschaft!$M$22)+1)/DAY(Liegenschaft!$N$22)*Liegenschaft!$O$22) | X13: =IF(OR(D13="",Liegenschaft!$C$7=""),0,MAX(0,MIN(I13,Liegenschaft!$N$23)-MAX(H13,Liegenschaft!$M$23)+1)/DAY(Liegenschaft!$N$23)*Liegenschaft!$O$23) | Y13: =IF(OR(D13="",Liegenschaft!$C$7=""),0,MAX(0,MIN(I13,Liegenschaft!$N$24)-MAX(H13,Liegenschaft!$M$24)+1)/DAY(Liegenschaft!$N$24)*Liegenschaft!$O$24) | Z13: =IF(OR(D13="",Liegenschaft!$C$7=""),0,MAX(0,MIN(I13,Liegenschaft!$N$25)-MAX(H13,Liegenschaft!$M$25)+1)/DAY(Liegenschaft!$N$25)*Liegenschaft!$O$25)
B14: 9 | H14: =IF(D14="","",MAX(E14,Liegenschaft!$C$7)) | I14: =IF(D14="","",IF(F14="",Liegenschaft!$C$8,MIN(F14,Liegenschaft!$C$8))) | J14: =IF(D14="",0,MAX(0,I14-H14+1)) | K14: =IF(OR(D14="",Liegenschaft!$C$9=""),0,J14/Liegenschaft!$C$9) | L14: =IF(OR(D14="",Liegenschaft!$J$26=0),0,SUM(O14:Z14)/Liegenschaft!$J$26) | M14: =IF(D14="","",IF(ISNA(MATCH(C14,Liegenschaft!$B$14:$B$25,0)),"⚠ Wohnung unbekannt",IF(J14=0,"⚠ nicht in Periode",IF(SUMPRODUCT(($C$6:$C$35=C14)*($D$6:$D$35<>"")*($J$6:$J$35>0)*($H$6:$H$35<=I14)*($I$6:$I$35>=H14))>1,"⚠ Überschneidung mit anderem Mieter","✓")))) | O14: =IF(OR(D14="",Liegenschaft!$C$7=""),0,MAX(0,MIN(I14,Liegenschaft!$N$14)-MAX(H14,Liegenschaft!$M$14)+1)/DAY(Liegenschaft!$N$14)*Liegenschaft!$O$14) | P14: =IF(OR(D14="",Liegenschaft!$C$7=""),0,MAX(0,MIN(I14,Liegenschaft!$N$15)-MAX(H14,Liegenschaft!$M$15)+1)/DAY(Liegenschaft!$N$15)*Liegenschaft!$O$15) | Q14: =IF(OR(D14="",Liegenschaft!$C$7=""),0,MAX(0,MIN(I14,Liegenschaft!$N$16)-MAX(H14,Liegenschaft!$M$16)+1)/DAY(Liegenschaft!$N$16)*Liegenschaft!$O$16) | R14: =IF(OR(D14="",Liegenschaft!$C$7=""),0,MAX(0,MIN(I14,Liegenschaft!$N$17)-MAX(H14,Liegenschaft!$M$17)+1)/DAY(Liegenschaft!$N$17)*Liegenschaft!$O$17) | S14: =IF(OR(D14="",Liegenschaft!$C$7=""),0,MAX(0,MIN(I14,Liegenschaft!$N$18)-MAX(H14,Liegenschaft!$M$18)+1)/DAY(Liegenschaft!$N$18)*Liegenschaft!$O$18) | T14: =IF(OR(D14="",Liegenschaft!$C$7=""),0,MAX(0,MIN(I14,Liegenschaft!$N$19)-MAX(H14,Liegenschaft!$M$19)+1)/DAY(Liegenschaft!$N$19)*Liegenschaft!$O$19) | U14: =IF(OR(D14="",Liegenschaft!$C$7=""),0,MAX(0,MIN(I14,Liegenschaft!$N$20)-MAX(H14,Liegenschaft!$M$20)+1)/DAY(Liegenschaft!$N$20)*Liegenschaft!$O$20) | V14: =IF(OR(D14="",Liegenschaft!$C$7=""),0,MAX(0,MIN(I14,Liegenschaft!$N$21)-MAX(H14,Liegenschaft!$M$21)+1)/DAY(Liegenschaft!$N$21)*Liegenschaft!$O$21) | W14: =IF(OR(D14="",Liegenschaft!$C$7=""),0,MAX(0,MIN(I14,Liegenschaft!$N$22)-MAX(H14,Liegenschaft!$M$22)+1)/DAY(Liegenschaft!$N$22)*Liegenschaft!$O$22) | X14: =IF(OR(D14="",Liegenschaft!$C$7=""),0,MAX(0,MIN(I14,Liegenschaft!$N$23)-MAX(H14,Liegenschaft!$M$23)+1)/DAY(Liegenschaft!$N$23)*Liegenschaft!$O$23) | Y14: =IF(OR(D14="",Liegenschaft!$C$7=""),0,MAX(0,MIN(I14,Liegenschaft!$N$24)-MAX(H14,Liegenschaft!$M$24)+1)/DAY(Liegenschaft!$N$24)*Liegenschaft!$O$24) | Z14: =IF(OR(D14="",Liegenschaft!$C$7=""),0,MAX(0,MIN(I14,Liegenschaft!$N$25)-MAX(H14,Liegenschaft!$M$25)+1)/DAY(Liegenschaft!$N$25)*Liegenschaft!$O$25)
B15: 10 | H15: =IF(D15="","",MAX(E15,Liegenschaft!$C$7)) | I15: =IF(D15="","",IF(F15="",Liegenschaft!$C$8,MIN(F15,Liegenschaft!$C$8))) | J15: =IF(D15="",0,MAX(0,I15-H15+1)) | K15: =IF(OR(D15="",Liegenschaft!$C$9=""),0,J15/Liegenschaft!$C$9) | L15: =IF(OR(D15="",Liegenschaft!$J$26=0),0,SUM(O15:Z15)/Liegenschaft!$J$26) | M15: =IF(D15="","",IF(ISNA(MATCH(C15,Liegenschaft!$B$14:$B$25,0)),"⚠ Wohnung unbekannt",IF(J15=0,"⚠ nicht in Periode",IF(SUMPRODUCT(($C$6:$C$35=C15)*($D$6:$D$35<>"")*($J$6:$J$35>0)*($H$6:$H$35<=I15)*($I$6:$I$35>=H15))>1,"⚠ Überschneidung mit anderem Mieter","✓")))) | O15: =IF(OR(D15="",Liegenschaft!$C$7=""),0,MAX(0,MIN(I15,Liegenschaft!$N$14)-MAX(H15,Liegenschaft!$M$14)+1)/DAY(Liegenschaft!$N$14)*Liegenschaft!$O$14) | P15: =IF(OR(D15="",Liegenschaft!$C$7=""),0,MAX(0,MIN(I15,Liegenschaft!$N$15)-MAX(H15,Liegenschaft!$M$15)+1)/DAY(Liegenschaft!$N$15)*Liegenschaft!$O$15) | Q15: =IF(OR(D15="",Liegenschaft!$C$7=""),0,MAX(0,MIN(I15,Liegenschaft!$N$16)-MAX(H15,Liegenschaft!$M$16)+1)/DAY(Liegenschaft!$N$16)*Liegenschaft!$O$16) | R15: =IF(OR(D15="",Liegenschaft!$C$7=""),0,MAX(0,MIN(I15,Liegenschaft!$N$17)-MAX(H15,Liegenschaft!$M$17)+1)/DAY(Liegenschaft!$N$17)*Liegenschaft!$O$17) | S15: =IF(OR(D15="",Liegenschaft!$C$7=""),0,MAX(0,MIN(I15,Liegenschaft!$N$18)-MAX(H15,Liegenschaft!$M$18)+1)/DAY(Liegenschaft!$N$18)*Liegenschaft!$O$18) | T15: =IF(OR(D15="",Liegenschaft!$C$7=""),0,MAX(0,MIN(I15,Liegenschaft!$N$19)-MAX(H15,Liegenschaft!$M$19)+1)/DAY(Liegenschaft!$N$19)*Liegenschaft!$O$19) | U15: =IF(OR(D15="",Liegenschaft!$C$7=""),0,MAX(0,MIN(I15,Liegenschaft!$N$20)-MAX(H15,Liegenschaft!$M$20)+1)/DAY(Liegenschaft!$N$20)*Liegenschaft!$O$20) | V15: =IF(OR(D15="",Liegenschaft!$C$7=""),0,MAX(0,MIN(I15,Liegenschaft!$N$21)-MAX(H15,Liegenschaft!$M$21)+1)/DAY(Liegenschaft!$N$21)*Liegenschaft!$O$21) | W15: =IF(OR(D15="",Liegenschaft!$C$7=""),0,MAX(0,MIN(I15,Liegenschaft!$N$22)-MAX(H15,Liegenschaft!$M$22)+1)/DAY(Liegenschaft!$N$22)*Liegenschaft!$O$22) | X15: =IF(OR(D15="",Liegenschaft!$C$7=""),0,MAX(0,MIN(I15,Liegenschaft!$N$23)-MAX(H15,Liegenschaft!$M$23)+1)/DAY(Liegenschaft!$N$23)*Liegenschaft!$O$23) | Y15: =IF(OR(D15="",Liegenschaft!$C$7=""),0,MAX(0,MIN(I15,Liegenschaft!$N$24)-MAX(H15,Liegenschaft!$M$24)+1)/DAY(Liegenschaft!$N$24)*Liegenschaft!$O$24) | Z15: =IF(OR(D15="",Liegenschaft!$C$7=""),0,MAX(0,MIN(I15,Liegenschaft!$N$25)-MAX(H15,Liegenschaft!$M$25)+1)/DAY(Liegenschaft!$N$25)*Liegenschaft!$O$25)
B16: 11 | H16: =IF(D16="","",MAX(E16,Liegenschaft!$C$7)) | I16: =IF(D16="","",IF(F16="",Liegenschaft!$C$8,MIN(F16,Liegenschaft!$C$8))) | J16: =IF(D16="",0,MAX(0,I16-H16+1)) | K16: =IF(OR(D16="",Liegenschaft!$C$9=""),0,J16/Liegenschaft!$C$9) | L16: =IF(OR(D16="",Liegenschaft!$J$26=0),0,SUM(O16:Z16)/Liegenschaft!$J$26) | M16: =IF(D16="","",IF(ISNA(MATCH(C16,Liegenschaft!$B$14:$B$25,0)),"⚠ Wohnung unbekannt",IF(J16=0,"⚠ nicht in Periode",IF(SUMPRODUCT(($C$6:$C$35=C16)*($D$6:$D$35<>"")*($J$6:$J$35>0)*($H$6:$H$35<=I16)*($I$6:$I$35>=H16))>1,"⚠ Überschneidung mit anderem Mieter","✓")))) | O16: =IF(OR(D16="",Liegenschaft!$C$7=""),0,MAX(0,MIN(I16,Liegenschaft!$N$14)-MAX(H16,Liegenschaft!$M$14)+1)/DAY(Liegenschaft!$N$14)*Liegenschaft!$O$14) | P16: =IF(OR(D16="",Liegenschaft!$C$7=""),0,MAX(0,MIN(I16,Liegenschaft!$N$15)-MAX(H16,Liegenschaft!$M$15)+1)/DAY(Liegenschaft!$N$15)*Liegenschaft!$O$15) | Q16: =IF(OR(D16="",Liegenschaft!$C$7=""),0,MAX(0,MIN(I16,Liegenschaft!$N$16)-MAX(H16,Liegenschaft!$M$16)+1)/DAY(Liegenschaft!$N$16)*Liegenschaft!$O$16) | R16: =IF(OR(D16="",Liegenschaft!$C$7=""),0,MAX(0,MIN(I16,Liegenschaft!$N$17)-MAX(H16,Liegenschaft!$M$17)+1)/DAY(Liegenschaft!$N$17)*Liegenschaft!$O$17) | S16: =IF(OR(D16="",Liegenschaft!$C$7=""),0,MAX(0,MIN(I16,Liegenschaft!$N$18)-MAX(H16,Liegenschaft!$M$18)+1)/DAY(Liegenschaft!$N$18)*Liegenschaft!$O$18) | T16: =IF(OR(D16="",Liegenschaft!$C$7=""),0,MAX(0,MIN(I16,Liegenschaft!$N$19)-MAX(H16,Liegenschaft!$M$19)+1)/DAY(Liegenschaft!$N$19)*Liegenschaft!$O$19) | U16: =IF(OR(D16="",Liegenschaft!$C$7=""),0,MAX(0,MIN(I16,Liegenschaft!$N$20)-MAX(H16,Liegenschaft!$M$20)+1)/DAY(Liegenschaft!$N$20)*Liegenschaft!$O$20) | V16: =IF(OR(D16="",Liegenschaft!$C$7=""),0,MAX(0,MIN(I16,Liegenschaft!$N$21)-MAX(H16,Liegenschaft!$M$21)+1)/DAY(Liegenschaft!$N$21)*Liegenschaft!$O$21) | W16: =IF(OR(D16="",Liegenschaft!$C$7=""),0,MAX(0,MIN(I16,Liegenschaft!$N$22)-MAX(H16,Liegenschaft!$M$22)+1)/DAY(Liegenschaft!$N$22)*Liegenschaft!$O$22) | X16: =IF(OR(D16="",Liegenschaft!$C$7=""),0,MAX(0,MIN(I16,Liegenschaft!$N$23)-MAX(H16,Liegenschaft!$M$23)+1)/DAY(Liegenschaft!$N$23)*Liegenschaft!$O$23) | Y16: =IF(OR(D16="",Liegenschaft!$C$7=""),0,MAX(0,MIN(I16,Liegenschaft!$N$24)-MAX(H16,Liegenschaft!$M$24)+1)/DAY(Liegenschaft!$N$24)*Liegenschaft!$O$24) | Z16: =IF(OR(D16="",Liegenschaft!$C$7=""),0,MAX(0,MIN(I16,Liegenschaft!$N$25)-MAX(H16,Liegenschaft!$M$25)+1)/DAY(Liegenschaft!$N$25)*Liegenschaft!$O$25)
B17: 12 | H17: =IF(D17="","",MAX(E17,Liegenschaft!$C$7)) | I17: =IF(D17="","",IF(F17="",Liegenschaft!$C$8,MIN(F17,Liegenschaft!$C$8))) | J17: =IF(D17="",0,MAX(0,I17-H17+1)) | K17: =IF(OR(D17="",Liegenschaft!$C$9=""),0,J17/Liegenschaft!$C$9) | L17: =IF(OR(D17="",Liegenschaft!$J$26=0),0,SUM(O17:Z17)/Liegenschaft!$J$26) | M17: =IF(D17="","",IF(ISNA(MATCH(C17,Liegenschaft!$B$14:$B$25,0)),"⚠ Wohnung unbekannt",IF(J17=0,"⚠ nicht in Periode",IF(SUMPRODUCT(($C$6:$C$35=C17)*($D$6:$D$35<>"")*($J$6:$J$35>0)*($H$6:$H$35<=I17)*($I$6:$I$35>=H17))>1,"⚠ Überschneidung mit anderem Mieter","✓")))) | O17: =IF(OR(D17="",Liegenschaft!$C$7=""),0,MAX(0,MIN(I17,Liegenschaft!$N$14)-MAX(H17,Liegenschaft!$M$14)+1)/DAY(Liegenschaft!$N$14)*Liegenschaft!$O$14) | P17: =IF(OR(D17="",Liegenschaft!$C$7=""),0,MAX(0,MIN(I17,Liegenschaft!$N$15)-MAX(H17,Liegenschaft!$M$15)+1)/DAY(Liegenschaft!$N$15)*Liegenschaft!$O$15) | Q17: =IF(OR(D17="",Liegenschaft!$C$7=""),0,MAX(0,MIN(I17,Liegenschaft!$N$16)-MAX(H17,Liegenschaft!$M$16)+1)/DAY(Liegenschaft!$N$16)*Liegenschaft!$O$16) | R17: =IF(OR(D17="",Liegenschaft!$C$7=""),0,MAX(0,MIN(I17,Liegenschaft!$N$17)-MAX(H17,Liegenschaft!$M$17)+1)/DAY(Liegenschaft!$N$17)*Liegenschaft!$O$17) | S17: =IF(OR(D17="",Liegenschaft!$C$7=""),0,MAX(0,MIN(I17,Liegenschaft!$N$18)-MAX(H17,Liegenschaft!$M$18)+1)/DAY(Liegenschaft!$N$18)*Liegenschaft!$O$18) | T17: =IF(OR(D17="",Liegenschaft!$C$7=""),0,MAX(0,MIN(I17,Liegenschaft!$N$19)-MAX(H17,Liegenschaft!$M$19)+1)/DAY(Liegenschaft!$N$19)*Liegenschaft!$O$19) | U17: =IF(OR(D17="",Liegenschaft!$C$7=""),0,MAX(0,MIN(I17,Liegenschaft!$N$20)-MAX(H17,Liegenschaft!$M$20)+1)/DAY(Liegenschaft!$N$20)*Liegenschaft!$O$20) | V17: =IF(OR(D17="",Liegenschaft!$C$7=""),0,MAX(0,MIN(I17,Liegenschaft!$N$21)-MAX(H17,Liegenschaft!$M$21)+1)/DAY(Liegenschaft!$N$21)*Liegenschaft!$O$21) | W17: =IF(OR(D17="",Liegenschaft!$C$7=""),0,MAX(0,MIN(I17,Liegenschaft!$N$22)-MAX(H17,Liegenschaft!$M$22)+1)/DAY(Liegenschaft!$N$22)*Liegenschaft!$O$22) | X17: =IF(OR(D17="",Liegenschaft!$C$7=""),0,MAX(0,MIN(I17,Liegenschaft!$N$23)-MAX(H17,Liegenschaft!$M$23)+1)/DAY(Liegenschaft!$N$23)*Liegenschaft!$O$23) | Y17: =IF(OR(D17="",Liegenschaft!$C$7=""),0,MAX(0,MIN(I17,Liegenschaft!$N$24)-MAX(H17,Liegenschaft!$M$24)+1)/DAY(Liegenschaft!$N$24)*Liegenschaft!$O$24) | Z17: =IF(OR(D17="",Liegenschaft!$C$7=""),0,MAX(0,MIN(I17,Liegenschaft!$N$25)-MAX(H17,Liegenschaft!$M$25)+1)/DAY(Liegenschaft!$N$25)*Liegenschaft!$O$25)
... B35: 30 | H35: =IF(D35="","",MAX(E35,Liegenschaft!$C$7)) | I35: =IF(D35="","",IF(F35="",Liegenschaft!$C$8,MIN(F35,Liegenschaft!$C$8))) | J35: =IF(D35="",0,MAX(0,I35-H35+1)) | K35: =IF(OR(D35="",Liegenschaft!$C$9=""),0,J35/Liegenschaft!$C$9) | L35: =IF(OR(D35="",Liegenschaft!$J$26=0),0,SUM(O35:Z35)/Liegenschaft!$J$26) | M35: =IF(D35="","",IF(ISNA(MATCH(C35,Liegenschaft!$B$14:$B$25,0)),"⚠ Wohnung unbekannt",IF(J35=0,"⚠ nicht in Periode",IF(SUMPRODUCT(($C$6:$C$35=C35)*($D$6:$D$35<>"")*($J$6:$J$35>0)*($H$6:$H$35<=I35)*($I$6:$I$35>=H35))>1,"⚠ Überschneidung mit anderem Mieter","✓")))) | O35: =IF(OR(D35="",Liegenschaft!$C$7=""),0,MAX(0,MIN(I35,Liegenschaft!$N$14)-MAX(H35,Liegenschaft!$M$14)+1)/DAY(Liegenschaft!$N$14)*Liegenschaft!$O$14) | P35: =IF(OR(D35="",Liegenschaft!$C$7=""),0,MAX(0,MIN(I35,Liegenschaft!$N$15)-MAX(H35,Liegenschaft!$M$15)+1)/DAY(Liegenschaft!$N$15)*Liegenschaft!$O$15) | Q35: =IF(OR(D35="",Liegenschaft!$C$7=""),0,MAX(0,MIN(I35,Liegenschaft!$N$16)-MAX(H35,Liegenschaft!$M$16)+1)/DAY(Liegenschaft!$N$16)*Liegenschaft!$O$16) | R35: =IF(OR(D35="",Liegenschaft!$C$7=""),0,MAX(0,MIN(I35,Liegenschaft!$N$17)-MAX(H35,Liegenschaft!$M$17)+1)/DAY(Liegenschaft!$N$17)*Liegenschaft!$O$17) | S35: =IF(OR(D35="",Liegenschaft!$C$7=""),0,MAX(0,MIN(I35,Liegenschaft!$N$18)-MAX(H35,Liegenschaft!$M$18)+1)/DAY(Liegenschaft!$N$18)*Liegenschaft!$O$18) | T35: =IF(OR(D35="",Liegenschaft!$C$7=""),0,MAX(0,MIN(I35,Liegenschaft!$N$19)-MAX(H35,Liegenschaft!$M$19)+1)/DAY(Liegenschaft!$N$19)*Liegenschaft!$O$19) | U35: =IF(OR(D35="",Liegenschaft!$C$7=""),0,MAX(0,MIN(I35,Liegenschaft!$N$20)-MAX(H35,Liegenschaft!$M$20)+1)/DAY(Liegenschaft!$N$20)*Liegenschaft!$O$20) | V35: =IF(OR(D35="",Liegenschaft!$C$7=""),0,MAX(0,MIN(I35,Liegenschaft!$N$21)-MAX(H35,Liegenschaft!$M$21)+1)/DAY(Liegenschaft!$N$21)*Liegenschaft!$O$21) | W35: =IF(OR(D35="",Liegenschaft!$C$7=""),0,MAX(0,MIN(I35,Liegenschaft!$N$22)-MAX(H35,Liegenschaft!$M$22)+1)/DAY(Liegenschaft!$N$22)*Liegenschaft!$O$22) | X35: =IF(OR(D35="",Liegenschaft!$C$7=""),0,MAX(0,MIN(I35,Liegenschaft!$N$23)-MAX(H35,Liegenschaft!$M$23)+1)/DAY(Liegenschaft!$N$23)*Liegenschaft!$O$23) | Y35: =IF(OR(D35="",Liegenschaft!$C$7=""),0,MAX(0,MIN(I35,Liegenschaft!$N$24)-MAX(H35,Liegenschaft!$M$24)+1)/DAY(Liegenschaft!$N$24)*Liegenschaft!$O$24) | Z35: =IF(OR(D35="",Liegenschaft!$C$7=""),0,MAX(0,MIN(I35,Liegenschaft!$N$25)-MAX(H35,Liegenschaft!$M$25)+1)/DAY(Liegenschaft!$N$25)*Liegenschaft!$O$25)

Sheet Kosten
B2: Nebenkosten der Periode
B3: Rechnungsbeträge der ganzen Liegenschaft erfassen. Nur Positionen mit «Ja» / «Ja» werden den Mietern belastet.
B5: Kostenposition | C5: Betrag CHF | D5: Art | E5: Verteilschlüssel | F5: Im Mietvertrag ausgeschieden? | G5: Umlagefähig? | H5: Abrechenbar
H6: =IF(OR(B6="",C6=""),"",IF(AND(F6="Ja",G6="Ja",D6<>"",E6<>""),"Ja","Nein")) | I6: =IF(E6="",1,MATCH(E6,{"Fläche m²","Zimmer","Wertquote","Volumen m³","pro Einheit gleich"},0)) | J6: Hinweise
H7: =IF(OR(B7="",C7=""),"",IF(AND(F7="Ja",G7="Ja",D7<>"",E7<>""),"Ja","Nein")) | I7: =IF(E7="",1,MATCH(E7,{"Fläche m²","Zimmer","Wertquote","Volumen m³","pro Einheit gleich"},0)) | J7: Umlagefähig sind nur Betriebskosten (Heizung, Warmwasser, Wasser, Abwasser, Allgemeinstrom, Hauswart, Kehricht, Lift-Service …).
H8: =IF(OR(B8="",C8=""),"",IF(AND(F8="Ja",G8="Ja",D8<>"",E8<>""),"Ja","Nein")) | I8: =IF(E8="",1,MATCH(E8,{"Fläche m²","Zimmer","Wertquote","Volumen m³","pro Einheit gleich"},0)) | J8: NICHT umlagefähig: Reparaturen, Unterhalt, Erneuerungen, Hypothekarzinsen, Gebäudeversicherung (Praxis), Abschreibungen.
H9: =IF(OR(B9="",C9=""),"",IF(AND(F9="Ja",G9="Ja",D9<>"",E9<>""),"Ja","Nein")) | I9: =IF(E9="",1,MATCH(E9,{"Fläche m²","Zimmer","Wertquote","Volumen m³","pro Einheit gleich"},0)) | J9: Nebenkosten dürfen nur belastet werden, wenn sie im Mietvertrag einzeln ausgeschieden sind (Art. 257a Abs. 2 OR).
H10: =IF(OR(B10="",C10=""),"",IF(AND(F10="Ja",G10="Ja",D10<>"",E10<>""),"Ja","Nein")) | I10: =IF(E10="",1,MATCH(E10,{"Fläche m²","Zimmer","Wertquote","Volumen m³","pro Einheit gleich"},0)) | J10: Heizung/Warmwasser wird nach Heizgradtagen verteilt, alles andere zeitanteilig nach Tagen.
H11: =IF(OR(B11="",C11=""),"",IF(AND(F11="Ja",G11="Ja",D11<>"",E11<>""),"Ja","Nein")) | I11: =IF(E11="",1,MATCH(E11,{"Fläche m²","Zimmer","Wertquote","Volumen m³","pro Einheit gleich"},0))
H12: =IF(OR(B12="",C12=""),"",IF(AND(F12="Ja",G12="Ja",D12<>"",E12<>""),"Ja","Nein")) | I12: =IF(E12="",1,MATCH(E12,{"Fläche m²","Zimmer","Wertquote","Volumen m³","pro Einheit gleich"},0))
H13: =IF(OR(B13="",C13=""),"",IF(AND(F13="Ja",G13="Ja",D13<>"",E13<>""),"Ja","Nein")) | I13: =IF(E13="",1,MATCH(E13,{"Fläche m²","Zimmer","Wertquote","Volumen m³","pro Einheit gleich"},0))
H14: =IF(OR(B14="",C14=""),"",IF(AND(F14="Ja",G14="Ja",D14<>"",E14<>""),"Ja","Nein")) | I14: =IF(E14="",1,MATCH(E14,{"Fläche m²","Zimmer","Wertquote","Volumen m³","pro Einheit gleich"},0))
H15: =IF(OR(B15="",C15=""),"",IF(AND(F15="Ja",G15="Ja",D15<>"",E15<>""),"Ja","Nein")) | I15: =IF(E15="",1,MATCH(E15,{"Fläche m²","Zimmer","Wertquote","Volumen m³","pro Einheit gleich"},0))
H16: =IF(OR(B16="",C16=""),"",IF(AND(F16="Ja",G16="Ja",D16<>"",E16<>""),"Ja","Nein")) | I16: =IF(E16="",1,MATCH(E16,{"Fläche m²","Zimmer","Wertquote","Volumen m³","pro Einheit gleich"},0))
H17: =IF(OR(B17="",C17=""),"",IF(AND(F17="Ja",G17="Ja",D17<>"",E17<>""),"Ja","Nein")) | I17: =IF(E17="",1,MATCH(E17,{"Fläche m²","Zimmer","Wertquote","Volumen m³","pro Einheit gleich"},0))
H18: =IF(OR(B18="",C18=""),"",IF(AND(F18="Ja",G18="Ja",D18<>"",E18<>""),"Ja","Nein")) | I18: =IF(E18="",1,MATCH(E18,{"Fläche m²","Zimmer","Wertquote","Volumen m³","pro Einheit gleich"},0))
H19: =IF(OR(B19="",C19=""),"",IF(AND(F19="Ja",G19="Ja",D19<>"",E19<>""),"Ja","Nein")) | I19: =IF(E19="",1,MATCH(E19,{"Fläche m²","Zimmer","Wertquote","Volumen m³","pro Einheit gleich"},0))
H20: =IF(OR(B20="",C20=""),"",IF(AND(F20="Ja",G20="Ja",D20<>"",E20<>""),"Ja","Nein")) | I20: =IF(E20="",1,MATCH(E20,{"Fläche m²","Zimmer","Wertquote","Volumen m³","pro Einheit gleich"},0))
H21: =IF(OR(B21="",C21=""),"",IF(AND(F21="Ja",G21="Ja",D21<>"",E21<>""),"Ja","Nein")) | I21: =IF(E21="",1,MATCH(E21,{"Fläche m²","Zimmer","Wertquote","Volumen m³","pro Einheit gleich"},0))
H22: =IF(OR(B22="",C22=""),"",IF(AND(F22="Ja",G22="Ja",D22<>"",E22<>""),"Ja","Nein")) | I22: =IF(E22="",1,MATCH(E22,{"Fläche m²","Zimmer","Wertquote","Volumen m³","pro Einheit gleich"},0))
... H25: =IF(OR(B25="",C25=""),"",IF(AND(F25="Ja",G25="Ja",D25<>"",E25<>""),"Ja","Nein")) | I25: =IF(E25="",1,MATCH(E25,{"Fläche m²","Zimmer","Wertquote","Volumen m³","pro Einheit gleich"},0))
B26: Total erfasste Kosten | C26: =SUM(C6:C25)
B27: davon abrechenbar | C27: =SUMIF(H6:H25,"Ja",C6:C25)
B28: nicht abrechenbar (trägt Vermieter) | C28: =C26-C27

Sheet Verteilung
B2: Verteilung auf die Mietverhältnisse
B3: Wird automatisch berechnet. Zeilen = Mieter (wie Blatt «Mieter»), Spalten = Kostenpositionen.
B5: Nr | C5: Mieter/in | D5: =IF(Kosten!B6="","Pos. 1",Kosten!B6) | E5: =IF(Kosten!B7="","Pos. 2",Kosten!B7) | F5: =IF(Kosten!B8="","Pos. 3",Kosten!B8) | G5: =IF(Kosten!B9="","Pos. 4",Kosten!B9) | H5: =IF(Kosten!B10="","Pos. 5",Kosten!B10) | I5: =IF(Kosten!B11="","Pos. 6",Kosten!B11) | J5: =IF(Kosten!B12="","Pos. 7",Kosten!B12) | K5: =IF(Kosten!B13="","Pos. 8",Kosten!B13) | L5: =IF(Kosten!B14="","Pos. 9",Kosten!B14) | M5: =IF(Kosten!B15="","Pos. 10",Kosten!B15) | N5: =IF(Kosten!B16="","Pos. 11",Kosten!B16) | O5: =IF(Kosten!B17="","Pos. 12",Kosten!B17) | P5: =IF(Kosten!B18="","Pos. 13",Kosten!B18) | Q5: =IF(Kosten!B19="","Pos. 14",Kosten!B19) | R5: =IF(Kosten!B20="","Pos. 15",Kosten!B20) | S5: =IF(Kosten!B21="","Pos. 16",Kosten!B21) | T5: =IF(Kosten!B22="","Pos. 17",Kosten!B22) | U5: =IF(Kosten!B23="","Pos. 18",Kosten!B23) | V5: =IF(Kosten!B24="","Pos. 19",Kosten!B24) | W5: =IF(Kosten!B25="","Pos. 20",Kosten!B25) | X5: Nebenkosten | Y5: Verwaltungs-honorar | Z5: Total Anteil | AA5: Akonto bezahlt | AB5: Saldo (+ Nachzahlung / − Guthaben)
B6: 1 | C6: =IF(Mieter!D6="","",Mieter!D6) | D6: =IF(OR(Mieter!$D6="",Kosten!$H$6<>"Ja"),0,IFERROR(Kosten!$C$6*INDEX(Liegenschaft!$C$14:$G$25,MATCH(Mieter!$C6,Liegenschaft!$B$14:$B$25,0),Kosten!$I$6)/INDEX(Liegenschaft!$C$26:$G$26,1,Kosten!$I$6)*IF(Kosten!$D$6="Heizung/Warmwasser",Mieter!$L6,Mieter!$K6),0)) | E6: =IF(OR(Mieter!$D6="",Kosten!$H$7<>"Ja"),0,IFERROR(Kosten!$C$7*INDEX(Liegenschaft!$C$14:$G$25,MATCH(Mieter!$C6,Liegenschaft!$B$14:$B$25,0),Kosten!$I$7)/INDEX(Liegenschaft!$C$26:$G$26,1,Kosten!$I$7)*IF(Kosten!$D$7="Heizung/Warmwasser",Mieter!$L6,Mieter!$K6),0)) | F6: =IF(OR(Mieter!$D6="",Kosten!$H$8<>"Ja"),0,IFERROR(Kosten!$C$8*INDEX(Liegenschaft!$C$14:$G$25,MATCH(Mieter!$C6,Liegenschaft!$B$14:$B$25,0),Kosten!$I$8)/INDEX(Liegenschaft!$C$26:$G$26,1,Kosten!$I$8)*IF(Kosten!$D$8="Heizung/Warmwasser",Mieter!$L6,Mieter!$K6),0)) | G6: =IF(OR(Mieter!$D6="",Kosten!$H$9<>"Ja"),0,IFERROR(Kosten!$C$9*INDEX(Liegenschaft!$C$14:$G$25,MATCH(Mieter!$C6,Liegenschaft!$B$14:$B$25,0),Kosten!$I$9)/INDEX(Liegenschaft!$C$26:$G$26,1,Kosten!$I$9)*IF(Kosten!$D$9="Heizung/Warmwasser",Mieter!$L6,Mieter!$K6),0)) | H6: =IF(OR(Mieter!$D6="",Kosten!$H$10<>"Ja"),0,IFERROR(Kosten!$C$10*INDEX(Liegenschaft!$C$14:$G$25,MATCH(Mieter!$C6,Liegenschaft!$B$14:$B$25,0),Kosten!$I$10)/INDEX(Liegenschaft!$C$26:$G$26,1,Kosten!$I$10)*IF(Kosten!$D$10="Heizung/Warmwasser",Mieter!$L6,Mieter!$K6),0)) | I6: =IF(OR(Mieter!$D6="",Kosten!$H$11<>"Ja"),0,IFERROR(Kosten!$C$11*INDEX(Liegenschaft!$C$14:$G$25,MATCH(Mieter!$C6,Liegenschaft!$B$14:$B$25,0),Kosten!$I$11)/INDEX(Liegenschaft!$C$26:$G$26,1,Kosten!$I$11)*IF(Kosten!$D$11="Heizung/Warmwasser",Mieter!$L6,Mieter!$K6),0)) | J6: =IF(OR(Mieter!$D6="",Kosten!$H$12<>"Ja"),0,IFERROR(Kosten!$C$12*INDEX(Liegenschaft!$C$14:$G$25,MATCH(Mieter!$C6,Liegenschaft!$B$14:$B$25,0),Kosten!$I$12)/INDEX(Liegenschaft!$C$26:$G$26,1,Kosten!$I$12)*IF(Kosten!$D$12="Heizung/Warmwasser",Mieter!$L6,Mieter!$K6),0)) | K6: =IF(OR(Mieter!$D6="",Kosten!$H$13<>"Ja"),0,IFERROR(Kosten!$C$13*INDEX(Liegenschaft!$C$14:$G$25,MATCH(Mieter!$C6,Liegenschaft!$B$14:$B$25,0),Kosten!$I$13)/INDEX(Liegenschaft!$C$26:$G$26,1,Kosten!$I$13)*IF(Kosten!$D$13="Heizung/Warmwasser",Mieter!$L6,Mieter!$K6),0)) | L6: =IF(OR(Mieter!$D6="",Kosten!$H$14<>"Ja"),0,IFERROR(Kosten!$C$14*INDEX(Liegenschaft!$C$14:$G$25,MATCH(Mieter!$C6,Liegenschaft!$B$14:$B$25,0),Kosten!$I$14)/INDEX(Liegenschaft!$C$26:$G$26,1,Kosten!$I$14)*IF(Kosten!$D$14="Heizung/Warmwasser",Mieter!$L6,Mieter!$K6),0)) | M6: =IF(OR(Mieter!$D6="",Kosten!$H$15<>"Ja"),0,IFERROR(Kosten!$C$15*INDEX(Liegenschaft!$C$14:$G$25,MATCH(Mieter!$C6,Liegenschaft!$B$14:$B$25,0),Kosten!$I$15)/INDEX(Liegenschaft!$C$26:$G$26,1,Kosten!$I$15)*IF(Kosten!$D$15="Heizung/Warmwasser",Mieter!$L6,Mieter!$K6),0)) | N6: =IF(OR(Mieter!$D6="",Kosten!$H$16<>"Ja"),0,IFERROR(Kosten!$C$16*INDEX(Liegenschaft!$C$14:$G$25,MATCH(Mieter!$C6,Liegenschaft!$B$14:$B$25,0),Kosten!$I$16)/INDEX(Liegenschaft!$C$26:$G$26,1,Kosten!$I$16)*IF(Kosten!$D$16="Heizung/Warmwasser",Mieter!$L6,Mieter!$K6),0)) | O6: =IF(OR(Mieter!$D6="",Kosten!$H$17<>"Ja"),0,IFERROR(Kosten!$C$17*INDEX(Liegenschaft!$C$14:$G$25,MATCH(Mieter!$C6,Liegenschaft!$B$14:$B$25,0),Kosten!$I$17)/INDEX(Liegenschaft!$C$26:$G$26,1,Kosten!$I$17)*IF(Kosten!$D$17="Heizung/Warmwasser",Mieter!$L6,Mieter!$K6),0)) | P6: =IF(OR(Mieter!$D6="",Kosten!$H$18<>"Ja"),0,IFERROR(Kosten!$C$18*INDEX(Liegenschaft!$C$14:$G$25,MATCH(Mieter!$C6,Liegenschaft!$B$14:$B$25,0),Kosten!$I$18)/INDEX(Liegenschaft!$C$26:$G$26,1,Kosten!$I$18)*IF(Kosten!$D$18="Heizung/Warmwasser",Mieter!$L6,Mieter!$K6),0)) | Q6: =IF(OR(Mieter!$D6="",Kosten!$H$19<>"Ja"),0,IFERROR(Kosten!$C$19*INDEX(Liegenschaft!$C$14:$G$25,MATCH(Mieter!$C6,Liegenschaft!$B$14:$B$25,0),Kosten!$I$19)/INDEX(Liegenschaft!$C$26:$G$26,1,Kosten!$I$19)*IF(Kosten!$D$19="Heizung/Warmwasser",Mieter!$L6,Mieter!$K6),0)) | R6: =IF(OR(Mieter!$D6="",Kosten!$H$20<>"Ja"),0,IFERROR(Kosten!$C$20*INDEX(Liegenschaft!$C$14:$G$25,MATCH(Mieter!$C6,Liegenschaft!$B$14:$B$25,0),Kosten!$I$20)/INDEX(Liegenschaft!$C$26:$G$26,1,Kosten!$I$20)*IF(Kosten!$D$20="Heizung/Warmwasser",Mieter!$L6,Mieter!$K6),0)) | S6: =IF(OR(Mieter!$D6="",Kosten!$H$21<>"Ja"),0,IFERROR(Kosten!$C$21*INDEX(Liegenschaft!$C$14:$G$25,MATCH(Mieter!$C6,Liegenschaft!$B$14:$B$25,0),Kosten!$I$21)/INDEX(Liegenschaft!$C$26:$G$26,1,Kosten!$I$21)*IF(Kosten!$D$21="Heizung/Warmwasser",Mieter!$L6,Mieter!$K6),0)) | T6: =IF(OR(Mieter!$D6="",Kosten!$H$22<>"Ja"),0,IFERROR(Kosten!$C$22*INDEX(Liegenschaft!$C$14:$G$25,MATCH(Mieter!$C6,Liegenschaft!$B$14:$B$25,0),Kosten!$I$22)/INDEX(Liegenschaft!$C$26:$G$26,1,Kosten!$I$22)*IF(Kosten!$D$22="Heizung/Warmwasser",Mieter!$L6,Mieter!$K6),0)) | U6: =IF(OR(Mieter!$D6="",Kosten!$H$23<>"Ja"),0,IFERROR(Kosten!$C$23*INDEX(Liegenschaft!$C$14:$G$25,MATCH(Mieter!$C6,Liegenschaft!$B$14:$B$25,0),Kosten!$I$23)/INDEX(Liegenschaft!$C$26:$G$26,1,Kosten!$I$23)*IF(Kosten!$D$23="Heizung/Warmwasser",Mieter!$L6,Mieter!$K6),0)) | V6: =IF(OR(Mieter!$D6="",Kosten!$H$24<>"Ja"),0,IFERROR(Kosten!$C$24*INDEX(Liegenschaft!$C$14:$G$25,MATCH(Mieter!$C6,Liegenschaft!$B$14:$B$25,0),Kosten!$I$24)/INDEX(Liegenschaft!$C$26:$G$26,1,Kosten!$I$24)*IF(Kosten!$D$24="Heizung/Warmwasser",Mieter!$L6,Mieter!$K6),0)) | W6: =IF(OR(Mieter!$D6="",Kosten!$H$25<>"Ja"),0,IFERROR(Kosten!$C$25*INDEX(Liegenschaft!$C$14:$G$25,MATCH(Mieter!$C6,Liegenschaft!$B$14:$B$25,0),Kosten!$I$25)/INDEX(Liegenschaft!$C$26:$G$26,1,Kosten!$I$25)*IF(Kosten!$D$25="Heizung/Warmwasser",Mieter!$L6,Mieter!$K6),0)) | X6: =SUM(D6:W6) | Y6: =IF(Liegenschaft!$C$11="Ja",ROUND(X6*Liegenschaft!$C$10,2),0) | Z6: =ROUND(X6+Y6,2) | AA6: =N(Mieter!G6) | AB6: =IF(C6="",0,Z6-AA6)
B7: 2 | C7: =IF(Mieter!D7="","",Mieter!D7) | D7: =IF(OR(Mieter!$D7="",Kosten!$H$6<>"Ja"),0,IFERROR(Kosten!$C$6*INDEX(Liegenschaft!$C$14:$G$25,MATCH(Mieter!$C7,Liegenschaft!$B$14:$B$25,0),Kosten!$I$6)/INDEX(Liegenschaft!$C$26:$G$26,1,Kosten!$I$6)*IF(Kosten!$D$6="Heizung/Warmwasser",Mieter!$L7,Mieter!$K7),0)) | E7: =IF(OR(Mieter!$D7="",Kosten!$H$7<>"Ja"),0,IFERROR(Kosten!$C$7*INDEX(Liegenschaft!$C$14:$G$25,MATCH(Mieter!$C7,Liegenschaft!$B$14:$B$25,0),Kosten!$I$7)/INDEX(Liegenschaft!$C$26:$G$26,1,Kosten!$I$7)*IF(Kosten!$D$7="Heizung/Warmwasser",Mieter!$L7,Mieter!$K7),0)) | F7: =IF(OR(Mieter!$D7="",Kosten!$H$8<>"Ja"),0,IFERROR(Kosten!$C$8*INDEX(Liegenschaft!$C$14:$G$25,MATCH(Mieter!$C7,Liegenschaft!$B$14:$B$25,0),Kosten!$I$8)/INDEX(Liegenschaft!$C$26:$G$26,1,Kosten!$I$8)*IF(Kosten!$D$8="Heizung/Warmwasser",Mieter!$L7,Mieter!$K7),0)) | G7: =IF(OR(Mieter!$D7="",Kosten!$H$9<>"Ja"),0,IFERROR(Kosten!$C$9*INDEX(Liegenschaft!$C$14:$G$25,MATCH(Mieter!$C7,Liegenschaft!$B$14:$B$25,0),Kosten!$I$9)/INDEX(Liegenschaft!$C$26:$G$26,1,Kosten!$I$9)*IF(Kosten!$D$9="Heizung/Warmwasser",Mieter!$L7,Mieter!$K7),0)) | H7: =IF(OR(Mieter!$D7="",Kosten!$H$10<>"Ja"),0,IFERROR(Kosten!$C$10*INDEX(Liegenschaft!$C$14:$G$25,MATCH(Mieter!$C7,Liegenschaft!$B$14:$B$25,0),Kosten!$I$10)/INDEX(Liegenschaft!$C$26:$G$26,1,Kosten!$I$10)*IF(Kosten!$D$10="Heizung/Warmwasser",Mieter!$L7,Mieter!$K7),0)) | I7: =IF(OR(Mieter!$D7="",Kosten!$H$11<>"Ja"),0,IFERROR(Kosten!$C$11*INDEX(Liegenschaft!$C$14:$G$25,MATCH(Mieter!$C7,Liegenschaft!$B$14:$B$25,0),Kosten!$I$11)/INDEX(Liegenschaft!$C$26:$G$26,1,Kosten!$I$11)*IF(Kosten!$D$11="Heizung/Warmwasser",Mieter!$L7,Mieter!$K7),0)) | J7: =IF(OR(Mieter!$D7="",Kosten!$H$12<>"Ja"),0,IFERROR(Kosten!$C$12*INDEX(Liegenschaft!$C$14:$G$25,MATCH(Mieter!$C7,Liegenschaft!$B$14:$B$25,0),Kosten!$I$12)/INDEX(Liegenschaft!$C$26:$G$26,1,Kosten!$I$12)*IF(Kosten!$D$12="Heizung/Warmwasser",Mieter!$L7,Mieter!$K7),0)) | K7: =IF(OR(Mieter!$D7="",Kosten!$H$13<>"Ja"),0,IFERROR(Kosten!$C$13*INDEX(Liegenschaft!$C$14:$G$25,MATCH(Mieter!$C7,Liegenschaft!$B$14:$B$25,0),Kosten!$I$13)/INDEX(Liegenschaft!$C$26:$G$26,1,Kosten!$I$13)*IF(Kosten!$D$13="Heizung/Warmwasser",Mieter!$L7,Mieter!$K7),0)) | L7: =IF(OR(Mieter!$D7="",Kosten!$H$14<>"Ja"),0,IFERROR(Kosten!$C$14*INDEX(Liegenschaft!$C$14:$G$25,MATCH(Mieter!$C7,Liegenschaft!$B$14:$B$25,0),Kosten!$I$14)/INDEX(Liegenschaft!$C$26:$G$26,1,Kosten!$I$14)*IF(Kosten!$D$14="Heizung/Warmwasser",Mieter!$L7,Mieter!$K7),0)) | M7: =IF(OR(Mieter!$D7="",Kosten!$H$15<>"Ja"),0,IFERROR(Kosten!$C$15*INDEX(Liegenschaft!$C$14:$G$25,MATCH(Mieter!$C7,Liegenschaft!$B$14:$B$25,0),Kosten!$I$15)/INDEX(Liegenschaft!$C$26:$G$26,1,Kosten!$I$15)*IF(Kosten!$D$15="Heizung/Warmwasser",Mieter!$L7,Mieter!$K7),0)) | N7: =IF(OR(Mieter!$D7="",Kosten!$H$16<>"Ja"),0,IFERROR(Kosten!$C$16*INDEX(Liegenschaft!$C$14:$G$25,MATCH(Mieter!$C7,Liegenschaft!$B$14:$B$25,0),Kosten!$I$16)/INDEX(Liegenschaft!$C$26:$G$26,1,Kosten!$I$16)*IF(Kosten!$D$16="Heizung/Warmwasser",Mieter!$L7,Mieter!$K7),0)) | O7: =IF(OR(Mieter!$D7="",Kosten!$H$17<>"Ja"),0,IFERROR(Kosten!$C$17*INDEX(Liegenschaft!$C$14:$G$25,MATCH(Mieter!$C7,Liegenschaft!$B$14:$B$25,0),Kosten!$I$17)/INDEX(Liegenschaft!$C$26:$G$26,1,Kosten!$I$17)*IF(Kosten!$D$17="Heizung/Warmwasser",Mieter!$L7,Mieter!$K7),0)) | P7: =IF(OR(Mieter!$D7="",Kosten!$H$18<>"Ja"),0,IFERROR(Kosten!$C$18*INDEX(Liegenschaft!$C$14:$G$25,MATCH(Mieter!$C7,Liegenschaft!$B$14:$B$25,0),Kosten!$I$18)/INDEX(Liegenschaft!$C$26:$G$26,1,Kosten!$I$18)*IF(Kosten!$D$18="Heizung/Warmwasser",Mieter!$L7,Mieter!$K7),0)) | Q7: =IF(OR(Mieter!$D7="",Kosten!$H$19<>"Ja"),0,IFERROR(Kosten!$C$19*INDEX(Liegenschaft!$C$14:$G$25,MATCH(Mieter!$C7,Liegenschaft!$B$14:$B$25,0),Kosten!$I$19)/INDEX(Liegenschaft!$C$26:$G$26,1,Kosten!$I$19)*IF(Kosten!$D$19="Heizung/Warmwasser",Mieter!$L7,Mieter!$K7),0)) | R7: =IF(OR(Mieter!$D7="",Kosten!$H$20<>"Ja"),0,IFERROR(Kosten!$C$20*INDEX(Liegenschaft!$C$14:$G$25,MATCH(Mieter!$C7,Liegenschaft!$B$14:$B$25,0),Kosten!$I$20)/INDEX(Liegenschaft!$C$26:$G$26,1,Kosten!$I$20)*IF(Kosten!$D$20="Heizung/Warmwasser",Mieter!$L7,Mieter!$K7),0)) | S7: =IF(OR(Mieter!$D7="",Kosten!$H$21<>"Ja"),0,IFERROR(Kosten!$C$21*INDEX(Liegenschaft!$C$14:$G$25,MATCH(Mieter!$C7,Liegenschaft!$B$14:$B$25,0),Kosten!$I$21)/INDEX(Liegenschaft!$C$26:$G$26,1,Kosten!$I$21)*IF(Kosten!$D$21="Heizung/Warmwasser",Mieter!$L7,Mieter!$K7),0)) | T7: =IF(OR(Mieter!$D7="",Kosten!$H$22<>"Ja"),0,IFERROR(Kosten!$C$22*INDEX(Liegenschaft!$C$14:$G$25,MATCH(Mieter!$C7,Liegenschaft!$B$14:$B$25,0),Kosten!$I$22)/INDEX(Liegenschaft!$C$26:$G$26,1,Kosten!$I$22)*IF(Kosten!$D$22="Heizung/Warmwasser",Mieter!$L7,Mieter!$K7),0)) | U7: =IF(OR(Mieter!$D7="",Kosten!$H$23<>"Ja"),0,IFERROR(Kosten!$C$23*INDEX(Liegenschaft!$C$14:$G$25,MATCH(Mieter!$C7,Liegenschaft!$B$14:$B$25,0),Kosten!$I$23)/INDEX(Liegenschaft!$C$26:$G$26,1,Kosten!$I$23)*IF(Kosten!$D$23="Heizung/Warmwasser",Mieter!$L7,Mieter!$K7),0)) | V7: =IF(OR(Mieter!$D7="",Kosten!$H$24<>"Ja"),0,IFERROR(Kosten!$C$24*INDEX(Liegenschaft!$C$14:$G$25,MATCH(Mieter!$C7,Liegenschaft!$B$14:$B$25,0),Kosten!$I$24)/INDEX(Liegenschaft!$C$26:$G$26,1,Kosten!$I$24)*IF(Kosten!$D$24="Heizung/Warmwasser",Mieter!$L7,Mieter!$K7),0)) | W7: =IF(OR(Mieter!$D7="",Kosten!$H$25<>"Ja"),0,IFERROR(Kosten!$C$25*INDEX(Liegenschaft!$C$14:$G$25,MATCH(Mieter!$C7,Liegenschaft!$B$14:$B$25,0),Kosten!$I$25)/INDEX(Liegenschaft!$C$26:$G$26,1,Kosten!$I$25)*IF(Kosten!$D$25="Heizung/Warmwasser",Mieter!$L7,Mieter!$K7),0)) | X7: =SUM(D7:W7) | Y7: =IF(Liegenschaft!$C$11="Ja",ROUND(X7*Liegenschaft!$C$10,2),0) | Z7: =ROUND(X7+Y7,2) | AA7: =N(Mieter!G7) | AB7: =IF(C7="",0,Z7-AA7)
B8: 3 | C8: =IF(Mieter!D8="","",Mieter!D8) | D8: =IF(OR(Mieter!$D8="",Kosten!$H$6<>"Ja"),0,IFERROR(Kosten!$C$6*INDEX(Liegenschaft!$C$14:$G$25,MATCH(Mieter!$C8,Liegenschaft!$B$14:$B$25,0),Kosten!$I$6)/INDEX(Liegenschaft!$C$26:$G$26,1,Kosten!$I$6)*IF(Kosten!$D$6="Heizung/Warmwasser",Mieter!$L8,Mieter!$K8),0)) | E8: =IF(OR(Mieter!$D8="",Kosten!$H$7<>"Ja"),0,IFERROR(Kosten!$C$7*INDEX(Liegenschaft!$C$14:$G$25,MATCH(Mieter!$C8,Liegenschaft!$B$14:$B$25,0),Kosten!$I$7)/INDEX(Liegenschaft!$C$26:$G$26,1,Kosten!$I$7)*IF(Kosten!$D$7="Heizung/Warmwasser",Mieter!$L8,Mieter!$K8),0)) | F8: =IF(OR(Mieter!$D8="",Kosten!$H$8<>"Ja"),0,IFERROR(Kosten!$C$8*INDEX(Liegenschaft!$C$14:$G$25,MATCH(Mieter!$C8,Liegenschaft!$B$14:$B$25,0),Kosten!$I$8)/INDEX(Liegenschaft!$C$26:$G$26,1,Kosten!$I$8)*IF(Kosten!$D$8="Heizung/Warmwasser",Mieter!$L8,Mieter!$K8),0)) | G8: =IF(OR(Mieter!$D8="",Kosten!$H$9<>"Ja"),0,IFERROR(Kosten!$C$9*INDEX(Liegenschaft!$C$14:$G$25,MATCH(Mieter!$C8,Liegenschaft!$B$14:$B$25,0),Kosten!$I$9)/INDEX(Liegenschaft!$C$26:$G$26,1,Kosten!$I$9)*IF(Kosten!$D$9="Heizung/Warmwasser",Mieter!$L8,Mieter!$K8),0)) | H8: =IF(OR(Mieter!$D8="",Kosten!$H$10<>"Ja"),0,IFERROR(Kosten!$C$10*INDEX(Liegenschaft!$C$14:$G$25,MATCH(Mieter!$C8,Liegenschaft!$B$14:$B$25,0),Kosten!$I$10)/INDEX(Liegenschaft!$C$26:$G$26,1,Kosten!$I$10)*IF(Kosten!$D$10="Heizung/Warmwasser",Mieter!$L8,Mieter!$K8),0)) | I8: =IF(OR(Mieter!$D8="",Kosten!$H$11<>"Ja"),0,IFERROR(Kosten!$C$11*INDEX(Liegenschaft!$C$14:$G$25,MATCH(Mieter!$C8,Liegenschaft!$B$14:$B$25,0),Kosten!$I$11)/INDEX(Liegenschaft!$C$26:$G$26,1,Kosten!$I$11)*IF(Kosten!$D$11="Heizung/Warmwasser",Mieter!$L8,Mieter!$K8),0)) | J8: =IF(OR(Mieter!$D8="",Kosten!$H$12<>"Ja"),0,IFERROR(Kosten!$C$12*INDEX(Liegenschaft!$C$14:$G$25,MATCH(Mieter!$C8,Liegenschaft!$B$14:$B$25,0),Kosten!$I$12)/INDEX(Liegenschaft!$C$26:$G$26,1,Kosten!$I$12)*IF(Kosten!$D$12="Heizung/Warmwasser",Mieter!$L8,Mieter!$K8),0)) | K8: =IF(OR(Mieter!$D8="",Kosten!$H$13<>"Ja"),0,IFERROR(Kosten!$C$13*INDEX(Liegenschaft!$C$14:$G$25,MATCH(Mieter!$C8,Liegenschaft!$B$14:$B$25,0),Kosten!$I$13)/INDEX(Liegenschaft!$C$26:$G$26,1,Kosten!$I$13)*IF(Kosten!$D$13="Heizung/Warmwasser",Mieter!$L8,Mieter!$K8),0)) | L8: =IF(OR(Mieter!$D8="",Kosten!$H$14<>"Ja"),0,IFERROR(Kosten!$C$14*INDEX(Liegenschaft!$C$14:$G$25,MATCH(Mieter!$C8,Liegenschaft!$B$14:$B$25,0),Kosten!$I$14)/INDEX(Liegenschaft!$C$26:$G$26,1,Kosten!$I$14)*IF(Kosten!$D$14="Heizung/Warmwasser",Mieter!$L8,Mieter!$K8),0)) | M8: =IF(OR(Mieter!$D8="",Kosten!$H$15<>"Ja"),0,IFERROR(Kosten!$C$15*INDEX(Liegenschaft!$C$14:$G$25,MATCH(Mieter!$C8,Liegenschaft!$B$14:$B$25,0),Kosten!$I$15)/INDEX(Liegenschaft!$C$26:$G$26,1,Kosten!$I$15)*IF(Kosten!$D$15="Heizung/Warmwasser",Mieter!$L8,Mieter!$K8),0)) | N8: =IF(OR(Mieter!$D8="",Kosten!$H$16<>"Ja"),0,IFERROR(Kosten!$C$16*INDEX(Liegenschaft!$C$14:$G$25,MATCH(Mieter!$C8,Liegenschaft!$B$14:$B$25,0),Kosten!$I$16)/INDEX(Liegenschaft!$C$26:$G$26,1,Kosten!$I$16)*IF(Kosten!$D$16="Heizung/Warmwasser",Mieter!$L8,Mieter!$K8),0)) | O8: =IF(OR(Mieter!$D8="",Kosten!$H$17<>"Ja"),0,IFERROR(Kosten!$C$17*INDEX(Liegenschaft!$C$14:$G$25,MATCH(Mieter!$C8,Liegenschaft!$B$14:$B$25,0),Kosten!$I$17)/INDEX(Liegenschaft!$C$26:$G$26,1,Kosten!$I$17)*IF(Kosten!$D$17="Heizung/Warmwasser",Mieter!$L8,Mieter!$K8),0)) | P8: =IF(OR(Mieter!$D8="",Kosten!$H$18<>"Ja"),0,IFERROR(Kosten!$C$18*INDEX(Liegenschaft!$C$14:$G$25,MATCH(Mieter!$C8,Liegenschaft!$B$14:$B$25,0),Kosten!$I$18)/INDEX(Liegenschaft!$C$26:$G$26,1,Kosten!$I$18)*IF(Kosten!$D$18="Heizung/Warmwasser",Mieter!$L8,Mieter!$K8),0)) | Q8: =IF(OR(Mieter!$D8="",Kosten!$H$19<>"Ja"),0,IFERROR(Kosten!$C$19*INDEX(Liegenschaft!$C$14:$G$25,MATCH(Mieter!$C8,Liegenschaft!$B$14:$B$25,0),Kosten!$I$19)/INDEX(Liegenschaft!$C$26:$G$26,1,Kosten!$I$19)*IF(Kosten!$D$19="Heizung/Warmwasser",Mieter!$L8,Mieter!$K8),0)) | R8: =IF(OR(Mieter!$D8="",Kosten!$H$20<>"Ja"),0,IFERROR(Kosten!$C$20*INDEX(Liegenschaft!$C$14:$G$25,MATCH(Mieter!$C8,Liegenschaft!$B$14:$B$25,0),Kosten!$I$20)/INDEX(Liegenschaft!$C$26:$G$26,1,Kosten!$I$20)*IF(Kosten!$D$20="Heizung/Warmwasser",Mieter!$L8,Mieter!$K8),0)) | S8: =IF(OR(Mieter!$D8="",Kosten!$H$21<>"Ja"),0,IFERROR(Kosten!$C$21*INDEX(Liegenschaft!$C$14:$G$25,MATCH(Mieter!$C8,Liegenschaft!$B$14:$B$25,0),Kosten!$I$21)/INDEX(Liegenschaft!$C$26:$G$26,1,Kosten!$I$21)*IF(Kosten!$D$21="Heizung/Warmwasser",Mieter!$L8,Mieter!$K8),0)) | T8: =IF(OR(Mieter!$D8="",Kosten!$H$22<>"Ja"),0,IFERROR(Kosten!$C$22*INDEX(Liegenschaft!$C$14:$G$25,MATCH(Mieter!$C8,Liegenschaft!$B$14:$B$25,0),Kosten!$I$22)/INDEX(Liegenschaft!$C$26:$G$26,1,Kosten!$I$22)*IF(Kosten!$D$22="Heizung/Warmwasser",Mieter!$L8,Mieter!$K8),0)) | U8: =IF(OR(Mieter!$D8="",Kosten!$H$23<>"Ja"),0,IFERROR(Kosten!$C$23*INDEX(Liegenschaft!$C$14:$G$25,MATCH(Mieter!$C8,Liegenschaft!$B$14:$B$25,0),Kosten!$I$23)/INDEX(Liegenschaft!$C$26:$G$26,1,Kosten!$I$23)*IF(Kosten!$D$23="Heizung/Warmwasser",Mieter!$L8,Mieter!$K8),0)) | V8: =IF(OR(Mieter!$D8="",Kosten!$H$24<>"Ja"),0,IFERROR(Kosten!$C$24*INDEX(Liegenschaft!$C$14:$G$25,MATCH(Mieter!$C8,Liegenschaft!$B$14:$B$25,0),Kosten!$I$24)/INDEX(Liegenschaft!$C$26:$G$26,1,Kosten!$I$24)*IF(Kosten!$D$24="Heizung/Warmwasser",Mieter!$L8,Mieter!$K8),0)) | W8: =IF(OR(Mieter!$D8="",Kosten!$H$25<>"Ja"),0,IFERROR(Kosten!$C$25*INDEX(Liegenschaft!$C$14:$G$25,MATCH(Mieter!$C8,Liegenschaft!$B$14:$B$25,0),Kosten!$I$25)/INDEX(Liegenschaft!$C$26:$G$26,1,Kosten!$I$25)*IF(Kosten!$D$25="Heizung/Warmwasser",Mieter!$L8,Mieter!$K8),0)) | X8: =SUM(D8:W8) | Y8: =IF(Liegenschaft!$C$11="Ja",ROUND(X8*Liegenschaft!$C$10,2),0) | Z8: =ROUND(X8+Y8,2) | AA8: =N(Mieter!G8) | AB8: =IF(C8="",0,Z8-AA8)
