Workbook

Sheet Anleitung
A1: Mieterwechsel- und Fristenplaner Schweiz
A3: So gehen Sie vor
A4: 1. «Einstellungen»: ortsübliche Kündigungstermine Ihrer Gemeinde bzw. Ihres Mietvertrags ankreuzen und Feiertage eintragen.
A5: 2. «Wechsel»: pro Kündigung eine Zeile. Der Planer rechnet das Ende des Mietverhältnisses, alle Fristen, den Leerstand und dessen Kosten.
A6: 3. Erledigte Schritte mit «x» markieren. Spalte «Nächste Frist» zeigt, was als Nächstes fällig ist (rot = überfällig, gelb = innert 7 Tagen).
A8: Rechtliche Hinweise (ohne Gewähr, ersetzt keine Rechtsberatung)
A9: • Wohnungen: Kündigungsfrist mindestens 3 Monate auf einen ortsüblichen Termin (Art. 266c OR). Der Mietvertrag kann längere Fristen oder andere Termine vorsehen – dann diese eintragen.
A10: • Massgebend ist der Eingang der Kündigung beim Empfänger, nicht der Versand.
A11: • Kündigung durch den Vermieter nur mit amtlichem Formular (Art. 266l OR), bei Familienwohnungen separat an beide Ehegatten (Art. 266n OR).
A12: • Ausserterminliche Kündigung: Mieter wird frei, wenn er einen zumutbaren Nachmieter stellt (Art. 264 OR). Dann «vereinbartes Ende» eintragen.
A13: • Mängel bei der Rückgabe sofort rügen (Art. 267a OR). Der Planer setzt dafür 2 Werktage nach der Abnahme.
A14: • Mietkaution: Ohne Forderung innert eines Jahres nach Mietende kann der Mieter die Kaution bei der Bank herausverlangen (Art. 257e Abs. 3 OR).
A15: • Fällt das Mietende auf ein Wochenende oder einen Feiertag, findet die Rückgabe am nächsten Werktag statt.

Sheet Einstellungen
A1: Einstellungen
A3: Kündigungstermine (Monatsende) | D3: Feiertage (für Werktagsrechnung)
A4: Monat | B4: Termin? (x) | D4: Datum
A5: Januar
A6: Februar
A7: März | B7: x
A8: April
A9: Mai
A10: Juni | B10: x
A11: Juli
A12: August
A13: September | B13: x
A14: Oktober
A15: November
A16: Dezember
A18: Voreinstellung: Ende März, Juni, September (verbreitet). Viele Städte (z.B. Zürich) erlauben jedes Monatsende ausser Dezember. Massgebend sind Gemeinde und Mietvertrag.

Sheet Wechsel
A1: Mieterwechsel
A2: Heute: | B2: =TODAY()
AA3: Hilfsspalten (Kandidaten Mietende, offene Fristen)
A4: Einheit | B4: Mieter bisher | C4: Kündigung durch | D4: Eingang Kündigung | E4: Frist (Monate) | F4: Vereinbartes Ende (optional) | G4: Ende Mietverhältnis | H4: Nettomiete / Monat CHF | I4: Neuer Mieter ab | J4: Leerstand Tage | K4: Leerstandskosten CHF | L4: Nachmieter suchen ab | M4: erl. | N4: Vorabnahme | O4: erl. | P4: Abnahme / Übergabe | Q4: erl. | R4: Mängelrüge bis | S4: erl. | T4: Kaution: Forderung bis | U4: erl. | V4: Nächste Frist | W4: Tage bis | X4: Hinweis
G5: =IF(F5<>"",F5,IF(D5<>"",IF(COUNT(AA5:AX5)=0,"",MIN(AA5:AX5)),"")) | J5: =IF(OR(G5="",I5=""),"",MAX(0,I5-G5-1)) | K5: =IF(OR(J5="",H5=""),"",ROUND(H5*12/365*J5,2)) | L5: =IF(D5<>"",D5,"") | N5: =IF(G5="","",WORKDAY(G5,-10,Einstellungen!$D$5:$D$34)) | P5: =IF(G5="","",WORKDAY(G5-1,1,Einstellungen!$D$5:$D$34)) | R5: =IF(P5="","",WORKDAY(P5,2,Einstellungen!$D$5:$D$34)) | T5: =IF(G5="","",EDATE(G5,12)) | V5: =IF(COUNT(AY5:BC5)=0,"",MIN(AY5:BC5)) | W5: =IF(V5="","",V5-$B$2) | X5: =IF(C5="Vermieter","Amtliches Formular verwendet? Bei Familienwohnung an beide Ehegatten.",IF(C5="Ausserterminlich","Nachmieter zumutbar? Vereinbartes Ende eintragen.",IF(AND(G5<>"",I5=""),"Noch kein Nachmieter.",""))) | AA5: =IF(D5<>"",IF(OR(COUNTIF(Einstellungen!$B$5:$B$16,"x")=0,INDEX(Einstellungen!$B$5:$B$16,MONTH(EOMONTH(D5,IF(E5="",3,E5)+0)))="x"),EOMONTH(D5,IF(E5="",3,E5)+0),""),"") | AB5: =IF(D5<>"",IF(OR(COUNTIF(Einstellungen!$B$5:$B$16,"x")=0,INDEX(Einstellungen!$B$5:$B$16,MONTH(EOMONTH(D5,IF(E5="",3,E5)+1)))="x"),EOMONTH(D5,IF(E5="",3,E5)+1),""),"") | AC5: =IF(D5<>"",IF(OR(COUNTIF(Einstellungen!$B$5:$B$16,"x")=0,INDEX(Einstellungen!$B$5:$B$16,MONTH(EOMONTH(D5,IF(E5="",3,E5)+2)))="x"),EOMONTH(D5,IF(E5="",3,E5)+2),""),"") | AD5: =IF(D5<>"",IF(OR(COUNTIF(Einstellungen!$B$5:$B$16,"x")=0,INDEX(Einstellungen!$B$5:$B$16,MONTH(EOMONTH(D5,IF(E5="",3,E5)+3)))="x"),EOMONTH(D5,IF(E5="",3,E5)+3),""),"") | AE5: =IF(D5<>"",IF(OR(COUNTIF(Einstellungen!$B$5:$B$16,"x")=0,INDEX(Einstellungen!$B$5:$B$16,MONTH(EOMONTH(D5,IF(E5="",3,E5)+4)))="x"),EOMONTH(D5,IF(E5="",3,E5)+4),""),"") | AF5: =IF(D5<>"",IF(OR(COUNTIF(Einstellungen!$B$5:$B$16,"x")=0,INDEX(Einstellungen!$B$5:$B$16,MONTH(EOMONTH(D5,IF(E5="",3,E5)+5)))="x"),EOMONTH(D5,IF(E5="",3,E5)+5),""),"") | AG5: =IF(D5<>"",IF(OR(COUNTIF(Einstellungen!$B$5:$B$16,"x")=0,INDEX(Einstellungen!$B$5:$B$16,MONTH(EOMONTH(D5,IF(E5="",3,E5)+6)))="x"),EOMONTH(D5,IF(E5="",3,E5)+6),""),"") | AH5: =IF(D5<>"",IF(OR(COUNTIF(Einstellungen!$B$5:$B$16,"x")=0,INDEX(Einstellungen!$B$5:$B$16,MONTH(EOMONTH(D5,IF(E5="",3,E5)+7)))="x"),EOMONTH(D5,IF(E5="",3,E5)+7),""),"") | AI5: =IF(D5<>"",IF(OR(COUNTIF(Einstellungen!$B$5:$B$16,"x")=0,INDEX(Einstellungen!$B$5:$B$16,MONTH(EOMONTH(D5,IF(E5="",3,E5)+8)))="x"),EOMONTH(D5,IF(E5="",3,E5)+8),""),"") | AJ5: =IF(D5<>"",IF(OR(COUNTIF(Einstellungen!$B$5:$B$16,"x")=0,INDEX(Einstellungen!$B$5:$B$16,MONTH(EOMONTH(D5,IF(E5="",3,E5)+9)))="x"),EOMONTH(D5,IF(E5="",3,E5)+9),""),"") | AK5: =IF(D5<>"",IF(OR(COUNTIF(Einstellungen!$B$5:$B$16,"x")=0,INDEX(Einstellungen!$B$5:$B$16,MONTH(EOMONTH(D5,IF(E5="",3,E5)+10)))="x"),EOMONTH(D5,IF(E5="",3,E5)+10),""),"") | AL5: =IF(D5<>"",IF(OR(COUNTIF(Einstellungen!$B$5:$B$16,"x")=0,INDEX(Einstellungen!$B$5:$B$16,MONTH(EOMONTH(D5,IF(E5="",3,E5)+11)))="x"),EOMONTH(D5,IF(E5="",3,E5)+11),""),"") | AM5: =IF(D5<>"",IF(OR(COUNTIF(Einstellungen!$B$5:$B$16,"x")=0,INDEX(Einstellungen!$B$5:$B$16,MONTH(EOMONTH(D5,IF(E5="",3,E5)+12)))="x"),EOMONTH(D5,IF(E5="",3,E5)+12),""),"") | AN5: =IF(D5<>"",IF(OR(COUNTIF(Einstellungen!$B$5:$B$16,"x")=0,INDEX(Einstellungen!$B$5:$B$16,MONTH(EOMONTH(D5,IF(E5="",3,E5)+13)))="x"),EOMONTH(D5,IF(E5="",3,E5)+13),""),"") | AO5: =IF(D5<>"",IF(OR(COUNTIF(Einstellungen!$B$5:$B$16,"x")=0,INDEX(Einstellungen!$B$5:$B$16,MONTH(EOMONTH(D5,IF(E5="",3,E5)+14)))="x"),EOMONTH(D5,IF(E5="",3,E5)+14),""),"") | AP5: =IF(D5<>"",IF(OR(COUNTIF(Einstellungen!$B$5:$B$16,"x")=0,INDEX(Einstellungen!$B$5:$B$16,MONTH(EOMONTH(D5,IF(E5="",3,E5)+15)))="x"),EOMONTH(D5,IF(E5="",3,E5)+15),""),"") | AQ5: =IF(D5<>"",IF(OR(COUNTIF(Einstellungen!$B$5:$B$16,"x")=0,INDEX(Einstellungen!$B$5:$B$16,MONTH(EOMONTH(D5,IF(E5="",3,E5)+16)))="x"),EOMONTH(D5,IF(E5="",3,E5)+16),""),"") | AR5: =IF(D5<>"",IF(OR(COUNTIF(Einstellungen!$B$5:$B$16,"x")=0,INDEX(Einstellungen!$B$5:$B$16,MONTH(EOMONTH(D5,IF(E5="",3,E5)+17)))="x"),EOMONTH(D5,IF(E5="",3,E5)+17),""),"") | AS5: =IF(D5<>"",IF(OR(COUNTIF(Einstellungen!$B$5:$B$16,"x")=0,INDEX(Einstellungen!$B$5:$B$16,MONTH(EOMONTH(D5,IF(E5="",3,E5)+18)))="x"),EOMONTH(D5,IF(E5="",3,E5)+18),""),"") | AT5: =IF(D5<>"",IF(OR(COUNTIF(Einstellungen!$B$5:$B$16,"x")=0,INDEX(Einstellungen!$B$5:$B$16,MONTH(EOMONTH(D5,IF(E5="",3,E5)+19)))="x"),EOMONTH(D5,IF(E5="",3,E5)+19),""),"") | AU5: =IF(D5<>"",IF(OR(COUNTIF(Einstellungen!$B$5:$B$16,"x")=0,INDEX(Einstellungen!$B$5:$B$16,MONTH(EOMONTH(D5,IF(E5="",3,E5)+20)))="x"),EOMONTH(D5,IF(E5="",3,E5)+20),""),"") | AV5: =IF(D5<>"",IF(OR(COUNTIF(Einstellungen!$B$5:$B$16,"x")=0,INDEX(Einstellungen!$B$5:$B$16,MONTH(EOMONTH(D5,IF(E5="",3,E5)+21)))="x"),EOMONTH(D5,IF(E5="",3,E5)+21),""),"") | AW5: =IF(D5<>"",IF(OR(COUNTIF(Einstellungen!$B$5:$B$16,"x")=0,INDEX(Einstellungen!$B$5:$B$16,MONTH(EOMONTH(D5,IF(E5="",3,E5)+22)))="x"),EOMONTH(D5,IF(E5="",3,E5)+22),""),"") | AX5: =IF(D5<>"",IF(OR(COUNTIF(Einstellungen!$B$5:$B$16,"x")=0,INDEX(Einstellungen!$B$5:$B$16,MONTH(EOMONTH(D5,IF(E5="",3,E5)+23)))="x"),EOMONTH(D5,IF(E5="",3,E5)+23),""),"") | AY5: =IF(AND(L5<>"",M5=""),L5,"") | AZ5: =IF(AND(N5<>"",O5=""),N5,"") | BA5: =IF(AND(P5<>"",Q5=""),P5,"") | BB5: =IF(AND(R5<>"",S5=""),R5,"") | BC5: =IF(AND(T5<>"",U5=""),T5,"")
G6: =IF(F6<>"",F6,IF(D6<>"",IF(COUNT(AA6:AX6)=0,"",MIN(AA6:AX6)),"")) | J6: =IF(OR(G6="",I6=""),"",MAX(0,I6-G6-1)) | K6: =IF(OR(J6="",H6=""),"",ROUND(H6*12/365*J6,2)) | L6: =IF(D6<>"",D6,"") | N6: =IF(G6="","",WORKDAY(G6,-10,Einstellungen!$D$5:$D$34)) | P6: =IF(G6="","",WORKDAY(G6-1,1,Einstellungen!$D$5:$D$34)) | R6: =IF(P6="","",WORKDAY(P6,2,Einstellungen!$D$5:$D$34)) | T6: =IF(G6="","",EDATE(G6,12)) | V6: =IF(COUNT(AY6:BC6)=0,"",MIN(AY6:BC6)) | W6: =IF(V6="","",V6-$B$2) | X6: =IF(C6="Vermieter","Amtliches Formular verwendet? Bei Familienwohnung an beide Ehegatten.",IF(C6="Ausserterminlich","Nachmieter zumutbar? Vereinbartes Ende eintragen.",IF(AND(G6<>"",I6=""),"Noch kein Nachmieter.",""))) | AA6: =IF(D6<>"",IF(OR(COUNTIF(Einstellungen!$B$5:$B$16,"x")=0,INDEX(Einstellungen!$B$5:$B$16,MONTH(EOMONTH(D6,IF(E6="",3,E6)+0)))="x"),EOMONTH(D6,IF(E6="",3,E6)+0),""),"") | AB6: =IF(D6<>"",IF(OR(COUNTIF(Einstellungen!$B$5:$B$16,"x")=0,INDEX(Einstellungen!$B$5:$B$16,MONTH(EOMONTH(D6,IF(E6="",3,E6)+1)))="x"),EOMONTH(D6,IF(E6="",3,E6)+1),""),"") | AC6: =IF(D6<>"",IF(OR(COUNTIF(Einstellungen!$B$5:$B$16,"x")=0,INDEX(Einstellungen!$B$5:$B$16,MONTH(EOMONTH(D6,IF(E6="",3,E6)+2)))="x"),EOMONTH(D6,IF(E6="",3,E6)+2),""),"") | AD6: =IF(D6<>"",IF(OR(COUNTIF(Einstellungen!$B$5:$B$16,"x")=0,INDEX(Einstellungen!$B$5:$B$16,MONTH(EOMONTH(D6,IF(E6="",3,E6)+3)))="x"),EOMONTH(D6,IF(E6="",3,E6)+3),""),"") | AE6: =IF(D6<>"",IF(OR(COUNTIF(Einstellungen!$B$5:$B$16,"x")=0,INDEX(Einstellungen!$B$5:$B$16,MONTH(EOMONTH(D6,IF(E6="",3,E6)+4)))="x"),EOMONTH(D6,IF(E6="",3,E6)+4),""),"") | AF6: =IF(D6<>"",IF(OR(COUNTIF(Einstellungen!$B$5:$B$16,"x")=0,INDEX(Einstellungen!$B$5:$B$16,MONTH(EOMONTH(D6,IF(E6="",3,E6)+5)))="x"),EOMONTH(D6,IF(E6="",3,E6)+5),""),"") | AG6: =IF(D6<>"",IF(OR(COUNTIF(Einstellungen!$B$5:$B$16,"x")=0,INDEX(Einstellungen!$B$5:$B$16,MONTH(EOMONTH(D6,IF(E6="",3,E6)+6)))="x"),EOMONTH(D6,IF(E6="",3,E6)+6),""),"") | AH6: =IF(D6<>"",IF(OR(COUNTIF(Einstellungen!$B$5:$B$16,"x")=0,INDEX(Einstellungen!$B$5:$B$16,MONTH(EOMONTH(D6,IF(E6="",3,E6)+7)))="x"),EOMONTH(D6,IF(E6="",3,E6)+7),""),"") | AI6: =IF(D6<>"",IF(OR(COUNTIF(Einstellungen!$B$5:$B$16,"x")=0,INDEX(Einstellungen!$B$5:$B$16,MONTH(EOMONTH(D6,IF(E6="",3,E6)+8)))="x"),EOMONTH(D6,IF(E6="",3,E6)+8),""),"") | AJ6: =IF(D6<>"",IF(OR(COUNTIF(Einstellungen!$B$5:$B$16,"x")=0,INDEX(Einstellungen!$B$5:$B$16,MONTH(EOMONTH(D6,IF(E6="",3,E6)+9)))="x"),EOMONTH(D6,IF(E6="",3,E6)+9),""),"") | AK6: =IF(D6<>"",IF(OR(COUNTIF(Einstellungen!$B$5:$B$16,"x")=0,INDEX(Einstellungen!$B$5:$B$16,MONTH(EOMONTH(D6,IF(E6="",3,E6)+10)))="x"),EOMONTH(D6,IF(E6="",3,E6)+10),""),"") | AL6: =IF(D6<>"",IF(OR(COUNTIF(Einstellungen!$B$5:$B$16,"x")=0,INDEX(Einstellungen!$B$5:$B$16,MONTH(EOMONTH(D6,IF(E6="",3,E6)+11)))="x"),EOMONTH(D6,IF(E6="",3,E6)+11),""),"") | AM6: =IF(D6<>"",IF(OR(COUNTIF(Einstellungen!$B$5:$B$16,"x")=0,INDEX(Einstellungen!$B$5:$B$16,MONTH(EOMONTH(D6,IF(E6="",3,E6)+12)))="x"),EOMONTH(D6,IF(E6="",3,E6)+12),""),"") | AN6: =IF(D6<>"",IF(OR(COUNTIF(Einstellungen!$B$5:$B$16,"x")=0,INDEX(Einstellungen!$B$5:$B$16,MONTH(EOMONTH(D6,IF(E6="",3,E6)+13)))="x"),EOMONTH(D6,IF(E6="",3,E6)+13),""),"") | AO6: =IF(D6<>"",IF(OR(COUNTIF(Einstellungen!$B$5:$B$16,"x")=0,INDEX(Einstellungen!$B$5:$B$16,MONTH(EOMONTH(D6,IF(E6="",3,E6)+14)))="x"),EOMONTH(D6,IF(E6="",3,E6)+14),""),"") | AP6: =IF(D6<>"",IF(OR(COUNTIF(Einstellungen!$B$5:$B$16,"x")=0,INDEX(Einstellungen!$B$5:$B$16,MONTH(EOMONTH(D6,IF(E6="",3,E6)+15)))="x"),EOMONTH(D6,IF(E6="",3,E6)+15),""),"") | AQ6: =IF(D6<>"",IF(OR(COUNTIF(Einstellungen!$B$5:$B$16,"x")=0,INDEX(Einstellungen!$B$5:$B$16,MONTH(EOMONTH(D6,IF(E6="",3,E6)+16)))="x"),EOMONTH(D6,IF(E6="",3,E6)+16),""),"") | AR6: =IF(D6<>"",IF(OR(COUNTIF(Einstellungen!$B$5:$B$16,"x")=0,INDEX(Einstellungen!$B$5:$B$16,MONTH(EOMONTH(D6,IF(E6="",3,E6)+17)))="x"),EOMONTH(D6,IF(E6="",3,E6)+17),""),"") | AS6: =IF(D6<>"",IF(OR(COUNTIF(Einstellungen!$B$5:$B$16,"x")=0,INDEX(Einstellungen!$B$5:$B$16,MONTH(EOMONTH(D6,IF(E6="",3,E6)+18)))="x"),EOMONTH(D6,IF(E6="",3,E6)+18),""),"") | AT6: =IF(D6<>"",IF(OR(COUNTIF(Einstellungen!$B$5:$B$16,"x")=0,INDEX(Einstellungen!$B$5:$B$16,MONTH(EOMONTH(D6,IF(E6="",3,E6)+19)))="x"),EOMONTH(D6,IF(E6="",3,E6)+19),""),"") | AU6: =IF(D6<>"",IF(OR(COUNTIF(Einstellungen!$B$5:$B$16,"x")=0,INDEX(Einstellungen!$B$5:$B$16,MONTH(EOMONTH(D6,IF(E6="",3,E6)+20)))="x"),EOMONTH(D6,IF(E6="",3,E6)+20),""),"") | AV6: =IF(D6<>"",IF(OR(COUNTIF(Einstellungen!$B$5:$B$16,"x")=0,INDEX(Einstellungen!$B$5:$B$16,MONTH(EOMONTH(D6,IF(E6="",3,E6)+21)))="x"),EOMONTH(D6,IF(E6="",3,E6)+21),""),"") | AW6: =IF(D6<>"",IF(OR(COUNTIF(Einstellungen!$B$5:$B$16,"x")=0,INDEX(Einstellungen!$B$5:$B$16,MONTH(EOMONTH(D6,IF(E6="",3,E6)+22)))="x"),EOMONTH(D6,IF(E6="",3,E6)+22),""),"") | AX6: =IF(D6<>"",IF(OR(COUNTIF(Einstellungen!$B$5:$B$16,"x")=0,INDEX(Einstellungen!$B$5:$B$16,MONTH(EOMONTH(D6,IF(E6="",3,E6)+23)))="x"),EOMONTH(D6,IF(E6="",3,E6)+23),""),"") | AY6: =IF(AND(L6<>"",M6=""),L6,"") | AZ6: =IF(AND(N6<>"",O6=""),N6,"") | BA6: =IF(AND(P6<>"",Q6=""),P6,"") | BB6: =IF(AND(R6<>"",S6=""),R6,"") | BC6: =IF(AND(T6<>"",U6=""),T6,"")
G7: =IF(F7<>"",F7,IF(D7<>"",IF(COUNT(AA7:AX7)=0,"",MIN(AA7:AX7)),"")) | J7: =IF(OR(G7="",I7=""),"",MAX(0,I7-G7-1)) | K7: =IF(OR(J7="",H7=""),"",ROUND(H7*12/365*J7,2)) | L7: =IF(D7<>"",D7,"") | N7: =IF(G7="","",WORKDAY(G7,-10,Einstellungen!$D$5:$D$34)) | P7: =IF(G7="","",WORKDAY(G7-1,1,Einstellungen!$D$5:$D$34)) | R7: =IF(P7="","",WORKDAY(P7,2,Einstellungen!$D$5:$D$34)) | T7: =IF(G7="","",EDATE(G7,12)) | V7: =IF(COUNT(AY7:BC7)=0,"",MIN(AY7:BC7)) | W7: =IF(V7="","",V7-$B$2) | X7: =IF(C7="Vermieter","Amtliches Formular verwendet? Bei Familienwohnung an beide Ehegatten.",IF(C7="Ausserterminlich","Nachmieter zumutbar? Vereinbartes Ende eintragen.",IF(AND(G7<>"",I7=""),"Noch kein Nachmieter.",""))) | AA7: =IF(D7<>"",IF(OR(COUNTIF(Einstellungen!$B$5:$B$16,"x")=0,INDEX(Einstellungen!$B$5:$B$16,MONTH(EOMONTH(D7,IF(E7="",3,E7)+0)))="x"),EOMONTH(D7,IF(E7="",3,E7)+0),""),"") | AB7: =IF(D7<>"",IF(OR(COUNTIF(Einstellungen!$B$5:$B$16,"x")=0,INDEX(Einstellungen!$B$5:$B$16,MONTH(EOMONTH(D7,IF(E7="",3,E7)+1)))="x"),EOMONTH(D7,IF(E7="",3,E7)+1),""),"") | AC7: =IF(D7<>"",IF(OR(COUNTIF(Einstellungen!$B$5:$B$16,"x")=0,INDEX(Einstellungen!$B$5:$B$16,MONTH(EOMONTH(D7,IF(E7="",3,E7)+2)))="x"),EOMONTH(D7,IF(E7="",3,E7)+2),""),"") | AD7: =IF(D7<>"",IF(OR(COUNTIF(Einstellungen!$B$5:$B$16,"x")=0,INDEX(Einstellungen!$B$5:$B$16,MONTH(EOMONTH(D7,IF(E7="",3,E7)+3)))="x"),EOMONTH(D7,IF(E7="",3,E7)+3),""),"") | AE7: =IF(D7<>"",IF(OR(COUNTIF(Einstellungen!$B$5:$B$16,"x")=0,INDEX(Einstellungen!$B$5:$B$16,MONTH(EOMONTH(D7,IF(E7="",3,E7)+4)))="x"),EOMONTH(D7,IF(E7="",3,E7)+4),""),"") | AF7: =IF(D7<>"",IF(OR(COUNTIF(Einstellungen!$B$5:$B$16,"x")=0,INDEX(Einstellungen!$B$5:$B$16,MONTH(EOMONTH(D7,IF(E7="",3,E7)+5)))="x"),EOMONTH(D7,IF(E7="",3,E7)+5),""),"") | AG7: =IF(D7<>"",IF(OR(COUNTIF(Einstellungen!$B$5:$B$16,"x")=0,INDEX(Einstellungen!$B$5:$B$16,MONTH(EOMONTH(D7,IF(E7="",3,E7)+6)))="x"),EOMONTH(D7,IF(E7="",3,E7)+6),""),"") | AH7: =IF(D7<>"",IF(OR(COUNTIF(Einstellungen!$B$5:$B$16,"x")=0,INDEX(Einstellungen!$B$5:$B$16,MONTH(EOMONTH(D7,IF(E7="",3,E7)+7)))="x"),EOMONTH(D7,IF(E7="",3,E7)+7),""),"") | AI7: =IF(D7<>"",IF(OR(COUNTIF(Einstellungen!$B$5:$B$16,"x")=0,INDEX(Einstellungen!$B$5:$B$16,MONTH(EOMONTH(D7,IF(E7="",3,E7)+8)))="x"),EOMONTH(D7,IF(E7="",3,E7)+8),""),"") | AJ7: =IF(D7<>"",IF(OR(COUNTIF(Einstellungen!$B$5:$B$16,"x")=0,INDEX(Einstellungen!$B$5:$B$16,MONTH(EOMONTH(D7,IF(E7="",3,E7)+9)))="x"),EOMONTH(D7,IF(E7="",3,E7)+9),""),"") | AK7: =IF(D7<>"",IF(OR(COUNTIF(Einstellungen!$B$5:$B$16,"x")=0,INDEX(Einstellungen!$B$5:$B$16,MONTH(EOMONTH(D7,IF(E7="",3,E7)+10)))="x"),EOMONTH(D7,IF(E7="",3,E7)+10),""),"") | AL7: =IF(D7<>"",IF(OR(COUNTIF(Einstellungen!$B$5:$B$16,"x")=0,INDEX(Einstellungen!$B$5:$B$16,MONTH(EOMONTH(D7,IF(E7="",3,E7)+11)))="x"),EOMONTH(D7,IF(E7="",3,E7)+11),""),"") | AM7: =IF(D7<>"",IF(OR(COUNTIF(Einstellungen!$B$5:$B$16,"x")=0,INDEX(Einstellungen!$B$5:$B$16,MONTH(EOMONTH(D7,IF(E7="",3,E7)+12)))="x"),EOMONTH(D7,IF(E7="",3,E7)+12),""),"") | AN7: =IF(D7<>"",IF(OR(COUNTIF(Einstellungen!$B$5:$B$16,"x")=0,INDEX(Einstellungen!$B$5:$B$16,MONTH(EOMONTH(D7,IF(E7="",3,E7)+13)))="x"),EOMONTH(D7,IF(E7="",3,E7)+13),""),"") | AO7: =IF(D7<>"",IF(OR(COUNTIF(Einstellungen!$B$5:$B$16,"x")=0,INDEX(Einstellungen!$B$5:$B$16,MONTH(EOMONTH(D7,IF(E7="",3,E7)+14)))="x"),EOMONTH(D7,IF(E7="",3,E7)+14),""),"") | AP7: =IF(D7<>"",IF(OR(COUNTIF(Einstellungen!$B$5:$B$16,"x")=0,INDEX(Einstellungen!$B$5:$B$16,MONTH(EOMONTH(D7,IF(E7="",3,E7)+15)))="x"),EOMONTH(D7,IF(E7="",3,E7)+15),""),"") | AQ7: =IF(D7<>"",IF(OR(COUNTIF(Einstellungen!$B$5:$B$16,"x")=0,INDEX(Einstellungen!$B$5:$B$16,MONTH(EOMONTH(D7,IF(E7="",3,E7)+16)))="x"),EOMONTH(D7,IF(E7="",3,E7)+16),""),"") | AR7: =IF(D7<>"",IF(OR(COUNTIF(Einstellungen!$B$5:$B$16,"x")=0,INDEX(Einstellungen!$B$5:$B$16,MONTH(EOMONTH(D7,IF(E7="",3,E7)+17)))="x"),EOMONTH(D7,IF(E7="",3,E7)+17),""),"") | AS7: =IF(D7<>"",IF(OR(COUNTIF(Einstellungen!$B$5:$B$16,"x")=0,INDEX(Einstellungen!$B$5:$B$16,MONTH(EOMONTH(D7,IF(E7="",3,E7)+18)))="x"),EOMONTH(D7,IF(E7="",3,E7)+18),""),"") | AT7: =IF(D7<>"",IF(OR(COUNTIF(Einstellungen!$B$5:$B$16,"x")=0,INDEX(Einstellungen!$B$5:$B$16,MONTH(EOMONTH(D7,IF(E7="",3,E7)+19)))="x"),EOMONTH(D7,IF(E7="",3,E7)+19),""),"") | AU7: =IF(D7<>"",IF(OR(COUNTIF(Einstellungen!$B$5:$B$16,"x")=0,INDEX(Einstellungen!$B$5:$B$16,MONTH(EOMONTH(D7,IF(E7="",3,E7)+20)))="x"),EOMONTH(D7,IF(E7="",3,E7)+20),""),"") | AV7: =IF(D7<>"",IF(OR(COUNTIF(Einstellungen!$B$5:$B$16,"x")=0,INDEX(Einstellungen!$B$5:$B$16,MONTH(EOMONTH(D7,IF(E7="",3,E7)+21)))="x"),EOMONTH(D7,IF(E7="",3,E7)+21),""),"") | AW7: =IF(D7<>"",IF(OR(COUNTIF(Einstellungen!$B$5:$B$16,"x")=0,INDEX(Einstellungen!$B$5:$B$16,MONTH(EOMONTH(D7,IF(E7="",3,E7)+22)))="x"),EOMONTH(D7,IF(E7="",3,E7)+22),""),"") | AX7: =IF(D7<>"",IF(OR(COUNTIF(Einstellungen!$B$5:$B$16,"x")=0,INDEX(Einstellungen!$B$5:$B$16,MONTH(EOMONTH(D7,IF(E7="",3,E7)+23)))="x"),EOMONTH(D7,IF(E7="",3,E7)+23),""),"") | AY7: =IF(AND(L7<>"",M7=""),L7,"") | AZ7: =IF(AND(N7<>"",O7=""),N7,"") | BA7: =IF(AND(P7<>"",Q7=""),P7,"") | BB7: =IF(AND(R7<>"",S7=""),R7,"") | BC7: =IF(AND(T7<>"",U7=""),T7,"")
G8: =IF(F8<>"",F8,IF(D8<>"",IF(COUNT(AA8:AX8)=0,"",MIN(AA8:AX8)),"")) | J8: =IF(OR(G8="",I8=""),"",MAX(0,I8-G8-1)) | K8: =IF(OR(J8="",H8=""),"",ROUND(H8*12/365*J8,2)) | L8: =IF(D8<>"",D8,"") | N8: =IF(G8="","",WORKDAY(G8,-10,Einstellungen!$D$5:$D$34)) | P8: =IF(G8="","",WORKDAY(G8-1,1,Einstellungen!$D$5:$D$34)) | R8: =IF(P8="","",WORKDAY(P8,2,Einstellungen!$D$5:$D$34)) | T8: =IF(G8="","",EDATE(G8,12)) | V8: =IF(COUNT(AY8:BC8)=0,"",MIN(AY8:BC8)) | W8: =IF(V8="","",V8-$B$2) | X8: =IF(C8="Vermieter","Amtliches Formular verwendet? Bei Familienwohnung an beide Ehegatten.",IF(C8="Ausserterminlich","Nachmieter zumutbar? Vereinbartes Ende eintragen.",IF(AND(G8<>"",I8=""),"Noch kein Nachmieter.",""))) | AA8: =IF(D8<>"",IF(OR(COUNTIF(Einstellungen!$B$5:$B$16,"x")=0,INDEX(Einstellungen!$B$5:$B$16,MONTH(EOMONTH(D8,IF(E8="",3,E8)+0)))="x"),EOMONTH(D8,IF(E8="",3,E8)+0),""),"") | AB8: =IF(D8<>"",IF(OR(COUNTIF(Einstellungen!$B$5:$B$16,"x")=0,INDEX(Einstellungen!$B$5:$B$16,MONTH(EOMONTH(D8,IF(E8="",3,E8)+1)))="x"),EOMONTH(D8,IF(E8="",3,E8)+1),""),"") | AC8: =IF(D8<>"",IF(OR(COUNTIF(Einstellungen!$B$5:$B$16,"x")=0,INDEX(Einstellungen!$B$5:$B$16,MONTH(EOMONTH(D8,IF(E8="",3,E8)+2)))="x"),EOMONTH(D8,IF(E8="",3,E8)+2),""),"") | AD8: =IF(D8<>"",IF(OR(COUNTIF(Einstellungen!$B$5:$B$16,"x")=0,INDEX(Einstellungen!$B$5:$B$16,MONTH(EOMONTH(D8,IF(E8="",3,E8)+3)))="x"),EOMONTH(D8,IF(E8="",3,E8)+3),""),"") | AE8: =IF(D8<>"",IF(OR(COUNTIF(Einstellungen!$B$5:$B$16,"x")=0,INDEX(Einstellungen!$B$5:$B$16,MONTH(EOMONTH(D8,IF(E8="",3,E8)+4)))="x"),EOMONTH(D8,IF(E8="",3,E8)+4),""),"") | AF8: =IF(D8<>"",IF(OR(COUNTIF(Einstellungen!$B$5:$B$16,"x")=0,INDEX(Einstellungen!$B$5:$B$16,MONTH(EOMONTH(D8,IF(E8="",3,E8)+5)))="x"),EOMONTH(D8,IF(E8="",3,E8)+5),""),"") | AG8: =IF(D8<>"",IF(OR(COUNTIF(Einstellungen!$B$5:$B$16,"x")=0,INDEX(Einstellungen!$B$5:$B$16,MONTH(EOMONTH(D8,IF(E8="",3,E8)+6)))="x"),EOMONTH(D8,IF(E8="",3,E8)+6),""),"") | AH8: =IF(D8<>"",IF(OR(COUNTIF(Einstellungen!$B$5:$B$16,"x")=0,INDEX(Einstellungen!$B$5:$B$16,MONTH(EOMONTH(D8,IF(E8="",3,E8)+7)))="x"),EOMONTH(D8,IF(E8="",3,E8)+7),""),"") | AI8: =IF(D8<>"",IF(OR(COUNTIF(Einstellungen!$B$5:$B$16,"x")=0,INDEX(Einstellungen!$B$5:$B$16,MONTH(EOMONTH(D8,IF(E8="",3,E8)+8)))="x"),EOMONTH(D8,IF(E8="",3,E8)+8),""),"") | AJ8: =IF(D8<>"",IF(OR(COUNTIF(Einstellungen!$B$5:$B$16,"x")=0,INDEX(Einstellungen!$B$5:$B$16,MONTH(EOMONTH(D8,IF(E8="",3,E8)+9)))="x"),EOMONTH(D8,IF(E8="",3,E8)+9),""),"") | AK8: =IF(D8<>"",IF(OR(COUNTIF(Einstellungen!$B$5:$B$16,"x")=0,INDEX(Einstellungen!$B$5:$B$16,MONTH(EOMONTH(D8,IF(E8="",3,E8)+10)))="x"),EOMONTH(D8,IF(E8="",3,E8)+10),""),"") | AL8: =IF(D8<>"",IF(OR(COUNTIF(Einstellungen!$B$5:$B$16,"x")=0,INDEX(Einstellungen!$B$5:$B$16,MONTH(EOMONTH(D8,IF(E8="",3,E8)+11)))="x"),EOMONTH(D8,IF(E8="",3,E8)+11),""),"") | AM8: =IF(D8<>"",IF(OR(COUNTIF(Einstellungen!$B$5:$B$16,"x")=0,INDEX(Einstellungen!$B$5:$B$16,MONTH(EOMONTH(D8,IF(E8="",3,E8)+12)))="x"),EOMONTH(D8,IF(E8="",3,E8)+12),""),"") | AN8: =IF(D8<>"",IF(OR(COUNTIF(Einstellungen!$B$5:$B$16,"x")=0,INDEX(Einstellungen!$B$5:$B$16,MONTH(EOMONTH(D8,IF(E8="",3,E8)+13)))="x"),EOMONTH(D8,IF(E8="",3,E8)+13),""),"") | AO8: =IF(D8<>"",IF(OR(COUNTIF(Einstellungen!$B$5:$B$16,"x")=0,INDEX(Einstellungen!$B$5:$B$16,MONTH(EOMONTH(D8,IF(E8="",3,E8)+14)))="x"),EOMONTH(D8,IF(E8="",3,E8)+14),""),"") | AP8: =IF(D8<>"",IF(OR(COUNTIF(Einstellungen!$B$5:$B$16,"x")=0,INDEX(Einstellungen!$B$5:$B$16,MONTH(EOMONTH(D8,IF(E8="",3,E8)+15)))="x"),EOMONTH(D8,IF(E8="",3,E8)+15),""),"") | AQ8: =IF(D8<>"",IF(OR(COUNTIF(Einstellungen!$B$5:$B$16,"x")=0,INDEX(Einstellungen!$B$5:$B$16,MONTH(EOMONTH(D8,IF(E8="",3,E8)+16)))="x"),EOMONTH(D8,IF(E8="",3,E8)+16),""),"") | AR8: =IF(D8<>"",IF(OR(COUNTIF(Einstellungen!$B$5:$B$16,"x")=0,INDEX(Einstellungen!$B$5:$B$16,MONTH(EOMONTH(D8,IF(E8="",3,E8)+17)))="x"),EOMONTH(D8,IF(E8="",3,E8)+17),""),"") | AS8: =IF(D8<>"",IF(OR(COUNTIF(Einstellungen!$B$5:$B$16,"x")=0,INDEX(Einstellungen!$B$5:$B$16,MONTH(EOMONTH(D8,IF(E8="",3,E8)+18)))="x"),EOMONTH(D8,IF(E8="",3,E8)+18),""),"") | AT8: =IF(D8<>"",IF(OR(COUNTIF(Einstellungen!$B$5:$B$16,"x")=0,INDEX(Einstellungen!$B$5:$B$16,MONTH(EOMONTH(D8,IF(E8="",3,E8)+19)))="x"),EOMONTH(D8,IF(E8="",3,E8)+19),""),"") | AU8: =IF(D8<>"",IF(OR(COUNTIF(Einstellungen!$B$5:$B$16,"x")=0,INDEX(Einstellungen!$B$5:$B$16,MONTH(EOMONTH(D8,IF(E8="",3,E8)+20)))="x"),EOMONTH(D8,IF(E8="",3,E8)+20),""),"") | AV8: =IF(D8<>"",IF(OR(COUNTIF(Einstellungen!$B$5:$B$16,"x")=0,INDEX(Einstellungen!$B$5:$B$16,MONTH(EOMONTH(D8,IF(E8="",3,E8)+21)))="x"),EOMONTH(D8,IF(E8="",3,E8)+21),""),"") | AW8: =IF(D8<>"",IF(OR(COUNTIF(Einstellungen!$B$5:$B$16,"x")=0,INDEX(Einstellungen!$B$5:$B$16,MONTH(EOMONTH(D8,IF(E8="",3,E8)+22)))="x"),EOMONTH(D8,IF(E8="",3,E8)+22),""),"") | AX8: =IF(D8<>"",IF(OR(COUNTIF(Einstellungen!$B$5:$B$16,"x")=0,INDEX(Einstellungen!$B$5:$B$16,MONTH(EOMONTH(D8,IF(E8="",3,E8)+23)))="x"),EOMONTH(D8,IF(E8="",3,E8)+23),""),"") | AY8: =IF(AND(L8<>"",M8=""),L8,"") | AZ8: =IF(AND(N8<>"",O8=""),N8,"") | BA8: =IF(AND(P8<>"",Q8=""),P8,"") | BB8: =IF(AND(R8<>"",S8=""),R8,"") | BC8: =IF(AND(T8<>"",U8=""),T8,"")
G9: =IF(F9<>"",F9,IF(D9<>"",IF(COUNT(AA9:AX9)=0,"",MIN(AA9:AX9)),"")) | J9: =IF(OR(G9="",I9=""),"",MAX(0,I9-G9-1)) | K9: =IF(OR(J9="",H9=""),"",ROUND(H9*12/365*J9,2)) | L9: =IF(D9<>"",D9,"") | N9: =IF(G9="","",WORKDAY(G9,-10,Einstellungen!$D$5:$D$34)) | P9: =IF(G9="","",WORKDAY(G9-1,1,Einstellungen!$D$5:$D$34)) | R9: =IF(P9="","",WORKDAY(P9,2,Einstellungen!$D$5:$D$34)) | T9: =IF(G9="","",EDATE(G9,12)) | V9: =IF(COUNT(AY9:BC9)=0,"",MIN(AY9:BC9)) | W9: =IF(V9="","",V9-$B$2) | X9: =IF(C9="Vermieter","Amtliches Formular verwendet? Bei Familienwohnung an beide Ehegatten.",IF(C9="Ausserterminlich","Nachmieter zumutbar? Vereinbartes Ende eintragen.",IF(AND(G9<>"",I9=""),"Noch kein Nachmieter.",""))) | AA9: =IF(D9<>"",IF(OR(COUNTIF(Einstellungen!$B$5:$B$16,"x")=0,INDEX(Einstellungen!$B$5:$B$16,MONTH(EOMONTH(D9,IF(E9="",3,E9)+0)))="x"),EOMONTH(D9,IF(E9="",3,E9)+0),""),"") | AB9: =IF(D9<>"",IF(OR(COUNTIF(Einstellungen!$B$5:$B$16,"x")=0,INDEX(Einstellungen!$B$5:$B$16,MONTH(EOMONTH(D9,IF(E9="",3,E9)+1)))="x"),EOMONTH(D9,IF(E9="",3,E9)+1),""),"") | AC9: =IF(D9<>"",IF(OR(COUNTIF(Einstellungen!$B$5:$B$16,"x")=0,INDEX(Einstellungen!$B$5:$B$16,MONTH(EOMONTH(D9,IF(E9="",3,E9)+2)))="x"),EOMONTH(D9,IF(E9="",3,E9)+2),""),"") | AD9: =IF(D9<>"",IF(OR(COUNTIF(Einstellungen!$B$5:$B$16,"x")=0,INDEX(Einstellungen!$B$5:$B$16,MONTH(EOMONTH(D9,IF(E9="",3,E9)+3)))="x"),EOMONTH(D9,IF(E9="",3,E9)+3),""),"") | AE9: =IF(D9<>"",IF(OR(COUNTIF(Einstellungen!$B$5:$B$16,"x")=0,INDEX(Einstellungen!$B$5:$B$16,MONTH(EOMONTH(D9,IF(E9="",3,E9)+4)))="x"),EOMONTH(D9,IF(E9="",3,E9)+4),""),"") | AF9: =IF(D9<>"",IF(OR(COUNTIF(Einstellungen!$B$5:$B$16,"x")=0,INDEX(Einstellungen!$B$5:$B$16,MONTH(EOMONTH(D9,IF(E9="",3,E9)+5)))="x"),EOMONTH(D9,IF(E9="",3,E9)+5),""),"") | AG9: =IF(D9<>"",IF(OR(COUNTIF(Einstellungen!$B$5:$B$16,"x")=0,INDEX(Einstellungen!$B$5:$B$16,MONTH(EOMONTH(D9,IF(E9="",3,E9)+6)))="x"),EOMONTH(D9,IF(E9="",3,E9)+6),""),"") | AH9: =IF(D9<>"",IF(OR(COUNTIF(Einstellungen!$B$5:$B$16,"x")=0,INDEX(Einstellungen!$B$5:$B$16,MONTH(EOMONTH(D9,IF(E9="",3,E9)+7)))="x"),EOMONTH(D9,IF(E9="",3,E9)+7),""),"") | AI9: =IF(D9<>"",IF(OR(COUNTIF(Einstellungen!$B$5:$B$16,"x")=0,INDEX(Einstellungen!$B$5:$B$16,MONTH(EOMONTH(D9,IF(E9="",3,E9)+8)))="x"),EOMONTH(D9,IF(E9="",3,E9)+8),""),"") | AJ9: =IF(D9<>"",IF(OR(COUNTIF(Einstellungen!$B$5:$B$16,"x")=0,INDEX(Einstellungen!$B$5:$B$16,MONTH(EOMONTH(D9,IF(E9="",3,E9)+9)))="x"),EOMONTH(D9,IF(E9="",3,E9)+9),""),"") | AK9: =IF(D9<>"",IF(OR(COUNTIF(Einstellungen!$B$5:$B$16,"x")=0,INDEX(Einstellungen!$B$5:$B$16,MONTH(EOMONTH(D9,IF(E9="",3,E9)+10)))="x"),EOMONTH(D9,IF(E9="",3,E9)+10),""),"") | AL9: =IF(D9<>"",IF(OR(COUNTIF(Einstellungen!$B$5:$B$16,"x")=0,INDEX(Einstellungen!$B$5:$B$16,MONTH(EOMONTH(D9,IF(E9="",3,E9)+11)))="x"),EOMONTH(D9,IF(E9="",3,E9)+11),""),"") | AM9: =IF(D9<>"",IF(OR(COUNTIF(Einstellungen!$B$5:$B$16,"x")=0,INDEX(Einstellungen!$B$5:$B$16,MONTH(EOMONTH(D9,IF(E9="",3,E9)+12)))="x"),EOMONTH(D9,IF(E9="",3,E9)+12),""),"") | AN9: =IF(D9<>"",IF(OR(COUNTIF(Einstellungen!$B$5:$B$16,"x")=0,INDEX(Einstellungen!$B$5:$B$16,MONTH(EOMONTH(D9,IF(E9="",3,E9)+13)))="x"),EOMONTH(D9,IF(E9="",3,E9)+13),""),"") | AO9: =IF(D9<>"",IF(OR(COUNTIF(Einstellungen!$B$5:$B$16,"x")=0,INDEX(Einstellungen!$B$5:$B$16,MONTH(EOMONTH(D9,IF(E9="",3,E9)+14)))="x"),EOMONTH(D9,IF(E9="",3,E9)+14),""),"") | AP9: =IF(D9<>"",IF(OR(COUNTIF(Einstellungen!$B$5:$B$16,"x")=0,INDEX(Einstellungen!$B$5:$B$16,MONTH(EOMONTH(D9,IF(E9="",3,E9)+15)))="x"),EOMONTH(D9,IF(E9="",3,E9)+15),""),"") | AQ9: =IF(D9<>"",IF(OR(COUNTIF(Einstellungen!$B$5:$B$16,"x")=0,INDEX(Einstellungen!$B$5:$B$16,MONTH(EOMONTH(D9,IF(E9="",3,E9)+16)))="x"),EOMONTH(D9,IF(E9="",3,E9)+16),""),"") | AR9: =IF(D9<>"",IF(OR(COUNTIF(Einstellungen!$B$5:$B$16,"x")=0,INDEX(Einstellungen!$B$5:$B$16,MONTH(EOMONTH(D9,IF(E9="",3,E9)+17)))="x"),EOMONTH(D9,IF(E9="",3,E9)+17),""),"") | AS9: =IF(D9<>"",IF(OR(COUNTIF(Einstellungen!$B$5:$B$16,"x")=0,INDEX(Einstellungen!$B$5:$B$16,MONTH(EOMONTH(D9,IF(E9="",3,E9)+18)))="x"),EOMONTH(D9,IF(E9="",3,E9)+18),""),"") | AT9: =IF(D9<>"",IF(OR(COUNTIF(Einstellungen!$B$5:$B$16,"x")=0,INDEX(Einstellungen!$B$5:$B$16,MONTH(EOMONTH(D9,IF(E9="",3,E9)+19)))="x"),EOMONTH(D9,IF(E9="",3,E9)+19),""),"") | AU9: =IF(D9<>"",IF(OR(COUNTIF(Einstellungen!$B$5:$B$16,"x")=0,INDEX(Einstellungen!$B$5:$B$16,MONTH(EOMONTH(D9,IF(E9="",3,E9)+20)))="x"),EOMONTH(D9,IF(E9="",3,E9)+20),""),"") | AV9: =IF(D9<>"",IF(OR(COUNTIF(Einstellungen!$B$5:$B$16,"x")=0,INDEX(Einstellungen!$B$5:$B$16,MONTH(EOMONTH(D9,IF(E9="",3,E9)+21)))="x"),EOMONTH(D9,IF(E9="",3,E9)+21),""),"") | AW9: =IF(D9<>"",IF(OR(COUNTIF(Einstellungen!$B$5:$B$16,"x")=0,INDEX(Einstellungen!$B$5:$B$16,MONTH(EOMONTH(D9,IF(E9="",3,E9)+22)))="x"),EOMONTH(D9,IF(E9="",3,E9)+22),""),"") | AX9: =IF(D9<>"",IF(OR(COUNTIF(Einstellungen!$B$5:$B$16,"x")=0,INDEX(Einstellungen!$B$5:$B$16,MONTH(EOMONTH(D9,IF(E9="",3,E9)+23)))="x"),EOMONTH(D9,IF(E9="",3,E9)+23),""),"") | AY9: =IF(AND(L9<>"",M9=""),L9,"") | AZ9: =IF(AND(N9<>"",O9=""),N9,"") | BA9: =IF(AND(P9<>"",Q9=""),P9,"") | BB9: =IF(AND(R9<>"",S9=""),R9,"") | BC9: =IF(AND(T9<>"",U9=""),T9,"")
G10: =IF(F10<>"",F10,IF(D10<>"",IF(COUNT(AA10:AX10)=0,"",MIN(AA10:AX10)),"")) | J10: =IF(OR(G10="",I10=""),"",MAX(0,I10-G10-1)) | K10: =IF(OR(J10="",H10=""),"",ROUND(H10*12/365*J10,2)) | L10: =IF(D10<>"",D10,"") | N10: =IF(G10="","",WORKDAY(G10,-10,Einstellungen!$D$5:$D$34)) | P10: =IF(G10="","",WORKDAY(G10-1,1,Einstellungen!$D$5:$D$34)) | R10: =IF(P10="","",WORKDAY(P10,2,Einstellungen!$D$5:$D$34)) | T10: =IF(G10="","",EDATE(G10,12)) | V10: =IF(COUNT(AY10:BC10)=0,"",MIN(AY10:BC10)) | W10: =IF(V10="","",V10-$B$2) | X10: =IF(C10="Vermieter","Amtliches Formular verwendet? Bei Familienwohnung an beide Ehegatten.",IF(C10="Ausserterminlich","Nachmieter zumutbar? Vereinbartes Ende eintragen.",IF(AND(G10<>"",I10=""),"Noch kein Nachmieter.",""))) | AA10: =IF(D10<>"",IF(OR(COUNTIF(Einstellungen!$B$5:$B$16,"x")=0,INDEX(Einstellungen!$B$5:$B$16,MONTH(EOMONTH(D10,IF(E10="",3,E10)+0)))="x"),EOMONTH(D10,IF(E10="",3,E10)+0),""),"") | AB10: =IF(D10<>"",IF(OR(COUNTIF(Einstellungen!$B$5:$B$16,"x")=0,INDEX(Einstellungen!$B$5:$B$16,MONTH(EOMONTH(D10,IF(E10="",3,E10)+1)))="x"),EOMONTH(D10,IF(E10="",3,E10)+1),""),"") | AC10: =IF(D10<>"",IF(OR(COUNTIF(Einstellungen!$B$5:$B$16,"x")=0,INDEX(Einstellungen!$B$5:$B$16,MONTH(EOMONTH(D10,IF(E10="",3,E10)+2)))="x"),EOMONTH(D10,IF(E10="",3,E10)+2),""),"") | AD10: =IF(D10<>"",IF(OR(COUNTIF(Einstellungen!$B$5:$B$16,"x")=0,INDEX(Einstellungen!$B$5:$B$16,MONTH(EOMONTH(D10,IF(E10="",3,E10)+3)))="x"),EOMONTH(D10,IF(E10="",3,E10)+3),""),"") | AE10: =IF(D10<>"",IF(OR(COUNTIF(Einstellungen!$B$5:$B$16,"x")=0,INDEX(Einstellungen!$B$5:$B$16,MONTH(EOMONTH(D10,IF(E10="",3,E10)+4)))="x"),EOMONTH(D10,IF(E10="",3,E10)+4),""),"") | AF10: =IF(D10<>"",IF(OR(COUNTIF(Einstellungen!$B$5:$B$16,"x")=0,INDEX(Einstellungen!$B$5:$B$16,MONTH(EOMONTH(D10,IF(E10="",3,E10)+5)))="x"),EOMONTH(D10,IF(E10="",3,E10)+5),""),"") | AG10: =IF(D10<>"",IF(OR(COUNTIF(Einstellungen!$B$5:$B$16,"x")=0,INDEX(Einstellungen!$B$5:$B$16,MONTH(EOMONTH(D10,IF(E10="",3,E10)+6)))="x"),EOMONTH(D10,IF(E10="",3,E10)+6),""),"") | AH10: =IF(D10<>"",IF(OR(COUNTIF(Einstellungen!$B$5:$B$16,"x")=0,INDEX(Einstellungen!$B$5:$B$16,MONTH(EOMONTH(D10,IF(E10="",3,E10)+7)))="x"),EOMONTH(D10,IF(E10="",3,E10)+7),""),"") | AI10: =IF(D10<>"",IF(OR(COUNTIF(Einstellungen!$B$5:$B$16,"x")=0,INDEX(Einstellungen!$B$5:$B$16,MONTH(EOMONTH(D10,IF(E10="",3,E10)+8)))="x"),EOMONTH(D10,IF(E10="",3,E10)+8),""),"") | AJ10: =IF(D10<>"",IF(OR(COUNTIF(Einstellungen!$B$5:$B$16,"x")=0,INDEX(Einstellungen!$B$5:$B$16,MONTH(EOMONTH(D10,IF(E10="",3,E10)+9)))="x"),EOMONTH(D10,IF(E10="",3,E10)+9),""),"") | AK10: =IF(D10<>"",IF(OR(COUNTIF(Einstellungen!$B$5:$B$16,"x")=0,INDEX(Einstellungen!$B$5:$B$16,MONTH(EOMONTH(D10,IF(E10="",3,E10)+10)))="x"),EOMONTH(D10,IF(E10="",3,E10)+10),""),"") | AL10: =IF(D10<>"",IF(OR(COUNTIF(Einstellungen!$B$5:$B$16,"x")=0,INDEX(Einstellungen!$B$5:$B$16,MONTH(EOMONTH(D10,IF(E10="",3,E10)+11)))="x"),EOMONTH(D10,IF(E10="",3,E10)+11),""),"") | AM10: =IF(D10<>"",IF(OR(COUNTIF(Einstellungen!$B$5:$B$16,"x")=0,INDEX(Einstellungen!$B$5:$B$16,MONTH(EOMONTH(D10,IF(E10="",3,E10)+12)))="x"),EOMONTH(D10,IF(E10="",3,E10)+12),""),"") | AN10: =IF(D10<>"",IF(OR(COUNTIF(Einstellungen!$B$5:$B$16,"x")=0,INDEX(Einstellungen!$B$5:$B$16,MONTH(EOMONTH(D10,IF(E10="",3,E10)+13)))="x"),EOMONTH(D10,IF(E10="",3,E10)+13),""),"") | AO10: =IF(D10<>"",IF(OR(COUNTIF(Einstellungen!$B$5:$B$16,"x")=0,INDEX(Einstellungen!$B$5:$B$16,MONTH(EOMONTH(D10,IF(E10="",3,E10)+14)))="x"),EOMONTH(D10,IF(E10="",3,E10)+14),""),"") | AP10: =IF(D10<>"",IF(OR(COUNTIF(Einstellungen!$B$5:$B$16,"x")=0,INDEX(Einstellungen!$B$5:$B$16,MONTH(EOMONTH(D10,IF(E10="",3,E10)+15)))="x"),EOMONTH(D10,IF(E10="",3,E10)+15),""),"") | AQ10: =IF(D10<>"",IF(OR(COUNTIF(Einstellungen!$B$5:$B$16,"x")=0,INDEX(Einstellungen!$B$5:$B$16,MONTH(EOMONTH(D10,IF(E10="",3,E10)+16)))="x"),EOMONTH(D10,IF(E10="",3,E10)+16),""),"") | AR10: =IF(D10<>"",IF(OR(COUNTIF(Einstellungen!$B$5:$B$16,"x")=0,INDEX(Einstellungen!$B$5:$B$16,MONTH(EOMONTH(D10,IF(E10="",3,E10)+17)))="x"),EOMONTH(D10,IF(E10="",3,E10)+17),""),"") | AS10: =IF(D10<>"",IF(OR(COUNTIF(Einstellungen!$B$5:$B$16,"x")=0,INDEX(Einstellungen!$B$5:$B$16,MONTH(EOMONTH(D10,IF(E10="",3,E10)+18)))="x"),EOMONTH(D10,IF(E10="",3,E10)+18),""),"") | AT10: =IF(D10<>"",IF(OR(COUNTIF(Einstellungen!$B$5:$B$16,"x")=0,INDEX(Einstellungen!$B$5:$B$16,MONTH(EOMONTH(D10,IF(E10="",3,E10)+19)))="x"),EOMONTH(D10,IF(E10="",3,E10)+19),""),"") | AU10: =IF(D10<>"",IF(OR(COUNTIF(Einstellungen!$B$5:$B$16,"x")=0,INDEX(Einstellungen!$B$5:$B$16,MONTH(EOMONTH(D10,IF(E10="",3,E10)+20)))="x"),EOMONTH(D10,IF(E10="",3,E10)+20),""),"") | AV10: =IF(D10<>"",IF(OR(COUNTIF(Einstellungen!$B$5:$B$16,"x")=0,INDEX(Einstellungen!$B$5:$B$16,MONTH(EOMONTH(D10,IF(E10="",3,E10)+21)))="x"),EOMONTH(D10,IF(E10="",3,E10)+21),""),"") | AW10: =IF(D10<>"",IF(OR(COUNTIF(Einstellungen!$B$5:$B$16,"x")=0,INDEX(Einstellungen!$B$5:$B$16,MONTH(EOMONTH(D10,IF(E10="",3,E10)+22)))="x"),EOMONTH(D10,IF(E10="",3,E10)+22),""),"") | AX10: =IF(D10<>"",IF(OR(COUNTIF(Einstellungen!$B$5:$B$16,"x")=0,INDEX(Einstellungen!$B$5:$B$16,MONTH(EOMONTH(D10,IF(E10="",3,E10)+23)))="x"),EOMONTH(D10,IF(E10="",3,E10)+23),""),"") | AY10: =IF(AND(L10<>"",M10=""),L10,"") | AZ10: =IF(AND(N10<>"",O10=""),N10,"") | BA10: =IF(AND(P10<>"",Q10=""),P10,"") | BB10: =IF(AND(R10<>"",S10=""),R10,"") | BC10: =IF(AND(T10<>"",U10=""),T10,"")
G11: =IF(F11<>"",F11,IF(D11<>"",IF(COUNT(AA11:AX11)=0,"",MIN(AA11:AX11)),"")) | J11: =IF(OR(G11="",I11=""),"",MAX(0,I11-G11-1)) | K11: =IF(OR(J11="",H11=""),"",ROUND(H11*12/365*J11,2)) | L11: =IF(D11<>"",D11,"") | N11: =IF(G11="","",WORKDAY(G11,-10,Einstellungen!$D$5:$D$34)) | P11: =IF(G11="","",WORKDAY(G11-1,1,Einstellungen!$D$5:$D$34)) | R11: =IF(P11="","",WORKDAY(P11,2,Einstellungen!$D$5:$D$34)) | T11: =IF(G11="","",EDATE(G11,12)) | V11: =IF(COUNT(AY11:BC11)=0,"",MIN(AY11:BC11)) | W11: =IF(V11="","",V11-$B$2) | X11: =IF(C11="Vermieter","Amtliches Formular verwendet? Bei Familienwohnung an beide Ehegatten.",IF(C11="Ausserterminlich","Nachmieter zumutbar? Vereinbartes Ende eintragen.",IF(AND(G11<>"",I11=""),"Noch kein Nachmieter.",""))) | AA11: =IF(D11<>"",IF(OR(COUNTIF(Einstellungen!$B$5:$B$16,"x")=0,INDEX(Einstellungen!$B$5:$B$16,MONTH(EOMONTH(D11,IF(E11="",3,E11)+0)))="x"),EOMONTH(D11,IF(E11="",3,E11)+0),""),"") | AB11: =IF(D11<>"",IF(OR(COUNTIF(Einstellungen!$B$5:$B$16,"x")=0,INDEX(Einstellungen!$B$5:$B$16,MONTH(EOMONTH(D11,IF(E11="",3,E11)+1)))="x"),EOMONTH(D11,IF(E11="",3,E11)+1),""),"") | AC11: =IF(D11<>"",IF(OR(COUNTIF(Einstellungen!$B$5:$B$16,"x")=0,INDEX(Einstellungen!$B$5:$B$16,MONTH(EOMONTH(D11,IF(E11="",3,E11)+2)))="x"),EOMONTH(D11,IF(E11="",3,E11)+2),""),"") | AD11: =IF(D11<>"",IF(OR(COUNTIF(Einstellungen!$B$5:$B$16,"x")=0,INDEX(Einstellungen!$B$5:$B$16,MONTH(EOMONTH(D11,IF(E11="",3,E11)+3)))="x"),EOMONTH(D11,IF(E11="",3,E11)+3),""),"") | AE11: =IF(D11<>"",IF(OR(COUNTIF(Einstellungen!$B$5:$B$16,"x")=0,INDEX(Einstellungen!$B$5:$B$16,MONTH(EOMONTH(D11,IF(E11="",3,E11)+4)))="x"),EOMONTH(D11,IF(E11="",3,E11)+4),""),"") | AF11: =IF(D11<>"",IF(OR(COUNTIF(Einstellungen!$B$5:$B$16,"x")=0,INDEX(Einstellungen!$B$5:$B$16,MONTH(EOMONTH(D11,IF(E11="",3,E11)+5)))="x"),EOMONTH(D11,IF(E11="",3,E11)+5),""),"") | AG11: =IF(D11<>"",IF(OR(COUNTIF(Einstellungen!$B$5:$B$16,"x")=0,INDEX(Einstellungen!$B$5:$B$16,MONTH(EOMONTH(D11,IF(E11="",3,E11)+6)))="x"),EOMONTH(D11,IF(E11="",3,E11)+6),""),"") | AH11: =IF(D11<>"",IF(OR(COUNTIF(Einstellungen!$B$5:$B$16,"x")=0,INDEX(Einstellungen!$B$5:$B$16,MONTH(EOMONTH(D11,IF(E11="",3,E11)+7)))="x"),EOMONTH(D11,IF(E11="",3,E11)+7),""),"") | AI11: =IF(D11<>"",IF(OR(COUNTIF(Einstellungen!$B$5:$B$16,"x")=0,INDEX(Einstellungen!$B$5:$B$16,MONTH(EOMONTH(D11,IF(E11="",3,E11)+8)))="x"),EOMONTH(D11,IF(E11="",3,E11)+8),""),"") | AJ11: =IF(D11<>"",IF(OR(COUNTIF(Einstellungen!$B$5:$B$16,"x")=0,INDEX(Einstellungen!$B$5:$B$16,MONTH(EOMONTH(D11,IF(E11="",3,E11)+9)))="x"),EOMONTH(D11,IF(E11="",3,E11)+9),""),"") | AK11: =IF(D11<>"",IF(OR(COUNTIF(Einstellungen!$B$5:$B$16,"x")=0,INDEX(Einstellungen!$B$5:$B$16,MONTH(EOMONTH(D11,IF(E11="",3,E11)+10)))="x"),EOMONTH(D11,IF(E11="",3,E11)+10),""),"") | AL11: =IF(D11<>"",IF(OR(COUNTIF(Einstellungen!$B$5:$B$16,"x")=0,INDEX(Einstellungen!$B$5:$B$16,MONTH(EOMONTH(D11,IF(E11="",3,E11)+11)))="x"),EOMONTH(D11,IF(E11="",3,E11)+11),""),"") | AM11: =IF(D11<>"",IF(OR(COUNTIF(Einstellungen!$B$5:$B$16,"x")=0,INDEX(Einstellungen!$B$5:$B$16,MONTH(EOMONTH(D11,IF(E11="",3,E11)+12)))="x"),EOMONTH(D11,IF(E11="",3,E11)+12),""),"") | AN11: =IF(D11<>"",IF(OR(COUNTIF(Einstellungen!$B$5:$B$16,"x")=0,INDEX(Einstellungen!$B$5:$B$16,MONTH(EOMONTH(D11,IF(E11="",3,E11)+13)))="x"),EOMONTH(D11,IF(E11="",3,E11)+13),""),"") | AO11: =IF(D11<>"",IF(OR(COUNTIF(Einstellungen!$B$5:$B$16,"x")=0,INDEX(Einstellungen!$B$5:$B$16,MONTH(EOMONTH(D11,IF(E11="",3,E11)+14)))="x"),EOMONTH(D11,IF(E11="",3,E11)+14),""),"") | AP11: =IF(D11<>"",IF(OR(COUNTIF(Einstellungen!$B$5:$B$16,"x")=0,INDEX(Einstellungen!$B$5:$B$16,MONTH(EOMONTH(D11,IF(E11="",3,E11)+15)))="x"),EOMONTH(D11,IF(E11="",3,E11)+15),""),"") | AQ11: =IF(D11<>"",IF(OR(COUNTIF(Einstellungen!$B$5:$B$16,"x")=0,INDEX(Einstellungen!$B$5:$B$16,MONTH(EOMONTH(D11,IF(E11="",3,E11)+16)))="x"),EOMONTH(D11,IF(E11="",3,E11)+16),""),"") | AR11: =IF(D11<>"",IF(OR(COUNTIF(Einstellungen!$B$5:$B$16,"x")=0,INDEX(Einstellungen!$B$5:$B$16,MONTH(EOMONTH(D11,IF(E11="",3,E11)+17)))="x"),EOMONTH(D11,IF(E11="",3,E11)+17),""),"") | AS11: =IF(D11<>"",IF(OR(COUNTIF(Einstellungen!$B$5:$B$16,"x")=0,INDEX(Einstellungen!$B$5:$B$16,MONTH(EOMONTH(D11,IF(E11="",3,E11)+18)))="x"),EOMONTH(D11,IF(E11="",3,E11)+18),""),"") | AT11: =IF(D11<>"",IF(OR(COUNTIF(Einstellungen!$B$5:$B$16,"x")=0,INDEX(Einstellungen!$B$5:$B$16,MONTH(EOMONTH(D11,IF(E11="",3,E11)+19)))="x"),EOMONTH(D11,IF(E11="",3,E11)+19),""),"") | AU11: =IF(D11<>"",IF(OR(COUNTIF(Einstellungen!$B$5:$B$16,"x")=0,INDEX(Einstellungen!$B$5:$B$16,MONTH(EOMONTH(D11,IF(E11="",3,E11)+20)))="x"),EOMONTH(D11,IF(E11="",3,E11)+20),""),"") | AV11: =IF(D11<>"",IF(OR(COUNTIF(Einstellungen!$B$5:$B$16,"x")=0,INDEX(Einstellungen!$B$5:$B$16,MONTH(EOMONTH(D11,IF(E11="",3,E11)+21)))="x"),EOMONTH(D11,IF(E11="",3,E11)+21),""),"") | AW11: =IF(D11<>"",IF(OR(COUNTIF(Einstellungen!$B$5:$B$16,"x")=0,INDEX(Einstellungen!$B$5:$B$16,MONTH(EOMONTH(D11,IF(E11="",3,E11)+22)))="x"),EOMONTH(D11,IF(E11="",3,E11)+22),""),"") | AX11: =IF(D11<>"",IF(OR(COUNTIF(Einstellungen!$B$5:$B$16,"x")=0,INDEX(Einstellungen!$B$5:$B$16,MONTH(EOMONTH(D11,IF(E11="",3,E11)+23)))="x"),EOMONTH(D11,IF(E11="",3,E11)+23),""),"") | AY11: =IF(AND(L11<>"",M11=""),L11,"") | AZ11: =IF(AND(N11<>"",O11=""),N11,"") | BA11: =IF(AND(P11<>"",Q11=""),P11,"") | BB11: =IF(AND(R11<>"",S11=""),R11,"") | BC11: =IF(AND(T11<>"",U11=""),T11,"")
G12: =IF(F12<>"",F12,IF(D12<>"",IF(COUNT(AA12:AX12)=0,"",MIN(AA12:AX12)),"")) | J12: =IF(OR(G12="",I12=""),"",MAX(0,I12-G12-1)) | K12: =IF(OR(J12="",H12=""),"",ROUND(H12*12/365*J12,2)) | L12: =IF(D12<>"",D12,"") | N12: =IF(G12="","",WORKDAY(G12,-10,Einstellungen!$D$5:$D$34)) | P12: =IF(G12="","",WORKDAY(G12-1,1,Einstellungen!$D$5:$D$34)) | R12: =IF(P12="","",WORKDAY(P12,2,Einstellungen!$D$5:$D$34)) | T12: =IF(G12="","",EDATE(G12,12)) | V12: =IF(COUNT(AY12:BC12)=0,"",MIN(AY12:BC12)) | W12: =IF(V12="","",V12-$B$2) | X12: =IF(C12="Vermieter","Amtliches Formular verwendet? Bei Familienwohnung an beide Ehegatten.",IF(C12="Ausserterminlich","Nachmieter zumutbar? Vereinbartes Ende eintragen.",IF(AND(G12<>"",I12=""),"Noch kein Nachmieter.",""))) | AA12: =IF(D12<>"",IF(OR(COUNTIF(Einstellungen!$B$5:$B$16,"x")=0,INDEX(Einstellungen!$B$5:$B$16,MONTH(EOMONTH(D12,IF(E12="",3,E12)+0)))="x"),EOMONTH(D12,IF(E12="",3,E12)+0),""),"") | AB12: =IF(D12<>"",IF(OR(COUNTIF(Einstellungen!$B$5:$B$16,"x")=0,INDEX(Einstellungen!$B$5:$B$16,MONTH(EOMONTH(D12,IF(E12="",3,E12)+1)))="x"),EOMONTH(D12,IF(E12="",3,E12)+1),""),"") | AC12: =IF(D12<>"",IF(OR(COUNTIF(Einstellungen!$B$5:$B$16,"x")=0,INDEX(Einstellungen!$B$5:$B$16,MONTH(EOMONTH(D12,IF(E12="",3,E12)+2)))="x"),EOMONTH(D12,IF(E12="",3,E12)+2),""),"") | AD12: =IF(D12<>"",IF(OR(COUNTIF(Einstellungen!$B$5:$B$16,"x")=0,INDEX(Einstellungen!$B$5:$B$16,MONTH(EOMONTH(D12,IF(E12="",3,E12)+3)))="x"),EOMONTH(D12,IF(E12="",3,E12)+3),""),"") | AE12: =IF(D12<>"",IF(OR(COUNTIF(Einstellungen!$B$5:$B$16,"x")=0,INDEX(Einstellungen!$B$5:$B$16,MONTH(EOMONTH(D12,IF(E12="",3,E12)+4)))="x"),EOMONTH(D12,IF(E12="",3,E12)+4),""),"") | AF12: =IF(D12<>"",IF(OR(COUNTIF(Einstellungen!$B$5:$B$16,"x")=0,INDEX(Einstellungen!$B$5:$B$16,MONTH(EOMONTH(D12,IF(E12="",3,E12)+5)))="x"),EOMONTH(D12,IF(E12="",3,E12)+5),""),"") | AG12: =IF(D12<>"",IF(OR(COUNTIF(Einstellungen!$B$5:$B$16,"x")=0,INDEX(Einstellungen!$B$5:$B$16,MONTH(EOMONTH(D12,IF(E12="",3,E12)+6)))="x"),EOMONTH(D12,IF(E12="",3,E12)+6),""),"") | AH12: =IF(D12<>"",IF(OR(COUNTIF(Einstellungen!$B$5:$B$16,"x")=0,INDEX(Einstellungen!$B$5:$B$16,MONTH(EOMONTH(D12,IF(E12="",3,E12)+7)))="x"),EOMONTH(D12,IF(E12="",3,E12)+7),""),"") | AI12: =IF(D12<>"",IF(OR(COUNTIF(Einstellungen!$B$5:$B$16,"x")=0,INDEX(Einstellungen!$B$5:$B$16,MONTH(EOMONTH(D12,IF(E12="",3,E12)+8)))="x"),EOMONTH(D12,IF(E12="",3,E12)+8),""),"") | AJ12: =IF(D12<>"",IF(OR(COUNTIF(Einstellungen!$B$5:$B$16,"x")=0,INDEX(Einstellungen!$B$5:$B$16,MONTH(EOMONTH(D12,IF(E12="",3,E12)+9)))="x"),EOMONTH(D12,IF(E12="",3,E12)+9),""),"") | AK12: =IF(D12<>"",IF(OR(COUNTIF(Einstellungen!$B$5:$B$16,"x")=0,INDEX(Einstellungen!$B$5:$B$16,MONTH(EOMONTH(D12,IF(E12="",3,E12)+10)))="x"),EOMONTH(D12,IF(E12="",3,E12)+10),""),"") | AL12: =IF(D12<>"",IF(OR(COUNTIF(Einstellungen!$B$5:$B$16,"x")=0,INDEX(Einstellungen!$B$5:$B$16,MONTH(EOMONTH(D12,IF(E12="",3,E12)+11)))="x"),EOMONTH(D12,IF(E12="",3,E12)+11),""),"") | AM12: =IF(D12<>"",IF(OR(COUNTIF(Einstellungen!$B$5:$B$16,"x")=0,INDEX(Einstellungen!$B$5:$B$16,MONTH(EOMONTH(D12,IF(E12="",3,E12)+12)))="x"),EOMONTH(D12,IF(E12="",3,E12)+12),""),"") | AN12: =IF(D12<>"",IF(OR(COUNTIF(Einstellungen!$B$5:$B$16,"x")=0,INDEX(Einstellungen!$B$5:$B$16,MONTH(EOMONTH(D12,IF(E12="",3,E12)+13)))="x"),EOMONTH(D12,IF(E12="",3,E12)+13),""),"") | AO12: =IF(D12<>"",IF(OR(COUNTIF(Einstellungen!$B$5:$B$16,"x")=0,INDEX(Einstellungen!$B$5:$B$16,MONTH(EOMONTH(D12,IF(E12="",3,E12)+14)))="x"),EOMONTH(D12,IF(E12="",3,E12)+14),""),"") | AP12: =IF(D12<>"",IF(OR(COUNTIF(Einstellungen!$B$5:$B$16,"x")=0,INDEX(Einstellungen!$B$5:$B$16,MONTH(EOMONTH(D12,IF(E12="",3,E12)+15)))="x"),EOMONTH(D12,IF(E12="",3,E12)+15),""),"") | AQ12: =IF(D12<>"",IF(OR(COUNTIF(Einstellungen!$B$5:$B$16,"x")=0,INDEX(Einstellungen!$B$5:$B$16,MONTH(EOMONTH(D12,IF(E12="",3,E12)+16)))="x"),EOMONTH(D12,IF(E12="",3,E12)+16),""),"") | AR12: =IF(D12<>"",IF(OR(COUNTIF(Einstellungen!$B$5:$B$16,"x")=0,INDEX(Einstellungen!$B$5:$B$16,MONTH(EOMONTH(D12,IF(E12="",3,E12)+17)))="x"),EOMONTH(D12,IF(E12="",3,E12)+17),""),"") | AS12: =IF(D12<>"",IF(OR(COUNTIF(Einstellungen!$B$5:$B$16,"x")=0,INDEX(Einstellungen!$B$5:$B$16,MONTH(EOMONTH(D12,IF(E12="",3,E12)+18)))="x"),EOMONTH(D12,IF(E12="",3,E12)+18),""),"") | AT12: =IF(D12<>"",IF(OR(COUNTIF(Einstellungen!$B$5:$B$16,"x")=0,INDEX(Einstellungen!$B$5:$B$16,MONTH(EOMONTH(D12,IF(E12="",3,E12)+19)))="x"),EOMONTH(D12,IF(E12="",3,E12)+19),""),"") | AU12: =IF(D12<>"",IF(OR(COUNTIF(Einstellungen!$B$5:$B$16,"x")=0,INDEX(Einstellungen!$B$5:$B$16,MONTH(EOMONTH(D12,IF(E12="",3,E12)+20)))="x"),EOMONTH(D12,IF(E12="",3,E12)+20),""),"") | AV12: =IF(D12<>"",IF(OR(COUNTIF(Einstellungen!$B$5:$B$16,"x")=0,INDEX(Einstellungen!$B$5:$B$16,MONTH(EOMONTH(D12,IF(E12="",3,E12)+21)))="x"),EOMONTH(D12,IF(E12="",3,E12)+21),""),"") | AW12: =IF(D12<>"",IF(OR(COUNTIF(Einstellungen!$B$5:$B$16,"x")=0,INDEX(Einstellungen!$B$5:$B$16,MONTH(EOMONTH(D12,IF(E12="",3,E12)+22)))="x"),EOMONTH(D12,IF(E12="",3,E12)+22),""),"") | AX12: =IF(D12<>"",IF(OR(COUNTIF(Einstellungen!$B$5:$B$16,"x")=0,INDEX(Einstellungen!$B$5:$B$16,MONTH(EOMONTH(D12,IF(E12="",3,E12)+23)))="x"),EOMONTH(D12,IF(E12="",3,E12)+23),""),"") | AY12: =IF(AND(L12<>"",M12=""),L12,"") | AZ12: =IF(AND(N12<>"",O12=""),N12,"") | BA12: =IF(AND(P12<>"",Q12=""),P12,"") | BB12: =IF(AND(R12<>"",S12=""),R12,"") | BC12: =IF(AND(T12<>"",U12=""),T12,"")
G13: =IF(F13<>"",F13,IF(D13<>"",IF(COUNT(AA13:AX13)=0,"",MIN(AA13:AX13)),"")) | J13: =IF(OR(G13="",I13=""),"",MAX(0,I13-G13-1)) | K13: =IF(OR(J13="",H13=""),"",ROUND(H13*12/365*J13,2)) | L13: =IF(D13<>"",D13,"") | N13: =IF(G13="","",WORKDAY(G13,-10,Einstellungen!$D$5:$D$34)) | P13: =IF(G13="","",WORKDAY(G13-1,1,Einstellungen!$D$5:$D$34)) | R13: =IF(P13="","",WORKDAY(P13,2,Einstellungen!$D$5:$D$34)) | T13: =IF(G13="","",EDATE(G13,12)) | V13: =IF(COUNT(AY13:BC13)=0,"",MIN(AY13:BC13)) | W13: =IF(V13="","",V13-$B$2) | X13: =IF(C13="Vermieter","Amtliches Formular verwendet? Bei Familienwohnung an beide Ehegatten.",IF(C13="Ausserterminlich","Nachmieter zumutbar? Vereinbartes Ende eintragen.",IF(AND(G13<>"",I13=""),"Noch kein Nachmieter.",""))) | AA13: =IF(D13<>"",IF(OR(COUNTIF(Einstellungen!$B$5:$B$16,"x")=0,INDEX(Einstellungen!$B$5:$B$16,MONTH(EOMONTH(D13,IF(E13="",3,E13)+0)))="x"),EOMONTH(D13,IF(E13="",3,E13)+0),""),"") | AB13: =IF(D13<>"",IF(OR(COUNTIF(Einstellungen!$B$5:$B$16,"x")=0,INDEX(Einstellungen!$B$5:$B$16,MONTH(EOMONTH(D13,IF(E13="",3,E13)+1)))="x"),EOMONTH(D13,IF(E13="",3,E13)+1),""),"") | AC13: =IF(D13<>"",IF(OR(COUNTIF(Einstellungen!$B$5:$B$16,"x")=0,INDEX(Einstellungen!$B$5:$B$16,MONTH(EOMONTH(D13,IF(E13="",3,E13)+2)))="x"),EOMONTH(D13,IF(E13="",3,E13)+2),""),"") | AD13: =IF(D13<>"",IF(OR(COUNTIF(Einstellungen!$B$5:$B$16,"x")=0,INDEX(Einstellungen!$B$5:$B$16,MONTH(EOMONTH(D13,IF(E13="",3,E13)+3)))="x"),EOMONTH(D13,IF(E13="",3,E13)+3),""),"") | AE13: =IF(D13<>"",IF(OR(COUNTIF(Einstellungen!$B$5:$B$16,"x")=0,INDEX(Einstellungen!$B$5:$B$16,MONTH(EOMONTH(D13,IF(E13="",3,E13)+4)))="x"),EOMONTH(D13,IF(E13="",3,E13)+4),""),"") | AF13: =IF(D13<>"",IF(OR(COUNTIF(Einstellungen!$B$5:$B$16,"x")=0,INDEX(Einstellungen!$B$5:$B$16,MONTH(EOMONTH(D13,IF(E13="",3,E13)+5)))="x"),EOMONTH(D13,IF(E13="",3,E13)+5),""),"") | AG13: =IF(D13<>"",IF(OR(COUNTIF(Einstellungen!$B$5:$B$16,"x")=0,INDEX(Einstellungen!$B$5:$B$16,MONTH(EOMONTH(D13,IF(E13="",3,E13)+6)))="x"),EOMONTH(D13,IF(E13="",3,E13)+6),""),"") | AH13: =IF(D13<>"",IF(OR(COUNTIF(Einstellungen!$B$5:$B$16,"x")=0,INDEX(Einstellungen!$B$5:$B$16,MONTH(EOMONTH(D13,IF(E13="",3,E13)+7)))="x"),EOMONTH(D13,IF(E13="",3,E13)+7),""),"") | AI13: =IF(D13<>"",IF(OR(COUNTIF(Einstellungen!$B$5:$B$16,"x")=0,INDEX(Einstellungen!$B$5:$B$16,MONTH(EOMONTH(D13,IF(E13="",3,E13)+8)))="x"),EOMONTH(D13,IF(E13="",3,E13)+8),""),"") | AJ13: =IF(D13<>"",IF(OR(COUNTIF(Einstellungen!$B$5:$B$16,"x")=0,INDEX(Einstellungen!$B$5:$B$16,MONTH(EOMONTH(D13,IF(E13="",3,E13)+9)))="x"),EOMONTH(D13,IF(E13="",3,E13)+9),""),"") | AK13: =IF(D13<>"",IF(OR(COUNTIF(Einstellungen!$B$5:$B$16,"x")=0,INDEX(Einstellungen!$B$5:$B$16,MONTH(EOMONTH(D13,IF(E13="",3,E13)+10)))="x"),EOMONTH(D13,IF(E13="",3,E13)+10),""),"") | AL13: =IF(D13<>"",IF(OR(COUNTIF(Einstellungen!$B$5:$B$16,"x")=0,INDEX(Einstellungen!$B$5:$B$16,MONTH(EOMONTH(D13,IF(E13="",3,E13)+11)))="x"),EOMONTH(D13,IF(E13="",3,E13)+11),""),"") | AM13: =IF(D13<>"",IF(OR(COUNTIF(Einstellungen!$B$5:$B$16,"x")=0,INDEX(Einstellungen!$B$5:$B$16,MONTH(EOMONTH(D13,IF(E13="",3,E13)+12)))="x"),EOMONTH(D13,IF(E13="",3,E13)+12),""),"") | AN13: =IF(D13<>"",IF(OR(COUNTIF(Einstellungen!$B$5:$B$16,"x")=0,INDEX(Einstellungen!$B$5:$B$16,MONTH(EOMONTH(D13,IF(E13="",3,E13)+13)))="x"),EOMONTH(D13,IF(E13="",3,E13)+13),""),"") | AO13: =IF(D13<>"",IF(OR(COUNTIF(Einstellungen!$B$5:$B$16,"x")=0,INDEX(Einstellungen!$B$5:$B$16,MONTH(EOMONTH(D13,IF(E13="",3,E13)+14)))="x"),EOMONTH(D13,IF(E13="",3,E13)+14),""),"") | AP13: =IF(D13<>"",IF(OR(COUNTIF(Einstellungen!$B$5:$B$16,"x")=0,INDEX(Einstellungen!$B$5:$B$16,MONTH(EOMONTH(D13,IF(E13="",3,E13)+15)))="x"),EOMONTH(D13,IF(E13="",3,E13)+15),""),"") | AQ13: =IF(D13<>"",IF(OR(COUNTIF(Einstellungen!$B$5:$B$16,"x")=0,INDEX(Einstellungen!$B$5:$B$16,MONTH(EOMONTH(D13,IF(E13="",3,E13)+16)))="x"),EOMONTH(D13,IF(E13="",3,E13)+16),""),"") | AR13: =IF(D13<>"",IF(OR(COUNTIF(Einstellungen!$B$5:$B$16,"x")=0,INDEX(Einstellungen!$B$5:$B$16,MONTH(EOMONTH(D13,IF(E13="",3,E13)+17)))="x"),EOMONTH(D13,IF(E13="",3,E13)+17),""),"") | AS13: =IF(D13<>"",IF(OR(COUNTIF(Einstellungen!$B$5:$B$16,"x")=0,INDEX(Einstellungen!$B$5:$B$16,MONTH(EOMONTH(D13,IF(E13="",3,E13)+18)))="x"),EOMONTH(D13,IF(E13="",3,E13)+18),""),"") | AT13: =IF(D13<>"",IF(OR(COUNTIF(Einstellungen!$B$5:$B$16,"x")=0,INDEX(Einstellungen!$B$5:$B$16,MONTH(EOMONTH(D13,IF(E13="",3,E13)+19)))="x"),EOMONTH(D13,IF(E13="",3,E13)+19),""),"") | AU13: =IF(D13<>"",IF(OR(COUNTIF(Einstellungen!$B$5:$B$16,"x")=0,INDEX(Einstellungen!$B$5:$B$16,MONTH(EOMONTH(D13,IF(E13="",3,E13)+20)))="x"),EOMONTH(D13,IF(E13="",3,E13)+20),""),"") | AV13: =IF(D13<>"",IF(OR(COUNTIF(Einstellungen!$B$5:$B$16,"x")=0,INDEX(Einstellungen!$B$5:$B$16,MONTH(EOMONTH(D13,IF(E13="",3,E13)+21)))="x"),EOMONTH(D13,IF(E13="",3,E13)+21),""),"") | AW13: =IF(D13<>"",IF(OR(COUNTIF(Einstellungen!$B$5:$B$16,"x")=0,INDEX(Einstellungen!$B$5:$B$16,MONTH(EOMONTH(D13,IF(E13="",3,E13)+22)))="x"),EOMONTH(D13,IF(E13="",3,E13)+22),""),"") | AX13: =IF(D13<>"",IF(OR(COUNTIF(Einstellungen!$B$5:$B$16,"x")=0,INDEX(Einstellungen!$B$5:$B$16,MONTH(EOMONTH(D13,IF(E13="",3,E13)+23)))="x"),EOMONTH(D13,IF(E13="",3,E13)+23),""),"") | AY13: =IF(AND(L13<>"",M13=""),L13,"") | AZ13: =IF(AND(N13<>"",O13=""),N13,"") | BA13: =IF(AND(P13<>"",Q13=""),P13,"") | BB13: =IF(AND(R13<>"",S13=""),R13,"") | BC13: =IF(AND(T13<>"",U13=""),T13,"")
G14: =IF(F14<>"",F14,IF(D14<>"",IF(COUNT(AA14:AX14)=0,"",MIN(AA14:AX14)),"")) | J14: =IF(OR(G14="",I14=""),"",MAX(0,I14-G14-1)) | K14: =IF(OR(J14="",H14=""),"",ROUND(H14*12/365*J14,2)) | L14: =IF(D14<>"",D14,"") | N14: =IF(G14="","",WORKDAY(G14,-10,Einstellungen!$D$5:$D$34)) | P14: =IF(G14="","",WORKDAY(G14-1,1,Einstellungen!$D$5:$D$34)) | R14: =IF(P14="","",WORKDAY(P14,2,Einstellungen!$D$5:$D$34)) | T14: =IF(G14="","",EDATE(G14,12)) | V14: =IF(COUNT(AY14:BC14)=0,"",MIN(AY14:BC14)) | W14: =IF(V14="","",V14-$B$2) | X14: =IF(C14="Vermieter","Amtliches Formular verwendet? Bei Familienwohnung an beide Ehegatten.",IF(C14="Ausserterminlich","Nachmieter zumutbar? Vereinbartes Ende eintragen.",IF(AND(G14<>"",I14=""),"Noch kein Nachmieter.",""))) | AA14: =IF(D14<>"",IF(OR(COUNTIF(Einstellungen!$B$5:$B$16,"x")=0,INDEX(Einstellungen!$B$5:$B$16,MONTH(EOMONTH(D14,IF(E14="",3,E14)+0)))="x"),EOMONTH(D14,IF(E14="",3,E14)+0),""),"") | AB14: =IF(D14<>"",IF(OR(COUNTIF(Einstellungen!$B$5:$B$16,"x")=0,INDEX(Einstellungen!$B$5:$B$16,MONTH(EOMONTH(D14,IF(E14="",3,E14)+1)))="x"),EOMONTH(D14,IF(E14="",3,E14)+1),""),"") | AC14: =IF(D14<>"",IF(OR(COUNTIF(Einstellungen!$B$5:$B$16,"x")=0,INDEX(Einstellungen!$B$5:$B$16,MONTH(EOMONTH(D14,IF(E14="",3,E14)+2)))="x"),EOMONTH(D14,IF(E14="",3,E14)+2),""),"") | AD14: =IF(D14<>"",IF(OR(COUNTIF(Einstellungen!$B$5:$B$16,"x")=0,INDEX(Einstellungen!$B$5:$B$16,MONTH(EOMONTH(D14,IF(E14="",3,E14)+3)))="x"),EOMONTH(D14,IF(E14="",3,E14)+3),""),"") | AE14: =IF(D14<>"",IF(OR(COUNTIF(Einstellungen!$B$5:$B$16,"x")=0,INDEX(Einstellungen!$B$5:$B$16,MONTH(EOMONTH(D14,IF(E14="",3,E14)+4)))="x"),EOMONTH(D14,IF(E14="",3,E14)+4),""),"") | AF14: =IF(D14<>"",IF(OR(COUNTIF(Einstellungen!$B$5:$B$16,"x")=0,INDEX(Einstellungen!$B$5:$B$16,MONTH(EOMONTH(D14,IF(E14="",3,E14)+5)))="x"),EOMONTH(D14,IF(E14="",3,E14)+5),""),"") | AG14: =IF(D14<>"",IF(OR(COUNTIF(Einstellungen!$B$5:$B$16,"x")=0,INDEX(Einstellungen!$B$5:$B$16,MONTH(EOMONTH(D14,IF(E14="",3,E14)+6)))="x"),EOMONTH(D14,IF(E14="",3,E14)+6),""),"") | AH14: =IF(D14<>"",IF(OR(COUNTIF(Einstellungen!$B$5:$B$16,"x")=0,INDEX(Einstellungen!$B$5:$B$16,MONTH(EOMONTH(D14,IF(E14="",3,E14)+7)))="x"),EOMONTH(D14,IF(E14="",3,E14)+7),""),"") | AI14: =IF(D14<>"",IF(OR(COUNTIF(Einstellungen!$B$5:$B$16,"x")=0,INDEX(Einstellungen!$B$5:$B$16,MONTH(EOMONTH(D14,IF(E14="",3,E14)+8)))="x"),EOMONTH(D14,IF(E14="",3,E14)+8),""),"") | AJ14: =IF(D14<>"",IF(OR(COUNTIF(Einstellungen!$B$5:$B$16,"x")=0,INDEX(Einstellungen!$B$5:$B$16,MONTH(EOMONTH(D14,IF(E14="",3,E14)+9)))="x"),EOMONTH(D14,IF(E14="",3,E14)+9),""),"") | AK14: =IF(D14<>"",IF(OR(COUNTIF(Einstellungen!$B$5:$B$16,"x")=0,INDEX(Einstellungen!$B$5:$B$16,MONTH(EOMONTH(D14,IF(E14="",3,E14)+10)))="x"),EOMONTH(D14,IF(E14="",3,E14)+10),""),"") | AL14: =IF(D14<>"",IF(OR(COUNTIF(Einstellungen!$B$5:$B$16,"x")=0,INDEX(Einstellungen!$B$5:$B$16,MONTH(EOMONTH(D14,IF(E14="",3,E14)+11)))="x"),EOMONTH(D14,IF(E14="",3,E14)+11),""),"") | AM14: =IF(D14<>"",IF(OR(COUNTIF(Einstellungen!$B$5:$B$16,"x")=0,INDEX(Einstellungen!$B$5:$B$16,MONTH(EOMONTH(D14,IF(E14="",3,E14)+12)))="x"),EOMONTH(D14,IF(E14="",3,E14)+12),""),"") | AN14: =IF(D14<>"",IF(OR(COUNTIF(Einstellungen!$B$5:$B$16,"x")=0,INDEX(Einstellungen!$B$5:$B$16,MONTH(EOMONTH(D14,IF(E14="",3,E14)+13)))="x"),EOMONTH(D14,IF(E14="",3,E14)+13),""),"") | AO14: =IF(D14<>"",IF(OR(COUNTIF(Einstellungen!$B$5:$B$16,"x")=0,INDEX(Einstellungen!$B$5:$B$16,MONTH(EOMONTH(D14,IF(E14="",3,E14)+14)))="x"),EOMONTH(D14,IF(E14="",3,E14)+14),""),"") | AP14: =IF(D14<>"",IF(OR(COUNTIF(Einstellungen!$B$5:$B$16,"x")=0,INDEX(Einstellungen!$B$5:$B$16,MONTH(EOMONTH(D14,IF(E14="",3,E14)+15)))="x"),EOMONTH(D14,IF(E14="",3,E14)+15),""),"") | AQ14: =IF(D14<>"",IF(OR(COUNTIF(Einstellungen!$B$5:$B$16,"x")=0,INDEX(Einstellungen!$B$5:$B$16,MONTH(EOMONTH(D14,IF(E14="",3,E14)+16)))="x"),EOMONTH(D14,IF(E14="",3,E14)+16),""),"") | AR14: =IF(D14<>"",IF(OR(COUNTIF(Einstellungen!$B$5:$B$16,"x")=0,INDEX(Einstellungen!$B$5:$B$16,MONTH(EOMONTH(D14,IF(E14="",3,E14)+17)))="x"),EOMONTH(D14,IF(E14="",3,E14)+17),""),"") | AS14: =IF(D14<>"",IF(OR(COUNTIF(Einstellungen!$B$5:$B$16,"x")=0,INDEX(Einstellungen!$B$5:$B$16,MONTH(EOMONTH(D14,IF(E14="",3,E14)+18)))="x"),EOMONTH(D14,IF(E14="",3,E14)+18),""),"") | AT14: =IF(D14<>"",IF(OR(COUNTIF(Einstellungen!$B$5:$B$16,"x")=0,INDEX(Einstellungen!$B$5:$B$16,MONTH(EOMONTH(D14,IF(E14="",3,E14)+19)))="x"),EOMONTH(D14,IF(E14="",3,E14)+19),""),"") | AU14: =IF(D14<>"",IF(OR(COUNTIF(Einstellungen!$B$5:$B$16,"x")=0,INDEX(Einstellungen!$B$5:$B$16,MONTH(EOMONTH(D14,IF(E14="",3,E14)+20)))="x"),EOMONTH(D14,IF(E14="",3,E14)+20),""),"") | AV14: =IF(D14<>"",IF(OR(COUNTIF(Einstellungen!$B$5:$B$16,"x")=0,INDEX(Einstellungen!$B$5:$B$16,MONTH(EOMONTH(D14,IF(E14="",3,E14)+21)))="x"),EOMONTH(D14,IF(E14="",3,E14)+21),""),"") | AW14: =IF(D14<>"",IF(OR(COUNTIF(Einstellungen!$B$5:$B$16,"x")=0,INDEX(Einstellungen!$B$5:$B$16,MONTH(EOMONTH(D14,IF(E14="",3,E14)+22)))="x"),EOMONTH(D14,IF(E14="",3,E14)+22),""),"") | AX14: =IF(D14<>"",IF(OR(COUNTIF(Einstellungen!$B$5:$B$16,"x")=0,INDEX(Einstellungen!$B$5:$B$16,MONTH(EOMONTH(D14,IF(E14="",3,E14)+23)))="x"),EOMONTH(D14,IF(E14="",3,E14)+23),""),"") | AY14: =IF(AND(L14<>"",M14=""),L14,"") | AZ14: =IF(AND(N14<>"",O14=""),N14,"") | BA14: =IF(AND(P14<>"",Q14=""),P14,"") | BB14: =IF(AND(R14<>"",S14=""),R14,"") | BC14: =IF(AND(T14<>"",U14=""),T14,"")
