Workbook

Sheet Start
A1: Vermieter-Ordner Schweiz
A2: Die wichtigsten Aufgaben einer privaten Mietliegenschaft – nach Schweizer Mietrecht, ohne Abo, ohne Makros.
A4: So arbeiten Sie
A5: 1 · Mein Haus | B5: Wohnungen und Mieter einmal erfassen
A6: 2 · Mieterwechsel | B6: Kündigung → Mietende und zehn Schritte mit Datum
A7: 3 · Rückgabe | B7: Protokoll, Schaden nach Lebensdauer, Kaution
A8: 4 · Nebenkosten | B8: Kosten verteilen, Abrechnung pro Mieter
A9: 5 · Mietzins | B9: Referenzzins, Teuerung, Kostensteigerung
A10: 6 · Kontrolle | B10: Alles plausibel? Hier steht es.
A12: Was steht an?
A13: Datum | B13: Mieter | C13: Schritt | D13: Tage
A14: =IFERROR(INT(SMALL(Mieterwechsel!$BS$9:$BS$28,1)),"") | B14: =IFERROR(INDEX(Mieterwechsel!$B$9:$B$28,MATCH(SMALL(Mieterwechsel!$BS$9:$BS$28,1),Mieterwechsel!$BS$9:$BS$28,0)),"") | C14: =IFERROR(INDEX(Mieterwechsel!$AH$9:$AH$28,MATCH(SMALL(Mieterwechsel!$BS$9:$BS$28,1),Mieterwechsel!$BS$9:$BS$28,0)),"") | D14: =IFERROR(INT(SMALL(Mieterwechsel!$BS$9:$BS$28,1))-TODAY(),"")
A15: =IFERROR(INT(SMALL(Mieterwechsel!$BS$9:$BS$28,2)),"") | B15: =IFERROR(INDEX(Mieterwechsel!$B$9:$B$28,MATCH(SMALL(Mieterwechsel!$BS$9:$BS$28,2),Mieterwechsel!$BS$9:$BS$28,0)),"") | C15: =IFERROR(INDEX(Mieterwechsel!$AH$9:$AH$28,MATCH(SMALL(Mieterwechsel!$BS$9:$BS$28,2),Mieterwechsel!$BS$9:$BS$28,0)),"") | D15: =IFERROR(INT(SMALL(Mieterwechsel!$BS$9:$BS$28,2))-TODAY(),"")
A16: =IFERROR(INT(SMALL(Mieterwechsel!$BS$9:$BS$28,3)),"") | B16: =IFERROR(INDEX(Mieterwechsel!$B$9:$B$28,MATCH(SMALL(Mieterwechsel!$BS$9:$BS$28,3),Mieterwechsel!$BS$9:$BS$28,0)),"") | C16: =IFERROR(INDEX(Mieterwechsel!$AH$9:$AH$28,MATCH(SMALL(Mieterwechsel!$BS$9:$BS$28,3),Mieterwechsel!$BS$9:$BS$28,0)),"") | D16: =IFERROR(INT(SMALL(Mieterwechsel!$BS$9:$BS$28,3))-TODAY(),"")
A17: =IFERROR(INT(SMALL(Mieterwechsel!$BS$9:$BS$28,4)),"") | B17: =IFERROR(INDEX(Mieterwechsel!$B$9:$B$28,MATCH(SMALL(Mieterwechsel!$BS$9:$BS$28,4),Mieterwechsel!$BS$9:$BS$28,0)),"") | C17: =IFERROR(INDEX(Mieterwechsel!$AH$9:$AH$28,MATCH(SMALL(Mieterwechsel!$BS$9:$BS$28,4),Mieterwechsel!$BS$9:$BS$28,0)),"") | D17: =IFERROR(INT(SMALL(Mieterwechsel!$BS$9:$BS$28,4))-TODAY(),"")
A18: =IFERROR(INT(SMALL(Mieterwechsel!$BS$9:$BS$28,5)),"") | B18: =IFERROR(INDEX(Mieterwechsel!$B$9:$B$28,MATCH(SMALL(Mieterwechsel!$BS$9:$BS$28,5),Mieterwechsel!$BS$9:$BS$28,0)),"") | C18: =IFERROR(INDEX(Mieterwechsel!$AH$9:$AH$28,MATCH(SMALL(Mieterwechsel!$BS$9:$BS$28,5),Mieterwechsel!$BS$9:$BS$28,0)),"") | D18: =IFERROR(INT(SMALL(Mieterwechsel!$BS$9:$BS$28,5))-TODAY(),"")
A21: Kennzahlen
A22: Laufende Mietverhältnisse | B22: =COUNTIF('Mein Haus'!N45:N104,"aktiv")
A23: Nettomieten pro Monat | B23: =SUMIF('Mein Haus'!N45:N104,"aktiv",'Mein Haus'!G45:G104)
A24: Kautionen laufender Mietverhältnisse | B24: =SUMIF('Mein Haus'!N45:N104,"aktiv",'Mein Haus'!I45:I104)
A25: Einheiten ohne laufendes Mietverhältnis | B25: =MAX(0,N('Mein Haus'!F41)-B22)
A26: Kontrolle | B26: =Kontrolle!B16
A29: Gelb = Eingabe · Blau = rechnet automatisch (Blattschutz ohne Passwort).
A30: Ersetzt keine Rechtsberatung. Bei Streit: Schlichtungsbehörde Ihres Kantons oder Ihr Verband.

Sheet Mein Haus
A1: Mein Haus
A2: Alles, was mehrere Teile brauchen, steht nur hier. Gelb = Eingabe, Blau = rechnet.
A4: Liegenschaft | B4: Musterstrasse 12, 8004 Zürich
A5: Vermieter | B5: Hans Beispiel, Bergstrasse 1, 8004 Zürich
A6: IBAN Vermieter
A9: Einheiten
A10: Nr. | B10: Bezeichnung | C10: Zimmer | D10: Fläche m² | E10: Anteil (Wertquote ‰ o.ä.) | F10: Zähler
A11: 1 | B11: EG links | C11: 3.5 | D11: 82 | E11: 250 | F11: =IF(A11="","",1)
A12: 2 | B12: EG rechts | C12: 2.5 | D12: 61 | E12: 190 | F12: =IF(A12="","",1)
A13: 3 | B13: 1. OG | C13: 4.5 | D13: 104 | E13: 320 | F13: =IF(A13="","",1)
A14: 4 | B14: DG | C14: 3.5 | D14: 78 | E14: 240 | F14: =IF(A14="","",1)
F15: =IF(A15="","",1)
F16: =IF(A16="","",1)
F17: =IF(A17="","",1)
F18: =IF(A18="","",1)
F19: =IF(A19="","",1)
F20: =IF(A20="","",1)
F21: =IF(A21="","",1)
F22: =IF(A22="","",1)
F23: =IF(A23="","",1)
F24: =IF(A24="","",1)
F25: =IF(A25="","",1)
F26: =IF(A26="","",1)
... F40: =IF(A40="","",1)
B41: Total | D41: =SUM(D11:D40) | E41: =SUM(E11:E40) | F41: =SUM(F11:F40)
A43: Mietverhältnisse
A44: ID | B44: Einheit Nr. | C44: Mieter | D44: Mietbeginn | E44: Mietende (manuell) | F44: Mietende wirksam | G44: Nettomiete / Mt. | H44: Akonto NK / Mt. | I44: Kaution | J44: Kautionskonto (Bank) | K44: Referenzzins Basis % | L44: LIK Basis (Punkte) | M44: Basis seit (letzte Anpassung) | N44: Status | O44: Prüfen
A45: 1 | B45: 1 | C45: Muster Anna | D45: 43556 | F45: =IF(E45<>"",E45,IFERROR(INDEX(Mieterwechsel!$H$9:$H$28,MATCH(A45,Mieterwechsel!$A$9:$A$28,0)),"")) | G45: 1650 | H45: 380 | I45: 4950 | J45: Musterbank, Konto 11-1 | K45: 1.75 | L45: 106.2 | M45: 45261 | N45: =IF(C45="","",IF(AND(F45<>"",F45<TODAY()),"beendet",IF(AND(D45<>"",D45>TODAY()),"künftig","aktiv"))) | O45: =IF(C45="","",IF(B45="","Einheit fehlt",IF(ISNA(MATCH(B45,$A$11:$A$40,0)),"Einheit unbekannt",IF(AND(D45<>"",F45<>"",F45<D45),"Ende vor Beginn",IF(R45>0,"Überschneidung mit anderem Mieter",""))))) | P45: =IF(C45="","",IF(D45="",1,D45)) | Q45: =IF(C45="","",IF(F45="",401768,F45)) | R45: =IF(C45="",0,COUNTIFS($B$45:$B$104,B45,$P$45:$P$104,"<="&Q45,$Q$45:$Q$104,">="&P45)-1)
A46: 2 | B46: 2 | C46: Beispiel Marco | D46: 43009 | F46: =IF(E46<>"",E46,IFERROR(INDEX(Mieterwechsel!$H$9:$H$28,MATCH(A46,Mieterwechsel!$A$9:$A$28,0)),"")) | G46: 1290 | H46: 400 | I46: 3870 | J46: Musterbank, Konto 11-2 | K46: 1.5 | L46: 104.9 | M46: 44652 | N46: =IF(C46="","",IF(AND(F46<>"",F46<TODAY()),"beendet",IF(AND(D46<>"",D46>TODAY()),"künftig","aktiv"))) | O46: =IF(C46="","",IF(B46="","Einheit fehlt",IF(ISNA(MATCH(B46,$A$11:$A$40,0)),"Einheit unbekannt",IF(AND(D46<>"",F46<>"",F46<D46),"Ende vor Beginn",IF(R46>0,"Überschneidung mit anderem Mieter",""))))) | P46: =IF(C46="","",IF(D46="",1,D46)) | Q46: =IF(C46="","",IF(F46="",401768,F46)) | R46: =IF(C46="",0,COUNTIFS($B$45:$B$104,B46,$P$45:$P$104,"<="&Q46,$Q$45:$Q$104,">="&P46)-1)
A47: 3 | B47: 2 | C47: Probst Lea | D47: 45748 | F47: =IF(E47<>"",E47,IFERROR(INDEX(Mieterwechsel!$H$9:$H$28,MATCH(A47,Mieterwechsel!$A$9:$A$28,0)),"")) | G47: 1350 | H47: 260 | I47: 4050 | J47: Musterbank, Konto 11-3 | K47: 1.75 | L47: 107.1 | M47: 45748 | N47: =IF(C47="","",IF(AND(F47<>"",F47<TODAY()),"beendet",IF(AND(D47<>"",D47>TODAY()),"künftig","aktiv"))) | O47: =IF(C47="","",IF(B47="","Einheit fehlt",IF(ISNA(MATCH(B47,$A$11:$A$40,0)),"Einheit unbekannt",IF(AND(D47<>"",F47<>"",F47<D47),"Ende vor Beginn",IF(R47>0,"Überschneidung mit anderem Mieter",""))))) | P47: =IF(C47="","",IF(D47="",1,D47)) | Q47: =IF(C47="","",IF(F47="",401768,F47)) | R47: =IF(C47="",0,COUNTIFS($B$45:$B$104,B47,$P$45:$P$104,"<="&Q47,$Q$45:$Q$104,">="&P47)-1)
A48: 4 | B48: 3 | C48: Keller Familie | D48: 41030 | F48: =IF(E48<>"",E48,IFERROR(INDEX(Mieterwechsel!$H$9:$H$28,MATCH(A48,Mieterwechsel!$A$9:$A$28,0)),"")) | G48: 2150 | H48: 480 | I48: 6000 | J48: Musterbank, Konto 11-4 | K48: 1.75 | L48: 106.2 | M48: 45261 | N48: =IF(C48="","",IF(AND(F48<>"",F48<TODAY()),"beendet",IF(AND(D48<>"",D48>TODAY()),"künftig","aktiv"))) | O48: =IF(C48="","",IF(B48="","Einheit fehlt",IF(ISNA(MATCH(B48,$A$11:$A$40,0)),"Einheit unbekannt",IF(AND(D48<>"",F48<>"",F48<D48),"Ende vor Beginn",IF(R48>0,"Überschneidung mit anderem Mieter",""))))) | P48: =IF(C48="","",IF(D48="",1,D48)) | Q48: =IF(C48="","",IF(F48="",401768,F48)) | R48: =IF(C48="",0,COUNTIFS($B$45:$B$104,B48,$P$45:$P$104,"<="&Q48,$Q$45:$Q$104,">="&P48)-1)
A49: 5 | B49: 4 | C49: Weber Tim | D49: 42430 | F49: =IF(E49<>"",E49,IFERROR(INDEX(Mieterwechsel!$H$9:$H$28,MATCH(A49,Mieterwechsel!$A$9:$A$28,0)),"")) | G49: 1720 | H49: 350 | I49: 4950 | J49: Musterbank, Konto 11-5 | K49: 1.75 | L49: 106.2 | M49: 45261 | N49: =IF(C49="","",IF(AND(F49<>"",F49<TODAY()),"beendet",IF(AND(D49<>"",D49>TODAY()),"künftig","aktiv"))) | O49: =IF(C49="","",IF(B49="","Einheit fehlt",IF(ISNA(MATCH(B49,$A$11:$A$40,0)),"Einheit unbekannt",IF(AND(D49<>"",F49<>"",F49<D49),"Ende vor Beginn",IF(R49>0,"Überschneidung mit anderem Mieter",""))))) | P49: =IF(C49="","",IF(D49="",1,D49)) | Q49: =IF(C49="","",IF(F49="",401768,F49)) | R49: =IF(C49="",0,COUNTIFS($B$45:$B$104,B49,$P$45:$P$104,"<="&Q49,$Q$45:$Q$104,">="&P49)-1)
A50: 6 | B50: 4 | C50: Frei Sara | D50: 45992 | F50: =IF(E50<>"",E50,IFERROR(INDEX(Mieterwechsel!$H$9:$H$28,MATCH(A50,Mieterwechsel!$A$9:$A$28,0)),"")) | G50: 1750 | H50: 200 | I50: 5250 | J50: Musterbank, Konto 11-6 | K50: 1.25 | L50: 107.3 | M50: 45992 | N50: =IF(C50="","",IF(AND(F50<>"",F50<TODAY()),"beendet",IF(AND(D50<>"",D50>TODAY()),"künftig","aktiv"))) | O50: =IF(C50="","",IF(B50="","Einheit fehlt",IF(ISNA(MATCH(B50,$A$11:$A$40,0)),"Einheit unbekannt",IF(AND(D50<>"",F50<>"",F50<D50),"Ende vor Beginn",IF(R50>0,"Überschneidung mit anderem Mieter",""))))) | P50: =IF(C50="","",IF(D50="",1,D50)) | Q50: =IF(C50="","",IF(F50="",401768,F50)) | R50: =IF(C50="",0,COUNTIFS($B$45:$B$104,B50,$P$45:$P$104,"<="&Q50,$Q$45:$Q$104,">="&P50)-1)
A51: 7 | F51: =IF(E51<>"",E51,IFERROR(INDEX(Mieterwechsel!$H$9:$H$28,MATCH(A51,Mieterwechsel!$A$9:$A$28,0)),"")) | N51: =IF(C51="","",IF(AND(F51<>"",F51<TODAY()),"beendet",IF(AND(D51<>"",D51>TODAY()),"künftig","aktiv"))) | O51: =IF(C51="","",IF(B51="","Einheit fehlt",IF(ISNA(MATCH(B51,$A$11:$A$40,0)),"Einheit unbekannt",IF(AND(D51<>"",F51<>"",F51<D51),"Ende vor Beginn",IF(R51>0,"Überschneidung mit anderem Mieter",""))))) | P51: =IF(C51="","",IF(D51="",1,D51)) | Q51: =IF(C51="","",IF(F51="",401768,F51)) | R51: =IF(C51="",0,COUNTIFS($B$45:$B$104,B51,$P$45:$P$104,"<="&Q51,$Q$45:$Q$104,">="&P51)-1)
A52: 8 | F52: =IF(E52<>"",E52,IFERROR(INDEX(Mieterwechsel!$H$9:$H$28,MATCH(A52,Mieterwechsel!$A$9:$A$28,0)),"")) | N52: =IF(C52="","",IF(AND(F52<>"",F52<TODAY()),"beendet",IF(AND(D52<>"",D52>TODAY()),"künftig","aktiv"))) | O52: =IF(C52="","",IF(B52="","Einheit fehlt",IF(ISNA(MATCH(B52,$A$11:$A$40,0)),"Einheit unbekannt",IF(AND(D52<>"",F52<>"",F52<D52),"Ende vor Beginn",IF(R52>0,"Überschneidung mit anderem Mieter",""))))) | P52: =IF(C52="","",IF(D52="",1,D52)) | Q52: =IF(C52="","",IF(F52="",401768,F52)) | R52: =IF(C52="",0,COUNTIFS($B$45:$B$104,B52,$P$45:$P$104,"<="&Q52,$Q$45:$Q$104,">="&P52)-1)
A53: 9 | F53: =IF(E53<>"",E53,IFERROR(INDEX(Mieterwechsel!$H$9:$H$28,MATCH(A53,Mieterwechsel!$A$9:$A$28,0)),"")) | N53: =IF(C53="","",IF(AND(F53<>"",F53<TODAY()),"beendet",IF(AND(D53<>"",D53>TODAY()),"künftig","aktiv"))) | O53: =IF(C53="","",IF(B53="","Einheit fehlt",IF(ISNA(MATCH(B53,$A$11:$A$40,0)),"Einheit unbekannt",IF(AND(D53<>"",F53<>"",F53<D53),"Ende vor Beginn",IF(R53>0,"Überschneidung mit anderem Mieter",""))))) | P53: =IF(C53="","",IF(D53="",1,D53)) | Q53: =IF(C53="","",IF(F53="",401768,F53)) | R53: =IF(C53="",0,COUNTIFS($B$45:$B$104,B53,$P$45:$P$104,"<="&Q53,$Q$45:$Q$104,">="&P53)-1)
A54: 10 | F54: =IF(E54<>"",E54,IFERROR(INDEX(Mieterwechsel!$H$9:$H$28,MATCH(A54,Mieterwechsel!$A$9:$A$28,0)),"")) | N54: =IF(C54="","",IF(AND(F54<>"",F54<TODAY()),"beendet",IF(AND(D54<>"",D54>TODAY()),"künftig","aktiv"))) | O54: =IF(C54="","",IF(B54="","Einheit fehlt",IF(ISNA(MATCH(B54,$A$11:$A$40,0)),"Einheit unbekannt",IF(AND(D54<>"",F54<>"",F54<D54),"Ende vor Beginn",IF(R54>0,"Überschneidung mit anderem Mieter",""))))) | P54: =IF(C54="","",IF(D54="",1,D54)) | Q54: =IF(C54="","",IF(F54="",401768,F54)) | R54: =IF(C54="",0,COUNTIFS($B$45:$B$104,B54,$P$45:$P$104,"<="&Q54,$Q$45:$Q$104,">="&P54)-1)
A55: 11 | F55: =IF(E55<>"",E55,IFERROR(INDEX(Mieterwechsel!$H$9:$H$28,MATCH(A55,Mieterwechsel!$A$9:$A$28,0)),"")) | N55: =IF(C55="","",IF(AND(F55<>"",F55<TODAY()),"beendet",IF(AND(D55<>"",D55>TODAY()),"künftig","aktiv"))) | O55: =IF(C55="","",IF(B55="","Einheit fehlt",IF(ISNA(MATCH(B55,$A$11:$A$40,0)),"Einheit unbekannt",IF(AND(D55<>"",F55<>"",F55<D55),"Ende vor Beginn",IF(R55>0,"Überschneidung mit anderem Mieter",""))))) | P55: =IF(C55="","",IF(D55="",1,D55)) | Q55: =IF(C55="","",IF(F55="",401768,F55)) | R55: =IF(C55="",0,COUNTIFS($B$45:$B$104,B55,$P$45:$P$104,"<="&Q55,$Q$45:$Q$104,">="&P55)-1)
A56: 12 | F56: =IF(E56<>"",E56,IFERROR(INDEX(Mieterwechsel!$H$9:$H$28,MATCH(A56,Mieterwechsel!$A$9:$A$28,0)),"")) | N56: =IF(C56="","",IF(AND(F56<>"",F56<TODAY()),"beendet",IF(AND(D56<>"",D56>TODAY()),"künftig","aktiv"))) | O56: =IF(C56="","",IF(B56="","Einheit fehlt",IF(ISNA(MATCH(B56,$A$11:$A$40,0)),"Einheit unbekannt",IF(AND(D56<>"",F56<>"",F56<D56),"Ende vor Beginn",IF(R56>0,"Überschneidung mit anderem Mieter",""))))) | P56: =IF(C56="","",IF(D56="",1,D56)) | Q56: =IF(C56="","",IF(F56="",401768,F56)) | R56: =IF(C56="",0,COUNTIFS($B$45:$B$104,B56,$P$45:$P$104,"<="&Q56,$Q$45:$Q$104,">="&P56)-1)
A57: 13 | F57: =IF(E57<>"",E57,IFERROR(INDEX(Mieterwechsel!$H$9:$H$28,MATCH(A57,Mieterwechsel!$A$9:$A$28,0)),"")) | N57: =IF(C57="","",IF(AND(F57<>"",F57<TODAY()),"beendet",IF(AND(D57<>"",D57>TODAY()),"künftig","aktiv"))) | O57: =IF(C57="","",IF(B57="","Einheit fehlt",IF(ISNA(MATCH(B57,$A$11:$A$40,0)),"Einheit unbekannt",IF(AND(D57<>"",F57<>"",F57<D57),"Ende vor Beginn",IF(R57>0,"Überschneidung mit anderem Mieter",""))))) | P57: =IF(C57="","",IF(D57="",1,D57)) | Q57: =IF(C57="","",IF(F57="",401768,F57)) | R57: =IF(C57="",0,COUNTIFS($B$45:$B$104,B57,$P$45:$P$104,"<="&Q57,$Q$45:$Q$104,">="&P57)-1)
...

Sheet Mieterwechsel
A1: Mieterwechsel & Fristen
A2: START: Pro Kündigung eine Zeile: Mietverhältnis-ID, wer kündigt, Eingangsdatum.
A3: BERECHNUNG: Mietende auf den nächsten zulässigen Termin, zehn Schritte mit Datum, Leerstand in Franken.
A4: ERGEBNIS: Spalte «Nächste Frist»: rot überfällig, gelb innert 7 Tagen. Erledigtes mit x markieren.
A5: AUSGABE: Blatt «Checkliste»: ein Mieterwechsel als druckbare Liste.
BI7: Kündigung schriftlich bestätigen | BJ7: Nachmieter suchen / Inserat | BK7: Vorabnahme | BL7: Neuen Mietvertrag abschliessen | BM7: Abnahme · Protokoll · Zähler · Schlüssel | BN7: Mängelrüge schriftlich | BO7: Übergabe an Neumieter | BP7: Kaution abrechnen | BQ7: Nebenkosten-Schlussabrechnung | BR7: Kautionsfrist (1 Jahr nach Mietende)
A8: ID | B8: Mieter | C8: Einheit | D8: Kündigung durch | E8: Eingang Kündigung | F8: Frist (Mt.) | G8: Vereinbartes Ende | H8: Ende Mietverhältnis | I8: Neuer Mieter ab | J8: Leerstand Tage | K8: Leerstandskosten | L8: Kündigung schriftlich bestätigen | M8: erl. | N8: Nachmieter suchen / Inserat | O8: erl. | P8: Vorabnahme | Q8: erl. | R8: Neuen Mietvertrag abschliessen | S8: erl. | T8: Abnahme · Protokoll · Zähler · Schlüssel | U8: erl. | V8: Mängelrüge schriftlich | W8: erl. | X8: Übergabe an Neumieter | Y8: erl. | Z8: Kaution abrechnen | AA8: erl. | AB8: Nebenkosten-Schlussabrechnung | AC8: erl. | AD8: Kautionsfrist (1 Jahr nach Mietende) | AE8: erl. | AF8: Nächste Frist | AG8: Tage | AH8: Nächster Schritt | AI8: Hinweis
A9: 2 | B9: =IF(A9="","",IFERROR(INDEX('Mein Haus'!$C$45:$C$104,A9)&"","")) | C9: =IF(A9="","",IFERROR(INDEX('Mein Haus'!$B$45:$B$104,A9)&"","")) | D9: Mieter | E9: 45636 | F9: 3 | H9: =IF(G9<>"",G9,IF(E9="","",IF(COUNT(AK9:BH9)=0,"",MIN(AK9:BH9)))) | I9: 45748 | J9: =IF(OR(H9="",I9=""),"",MAX(0,I9-H9-1)) | K9: =IF(J9="","",ROUND(N(IFERROR(INDEX('Mein Haus'!$G$45:$G$104,A9),0))*12/365*J9,2)) | L9: =IF(E9="","",E9+7) | M9: x | N9: =IF(E9="","",E9) | O9: x | P9: =IF(H9="","",WORKDAY(H9,-10,Einstellungen!$D$5:$D$34)) | Q9: x | R9: =IF(H9="","",H9-30) | S9: x | T9: =IF(H9="","",WORKDAY(H9-1,1,Einstellungen!$D$5:$D$34)) | U9: x | V9: =IF(T9="","",WORKDAY(T9,2,Einstellungen!$D$5:$D$34)) | W9: x | X9: =IF(I9="","",I9) | Y9: x | Z9: =IF(T9="","",T9+30) | AA9: x | AB9: =IF(OR(H9="",Nebenkosten!$B$7=""),"",EDATE(Nebenkosten!$B$7,12*MAX(1,ROUNDUP(((YEAR(H9)-YEAR(Nebenkosten!$B$7))*12+MONTH(H9)-MONTH(Nebenkosten!$B$7)+1)/12,0)))) | AC9: x | AD9: =IF(H9="","",EDATE(H9,12)) | AE9: x | AF9: =IF(COUNT(BI9:BR9)=0,"",MIN(BI9:BR9)) | AG9: =IF(AF9="","",AF9-TODAY()) | AH9: =IF(AF9="","",INDEX($BI$7:$BR$7,MATCH(AF9,BI9:BR9,0))) | AI9: =IF(A9="","",IF(B9="","ID ohne Mieter in «Mein Haus»",IF(AND(IFERROR(INDEX('Mein Haus'!$E$45:$E$104,A9),"")<>"",H9<>"",IFERROR(INDEX('Mein Haus'!$E$45:$E$104,A9),"")<>H9),"Mietende in «Mein Haus» weicht ab",IF(D9="Vermieter","Amtliches Formular? Familienwohnung: beide Ehegatten.",IF(D9="Ausserterminlich","Nachmieter zumutbar? Vereinbartes Ende eintragen.",""))))) | AK9: =IF(E9="","",IF(OR(COUNTIF(Einstellungen!$B$5:$B$16,"x")=0,INDEX(Einstellungen!$B$5:$B$16,MONTH(EOMONTH(E9,IF(F9="",3,F9)+0)))="x"),EOMONTH(E9,IF(F9="",3,F9)+0),"")) | AL9: =IF(E9="","",IF(OR(COUNTIF(Einstellungen!$B$5:$B$16,"x")=0,INDEX(Einstellungen!$B$5:$B$16,MONTH(EOMONTH(E9,IF(F9="",3,F9)+1)))="x"),EOMONTH(E9,IF(F9="",3,F9)+1),"")) | AM9: =IF(E9="","",IF(OR(COUNTIF(Einstellungen!$B$5:$B$16,"x")=0,INDEX(Einstellungen!$B$5:$B$16,MONTH(EOMONTH(E9,IF(F9="",3,F9)+2)))="x"),EOMONTH(E9,IF(F9="",3,F9)+2),"")) | AN9: =IF(E9="","",IF(OR(COUNTIF(Einstellungen!$B$5:$B$16,"x")=0,INDEX(Einstellungen!$B$5:$B$16,MONTH(EOMONTH(E9,IF(F9="",3,F9)+3)))="x"),EOMONTH(E9,IF(F9="",3,F9)+3),"")) | AO9: =IF(E9="","",IF(OR(COUNTIF(Einstellungen!$B$5:$B$16,"x")=0,INDEX(Einstellungen!$B$5:$B$16,MONTH(EOMONTH(E9,IF(F9="",3,F9)+4)))="x"),EOMONTH(E9,IF(F9="",3,F9)+4),"")) | AP9: =IF(E9="","",IF(OR(COUNTIF(Einstellungen!$B$5:$B$16,"x")=0,INDEX(Einstellungen!$B$5:$B$16,MONTH(EOMONTH(E9,IF(F9="",3,F9)+5)))="x"),EOMONTH(E9,IF(F9="",3,F9)+5),"")) | AQ9: =IF(E9="","",IF(OR(COUNTIF(Einstellungen!$B$5:$B$16,"x")=0,INDEX(Einstellungen!$B$5:$B$16,MONTH(EOMONTH(E9,IF(F9="",3,F9)+6)))="x"),EOMONTH(E9,IF(F9="",3,F9)+6),"")) | AR9: =IF(E9="","",IF(OR(COUNTIF(Einstellungen!$B$5:$B$16,"x")=0,INDEX(Einstellungen!$B$5:$B$16,MONTH(EOMONTH(E9,IF(F9="",3,F9)+7)))="x"),EOMONTH(E9,IF(F9="",3,F9)+7),"")) | AS9: =IF(E9="","",IF(OR(COUNTIF(Einstellungen!$B$5:$B$16,"x")=0,INDEX(Einstellungen!$B$5:$B$16,MONTH(EOMONTH(E9,IF(F9="",3,F9)+8)))="x"),EOMONTH(E9,IF(F9="",3,F9)+8),"")) | AT9: =IF(E9="","",IF(OR(COUNTIF(Einstellungen!$B$5:$B$16,"x")=0,INDEX(Einstellungen!$B$5:$B$16,MONTH(EOMONTH(E9,IF(F9="",3,F9)+9)))="x"),EOMONTH(E9,IF(F9="",3,F9)+9),"")) | AU9: =IF(E9="","",IF(OR(COUNTIF(Einstellungen!$B$5:$B$16,"x")=0,INDEX(Einstellungen!$B$5:$B$16,MONTH(EOMONTH(E9,IF(F9="",3,F9)+10)))="x"),EOMONTH(E9,IF(F9="",3,F9)+10),"")) | AV9: =IF(E9="","",IF(OR(COUNTIF(Einstellungen!$B$5:$B$16,"x")=0,INDEX(Einstellungen!$B$5:$B$16,MONTH(EOMONTH(E9,IF(F9="",3,F9)+11)))="x"),EOMONTH(E9,IF(F9="",3,F9)+11),"")) | AW9: =IF(E9="","",IF(OR(COUNTIF(Einstellungen!$B$5:$B$16,"x")=0,INDEX(Einstellungen!$B$5:$B$16,MONTH(EOMONTH(E9,IF(F9="",3,F9)+12)))="x"),EOMONTH(E9,IF(F9="",3,F9)+12),"")) | AX9: =IF(E9="","",IF(OR(COUNTIF(Einstellungen!$B$5:$B$16,"x")=0,INDEX(Einstellungen!$B$5:$B$16,MONTH(EOMONTH(E9,IF(F9="",3,F9)+13)))="x"),EOMONTH(E9,IF(F9="",3,F9)+13),"")) | AY9: =IF(E9="","",IF(OR(COUNTIF(Einstellungen!$B$5:$B$16,"x")=0,INDEX(Einstellungen!$B$5:$B$16,MONTH(EOMONTH(E9,IF(F9="",3,F9)+14)))="x"),EOMONTH(E9,IF(F9="",3,F9)+14),"")) | AZ9: =IF(E9="","",IF(OR(COUNTIF(Einstellungen!$B$5:$B$16,"x")=0,INDEX(Einstellungen!$B$5:$B$16,MONTH(EOMONTH(E9,IF(F9="",3,F9)+15)))="x"),EOMONTH(E9,IF(F9="",3,F9)+15),"")) | BA9: =IF(E9="","",IF(OR(COUNTIF(Einstellungen!$B$5:$B$16,"x")=0,INDEX(Einstellungen!$B$5:$B$16,MONTH(EOMONTH(E9,IF(F9="",3,F9)+16)))="x"),EOMONTH(E9,IF(F9="",3,F9)+16),"")) | BB9: =IF(E9="","",IF(OR(COUNTIF(Einstellungen!$B$5:$B$16,"x")=0,INDEX(Einstellungen!$B$5:$B$16,MONTH(EOMONTH(E9,IF(F9="",3,F9)+17)))="x"),EOMONTH(E9,IF(F9="",3,F9)+17),"")) | BC9: =IF(E9="","",IF(OR(COUNTIF(Einstellungen!$B$5:$B$16,"x")=0,INDEX(Einstellungen!$B$5:$B$16,MONTH(EOMONTH(E9,IF(F9="",3,F9)+18)))="x"),EOMONTH(E9,IF(F9="",3,F9)+18),"")) | BD9: =IF(E9="","",IF(OR(COUNTIF(Einstellungen!$B$5:$B$16,"x")=0,INDEX(Einstellungen!$B$5:$B$16,MONTH(EOMONTH(E9,IF(F9="",3,F9)+19)))="x"),EOMONTH(E9,IF(F9="",3,F9)+19),"")) | BE9: =IF(E9="","",IF(OR(COUNTIF(Einstellungen!$B$5:$B$16,"x")=0,INDEX(Einstellungen!$B$5:$B$16,MONTH(EOMONTH(E9,IF(F9="",3,F9)+20)))="x"),EOMONTH(E9,IF(F9="",3,F9)+20),"")) | BF9: =IF(E9="","",IF(OR(COUNTIF(Einstellungen!$B$5:$B$16,"x")=0,INDEX(Einstellungen!$B$5:$B$16,MONTH(EOMONTH(E9,IF(F9="",3,F9)+21)))="x"),EOMONTH(E9,IF(F9="",3,F9)+21),"")) | BG9: =IF(E9="","",IF(OR(COUNTIF(Einstellungen!$B$5:$B$16,"x")=0,INDEX(Einstellungen!$B$5:$B$16,MONTH(EOMONTH(E9,IF(F9="",3,F9)+22)))="x"),EOMONTH(E9,IF(F9="",3,F9)+22),"")) | BH9: =IF(E9="","",IF(OR(COUNTIF(Einstellungen!$B$5:$B$16,"x")=0,INDEX(Einstellungen!$B$5:$B$16,MONTH(EOMONTH(E9,IF(F9="",3,F9)+23)))="x"),EOMONTH(E9,IF(F9="",3,F9)+23),"")) | BI9: =IF(AND(L9<>"",M9=""),L9,"") | BJ9: =IF(AND(N9<>"",O9=""),N9,"") | BK9: =IF(AND(P9<>"",Q9=""),P9,"") | BL9: =IF(AND(R9<>"",S9=""),R9,"") | BM9: =IF(AND(T9<>"",U9=""),T9,"") | BN9: =IF(AND(V9<>"",W9=""),V9,"") | BO9: =IF(AND(X9<>"",Y9=""),X9,"") | BP9: =IF(AND(Z9<>"",AA9=""),Z9,"") | BQ9: =IF(AND(AB9<>"",AC9=""),AB9,"") | BR9: =IF(AND(AD9<>"",AE9=""),AD9,"") | BS9: =IF(AF9="","",AF9+ROW()/100000)
A10: 5 | B10: =IF(A10="","",IFERROR(INDEX('Mein Haus'!$C$45:$C$104,A10)&"","")) | C10: =IF(A10="","",IFERROR(INDEX('Mein Haus'!$B$45:$B$104,A10)&"","")) | D10: Vermieter | E10: 45838 | F10: 3 | H10: =IF(G10<>"",G10,IF(E10="","",IF(COUNT(AK10:BH10)=0,"",MIN(AK10:BH10)))) | I10: 45992 | J10: =IF(OR(H10="",I10=""),"",MAX(0,I10-H10-1)) | K10: =IF(J10="","",ROUND(N(IFERROR(INDEX('Mein Haus'!$G$45:$G$104,A10),0))*12/365*J10,2)) | L10: =IF(E10="","",E10+7) | M10: x | N10: =IF(E10="","",E10) | O10: x | P10: =IF(H10="","",WORKDAY(H10,-10,Einstellungen!$D$5:$D$34)) | Q10: x | R10: =IF(H10="","",H10-30) | S10: x | T10: =IF(H10="","",WORKDAY(H10-1,1,Einstellungen!$D$5:$D$34)) | U10: x | V10: =IF(T10="","",WORKDAY(T10,2,Einstellungen!$D$5:$D$34)) | W10: x | X10: =IF(I10="","",I10) | Y10: x | Z10: =IF(T10="","",T10+30) | AA10: x | AB10: =IF(OR(H10="",Nebenkosten!$B$7=""),"",EDATE(Nebenkosten!$B$7,12*MAX(1,ROUNDUP(((YEAR(H10)-YEAR(Nebenkosten!$B$7))*12+MONTH(H10)-MONTH(Nebenkosten!$B$7)+1)/12,0)))) | AC10: x | AD10: =IF(H10="","",EDATE(H10,12)) | AE10: x | AF10: =IF(COUNT(BI10:BR10)=0,"",MIN(BI10:BR10)) | AG10: =IF(AF10="","",AF10-TODAY()) | AH10: =IF(AF10="","",INDEX($BI$7:$BR$7,MATCH(AF10,BI10:BR10,0))) | AI10: =IF(A10="","",IF(B10="","ID ohne Mieter in «Mein Haus»",IF(AND(IFERROR(INDEX('Mein Haus'!$E$45:$E$104,A10),"")<>"",H10<>"",IFERROR(INDEX('Mein Haus'!$E$45:$E$104,A10),"")<>H10),"Mietende in «Mein Haus» weicht ab",IF(D10="Vermieter","Amtliches Formular? Familienwohnung: beide Ehegatten.",IF(D10="Ausserterminlich","Nachmieter zumutbar? Vereinbartes Ende eintragen.",""))))) | AK10: =IF(E10="","",IF(OR(COUNTIF(Einstellungen!$B$5:$B$16,"x")=0,INDEX(Einstellungen!$B$5:$B$16,MONTH(EOMONTH(E10,IF(F10="",3,F10)+0)))="x"),EOMONTH(E10,IF(F10="",3,F10)+0),"")) | AL10: =IF(E10="","",IF(OR(COUNTIF(Einstellungen!$B$5:$B$16,"x")=0,INDEX(Einstellungen!$B$5:$B$16,MONTH(EOMONTH(E10,IF(F10="",3,F10)+1)))="x"),EOMONTH(E10,IF(F10="",3,F10)+1),"")) | AM10: =IF(E10="","",IF(OR(COUNTIF(Einstellungen!$B$5:$B$16,"x")=0,INDEX(Einstellungen!$B$5:$B$16,MONTH(EOMONTH(E10,IF(F10="",3,F10)+2)))="x"),EOMONTH(E10,IF(F10="",3,F10)+2),"")) | AN10: =IF(E10="","",IF(OR(COUNTIF(Einstellungen!$B$5:$B$16,"x")=0,INDEX(Einstellungen!$B$5:$B$16,MONTH(EOMONTH(E10,IF(F10="",3,F10)+3)))="x"),EOMONTH(E10,IF(F10="",3,F10)+3),"")) | AO10: =IF(E10="","",IF(OR(COUNTIF(Einstellungen!$B$5:$B$16,"x")=0,INDEX(Einstellungen!$B$5:$B$16,MONTH(EOMONTH(E10,IF(F10="",3,F10)+4)))="x"),EOMONTH(E10,IF(F10="",3,F10)+4),"")) | AP10: =IF(E10="","",IF(OR(COUNTIF(Einstellungen!$B$5:$B$16,"x")=0,INDEX(Einstellungen!$B$5:$B$16,MONTH(EOMONTH(E10,IF(F10="",3,F10)+5)))="x"),EOMONTH(E10,IF(F10="",3,F10)+5),"")) | AQ10: =IF(E10="","",IF(OR(COUNTIF(Einstellungen!$B$5:$B$16,"x")=0,INDEX(Einstellungen!$B$5:$B$16,MONTH(EOMONTH(E10,IF(F10="",3,F10)+6)))="x"),EOMONTH(E10,IF(F10="",3,F10)+6),"")) | AR10: =IF(E10="","",IF(OR(COUNTIF(Einstellungen!$B$5:$B$16,"x")=0,INDEX(Einstellungen!$B$5:$B$16,MONTH(EOMONTH(E10,IF(F10="",3,F10)+7)))="x"),EOMONTH(E10,IF(F10="",3,F10)+7),"")) | AS10: =IF(E10="","",IF(OR(COUNTIF(Einstellungen!$B$5:$B$16,"x")=0,INDEX(Einstellungen!$B$5:$B$16,MONTH(EOMONTH(E10,IF(F10="",3,F10)+8)))="x"),EOMONTH(E10,IF(F10="",3,F10)+8),"")) | AT10: =IF(E10="","",IF(OR(COUNTIF(Einstellungen!$B$5:$B$16,"x")=0,INDEX(Einstellungen!$B$5:$B$16,MONTH(EOMONTH(E10,IF(F10="",3,F10)+9)))="x"),EOMONTH(E10,IF(F10="",3,F10)+9),"")) | AU10: =IF(E10="","",IF(OR(COUNTIF(Einstellungen!$B$5:$B$16,"x")=0,INDEX(Einstellungen!$B$5:$B$16,MONTH(EOMONTH(E10,IF(F10="",3,F10)+10)))="x"),EOMONTH(E10,IF(F10="",3,F10)+10),"")) | AV10: =IF(E10="","",IF(OR(COUNTIF(Einstellungen!$B$5:$B$16,"x")=0,INDEX(Einstellungen!$B$5:$B$16,MONTH(EOMONTH(E10,IF(F10="",3,F10)+11)))="x"),EOMONTH(E10,IF(F10="",3,F10)+11),"")) | AW10: =IF(E10="","",IF(OR(COUNTIF(Einstellungen!$B$5:$B$16,"x")=0,INDEX(Einstellungen!$B$5:$B$16,MONTH(EOMONTH(E10,IF(F10="",3,F10)+12)))="x"),EOMONTH(E10,IF(F10="",3,F10)+12),"")) | AX10: =IF(E10="","",IF(OR(COUNTIF(Einstellungen!$B$5:$B$16,"x")=0,INDEX(Einstellungen!$B$5:$B$16,MONTH(EOMONTH(E10,IF(F10="",3,F10)+13)))="x"),EOMONTH(E10,IF(F10="",3,F10)+13),"")) | AY10: =IF(E10="","",IF(OR(COUNTIF(Einstellungen!$B$5:$B$16,"x")=0,INDEX(Einstellungen!$B$5:$B$16,MONTH(EOMONTH(E10,IF(F10="",3,F10)+14)))="x"),EOMONTH(E10,IF(F10="",3,F10)+14),"")) | AZ10: =IF(E10="","",IF(OR(COUNTIF(Einstellungen!$B$5:$B$16,"x")=0,INDEX(Einstellungen!$B$5:$B$16,MONTH(EOMONTH(E10,IF(F10="",3,F10)+15)))="x"),EOMONTH(E10,IF(F10="",3,F10)+15),"")) | BA10: =IF(E10="","",IF(OR(COUNTIF(Einstellungen!$B$5:$B$16,"x")=0,INDEX(Einstellungen!$B$5:$B$16,MONTH(EOMONTH(E10,IF(F10="",3,F10)+16)))="x"),EOMONTH(E10,IF(F10="",3,F10)+16),"")) | BB10: =IF(E10="","",IF(OR(COUNTIF(Einstellungen!$B$5:$B$16,"x")=0,INDEX(Einstellungen!$B$5:$B$16,MONTH(EOMONTH(E10,IF(F10="",3,F10)+17)))="x"),EOMONTH(E10,IF(F10="",3,F10)+17),"")) | BC10: =IF(E10="","",IF(OR(COUNTIF(Einstellungen!$B$5:$B$16,"x")=0,INDEX(Einstellungen!$B$5:$B$16,MONTH(EOMONTH(E10,IF(F10="",3,F10)+18)))="x"),EOMONTH(E10,IF(F10="",3,F10)+18),"")) | BD10: =IF(E10="","",IF(OR(COUNTIF(Einstellungen!$B$5:$B$16,"x")=0,INDEX(Einstellungen!$B$5:$B$16,MONTH(EOMONTH(E10,IF(F10="",3,F10)+19)))="x"),EOMONTH(E10,IF(F10="",3,F10)+19),"")) | BE10: =IF(E10="","",IF(OR(COUNTIF(Einstellungen!$B$5:$B$16,"x")=0,INDEX(Einstellungen!$B$5:$B$16,MONTH(EOMONTH(E10,IF(F10="",3,F10)+20)))="x"),EOMONTH(E10,IF(F10="",3,F10)+20),"")) | BF10: =IF(E10="","",IF(OR(COUNTIF(Einstellungen!$B$5:$B$16,"x")=0,INDEX(Einstellungen!$B$5:$B$16,MONTH(EOMONTH(E10,IF(F10="",3,F10)+21)))="x"),EOMONTH(E10,IF(F10="",3,F10)+21),"")) | BG10: =IF(E10="","",IF(OR(COUNTIF(Einstellungen!$B$5:$B$16,"x")=0,INDEX(Einstellungen!$B$5:$B$16,MONTH(EOMONTH(E10,IF(F10="",3,F10)+22)))="x"),EOMONTH(E10,IF(F10="",3,F10)+22),"")) | BH10: =IF(E10="","",IF(OR(COUNTIF(Einstellungen!$B$5:$B$16,"x")=0,INDEX(Einstellungen!$B$5:$B$16,MONTH(EOMONTH(E10,IF(F10="",3,F10)+23)))="x"),EOMONTH(E10,IF(F10="",3,F10)+23),"")) | BI10: =IF(AND(L10<>"",M10=""),L10,"") | BJ10: =IF(AND(N10<>"",O10=""),N10,"") | BK10: =IF(AND(P10<>"",Q10=""),P10,"") | BL10: =IF(AND(R10<>"",S10=""),R10,"") | BM10: =IF(AND(T10<>"",U10=""),T10,"") | BN10: =IF(AND(V10<>"",W10=""),V10,"") | BO10: =IF(AND(X10<>"",Y10=""),X10,"") | BP10: =IF(AND(Z10<>"",AA10=""),Z10,"") | BQ10: =IF(AND(AB10<>"",AC10=""),AB10,"") | BR10: =IF(AND(AD10<>"",AE10=""),AD10,"") | BS10: =IF(AF10="","",AF10+ROW()/100000)
A11: 1 | B11: =IF(A11="","",IFERROR(INDEX('Mein Haus'!$C$45:$C$104,A11)&"","")) | C11: =IF(A11="","",IFERROR(INDEX('Mein Haus'!$B$45:$B$104,A11)&"","")) | D11: Mieter | E11: 46254 | F11: 3 | H11: =IF(G11<>"",G11,IF(E11="","",IF(COUNT(AK11:BH11)=0,"",MIN(AK11:BH11)))) | J11: =IF(OR(H11="",I11=""),"",MAX(0,I11-H11-1)) | K11: =IF(J11="","",ROUND(N(IFERROR(INDEX('Mein Haus'!$G$45:$G$104,A11),0))*12/365*J11,2)) | L11: =IF(E11="","",E11+7) | N11: =IF(E11="","",E11) | P11: =IF(H11="","",WORKDAY(H11,-10,Einstellungen!$D$5:$D$34)) | R11: =IF(H11="","",H11-30) | T11: =IF(H11="","",WORKDAY(H11-1,1,Einstellungen!$D$5:$D$34)) | V11: =IF(T11="","",WORKDAY(T11,2,Einstellungen!$D$5:$D$34)) | X11: =IF(I11="","",I11) | Z11: =IF(T11="","",T11+30) | AB11: =IF(OR(H11="",Nebenkosten!$B$7=""),"",EDATE(Nebenkosten!$B$7,12*MAX(1,ROUNDUP(((YEAR(H11)-YEAR(Nebenkosten!$B$7))*12+MONTH(H11)-MONTH(Nebenkosten!$B$7)+1)/12,0)))) | AD11: =IF(H11="","",EDATE(H11,12)) | AF11: =IF(COUNT(BI11:BR11)=0,"",MIN(BI11:BR11)) | AG11: =IF(AF11="","",AF11-TODAY()) | AH11: =IF(AF11="","",INDEX($BI$7:$BR$7,MATCH(AF11,BI11:BR11,0))) | AI11: =IF(A11="","",IF(B11="","ID ohne Mieter in «Mein Haus»",IF(AND(IFERROR(INDEX('Mein Haus'!$E$45:$E$104,A11),"")<>"",H11<>"",IFERROR(INDEX('Mein Haus'!$E$45:$E$104,A11),"")<>H11),"Mietende in «Mein Haus» weicht ab",IF(D11="Vermieter","Amtliches Formular? Familienwohnung: beide Ehegatten.",IF(D11="Ausserterminlich","Nachmieter zumutbar? Vereinbartes Ende eintragen.",""))))) | AK11: =IF(E11="","",IF(OR(COUNTIF(Einstellungen!$B$5:$B$16,"x")=0,INDEX(Einstellungen!$B$5:$B$16,MONTH(EOMONTH(E11,IF(F11="",3,F11)+0)))="x"),EOMONTH(E11,IF(F11="",3,F11)+0),"")) | AL11: =IF(E11="","",IF(OR(COUNTIF(Einstellungen!$B$5:$B$16,"x")=0,INDEX(Einstellungen!$B$5:$B$16,MONTH(EOMONTH(E11,IF(F11="",3,F11)+1)))="x"),EOMONTH(E11,IF(F11="",3,F11)+1),"")) | AM11: =IF(E11="","",IF(OR(COUNTIF(Einstellungen!$B$5:$B$16,"x")=0,INDEX(Einstellungen!$B$5:$B$16,MONTH(EOMONTH(E11,IF(F11="",3,F11)+2)))="x"),EOMONTH(E11,IF(F11="",3,F11)+2),"")) | AN11: =IF(E11="","",IF(OR(COUNTIF(Einstellungen!$B$5:$B$16,"x")=0,INDEX(Einstellungen!$B$5:$B$16,MONTH(EOMONTH(E11,IF(F11="",3,F11)+3)))="x"),EOMONTH(E11,IF(F11="",3,F11)+3),"")) | AO11: =IF(E11="","",IF(OR(COUNTIF(Einstellungen!$B$5:$B$16,"x")=0,INDEX(Einstellungen!$B$5:$B$16,MONTH(EOMONTH(E11,IF(F11="",3,F11)+4)))="x"),EOMONTH(E11,IF(F11="",3,F11)+4),"")) | AP11: =IF(E11="","",IF(OR(COUNTIF(Einstellungen!$B$5:$B$16,"x")=0,INDEX(Einstellungen!$B$5:$B$16,MONTH(EOMONTH(E11,IF(F11="",3,F11)+5)))="x"),EOMONTH(E11,IF(F11="",3,F11)+5),"")) | AQ11: =IF(E11="","",IF(OR(COUNTIF(Einstellungen!$B$5:$B$16,"x")=0,INDEX(Einstellungen!$B$5:$B$16,MONTH(EOMONTH(E11,IF(F11="",3,F11)+6)))="x"),EOMONTH(E11,IF(F11="",3,F11)+6),"")) | AR11: =IF(E11="","",IF(OR(COUNTIF(Einstellungen!$B$5:$B$16,"x")=0,INDEX(Einstellungen!$B$5:$B$16,MONTH(EOMONTH(E11,IF(F11="",3,F11)+7)))="x"),EOMONTH(E11,IF(F11="",3,F11)+7),"")) | AS11: =IF(E11="","",IF(OR(COUNTIF(Einstellungen!$B$5:$B$16,"x")=0,INDEX(Einstellungen!$B$5:$B$16,MONTH(EOMONTH(E11,IF(F11="",3,F11)+8)))="x"),EOMONTH(E11,IF(F11="",3,F11)+8),"")) | AT11: =IF(E11="","",IF(OR(COUNTIF(Einstellungen!$B$5:$B$16,"x")=0,INDEX(Einstellungen!$B$5:$B$16,MONTH(EOMONTH(E11,IF(F11="",3,F11)+9)))="x"),EOMONTH(E11,IF(F11="",3,F11)+9),"")) | AU11: =IF(E11="","",IF(OR(COUNTIF(Einstellungen!$B$5:$B$16,"x")=0,INDEX(Einstellungen!$B$5:$B$16,MONTH(EOMONTH(E11,IF(F11="",3,F11)+10)))="x"),EOMONTH(E11,IF(F11="",3,F11)+10),"")) | AV11: =IF(E11="","",IF(OR(COUNTIF(Einstellungen!$B$5:$B$16,"x")=0,INDEX(Einstellungen!$B$5:$B$16,MONTH(EOMONTH(E11,IF(F11="",3,F11)+11)))="x"),EOMONTH(E11,IF(F11="",3,F11)+11),"")) | AW11: =IF(E11="","",IF(OR(COUNTIF(Einstellungen!$B$5:$B$16,"x")=0,INDEX(Einstellungen!$B$5:$B$16,MONTH(EOMONTH(E11,IF(F11="",3,F11)+12)))="x"),EOMONTH(E11,IF(F11="",3,F11)+12),"")) | AX11: =IF(E11="","",IF(OR(COUNTIF(Einstellungen!$B$5:$B$16,"x")=0,INDEX(Einstellungen!$B$5:$B$16,MONTH(EOMONTH(E11,IF(F11="",3,F11)+13)))="x"),EOMONTH(E11,IF(F11="",3,F11)+13),"")) | AY11: =IF(E11="","",IF(OR(COUNTIF(Einstellungen!$B$5:$B$16,"x")=0,INDEX(Einstellungen!$B$5:$B$16,MONTH(EOMONTH(E11,IF(F11="",3,F11)+14)))="x"),EOMONTH(E11,IF(F11="",3,F11)+14),"")) | AZ11: =IF(E11="","",IF(OR(COUNTIF(Einstellungen!$B$5:$B$16,"x")=0,INDEX(Einstellungen!$B$5:$B$16,MONTH(EOMONTH(E11,IF(F11="",3,F11)+15)))="x"),EOMONTH(E11,IF(F11="",3,F11)+15),"")) | BA11: =IF(E11="","",IF(OR(COUNTIF(Einstellungen!$B$5:$B$16,"x")=0,INDEX(Einstellungen!$B$5:$B$16,MONTH(EOMONTH(E11,IF(F11="",3,F11)+16)))="x"),EOMONTH(E11,IF(F11="",3,F11)+16),"")) | BB11: =IF(E11="","",IF(OR(COUNTIF(Einstellungen!$B$5:$B$16,"x")=0,INDEX(Einstellungen!$B$5:$B$16,MONTH(EOMONTH(E11,IF(F11="",3,F11)+17)))="x"),EOMONTH(E11,IF(F11="",3,F11)+17),"")) | BC11: =IF(E11="","",IF(OR(COUNTIF(Einstellungen!$B$5:$B$16,"x")=0,INDEX(Einstellungen!$B$5:$B$16,MONTH(EOMONTH(E11,IF(F11="",3,F11)+18)))="x"),EOMONTH(E11,IF(F11="",3,F11)+18),"")) | BD11: =IF(E11="","",IF(OR(COUNTIF(Einstellungen!$B$5:$B$16,"x")=0,INDEX(Einstellungen!$B$5:$B$16,MONTH(EOMONTH(E11,IF(F11="",3,F11)+19)))="x"),EOMONTH(E11,IF(F11="",3,F11)+19),"")) | BE11: =IF(E11="","",IF(OR(COUNTIF(Einstellungen!$B$5:$B$16,"x")=0,INDEX(Einstellungen!$B$5:$B$16,MONTH(EOMONTH(E11,IF(F11="",3,F11)+20)))="x"),EOMONTH(E11,IF(F11="",3,F11)+20),"")) | BF11: =IF(E11="","",IF(OR(COUNTIF(Einstellungen!$B$5:$B$16,"x")=0,INDEX(Einstellungen!$B$5:$B$16,MONTH(EOMONTH(E11,IF(F11="",3,F11)+21)))="x"),EOMONTH(E11,IF(F11="",3,F11)+21),"")) | BG11: =IF(E11="","",IF(OR(COUNTIF(Einstellungen!$B$5:$B$16,"x")=0,INDEX(Einstellungen!$B$5:$B$16,MONTH(EOMONTH(E11,IF(F11="",3,F11)+22)))="x"),EOMONTH(E11,IF(F11="",3,F11)+22),"")) | BH11: =IF(E11="","",IF(OR(COUNTIF(Einstellungen!$B$5:$B$16,"x")=0,INDEX(Einstellungen!$B$5:$B$16,MONTH(EOMONTH(E11,IF(F11="",3,F11)+23)))="x"),EOMONTH(E11,IF(F11="",3,F11)+23),"")) | BI11: =IF(AND(L11<>"",M11=""),L11,"") | BJ11: =IF(AND(N11<>"",O11=""),N11,"") | BK11: =IF(AND(P11<>"",Q11=""),P11,"") | BL11: =IF(AND(R11<>"",S11=""),R11,"") | BM11: =IF(AND(T11<>"",U11=""),T11,"") | BN11: =IF(AND(V11<>"",W11=""),V11,"") | BO11: =IF(AND(X11<>"",Y11=""),X11,"") | BP11: =IF(AND(Z11<>"",AA11=""),Z11,"") | BQ11: =IF(AND(AB11<>"",AC11=""),AB11,"") | BR11: =IF(AND(AD11<>"",AE11=""),AD11,"") | BS11: =IF(AF11="","",AF11+ROW()/100000)
B12: =IF(A12="","",IFERROR(INDEX('Mein Haus'!$C$45:$C$104,A12)&"","")) | C12: =IF(A12="","",IFERROR(INDEX('Mein Haus'!$B$45:$B$104,A12)&"","")) | H12: =IF(G12<>"",G12,IF(E12="","",IF(COUNT(AK12:BH12)=0,"",MIN(AK12:BH12)))) | J12: =IF(OR(H12="",I12=""),"",MAX(0,I12-H12-1)) | K12: =IF(J12="","",ROUND(N(IFERROR(INDEX('Mein Haus'!$G$45:$G$104,A12),0))*12/365*J12,2)) | L12: =IF(E12="","",E12+7) | N12: =IF(E12="","",E12) | P12: =IF(H12="","",WORKDAY(H12,-10,Einstellungen!$D$5:$D$34)) | R12: =IF(H12="","",H12-30) | T12: =IF(H12="","",WORKDAY(H12-1,1,Einstellungen!$D$5:$D$34)) | V12: =IF(T12="","",WORKDAY(T12,2,Einstellungen!$D$5:$D$34)) | X12: =IF(I12="","",I12) | Z12: =IF(T12="","",T12+30) | AB12: =IF(OR(H12="",Nebenkosten!$B$7=""),"",EDATE(Nebenkosten!$B$7,12*MAX(1,ROUNDUP(((YEAR(H12)-YEAR(Nebenkosten!$B$7))*12+MONTH(H12)-MONTH(Nebenkosten!$B$7)+1)/12,0)))) | AD12: =IF(H12="","",EDATE(H12,12)) | AF12: =IF(COUNT(BI12:BR12)=0,"",MIN(BI12:BR12)) | AG12: =IF(AF12="","",AF12-TODAY()) | AH12: =IF(AF12="","",INDEX($BI$7:$BR$7,MATCH(AF12,BI12:BR12,0))) | AI12: =IF(A12="","",IF(B12="","ID ohne Mieter in «Mein Haus»",IF(AND(IFERROR(INDEX('Mein Haus'!$E$45:$E$104,A12),"")<>"",H12<>"",IFERROR(INDEX('Mein Haus'!$E$45:$E$104,A12),"")<>H12),"Mietende in «Mein Haus» weicht ab",IF(D12="Vermieter","Amtliches Formular? Familienwohnung: beide Ehegatten.",IF(D12="Ausserterminlich","Nachmieter zumutbar? Vereinbartes Ende eintragen.",""))))) | AK12: =IF(E12="","",IF(OR(COUNTIF(Einstellungen!$B$5:$B$16,"x")=0,INDEX(Einstellungen!$B$5:$B$16,MONTH(EOMONTH(E12,IF(F12="",3,F12)+0)))="x"),EOMONTH(E12,IF(F12="",3,F12)+0),"")) | AL12: =IF(E12="","",IF(OR(COUNTIF(Einstellungen!$B$5:$B$16,"x")=0,INDEX(Einstellungen!$B$5:$B$16,MONTH(EOMONTH(E12,IF(F12="",3,F12)+1)))="x"),EOMONTH(E12,IF(F12="",3,F12)+1),"")) | AM12: =IF(E12="","",IF(OR(COUNTIF(Einstellungen!$B$5:$B$16,"x")=0,INDEX(Einstellungen!$B$5:$B$16,MONTH(EOMONTH(E12,IF(F12="",3,F12)+2)))="x"),EOMONTH(E12,IF(F12="",3,F12)+2),"")) | AN12: =IF(E12="","",IF(OR(COUNTIF(Einstellungen!$B$5:$B$16,"x")=0,INDEX(Einstellungen!$B$5:$B$16,MONTH(EOMONTH(E12,IF(F12="",3,F12)+3)))="x"),EOMONTH(E12,IF(F12="",3,F12)+3),"")) | AO12: =IF(E12="","",IF(OR(COUNTIF(Einstellungen!$B$5:$B$16,"x")=0,INDEX(Einstellungen!$B$5:$B$16,MONTH(EOMONTH(E12,IF(F12="",3,F12)+4)))="x"),EOMONTH(E12,IF(F12="",3,F12)+4),"")) | AP12: =IF(E12="","",IF(OR(COUNTIF(Einstellungen!$B$5:$B$16,"x")=0,INDEX(Einstellungen!$B$5:$B$16,MONTH(EOMONTH(E12,IF(F12="",3,F12)+5)))="x"),EOMONTH(E12,IF(F12="",3,F12)+5),"")) | AQ12: =IF(E12="","",IF(OR(COUNTIF(Einstellungen!$B$5:$B$16,"x")=0,INDEX(Einstellungen!$B$5:$B$16,MONTH(EOMONTH(E12,IF(F12="",3,F12)+6)))="x"),EOMONTH(E12,IF(F12="",3,F12)+6),"")) | AR12: =IF(E12="","",IF(OR(COUNTIF(Einstellungen!$B$5:$B$16,"x")=0,INDEX(Einstellungen!$B$5:$B$16,MONTH(EOMONTH(E12,IF(F12="",3,F12)+7)))="x"),EOMONTH(E12,IF(F12="",3,F12)+7),"")) | AS12: =IF(E12="","",IF(OR(COUNTIF(Einstellungen!$B$5:$B$16,"x")=0,INDEX(Einstellungen!$B$5:$B$16,MONTH(EOMONTH(E12,IF(F12="",3,F12)+8)))="x"),EOMONTH(E12,IF(F12="",3,F12)+8),"")) | AT12: =IF(E12="","",IF(OR(COUNTIF(Einstellungen!$B$5:$B$16,"x")=0,INDEX(Einstellungen!$B$5:$B$16,MONTH(EOMONTH(E12,IF(F12="",3,F12)+9)))="x"),EOMONTH(E12,IF(F12="",3,F12)+9),"")) | AU12: =IF(E12="","",IF(OR(COUNTIF(Einstellungen!$B$5:$B$16,"x")=0,INDEX(Einstellungen!$B$5:$B$16,MONTH(EOMONTH(E12,IF(F12="",3,F12)+10)))="x"),EOMONTH(E12,IF(F12="",3,F12)+10),"")) | AV12: =IF(E12="","",IF(OR(COUNTIF(Einstellungen!$B$5:$B$16,"x")=0,INDEX(Einstellungen!$B$5:$B$16,MONTH(EOMONTH(E12,IF(F12="",3,F12)+11)))="x"),EOMONTH(E12,IF(F12="",3,F12)+11),"")) | AW12: =IF(E12="","",IF(OR(COUNTIF(Einstellungen!$B$5:$B$16,"x")=0,INDEX(Einstellungen!$B$5:$B$16,MONTH(EOMONTH(E12,IF(F12="",3,F12)+12)))="x"),EOMONTH(E12,IF(F12="",3,F12)+12),"")) | AX12: =IF(E12="","",IF(OR(COUNTIF(Einstellungen!$B$5:$B$16,"x")=0,INDEX(Einstellungen!$B$5:$B$16,MONTH(EOMONTH(E12,IF(F12="",3,F12)+13)))="x"),EOMONTH(E12,IF(F12="",3,F12)+13),"")) | AY12: =IF(E12="","",IF(OR(COUNTIF(Einstellungen!$B$5:$B$16,"x")=0,INDEX(Einstellungen!$B$5:$B$16,MONTH(EOMONTH(E12,IF(F12="",3,F12)+14)))="x"),EOMONTH(E12,IF(F12="",3,F12)+14),"")) | AZ12: =IF(E12="","",IF(OR(COUNTIF(Einstellungen!$B$5:$B$16,"x")=0,INDEX(Einstellungen!$B$5:$B$16,MONTH(EOMONTH(E12,IF(F12="",3,F12)+15)))="x"),EOMONTH(E12,IF(F12="",3,F12)+15),"")) | BA12: =IF(E12="","",IF(OR(COUNTIF(Einstellungen!$B$5:$B$16,"x")=0,INDEX(Einstellungen!$B$5:$B$16,MONTH(EOMONTH(E12,IF(F12="",3,F12)+16)))="x"),EOMONTH(E12,IF(F12="",3,F12)+16),"")) | BB12: =IF(E12="","",IF(OR(COUNTIF(Einstellungen!$B$5:$B$16,"x")=0,INDEX(Einstellungen!$B$5:$B$16,MONTH(EOMONTH(E12,IF(F12="",3,F12)+17)))="x"),EOMONTH(E12,IF(F12="",3,F12)+17),"")) | BC12: =IF(E12="","",IF(OR(COUNTIF(Einstellungen!$B$5:$B$16,"x")=0,INDEX(Einstellungen!$B$5:$B$16,MONTH(EOMONTH(E12,IF(F12="",3,F12)+18)))="x"),EOMONTH(E12,IF(F12="",3,F12)+18),"")) | BD12: =IF(E12="","",IF(OR(COUNTIF(Einstellungen!$B$5:$B$16,"x")=0,INDEX(Einstellungen!$B$5:$B$16,MONTH(EOMONTH(E12,IF(F12="",3,F12)+19)))="x"),EOMONTH(E12,IF(F12="",3,F12)+19),"")) | BE12: =IF(E12="","",IF(OR(COUNTIF(Einstellungen!$B$5:$B$16,"x")=0,INDEX(Einstellungen!$B$5:$B$16,MONTH(EOMONTH(E12,IF(F12="",3,F12)+20)))="x"),EOMONTH(E12,IF(F12="",3,F12)+20),"")) | BF12: =IF(E12="","",IF(OR(COUNTIF(Einstellungen!$B$5:$B$16,"x")=0,INDEX(Einstellungen!$B$5:$B$16,MONTH(EOMONTH(E12,IF(F12="",3,F12)+21)))="x"),EOMONTH(E12,IF(F12="",3,F12)+21),"")) | BG12: =IF(E12="","",IF(OR(COUNTIF(Einstellungen!$B$5:$B$16,"x")=0,INDEX(Einstellungen!$B$5:$B$16,MONTH(EOMONTH(E12,IF(F12="",3,F12)+22)))="x"),EOMONTH(E12,IF(F12="",3,F12)+22),"")) | BH12: =IF(E12="","",IF(OR(COUNTIF(Einstellungen!$B$5:$B$16,"x")=0,INDEX(Einstellungen!$B$5:$B$16,MONTH(EOMONTH(E12,IF(F12="",3,F12)+23)))="x"),EOMONTH(E12,IF(F12="",3,F12)+23),"")) | BI12: =IF(AND(L12<>"",M12=""),L12,"") | BJ12: =IF(AND(N12<>"",O12=""),N12,"") | BK12: =IF(AND(P12<>"",Q12=""),P12,"") | BL12: =IF(AND(R12<>"",S12=""),R12,"") | BM12: =IF(AND(T12<>"",U12=""),T12,"") | BN12: =IF(AND(V12<>"",W12=""),V12,"") | BO12: =IF(AND(X12<>"",Y12=""),X12,"") | BP12: =IF(AND(Z12<>"",AA12=""),Z12,"") | BQ12: =IF(AND(AB12<>"",AC12=""),AB12,"") | BR12: =IF(AND(AD12<>"",AE12=""),AD12,"") | BS12: =IF(AF12="","",AF12+ROW()/100000)
B13: =IF(A13="","",IFERROR(INDEX('Mein Haus'!$C$45:$C$104,A13)&"","")) | C13: =IF(A13="","",IFERROR(INDEX('Mein Haus'!$B$45:$B$104,A13)&"","")) | H13: =IF(G13<>"",G13,IF(E13="","",IF(COUNT(AK13:BH13)=0,"",MIN(AK13:BH13)))) | J13: =IF(OR(H13="",I13=""),"",MAX(0,I13-H13-1)) | K13: =IF(J13="","",ROUND(N(IFERROR(INDEX('Mein Haus'!$G$45:$G$104,A13),0))*12/365*J13,2)) | L13: =IF(E13="","",E13+7) | N13: =IF(E13="","",E13) | P13: =IF(H13="","",WORKDAY(H13,-10,Einstellungen!$D$5:$D$34)) | R13: =IF(H13="","",H13-30) | T13: =IF(H13="","",WORKDAY(H13-1,1,Einstellungen!$D$5:$D$34)) | V13: =IF(T13="","",WORKDAY(T13,2,Einstellungen!$D$5:$D$34)) | X13: =IF(I13="","",I13) | Z13: =IF(T13="","",T13+30) | AB13: =IF(OR(H13="",Nebenkosten!$B$7=""),"",EDATE(Nebenkosten!$B$7,12*MAX(1,ROUNDUP(((YEAR(H13)-YEAR(Nebenkosten!$B$7))*12+MONTH(H13)-MONTH(Nebenkosten!$B$7)+1)/12,0)))) | AD13: =IF(H13="","",EDATE(H13,12)) | AF13: =IF(COUNT(BI13:BR13)=0,"",MIN(BI13:BR13)) | AG13: =IF(AF13="","",AF13-TODAY()) | AH13: =IF(AF13="","",INDEX($BI$7:$BR$7,MATCH(AF13,BI13:BR13,0))) | AI13: =IF(A13="","",IF(B13="","ID ohne Mieter in «Mein Haus»",IF(AND(IFERROR(INDEX('Mein Haus'!$E$45:$E$104,A13),"")<>"",H13<>"",IFERROR(INDEX('Mein Haus'!$E$45:$E$104,A13),"")<>H13),"Mietende in «Mein Haus» weicht ab",IF(D13="Vermieter","Amtliches Formular? Familienwohnung: beide Ehegatten.",IF(D13="Ausserterminlich","Nachmieter zumutbar? Vereinbartes Ende eintragen.",""))))) | AK13: =IF(E13="","",IF(OR(COUNTIF(Einstellungen!$B$5:$B$16,"x")=0,INDEX(Einstellungen!$B$5:$B$16,MONTH(EOMONTH(E13,IF(F13="",3,F13)+0)))="x"),EOMONTH(E13,IF(F13="",3,F13)+0),"")) | AL13: =IF(E13="","",IF(OR(COUNTIF(Einstellungen!$B$5:$B$16,"x")=0,INDEX(Einstellungen!$B$5:$B$16,MONTH(EOMONTH(E13,IF(F13="",3,F13)+1)))="x"),EOMONTH(E13,IF(F13="",3,F13)+1),"")) | AM13: =IF(E13="","",IF(OR(COUNTIF(Einstellungen!$B$5:$B$16,"x")=0,INDEX(Einstellungen!$B$5:$B$16,MONTH(EOMONTH(E13,IF(F13="",3,F13)+2)))="x"),EOMONTH(E13,IF(F13="",3,F13)+2),"")) | AN13: =IF(E13="","",IF(OR(COUNTIF(Einstellungen!$B$5:$B$16,"x")=0,INDEX(Einstellungen!$B$5:$B$16,MONTH(EOMONTH(E13,IF(F13="",3,F13)+3)))="x"),EOMONTH(E13,IF(F13="",3,F13)+3),"")) | AO13: =IF(E13="","",IF(OR(COUNTIF(Einstellungen!$B$5:$B$16,"x")=0,INDEX(Einstellungen!$B$5:$B$16,MONTH(EOMONTH(E13,IF(F13="",3,F13)+4)))="x"),EOMONTH(E13,IF(F13="",3,F13)+4),"")) | AP13: =IF(E13="","",IF(OR(COUNTIF(Einstellungen!$B$5:$B$16,"x")=0,INDEX(Einstellungen!$B$5:$B$16,MONTH(EOMONTH(E13,IF(F13="",3,F13)+5)))="x"),EOMONTH(E13,IF(F13="",3,F13)+5),"")) | AQ13: =IF(E13="","",IF(OR(COUNTIF(Einstellungen!$B$5:$B$16,"x")=0,INDEX(Einstellungen!$B$5:$B$16,MONTH(EOMONTH(E13,IF(F13="",3,F13)+6)))="x"),EOMONTH(E13,IF(F13="",3,F13)+6),"")) | AR13: =IF(E13="","",IF(OR(COUNTIF(Einstellungen!$B$5:$B$16,"x")=0,INDEX(Einstellungen!$B$5:$B$16,MONTH(EOMONTH(E13,IF(F13="",3,F13)+7)))="x"),EOMONTH(E13,IF(F13="",3,F13)+7),"")) | AS13: =IF(E13="","",IF(OR(COUNTIF(Einstellungen!$B$5:$B$16,"x")=0,INDEX(Einstellungen!$B$5:$B$16,MONTH(EOMONTH(E13,IF(F13="",3,F13)+8)))="x"),EOMONTH(E13,IF(F13="",3,F13)+8),"")) | AT13: =IF(E13="","",IF(OR(COUNTIF(Einstellungen!$B$5:$B$16,"x")=0,INDEX(Einstellungen!$B$5:$B$16,MONTH(EOMONTH(E13,IF(F13="",3,F13)+9)))="x"),EOMONTH(E13,IF(F13="",3,F13)+9),"")) | AU13: =IF(E13="","",IF(OR(COUNTIF(Einstellungen!$B$5:$B$16,"x")=0,INDEX(Einstellungen!$B$5:$B$16,MONTH(EOMONTH(E13,IF(F13="",3,F13)+10)))="x"),EOMONTH(E13,IF(F13="",3,F13)+10),"")) | AV13: =IF(E13="","",IF(OR(COUNTIF(Einstellungen!$B$5:$B$16,"x")=0,INDEX(Einstellungen!$B$5:$B$16,MONTH(EOMONTH(E13,IF(F13="",3,F13)+11)))="x"),EOMONTH(E13,IF(F13="",3,F13)+11),"")) | AW13: =IF(E13="","",IF(OR(COUNTIF(Einstellungen!$B$5:$B$16,"x")=0,INDEX(Einstellungen!$B$5:$B$16,MONTH(EOMONTH(E13,IF(F13="",3,F13)+12)))="x"),EOMONTH(E13,IF(F13="",3,F13)+12),"")) | AX13: =IF(E13="","",IF(OR(COUNTIF(Einstellungen!$B$5:$B$16,"x")=0,INDEX(Einstellungen!$B$5:$B$16,MONTH(EOMONTH(E13,IF(F13="",3,F13)+13)))="x"),EOMONTH(E13,IF(F13="",3,F13)+13),"")) | AY13: =IF(E13="","",IF(OR(COUNTIF(Einstellungen!$B$5:$B$16,"x")=0,INDEX(Einstellungen!$B$5:$B$16,MONTH(EOMONTH(E13,IF(F13="",3,F13)+14)))="x"),EOMONTH(E13,IF(F13="",3,F13)+14),"")) | AZ13: =IF(E13="","",IF(OR(COUNTIF(Einstellungen!$B$5:$B$16,"x")=0,INDEX(Einstellungen!$B$5:$B$16,MONTH(EOMONTH(E13,IF(F13="",3,F13)+15)))="x"),EOMONTH(E13,IF(F13="",3,F13)+15),"")) | BA13: =IF(E13="","",IF(OR(COUNTIF(Einstellungen!$B$5:$B$16,"x")=0,INDEX(Einstellungen!$B$5:$B$16,MONTH(EOMONTH(E13,IF(F13="",3,F13)+16)))="x"),EOMONTH(E13,IF(F13="",3,F13)+16),"")) | BB13: =IF(E13="","",IF(OR(COUNTIF(Einstellungen!$B$5:$B$16,"x")=0,INDEX(Einstellungen!$B$5:$B$16,MONTH(EOMONTH(E13,IF(F13="",3,F13)+17)))="x"),EOMONTH(E13,IF(F13="",3,F13)+17),"")) | BC13: =IF(E13="","",IF(OR(COUNTIF(Einstellungen!$B$5:$B$16,"x")=0,INDEX(Einstellungen!$B$5:$B$16,MONTH(EOMONTH(E13,IF(F13="",3,F13)+18)))="x"),EOMONTH(E13,IF(F13="",3,F13)+18),"")) | BD13: =IF(E13="","",IF(OR(COUNTIF(Einstellungen!$B$5:$B$16,"x")=0,INDEX(Einstellungen!$B$5:$B$16,MONTH(EOMONTH(E13,IF(F13="",3,F13)+19)))="x"),EOMONTH(E13,IF(F13="",3,F13)+19),"")) | BE13: =IF(E13="","",IF(OR(COUNTIF(Einstellungen!$B$5:$B$16,"x")=0,INDEX(Einstellungen!$B$5:$B$16,MONTH(EOMONTH(E13,IF(F13="",3,F13)+20)))="x"),EOMONTH(E13,IF(F13="",3,F13)+20),"")) | BF13: =IF(E13="","",IF(OR(COUNTIF(Einstellungen!$B$5:$B$16,"x")=0,INDEX(Einstellungen!$B$5:$B$16,MONTH(EOMONTH(E13,IF(F13="",3,F13)+21)))="x"),EOMONTH(E13,IF(F13="",3,F13)+21),"")) | BG13: =IF(E13="","",IF(OR(COUNTIF(Einstellungen!$B$5:$B$16,"x")=0,INDEX(Einstellungen!$B$5:$B$16,MONTH(EOMONTH(E13,IF(F13="",3,F13)+22)))="x"),EOMONTH(E13,IF(F13="",3,F13)+22),"")) | BH13: =IF(E13="","",IF(OR(COUNTIF(Einstellungen!$B$5:$B$16,"x")=0,INDEX(Einstellungen!$B$5:$B$16,MONTH(EOMONTH(E13,IF(F13="",3,F13)+23)))="x"),EOMONTH(E13,IF(F13="",3,F13)+23),"")) | BI13: =IF(AND(L13<>"",M13=""),L13,"") | BJ13: =IF(AND(N13<>"",O13=""),N13,"") | BK13: =IF(AND(P13<>"",Q13=""),P13,"") | BL13: =IF(AND(R13<>"",S13=""),R13,"") | BM13: =IF(AND(T13<>"",U13=""),T13,"") | BN13: =IF(AND(V13<>"",W13=""),V13,"") | BO13: =IF(AND(X13<>"",Y13=""),X13,"") | BP13: =IF(AND(Z13<>"",AA13=""),Z13,"") | BQ13: =IF(AND(AB13<>"",AC13=""),AB13,"") | BR13: =IF(AND(AD13<>"",AE13=""),AD13,"") | BS13: =IF(AF13="","",AF13+ROW()/100000)
B14: =IF(A14="","",IFERROR(INDEX('Mein Haus'!$C$45:$C$104,A14)&"","")) | C14: =IF(A14="","",IFERROR(INDEX('Mein Haus'!$B$45:$B$104,A14)&"","")) | H14: =IF(G14<>"",G14,IF(E14="","",IF(COUNT(AK14:BH14)=0,"",MIN(AK14:BH14)))) | J14: =IF(OR(H14="",I14=""),"",MAX(0,I14-H14-1)) | K14: =IF(J14="","",ROUND(N(IFERROR(INDEX('Mein Haus'!$G$45:$G$104,A14),0))*12/365*J14,2)) | L14: =IF(E14="","",E14+7) | N14: =IF(E14="","",E14) | P14: =IF(H14="","",WORKDAY(H14,-10,Einstellungen!$D$5:$D$34)) | R14: =IF(H14="","",H14-30) | T14: =IF(H14="","",WORKDAY(H14-1,1,Einstellungen!$D$5:$D$34)) | V14: =IF(T14="","",WORKDAY(T14,2,Einstellungen!$D$5:$D$34)) | X14: =IF(I14="","",I14) | Z14: =IF(T14="","",T14+30) | AB14: =IF(OR(H14="",Nebenkosten!$B$7=""),"",EDATE(Nebenkosten!$B$7,12*MAX(1,ROUNDUP(((YEAR(H14)-YEAR(Nebenkosten!$B$7))*12+MONTH(H14)-MONTH(Nebenkosten!$B$7)+1)/12,0)))) | AD14: =IF(H14="","",EDATE(H14,12)) | AF14: =IF(COUNT(BI14:BR14)=0,"",MIN(BI14:BR14)) | AG14: =IF(AF14="","",AF14-TODAY()) | AH14: =IF(AF14="","",INDEX($BI$7:$BR$7,MATCH(AF14,BI14:BR14,0))) | AI14: =IF(A14="","",IF(B14="","ID ohne Mieter in «Mein Haus»",IF(AND(IFERROR(INDEX('Mein Haus'!$E$45:$E$104,A14),"")<>"",H14<>"",IFERROR(INDEX('Mein Haus'!$E$45:$E$104,A14),"")<>H14),"Mietende in «Mein Haus» weicht ab",IF(D14="Vermieter","Amtliches Formular? Familienwohnung: beide Ehegatten.",IF(D14="Ausserterminlich","Nachmieter zumutbar? Vereinbartes Ende eintragen.",""))))) | AK14: =IF(E14="","",IF(OR(COUNTIF(Einstellungen!$B$5:$B$16,"x")=0,INDEX(Einstellungen!$B$5:$B$16,MONTH(EOMONTH(E14,IF(F14="",3,F14)+0)))="x"),EOMONTH(E14,IF(F14="",3,F14)+0),"")) | AL14: =IF(E14="","",IF(OR(COUNTIF(Einstellungen!$B$5:$B$16,"x")=0,INDEX(Einstellungen!$B$5:$B$16,MONTH(EOMONTH(E14,IF(F14="",3,F14)+1)))="x"),EOMONTH(E14,IF(F14="",3,F14)+1),"")) | AM14: =IF(E14="","",IF(OR(COUNTIF(Einstellungen!$B$5:$B$16,"x")=0,INDEX(Einstellungen!$B$5:$B$16,MONTH(EOMONTH(E14,IF(F14="",3,F14)+2)))="x"),EOMONTH(E14,IF(F14="",3,F14)+2),"")) | AN14: =IF(E14="","",IF(OR(COUNTIF(Einstellungen!$B$5:$B$16,"x")=0,INDEX(Einstellungen!$B$5:$B$16,MONTH(EOMONTH(E14,IF(F14="",3,F14)+3)))="x"),EOMONTH(E14,IF(F14="",3,F14)+3),"")) | AO14: =IF(E14="","",IF(OR(COUNTIF(Einstellungen!$B$5:$B$16,"x")=0,INDEX(Einstellungen!$B$5:$B$16,MONTH(EOMONTH(E14,IF(F14="",3,F14)+4)))="x"),EOMONTH(E14,IF(F14="",3,F14)+4),"")) | AP14: =IF(E14="","",IF(OR(COUNTIF(Einstellungen!$B$5:$B$16,"x")=0,INDEX(Einstellungen!$B$5:$B$16,MONTH(EOMONTH(E14,IF(F14="",3,F14)+5)))="x"),EOMONTH(E14,IF(F14="",3,F14)+5),"")) | AQ14: =IF(E14="","",IF(OR(COUNTIF(Einstellungen!$B$5:$B$16,"x")=0,INDEX(Einstellungen!$B$5:$B$16,MONTH(EOMONTH(E14,IF(F14="",3,F14)+6)))="x"),EOMONTH(E14,IF(F14="",3,F14)+6),"")) | AR14: =IF(E14="","",IF(OR(COUNTIF(Einstellungen!$B$5:$B$16,"x")=0,INDEX(Einstellungen!$B$5:$B$16,MONTH(EOMONTH(E14,IF(F14="",3,F14)+7)))="x"),EOMONTH(E14,IF(F14="",3,F14)+7),"")) | AS14: =IF(E14="","",IF(OR(COUNTIF(Einstellungen!$B$5:$B$16,"x")=0,INDEX(Einstellungen!$B$5:$B$16,MONTH(EOMONTH(E14,IF(F14="",3,F14)+8)))="x"),EOMONTH(E14,IF(F14="",3,F14)+8),"")) | AT14: =IF(E14="","",IF(OR(COUNTIF(Einstellungen!$B$5:$B$16,"x")=0,INDEX(Einstellungen!$B$5:$B$16,MONTH(EOMONTH(E14,IF(F14="",3,F14)+9)))="x"),EOMONTH(E14,IF(F14="",3,F14)+9),"")) | AU14: =IF(E14="","",IF(OR(COUNTIF(Einstellungen!$B$5:$B$16,"x")=0,INDEX(Einstellungen!$B$5:$B$16,MONTH(EOMONTH(E14,IF(F14="",3,F14)+10)))="x"),EOMONTH(E14,IF(F14="",3,F14)+10),"")) | AV14: =IF(E14="","",IF(OR(COUNTIF(Einstellungen!$B$5:$B$16,"x")=0,INDEX(Einstellungen!$B$5:$B$16,MONTH(EOMONTH(E14,IF(F14="",3,F14)+11)))="x"),EOMONTH(E14,IF(F14="",3,F14)+11),"")) | AW14: =IF(E14="","",IF(OR(COUNTIF(Einstellungen!$B$5:$B$16,"x")=0,INDEX(Einstellungen!$B$5:$B$16,MONTH(EOMONTH(E14,IF(F14="",3,F14)+12)))="x"),EOMONTH(E14,IF(F14="",3,F14)+12),"")) | AX14: =IF(E14="","",IF(OR(COUNTIF(Einstellungen!$B$5:$B$16,"x")=0,INDEX(Einstellungen!$B$5:$B$16,MONTH(EOMONTH(E14,IF(F14="",3,F14)+13)))="x"),EOMONTH(E14,IF(F14="",3,F14)+13),"")) | AY14: =IF(E14="","",IF(OR(COUNTIF(Einstellungen!$B$5:$B$16,"x")=0,INDEX(Einstellungen!$B$5:$B$16,MONTH(EOMONTH(E14,IF(F14="",3,F14)+14)))="x"),EOMONTH(E14,IF(F14="",3,F14)+14),"")) | AZ14: =IF(E14="","",IF(OR(COUNTIF(Einstellungen!$B$5:$B$16,"x")=0,INDEX(Einstellungen!$B$5:$B$16,MONTH(EOMONTH(E14,IF(F14="",3,F14)+15)))="x"),EOMONTH(E14,IF(F14="",3,F14)+15),"")) | BA14: =IF(E14="","",IF(OR(COUNTIF(Einstellungen!$B$5:$B$16,"x")=0,INDEX(Einstellungen!$B$5:$B$16,MONTH(EOMONTH(E14,IF(F14="",3,F14)+16)))="x"),EOMONTH(E14,IF(F14="",3,F14)+16),"")) | BB14: =IF(E14="","",IF(OR(COUNTIF(Einstellungen!$B$5:$B$16,"x")=0,INDEX(Einstellungen!$B$5:$B$16,MONTH(EOMONTH(E14,IF(F14="",3,F14)+17)))="x"),EOMONTH(E14,IF(F14="",3,F14)+17),"")) | BC14: =IF(E14="","",IF(OR(COUNTIF(Einstellungen!$B$5:$B$16,"x")=0,INDEX(Einstellungen!$B$5:$B$16,MONTH(EOMONTH(E14,IF(F14="",3,F14)+18)))="x"),EOMONTH(E14,IF(F14="",3,F14)+18),"")) | BD14: =IF(E14="","",IF(OR(COUNTIF(Einstellungen!$B$5:$B$16,"x")=0,INDEX(Einstellungen!$B$5:$B$16,MONTH(EOMONTH(E14,IF(F14="",3,F14)+19)))="x"),EOMONTH(E14,IF(F14="",3,F14)+19),"")) | BE14: =IF(E14="","",IF(OR(COUNTIF(Einstellungen!$B$5:$B$16,"x")=0,INDEX(Einstellungen!$B$5:$B$16,MONTH(EOMONTH(E14,IF(F14="",3,F14)+20)))="x"),EOMONTH(E14,IF(F14="",3,F14)+20),"")) | BF14: =IF(E14="","",IF(OR(COUNTIF(Einstellungen!$B$5:$B$16,"x")=0,INDEX(Einstellungen!$B$5:$B$16,MONTH(EOMONTH(E14,IF(F14="",3,F14)+21)))="x"),EOMONTH(E14,IF(F14="",3,F14)+21),"")) | BG14: =IF(E14="","",IF(OR(COUNTIF(Einstellungen!$B$5:$B$16,"x")=0,INDEX(Einstellungen!$B$5:$B$16,MONTH(EOMONTH(E14,IF(F14="",3,F14)+22)))="x"),EOMONTH(E14,IF(F14="",3,F14)+22),"")) | BH14: =IF(E14="","",IF(OR(COUNTIF(Einstellungen!$B$5:$B$16,"x")=0,INDEX(Einstellungen!$B$5:$B$16,MONTH(EOMONTH(E14,IF(F14="",3,F14)+23)))="x"),EOMONTH(E14,IF(F14="",3,F14)+23),"")) | BI14: =IF(AND(L14<>"",M14=""),L14,"") | BJ14: =IF(AND(N14<>"",O14=""),N14,"") | BK14: =IF(AND(P14<>"",Q14=""),P14,"") | BL14: =IF(AND(R14<>"",S14=""),R14,"") | BM14: =IF(AND(T14<>"",U14=""),T14,"") | BN14: =IF(AND(V14<>"",W14=""),V14,"") | BO14: =IF(AND(X14<>"",Y14=""),X14,"") | BP14: =IF(AND(Z14<>"",AA14=""),Z14,"") | BQ14: =IF(AND(AB14<>"",AC14=""),AB14,"") | BR14: =IF(AND(AD14<>"",AE14=""),AD14,"") | BS14: =IF(AF14="","",AF14+ROW()/100000)
B15: =IF(A15="","",IFERROR(INDEX('Mein Haus'!$C$45:$C$104,A15)&"","")) | C15: =IF(A15="","",IFERROR(INDEX('Mein Haus'!$B$45:$B$104,A15)&"","")) | H15: =IF(G15<>"",G15,IF(E15="","",IF(COUNT(AK15:BH15)=0,"",MIN(AK15:BH15)))) | J15: =IF(OR(H15="",I15=""),"",MAX(0,I15-H15-1)) | K15: =IF(J15="","",ROUND(N(IFERROR(INDEX('Mein Haus'!$G$45:$G$104,A15),0))*12/365*J15,2)) | L15: =IF(E15="","",E15+7) | N15: =IF(E15="","",E15) | P15: =IF(H15="","",WORKDAY(H15,-10,Einstellungen!$D$5:$D$34)) | R15: =IF(H15="","",H15-30) | T15: =IF(H15="","",WORKDAY(H15-1,1,Einstellungen!$D$5:$D$34)) | V15: =IF(T15="","",WORKDAY(T15,2,Einstellungen!$D$5:$D$34)) | X15: =IF(I15="","",I15) | Z15: =IF(T15="","",T15+30) | AB15: =IF(OR(H15="",Nebenkosten!$B$7=""),"",EDATE(Nebenkosten!$B$7,12*MAX(1,ROUNDUP(((YEAR(H15)-YEAR(Nebenkosten!$B$7))*12+MONTH(H15)-MONTH(Nebenkosten!$B$7)+1)/12,0)))) | AD15: =IF(H15="","",EDATE(H15,12)) | AF15: =IF(COUNT(BI15:BR15)=0,"",MIN(BI15:BR15)) | AG15: =IF(AF15="","",AF15-TODAY()) | AH15: =IF(AF15="","",INDEX($BI$7:$BR$7,MATCH(AF15,BI15:BR15,0))) | AI15: =IF(A15="","",IF(B15="","ID ohne Mieter in «Mein Haus»",IF(AND(IFERROR(INDEX('Mein Haus'!$E$45:$E$104,A15),"")<>"",H15<>"",IFERROR(INDEX('Mein Haus'!$E$45:$E$104,A15),"")<>H15),"Mietende in «Mein Haus» weicht ab",IF(D15="Vermieter","Amtliches Formular? Familienwohnung: beide Ehegatten.",IF(D15="Ausserterminlich","Nachmieter zumutbar? Vereinbartes Ende eintragen.",""))))) | AK15: =IF(E15="","",IF(OR(COUNTIF(Einstellungen!$B$5:$B$16,"x")=0,INDEX(Einstellungen!$B$5:$B$16,MONTH(EOMONTH(E15,IF(F15="",3,F15)+0)))="x"),EOMONTH(E15,IF(F15="",3,F15)+0),"")) | AL15: =IF(E15="","",IF(OR(COUNTIF(Einstellungen!$B$5:$B$16,"x")=0,INDEX(Einstellungen!$B$5:$B$16,MONTH(EOMONTH(E15,IF(F15="",3,F15)+1)))="x"),EOMONTH(E15,IF(F15="",3,F15)+1),"")) | AM15: =IF(E15="","",IF(OR(COUNTIF(Einstellungen!$B$5:$B$16,"x")=0,INDEX(Einstellungen!$B$5:$B$16,MONTH(EOMONTH(E15,IF(F15="",3,F15)+2)))="x"),EOMONTH(E15,IF(F15="",3,F15)+2),"")) | AN15: =IF(E15="","",IF(OR(COUNTIF(Einstellungen!$B$5:$B$16,"x")=0,INDEX(Einstellungen!$B$5:$B$16,MONTH(EOMONTH(E15,IF(F15="",3,F15)+3)))="x"),EOMONTH(E15,IF(F15="",3,F15)+3),"")) | AO15: =IF(E15="","",IF(OR(COUNTIF(Einstellungen!$B$5:$B$16,"x")=0,INDEX(Einstellungen!$B$5:$B$16,MONTH(EOMONTH(E15,IF(F15="",3,F15)+4)))="x"),EOMONTH(E15,IF(F15="",3,F15)+4),"")) | AP15: =IF(E15="","",IF(OR(COUNTIF(Einstellungen!$B$5:$B$16,"x")=0,INDEX(Einstellungen!$B$5:$B$16,MONTH(EOMONTH(E15,IF(F15="",3,F15)+5)))="x"),EOMONTH(E15,IF(F15="",3,F15)+5),"")) | AQ15: =IF(E15="","",IF(OR(COUNTIF(Einstellungen!$B$5:$B$16,"x")=0,INDEX(Einstellungen!$B$5:$B$16,MONTH(EOMONTH(E15,IF(F15="",3,F15)+6)))="x"),EOMONTH(E15,IF(F15="",3,F15)+6),"")) | AR15: =IF(E15="","",IF(OR(COUNTIF(Einstellungen!$B$5:$B$16,"x")=0,INDEX(Einstellungen!$B$5:$B$16,MONTH(EOMONTH(E15,IF(F15="",3,F15)+7)))="x"),EOMONTH(E15,IF(F15="",3,F15)+7),"")) | AS15: =IF(E15="","",IF(OR(COUNTIF(Einstellungen!$B$5:$B$16,"x")=0,INDEX(Einstellungen!$B$5:$B$16,MONTH(EOMONTH(E15,IF(F15="",3,F15)+8)))="x"),EOMONTH(E15,IF(F15="",3,F15)+8),"")) | AT15: =IF(E15="","",IF(OR(COUNTIF(Einstellungen!$B$5:$B$16,"x")=0,INDEX(Einstellungen!$B$5:$B$16,MONTH(EOMONTH(E15,IF(F15="",3,F15)+9)))="x"),EOMONTH(E15,IF(F15="",3,F15)+9),"")) | AU15: =IF(E15="","",IF(OR(COUNTIF(Einstellungen!$B$5:$B$16,"x")=0,INDEX(Einstellungen!$B$5:$B$16,MONTH(EOMONTH(E15,IF(F15="",3,F15)+10)))="x"),EOMONTH(E15,IF(F15="",3,F15)+10),"")) | AV15: =IF(E15="","",IF(OR(COUNTIF(Einstellungen!$B$5:$B$16,"x")=0,INDEX(Einstellungen!$B$5:$B$16,MONTH(EOMONTH(E15,IF(F15="",3,F15)+11)))="x"),EOMONTH(E15,IF(F15="",3,F15)+11),"")) | AW15: =IF(E15="","",IF(OR(COUNTIF(Einstellungen!$B$5:$B$16,"x")=0,INDEX(Einstellungen!$B$5:$B$16,MONTH(EOMONTH(E15,IF(F15="",3,F15)+12)))="x"),EOMONTH(E15,IF(F15="",3,F15)+12),"")) | AX15: =IF(E15="","",IF(OR(COUNTIF(Einstellungen!$B$5:$B$16,"x")=0,INDEX(Einstellungen!$B$5:$B$16,MONTH(EOMONTH(E15,IF(F15="",3,F15)+13)))="x"),EOMONTH(E15,IF(F15="",3,F15)+13),"")) | AY15: =IF(E15="","",IF(OR(COUNTIF(Einstellungen!$B$5:$B$16,"x")=0,INDEX(Einstellungen!$B$5:$B$16,MONTH(EOMONTH(E15,IF(F15="",3,F15)+14)))="x"),EOMONTH(E15,IF(F15="",3,F15)+14),"")) | AZ15: =IF(E15="","",IF(OR(COUNTIF(Einstellungen!$B$5:$B$16,"x")=0,INDEX(Einstellungen!$B$5:$B$16,MONTH(EOMONTH(E15,IF(F15="",3,F15)+15)))="x"),EOMONTH(E15,IF(F15="",3,F15)+15),"")) | BA15: =IF(E15="","",IF(OR(COUNTIF(Einstellungen!$B$5:$B$16,"x")=0,INDEX(Einstellungen!$B$5:$B$16,MONTH(EOMONTH(E15,IF(F15="",3,F15)+16)))="x"),EOMONTH(E15,IF(F15="",3,F15)+16),"")) | BB15: =IF(E15="","",IF(OR(COUNTIF(Einstellungen!$B$5:$B$16,"x")=0,INDEX(Einstellungen!$B$5:$B$16,MONTH(EOMONTH(E15,IF(F15="",3,F15)+17)))="x"),EOMONTH(E15,IF(F15="",3,F15)+17),"")) | BC15: =IF(E15="","",IF(OR(COUNTIF(Einstellungen!$B$5:$B$16,"x")=0,INDEX(Einstellungen!$B$5:$B$16,MONTH(EOMONTH(E15,IF(F15="",3,F15)+18)))="x"),EOMONTH(E15,IF(F15="",3,F15)+18),"")) | BD15: =IF(E15="","",IF(OR(COUNTIF(Einstellungen!$B$5:$B$16,"x")=0,INDEX(Einstellungen!$B$5:$B$16,MONTH(EOMONTH(E15,IF(F15="",3,F15)+19)))="x"),EOMONTH(E15,IF(F15="",3,F15)+19),"")) | BE15: =IF(E15="","",IF(OR(COUNTIF(Einstellungen!$B$5:$B$16,"x")=0,INDEX(Einstellungen!$B$5:$B$16,MONTH(EOMONTH(E15,IF(F15="",3,F15)+20)))="x"),EOMONTH(E15,IF(F15="",3,F15)+20),"")) | BF15: =IF(E15="","",IF(OR(COUNTIF(Einstellungen!$B$5:$B$16,"x")=0,INDEX(Einstellungen!$B$5:$B$16,MONTH(EOMONTH(E15,IF(F15="",3,F15)+21)))="x"),EOMONTH(E15,IF(F15="",3,F15)+21),"")) | BG15: =IF(E15="","",IF(OR(COUNTIF(Einstellungen!$B$5:$B$16,"x")=0,INDEX(Einstellungen!$B$5:$B$16,MONTH(EOMONTH(E15,IF(F15="",3,F15)+22)))="x"),EOMONTH(E15,IF(F15="",3,F15)+22),"")) | BH15: =IF(E15="","",IF(OR(COUNTIF(Einstellungen!$B$5:$B$16,"x")=0,INDEX(Einstellungen!$B$5:$B$16,MONTH(EOMONTH(E15,IF(F15="",3,F15)+23)))="x"),EOMONTH(E15,IF(F15="",3,F15)+23),"")) | BI15: =IF(AND(L15<>"",M15=""),L15,"") | BJ15: =IF(AND(N15<>"",O15=""),N15,"") | BK15: =IF(AND(P15<>"",Q15=""),P15,"") | BL15: =IF(AND(R15<>"",S15=""),R15,"") | BM15: =IF(AND(T15<>"",U15=""),T15,"") | BN15: =IF(AND(V15<>"",W15=""),V15,"") | BO15: =IF(AND(X15<>"",Y15=""),X15,"") | BP15: =IF(AND(Z15<>"",AA15=""),Z15,"") | BQ15: =IF(AND(AB15<>"",AC15=""),AB15,"") | BR15: =IF(AND(AD15<>"",AE15=""),AD15,"") | BS15: =IF(AF15="","",AF15+ROW()/100000)
