Workbook

Sheet Anleitung
A1: Nebenkostenabrechnung Schweiz
A2: Vorlage für private Vermieter · ohne Makros · Excel und LibreOffice
A4: So gehen Sie vor
A5: 1. «Stammdaten»: Liegenschaft, Beginn der Abrechnungsperiode (immer der 1. eines Monats) und Ihre Einheiten mit Fläche und Anteil erfassen.
A6: 2. «Kosten»: je Kostenart Betrag, Verteilschlüssel und Verteilungsart wählen. «Heizung» verteilt nach Monatsgewichten (Heizgradtage), «Linear» taggenau.
A7: 3. «Mieter»: alle Mietverhältnisse der Periode erfassen, auch ausgezogene. Leeres Mietende = Mietverhältnis läuft weiter.
A8: 4. «Abrechnung»: rechts oben die Mieter-Nr. wählen und das Blatt drucken oder als PDF speichern. Eine Seite pro Mieter.
A9: 5. «Kontrolle»: zeigt, dass jeder Franken verteilt ist. Leerstand bleibt beim Eigentümer und wird separat ausgewiesen.
A11: Gelbe Felder sind Eingaben. Blaue Felder rechnen automatisch und sind geschützt (Blattschutz ohne Passwort).
A13: Rechtliche Hinweise (Stand der Vorlage, ohne Gewähr)
A14: • Nebenkosten dürfen nur separat verrechnet werden, wenn sie im Mietvertrag einzeln vereinbart sind (Art. 257a OR).
A15: • Der Mieter kann Einsicht in die Belege verlangen (Art. 257b Abs. 2 OR).
... A18: • Diese Vorlage ersetzt keine Rechtsberatung. Bei Streitfällen: Schlichtungsbehörde Ihres Kantons oder Verband (HEV / SVIT).

Sheet Stammdaten
A1: Stammdaten
D3: Heizung: Monatsgewichte (Promille)
A4: Liegenschaft | D4: Monat | E4: Gewicht ‰
A5: Vermieter / Verwaltung | D5: Januar | E5: 170
A6: Beginn Abrechnungsperiode | D6: Februar | E6: 150
A7: Ende Abrechnungsperiode | B7: =IF(B6="","",EDATE(B6,12)-1) | D7: März | E7: 130
A8: Tage in der Periode | B8: =IF(B6="","",B7-B6+1) | D8: April | E8: 90
D9: Mai | E9: 40
D10: Juni | E10: 10
D11: Juli | E11: 0
D12: August | E12: 0
D13: September | E13: 30
D14: Oktober | E14: 80
D15: November | E15: 140
D16: Dezember | E16: 160
D17: Summe | E17: =SUM(E5:E16)
A20: Einheiten
A21: Nr. | B21: Bezeichnung | C21: Fläche m² | D21: Anteil (Wertquote, ‰ o.ä.) | E21: Zähler Einheiten
E22: =IF(A22="","",1)
E23: =IF(A23="","",1)
E24: =IF(A24="","",1)
E25: =IF(A25="","",1)
E26: =IF(A26="","",1)
E27: =IF(A27="","",1)
E28: =IF(A28="","",1)
E29: =IF(A29="","",1)
E30: =IF(A30="","",1)
E31: =IF(A31="","",1)
E32: =IF(A32="","",1)
E33: =IF(A33="","",1)
... E51: =IF(A51="","",1)
B52: Total | C52: =SUM(C22:C51) | D52: =SUM(D22:D51) | E52: =SUM(E22:E51)

Sheet Kosten
A1: Kosten der Periode
A2: Nur Kostenarten erfassen, die im Mietvertrag als Nebenkosten vereinbart sind.
A4: Kostenart | B4: Betrag CHF | C4: Schlüssel | D4: Verteilung | E4: Total Schlüssel
E5: =IF(C5="Fläche",Stammdaten!$C$52,IF(C5="Anteil",Stammdaten!$D$52,IF(C5="Einheiten",Stammdaten!$E$52,0)))
E6: =IF(C6="Fläche",Stammdaten!$C$52,IF(C6="Anteil",Stammdaten!$D$52,IF(C6="Einheiten",Stammdaten!$E$52,0)))
E7: =IF(C7="Fläche",Stammdaten!$C$52,IF(C7="Anteil",Stammdaten!$D$52,IF(C7="Einheiten",Stammdaten!$E$52,0)))
E8: =IF(C8="Fläche",Stammdaten!$C$52,IF(C8="Anteil",Stammdaten!$D$52,IF(C8="Einheiten",Stammdaten!$E$52,0)))
E9: =IF(C9="Fläche",Stammdaten!$C$52,IF(C9="Anteil",Stammdaten!$D$52,IF(C9="Einheiten",Stammdaten!$E$52,0)))
E10: =IF(C10="Fläche",Stammdaten!$C$52,IF(C10="Anteil",Stammdaten!$D$52,IF(C10="Einheiten",Stammdaten!$E$52,0)))
E11: =IF(C11="Fläche",Stammdaten!$C$52,IF(C11="Anteil",Stammdaten!$D$52,IF(C11="Einheiten",Stammdaten!$E$52,0)))
E12: =IF(C12="Fläche",Stammdaten!$C$52,IF(C12="Anteil",Stammdaten!$D$52,IF(C12="Einheiten",Stammdaten!$E$52,0)))
E13: =IF(C13="Fläche",Stammdaten!$C$52,IF(C13="Anteil",Stammdaten!$D$52,IF(C13="Einheiten",Stammdaten!$E$52,0)))
E14: =IF(C14="Fläche",Stammdaten!$C$52,IF(C14="Anteil",Stammdaten!$D$52,IF(C14="Einheiten",Stammdaten!$E$52,0)))
E15: =IF(C15="Fläche",Stammdaten!$C$52,IF(C15="Anteil",Stammdaten!$D$52,IF(C15="Einheiten",Stammdaten!$E$52,0)))
E16: =IF(C16="Fläche",Stammdaten!$C$52,IF(C16="Anteil",Stammdaten!$D$52,IF(C16="Einheiten",Stammdaten!$E$52,0)))
... E29: =IF(C29="Fläche",Stammdaten!$C$52,IF(C29="Anteil",Stammdaten!$D$52,IF(C29="Einheiten",Stammdaten!$E$52,0)))
A30: Total | B30: =SUM(B5:B29)

Sheet Mieter
A1: Mietverhältnisse der Periode
A2: Gelb erfassen. Hellblaue Spalten sind Hilfsrechnungen.
N3: Gewicht ‰ → | O3: =INDEX(Stammdaten!$E$5:$E$16,MONTH(EDATE(Stammdaten!$B$6,0))) | P3: =INDEX(Stammdaten!$E$5:$E$16,MONTH(EDATE(Stammdaten!$B$6,1))) | Q3: =INDEX(Stammdaten!$E$5:$E$16,MONTH(EDATE(Stammdaten!$B$6,2))) | R3: =INDEX(Stammdaten!$E$5:$E$16,MONTH(EDATE(Stammdaten!$B$6,3))) | S3: =INDEX(Stammdaten!$E$5:$E$16,MONTH(EDATE(Stammdaten!$B$6,4))) | T3: =INDEX(Stammdaten!$E$5:$E$16,MONTH(EDATE(Stammdaten!$B$6,5))) | U3: =INDEX(Stammdaten!$E$5:$E$16,MONTH(EDATE(Stammdaten!$B$6,6))) | V3: =INDEX(Stammdaten!$E$5:$E$16,MONTH(EDATE(Stammdaten!$B$6,7))) | W3: =INDEX(Stammdaten!$E$5:$E$16,MONTH(EDATE(Stammdaten!$B$6,8))) | X3: =INDEX(Stammdaten!$E$5:$E$16,MONTH(EDATE(Stammdaten!$B$6,9))) | Y3: =INDEX(Stammdaten!$E$5:$E$16,MONTH(EDATE(Stammdaten!$B$6,10))) | Z3: =INDEX(Stammdaten!$E$5:$E$16,MONTH(EDATE(Stammdaten!$B$6,11)))
A4: Nr. | B4: Mieter | C4: Einheit Nr. | D4: Mietbeginn | E4: Mietende | F4: Akonto bezahlt CHF | G4: Beginn in Periode | H4: Ende in Periode | I4: Tage | J4: Faktor linear | K4: Faktor Heizung | L4: Fläche | M4: Anteil | N4: Einheiten | O4: Belegung M1 | P4: Belegung M2 | Q4: Belegung M3 | R4: Belegung M4 | S4: Belegung M5 | T4: Belegung M6 | U4: Belegung M7 | V4: Belegung M8 | W4: Belegung M9 | X4: Belegung M10 | Y4: Belegung M11 | Z4: Belegung M12
A5: 1 | G5: =IF(C5<>"",MAX(IF(D5="",Stammdaten!$B$6,D5),Stammdaten!$B$6),"") | H5: =IF(C5<>"",MIN(IF(E5="",Stammdaten!$B$7,E5),Stammdaten!$B$7),"") | I5: =IF(C5<>"",MAX(0,H5-G5+1),0) | J5: =IF(C5<>"",I5/Stammdaten!$B$8,0) | K5: =IF(C5<>"",SUMPRODUCT(O5:Z5,$O$3:$Z$3)/Stammdaten!$E$17,0) | L5: =IF(C5<>"",IFERROR(INDEX(Stammdaten!$C$22:$C$51,MATCH(C5,Stammdaten!$A$22:$A$51,0)),0),0) | M5: =IF(C5<>"",IFERROR(INDEX(Stammdaten!$D$22:$D$51,MATCH(C5,Stammdaten!$A$22:$A$51,0)),0),0) | N5: =IF(C5<>"",IFERROR(INDEX(Stammdaten!$E$22:$E$51,MATCH(C5,Stammdaten!$A$22:$A$51,0)),0),0) | O5: =IF(C5<>"",MAX(0,MIN(H5,EOMONTH(EDATE(Stammdaten!$B$6,0),0))-MAX(G5,EDATE(Stammdaten!$B$6,0))+1)/DAY(EOMONTH(EDATE(Stammdaten!$B$6,0),0)),0) | P5: =IF(C5<>"",MAX(0,MIN(H5,EOMONTH(EDATE(Stammdaten!$B$6,1),0))-MAX(G5,EDATE(Stammdaten!$B$6,1))+1)/DAY(EOMONTH(EDATE(Stammdaten!$B$6,1),0)),0) | Q5: =IF(C5<>"",MAX(0,MIN(H5,EOMONTH(EDATE(Stammdaten!$B$6,2),0))-MAX(G5,EDATE(Stammdaten!$B$6,2))+1)/DAY(EOMONTH(EDATE(Stammdaten!$B$6,2),0)),0) | R5: =IF(C5<>"",MAX(0,MIN(H5,EOMONTH(EDATE(Stammdaten!$B$6,3),0))-MAX(G5,EDATE(Stammdaten!$B$6,3))+1)/DAY(EOMONTH(EDATE(Stammdaten!$B$6,3),0)),0) | S5: =IF(C5<>"",MAX(0,MIN(H5,EOMONTH(EDATE(Stammdaten!$B$6,4),0))-MAX(G5,EDATE(Stammdaten!$B$6,4))+1)/DAY(EOMONTH(EDATE(Stammdaten!$B$6,4),0)),0) | T5: =IF(C5<>"",MAX(0,MIN(H5,EOMONTH(EDATE(Stammdaten!$B$6,5),0))-MAX(G5,EDATE(Stammdaten!$B$6,5))+1)/DAY(EOMONTH(EDATE(Stammdaten!$B$6,5),0)),0) | U5: =IF(C5<>"",MAX(0,MIN(H5,EOMONTH(EDATE(Stammdaten!$B$6,6),0))-MAX(G5,EDATE(Stammdaten!$B$6,6))+1)/DAY(EOMONTH(EDATE(Stammdaten!$B$6,6),0)),0) | V5: =IF(C5<>"",MAX(0,MIN(H5,EOMONTH(EDATE(Stammdaten!$B$6,7),0))-MAX(G5,EDATE(Stammdaten!$B$6,7))+1)/DAY(EOMONTH(EDATE(Stammdaten!$B$6,7),0)),0) | W5: =IF(C5<>"",MAX(0,MIN(H5,EOMONTH(EDATE(Stammdaten!$B$6,8),0))-MAX(G5,EDATE(Stammdaten!$B$6,8))+1)/DAY(EOMONTH(EDATE(Stammdaten!$B$6,8),0)),0) | X5: =IF(C5<>"",MAX(0,MIN(H5,EOMONTH(EDATE(Stammdaten!$B$6,9),0))-MAX(G5,EDATE(Stammdaten!$B$6,9))+1)/DAY(EOMONTH(EDATE(Stammdaten!$B$6,9),0)),0) | Y5: =IF(C5<>"",MAX(0,MIN(H5,EOMONTH(EDATE(Stammdaten!$B$6,10),0))-MAX(G5,EDATE(Stammdaten!$B$6,10))+1)/DAY(EOMONTH(EDATE(Stammdaten!$B$6,10),0)),0) | Z5: =IF(C5<>"",MAX(0,MIN(H5,EOMONTH(EDATE(Stammdaten!$B$6,11),0))-MAX(G5,EDATE(Stammdaten!$B$6,11))+1)/DAY(EOMONTH(EDATE(Stammdaten!$B$6,11),0)),0)
A6: 2 | G6: =IF(C6<>"",MAX(IF(D6="",Stammdaten!$B$6,D6),Stammdaten!$B$6),"") | H6: =IF(C6<>"",MIN(IF(E6="",Stammdaten!$B$7,E6),Stammdaten!$B$7),"") | I6: =IF(C6<>"",MAX(0,H6-G6+1),0) | J6: =IF(C6<>"",I6/Stammdaten!$B$8,0) | K6: =IF(C6<>"",SUMPRODUCT(O6:Z6,$O$3:$Z$3)/Stammdaten!$E$17,0) | L6: =IF(C6<>"",IFERROR(INDEX(Stammdaten!$C$22:$C$51,MATCH(C6,Stammdaten!$A$22:$A$51,0)),0),0) | M6: =IF(C6<>"",IFERROR(INDEX(Stammdaten!$D$22:$D$51,MATCH(C6,Stammdaten!$A$22:$A$51,0)),0),0) | N6: =IF(C6<>"",IFERROR(INDEX(Stammdaten!$E$22:$E$51,MATCH(C6,Stammdaten!$A$22:$A$51,0)),0),0) | O6: =IF(C6<>"",MAX(0,MIN(H6,EOMONTH(EDATE(Stammdaten!$B$6,0),0))-MAX(G6,EDATE(Stammdaten!$B$6,0))+1)/DAY(EOMONTH(EDATE(Stammdaten!$B$6,0),0)),0) | P6: =IF(C6<>"",MAX(0,MIN(H6,EOMONTH(EDATE(Stammdaten!$B$6,1),0))-MAX(G6,EDATE(Stammdaten!$B$6,1))+1)/DAY(EOMONTH(EDATE(Stammdaten!$B$6,1),0)),0) | Q6: =IF(C6<>"",MAX(0,MIN(H6,EOMONTH(EDATE(Stammdaten!$B$6,2),0))-MAX(G6,EDATE(Stammdaten!$B$6,2))+1)/DAY(EOMONTH(EDATE(Stammdaten!$B$6,2),0)),0) | R6: =IF(C6<>"",MAX(0,MIN(H6,EOMONTH(EDATE(Stammdaten!$B$6,3),0))-MAX(G6,EDATE(Stammdaten!$B$6,3))+1)/DAY(EOMONTH(EDATE(Stammdaten!$B$6,3),0)),0) | S6: =IF(C6<>"",MAX(0,MIN(H6,EOMONTH(EDATE(Stammdaten!$B$6,4),0))-MAX(G6,EDATE(Stammdaten!$B$6,4))+1)/DAY(EOMONTH(EDATE(Stammdaten!$B$6,4),0)),0) | T6: =IF(C6<>"",MAX(0,MIN(H6,EOMONTH(EDATE(Stammdaten!$B$6,5),0))-MAX(G6,EDATE(Stammdaten!$B$6,5))+1)/DAY(EOMONTH(EDATE(Stammdaten!$B$6,5),0)),0) | U6: =IF(C6<>"",MAX(0,MIN(H6,EOMONTH(EDATE(Stammdaten!$B$6,6),0))-MAX(G6,EDATE(Stammdaten!$B$6,6))+1)/DAY(EOMONTH(EDATE(Stammdaten!$B$6,6),0)),0) | V6: =IF(C6<>"",MAX(0,MIN(H6,EOMONTH(EDATE(Stammdaten!$B$6,7),0))-MAX(G6,EDATE(Stammdaten!$B$6,7))+1)/DAY(EOMONTH(EDATE(Stammdaten!$B$6,7),0)),0) | W6: =IF(C6<>"",MAX(0,MIN(H6,EOMONTH(EDATE(Stammdaten!$B$6,8),0))-MAX(G6,EDATE(Stammdaten!$B$6,8))+1)/DAY(EOMONTH(EDATE(Stammdaten!$B$6,8),0)),0) | X6: =IF(C6<>"",MAX(0,MIN(H6,EOMONTH(EDATE(Stammdaten!$B$6,9),0))-MAX(G6,EDATE(Stammdaten!$B$6,9))+1)/DAY(EOMONTH(EDATE(Stammdaten!$B$6,9),0)),0) | Y6: =IF(C6<>"",MAX(0,MIN(H6,EOMONTH(EDATE(Stammdaten!$B$6,10),0))-MAX(G6,EDATE(Stammdaten!$B$6,10))+1)/DAY(EOMONTH(EDATE(Stammdaten!$B$6,10),0)),0) | Z6: =IF(C6<>"",MAX(0,MIN(H6,EOMONTH(EDATE(Stammdaten!$B$6,11),0))-MAX(G6,EDATE(Stammdaten!$B$6,11))+1)/DAY(EOMONTH(EDATE(Stammdaten!$B$6,11),0)),0)
A7: 3 | G7: =IF(C7<>"",MAX(IF(D7="",Stammdaten!$B$6,D7),Stammdaten!$B$6),"") | H7: =IF(C7<>"",MIN(IF(E7="",Stammdaten!$B$7,E7),Stammdaten!$B$7),"") | I7: =IF(C7<>"",MAX(0,H7-G7+1),0) | J7: =IF(C7<>"",I7/Stammdaten!$B$8,0) | K7: =IF(C7<>"",SUMPRODUCT(O7:Z7,$O$3:$Z$3)/Stammdaten!$E$17,0) | L7: =IF(C7<>"",IFERROR(INDEX(Stammdaten!$C$22:$C$51,MATCH(C7,Stammdaten!$A$22:$A$51,0)),0),0) | M7: =IF(C7<>"",IFERROR(INDEX(Stammdaten!$D$22:$D$51,MATCH(C7,Stammdaten!$A$22:$A$51,0)),0),0) | N7: =IF(C7<>"",IFERROR(INDEX(Stammdaten!$E$22:$E$51,MATCH(C7,Stammdaten!$A$22:$A$51,0)),0),0) | O7: =IF(C7<>"",MAX(0,MIN(H7,EOMONTH(EDATE(Stammdaten!$B$6,0),0))-MAX(G7,EDATE(Stammdaten!$B$6,0))+1)/DAY(EOMONTH(EDATE(Stammdaten!$B$6,0),0)),0) | P7: =IF(C7<>"",MAX(0,MIN(H7,EOMONTH(EDATE(Stammdaten!$B$6,1),0))-MAX(G7,EDATE(Stammdaten!$B$6,1))+1)/DAY(EOMONTH(EDATE(Stammdaten!$B$6,1),0)),0) | Q7: =IF(C7<>"",MAX(0,MIN(H7,EOMONTH(EDATE(Stammdaten!$B$6,2),0))-MAX(G7,EDATE(Stammdaten!$B$6,2))+1)/DAY(EOMONTH(EDATE(Stammdaten!$B$6,2),0)),0) | R7: =IF(C7<>"",MAX(0,MIN(H7,EOMONTH(EDATE(Stammdaten!$B$6,3),0))-MAX(G7,EDATE(Stammdaten!$B$6,3))+1)/DAY(EOMONTH(EDATE(Stammdaten!$B$6,3),0)),0) | S7: =IF(C7<>"",MAX(0,MIN(H7,EOMONTH(EDATE(Stammdaten!$B$6,4),0))-MAX(G7,EDATE(Stammdaten!$B$6,4))+1)/DAY(EOMONTH(EDATE(Stammdaten!$B$6,4),0)),0) | T7: =IF(C7<>"",MAX(0,MIN(H7,EOMONTH(EDATE(Stammdaten!$B$6,5),0))-MAX(G7,EDATE(Stammdaten!$B$6,5))+1)/DAY(EOMONTH(EDATE(Stammdaten!$B$6,5),0)),0) | U7: =IF(C7<>"",MAX(0,MIN(H7,EOMONTH(EDATE(Stammdaten!$B$6,6),0))-MAX(G7,EDATE(Stammdaten!$B$6,6))+1)/DAY(EOMONTH(EDATE(Stammdaten!$B$6,6),0)),0) | V7: =IF(C7<>"",MAX(0,MIN(H7,EOMONTH(EDATE(Stammdaten!$B$6,7),0))-MAX(G7,EDATE(Stammdaten!$B$6,7))+1)/DAY(EOMONTH(EDATE(Stammdaten!$B$6,7),0)),0) | W7: =IF(C7<>"",MAX(0,MIN(H7,EOMONTH(EDATE(Stammdaten!$B$6,8),0))-MAX(G7,EDATE(Stammdaten!$B$6,8))+1)/DAY(EOMONTH(EDATE(Stammdaten!$B$6,8),0)),0) | X7: =IF(C7<>"",MAX(0,MIN(H7,EOMONTH(EDATE(Stammdaten!$B$6,9),0))-MAX(G7,EDATE(Stammdaten!$B$6,9))+1)/DAY(EOMONTH(EDATE(Stammdaten!$B$6,9),0)),0) | Y7: =IF(C7<>"",MAX(0,MIN(H7,EOMONTH(EDATE(Stammdaten!$B$6,10),0))-MAX(G7,EDATE(Stammdaten!$B$6,10))+1)/DAY(EOMONTH(EDATE(Stammdaten!$B$6,10),0)),0) | Z7: =IF(C7<>"",MAX(0,MIN(H7,EOMONTH(EDATE(Stammdaten!$B$6,11),0))-MAX(G7,EDATE(Stammdaten!$B$6,11))+1)/DAY(EOMONTH(EDATE(Stammdaten!$B$6,11),0)),0)
A8: 4 | G8: =IF(C8<>"",MAX(IF(D8="",Stammdaten!$B$6,D8),Stammdaten!$B$6),"") | H8: =IF(C8<>"",MIN(IF(E8="",Stammdaten!$B$7,E8),Stammdaten!$B$7),"") | I8: =IF(C8<>"",MAX(0,H8-G8+1),0) | J8: =IF(C8<>"",I8/Stammdaten!$B$8,0) | K8: =IF(C8<>"",SUMPRODUCT(O8:Z8,$O$3:$Z$3)/Stammdaten!$E$17,0) | L8: =IF(C8<>"",IFERROR(INDEX(Stammdaten!$C$22:$C$51,MATCH(C8,Stammdaten!$A$22:$A$51,0)),0),0) | M8: =IF(C8<>"",IFERROR(INDEX(Stammdaten!$D$22:$D$51,MATCH(C8,Stammdaten!$A$22:$A$51,0)),0),0) | N8: =IF(C8<>"",IFERROR(INDEX(Stammdaten!$E$22:$E$51,MATCH(C8,Stammdaten!$A$22:$A$51,0)),0),0) | O8: =IF(C8<>"",MAX(0,MIN(H8,EOMONTH(EDATE(Stammdaten!$B$6,0),0))-MAX(G8,EDATE(Stammdaten!$B$6,0))+1)/DAY(EOMONTH(EDATE(Stammdaten!$B$6,0),0)),0) | P8: =IF(C8<>"",MAX(0,MIN(H8,EOMONTH(EDATE(Stammdaten!$B$6,1),0))-MAX(G8,EDATE(Stammdaten!$B$6,1))+1)/DAY(EOMONTH(EDATE(Stammdaten!$B$6,1),0)),0) | Q8: =IF(C8<>"",MAX(0,MIN(H8,EOMONTH(EDATE(Stammdaten!$B$6,2),0))-MAX(G8,EDATE(Stammdaten!$B$6,2))+1)/DAY(EOMONTH(EDATE(Stammdaten!$B$6,2),0)),0) | R8: =IF(C8<>"",MAX(0,MIN(H8,EOMONTH(EDATE(Stammdaten!$B$6,3),0))-MAX(G8,EDATE(Stammdaten!$B$6,3))+1)/DAY(EOMONTH(EDATE(Stammdaten!$B$6,3),0)),0) | S8: =IF(C8<>"",MAX(0,MIN(H8,EOMONTH(EDATE(Stammdaten!$B$6,4),0))-MAX(G8,EDATE(Stammdaten!$B$6,4))+1)/DAY(EOMONTH(EDATE(Stammdaten!$B$6,4),0)),0) | T8: =IF(C8<>"",MAX(0,MIN(H8,EOMONTH(EDATE(Stammdaten!$B$6,5),0))-MAX(G8,EDATE(Stammdaten!$B$6,5))+1)/DAY(EOMONTH(EDATE(Stammdaten!$B$6,5),0)),0) | U8: =IF(C8<>"",MAX(0,MIN(H8,EOMONTH(EDATE(Stammdaten!$B$6,6),0))-MAX(G8,EDATE(Stammdaten!$B$6,6))+1)/DAY(EOMONTH(EDATE(Stammdaten!$B$6,6),0)),0) | V8: =IF(C8<>"",MAX(0,MIN(H8,EOMONTH(EDATE(Stammdaten!$B$6,7),0))-MAX(G8,EDATE(Stammdaten!$B$6,7))+1)/DAY(EOMONTH(EDATE(Stammdaten!$B$6,7),0)),0) | W8: =IF(C8<>"",MAX(0,MIN(H8,EOMONTH(EDATE(Stammdaten!$B$6,8),0))-MAX(G8,EDATE(Stammdaten!$B$6,8))+1)/DAY(EOMONTH(EDATE(Stammdaten!$B$6,8),0)),0) | X8: =IF(C8<>"",MAX(0,MIN(H8,EOMONTH(EDATE(Stammdaten!$B$6,9),0))-MAX(G8,EDATE(Stammdaten!$B$6,9))+1)/DAY(EOMONTH(EDATE(Stammdaten!$B$6,9),0)),0) | Y8: =IF(C8<>"",MAX(0,MIN(H8,EOMONTH(EDATE(Stammdaten!$B$6,10),0))-MAX(G8,EDATE(Stammdaten!$B$6,10))+1)/DAY(EOMONTH(EDATE(Stammdaten!$B$6,10),0)),0) | Z8: =IF(C8<>"",MAX(0,MIN(H8,EOMONTH(EDATE(Stammdaten!$B$6,11),0))-MAX(G8,EDATE(Stammdaten!$B$6,11))+1)/DAY(EOMONTH(EDATE(Stammdaten!$B$6,11),0)),0)
A9: 5 | G9: =IF(C9<>"",MAX(IF(D9="",Stammdaten!$B$6,D9),Stammdaten!$B$6),"") | H9: =IF(C9<>"",MIN(IF(E9="",Stammdaten!$B$7,E9),Stammdaten!$B$7),"") | I9: =IF(C9<>"",MAX(0,H9-G9+1),0) | J9: =IF(C9<>"",I9/Stammdaten!$B$8,0) | K9: =IF(C9<>"",SUMPRODUCT(O9:Z9,$O$3:$Z$3)/Stammdaten!$E$17,0) | L9: =IF(C9<>"",IFERROR(INDEX(Stammdaten!$C$22:$C$51,MATCH(C9,Stammdaten!$A$22:$A$51,0)),0),0) | M9: =IF(C9<>"",IFERROR(INDEX(Stammdaten!$D$22:$D$51,MATCH(C9,Stammdaten!$A$22:$A$51,0)),0),0) | N9: =IF(C9<>"",IFERROR(INDEX(Stammdaten!$E$22:$E$51,MATCH(C9,Stammdaten!$A$22:$A$51,0)),0),0) | O9: =IF(C9<>"",MAX(0,MIN(H9,EOMONTH(EDATE(Stammdaten!$B$6,0),0))-MAX(G9,EDATE(Stammdaten!$B$6,0))+1)/DAY(EOMONTH(EDATE(Stammdaten!$B$6,0),0)),0) | P9: =IF(C9<>"",MAX(0,MIN(H9,EOMONTH(EDATE(Stammdaten!$B$6,1),0))-MAX(G9,EDATE(Stammdaten!$B$6,1))+1)/DAY(EOMONTH(EDATE(Stammdaten!$B$6,1),0)),0) | Q9: =IF(C9<>"",MAX(0,MIN(H9,EOMONTH(EDATE(Stammdaten!$B$6,2),0))-MAX(G9,EDATE(Stammdaten!$B$6,2))+1)/DAY(EOMONTH(EDATE(Stammdaten!$B$6,2),0)),0) | R9: =IF(C9<>"",MAX(0,MIN(H9,EOMONTH(EDATE(Stammdaten!$B$6,3),0))-MAX(G9,EDATE(Stammdaten!$B$6,3))+1)/DAY(EOMONTH(EDATE(Stammdaten!$B$6,3),0)),0) | S9: =IF(C9<>"",MAX(0,MIN(H9,EOMONTH(EDATE(Stammdaten!$B$6,4),0))-MAX(G9,EDATE(Stammdaten!$B$6,4))+1)/DAY(EOMONTH(EDATE(Stammdaten!$B$6,4),0)),0) | T9: =IF(C9<>"",MAX(0,MIN(H9,EOMONTH(EDATE(Stammdaten!$B$6,5),0))-MAX(G9,EDATE(Stammdaten!$B$6,5))+1)/DAY(EOMONTH(EDATE(Stammdaten!$B$6,5),0)),0) | U9: =IF(C9<>"",MAX(0,MIN(H9,EOMONTH(EDATE(Stammdaten!$B$6,6),0))-MAX(G9,EDATE(Stammdaten!$B$6,6))+1)/DAY(EOMONTH(EDATE(Stammdaten!$B$6,6),0)),0) | V9: =IF(C9<>"",MAX(0,MIN(H9,EOMONTH(EDATE(Stammdaten!$B$6,7),0))-MAX(G9,EDATE(Stammdaten!$B$6,7))+1)/DAY(EOMONTH(EDATE(Stammdaten!$B$6,7),0)),0) | W9: =IF(C9<>"",MAX(0,MIN(H9,EOMONTH(EDATE(Stammdaten!$B$6,8),0))-MAX(G9,EDATE(Stammdaten!$B$6,8))+1)/DAY(EOMONTH(EDATE(Stammdaten!$B$6,8),0)),0) | X9: =IF(C9<>"",MAX(0,MIN(H9,EOMONTH(EDATE(Stammdaten!$B$6,9),0))-MAX(G9,EDATE(Stammdaten!$B$6,9))+1)/DAY(EOMONTH(EDATE(Stammdaten!$B$6,9),0)),0) | Y9: =IF(C9<>"",MAX(0,MIN(H9,EOMONTH(EDATE(Stammdaten!$B$6,10),0))-MAX(G9,EDATE(Stammdaten!$B$6,10))+1)/DAY(EOMONTH(EDATE(Stammdaten!$B$6,10),0)),0) | Z9: =IF(C9<>"",MAX(0,MIN(H9,EOMONTH(EDATE(Stammdaten!$B$6,11),0))-MAX(G9,EDATE(Stammdaten!$B$6,11))+1)/DAY(EOMONTH(EDATE(Stammdaten!$B$6,11),0)),0)
A10: 6 | G10: =IF(C10<>"",MAX(IF(D10="",Stammdaten!$B$6,D10),Stammdaten!$B$6),"") | H10: =IF(C10<>"",MIN(IF(E10="",Stammdaten!$B$7,E10),Stammdaten!$B$7),"") | I10: =IF(C10<>"",MAX(0,H10-G10+1),0) | J10: =IF(C10<>"",I10/Stammdaten!$B$8,0) | K10: =IF(C10<>"",SUMPRODUCT(O10:Z10,$O$3:$Z$3)/Stammdaten!$E$17,0) | L10: =IF(C10<>"",IFERROR(INDEX(Stammdaten!$C$22:$C$51,MATCH(C10,Stammdaten!$A$22:$A$51,0)),0),0) | M10: =IF(C10<>"",IFERROR(INDEX(Stammdaten!$D$22:$D$51,MATCH(C10,Stammdaten!$A$22:$A$51,0)),0),0) | N10: =IF(C10<>"",IFERROR(INDEX(Stammdaten!$E$22:$E$51,MATCH(C10,Stammdaten!$A$22:$A$51,0)),0),0) | O10: =IF(C10<>"",MAX(0,MIN(H10,EOMONTH(EDATE(Stammdaten!$B$6,0),0))-MAX(G10,EDATE(Stammdaten!$B$6,0))+1)/DAY(EOMONTH(EDATE(Stammdaten!$B$6,0),0)),0) | P10: =IF(C10<>"",MAX(0,MIN(H10,EOMONTH(EDATE(Stammdaten!$B$6,1),0))-MAX(G10,EDATE(Stammdaten!$B$6,1))+1)/DAY(EOMONTH(EDATE(Stammdaten!$B$6,1),0)),0) | Q10: =IF(C10<>"",MAX(0,MIN(H10,EOMONTH(EDATE(Stammdaten!$B$6,2),0))-MAX(G10,EDATE(Stammdaten!$B$6,2))+1)/DAY(EOMONTH(EDATE(Stammdaten!$B$6,2),0)),0) | R10: =IF(C10<>"",MAX(0,MIN(H10,EOMONTH(EDATE(Stammdaten!$B$6,3),0))-MAX(G10,EDATE(Stammdaten!$B$6,3))+1)/DAY(EOMONTH(EDATE(Stammdaten!$B$6,3),0)),0) | S10: =IF(C10<>"",MAX(0,MIN(H10,EOMONTH(EDATE(Stammdaten!$B$6,4),0))-MAX(G10,EDATE(Stammdaten!$B$6,4))+1)/DAY(EOMONTH(EDATE(Stammdaten!$B$6,4),0)),0) | T10: =IF(C10<>"",MAX(0,MIN(H10,EOMONTH(EDATE(Stammdaten!$B$6,5),0))-MAX(G10,EDATE(Stammdaten!$B$6,5))+1)/DAY(EOMONTH(EDATE(Stammdaten!$B$6,5),0)),0) | U10: =IF(C10<>"",MAX(0,MIN(H10,EOMONTH(EDATE(Stammdaten!$B$6,6),0))-MAX(G10,EDATE(Stammdaten!$B$6,6))+1)/DAY(EOMONTH(EDATE(Stammdaten!$B$6,6),0)),0) | V10: =IF(C10<>"",MAX(0,MIN(H10,EOMONTH(EDATE(Stammdaten!$B$6,7),0))-MAX(G10,EDATE(Stammdaten!$B$6,7))+1)/DAY(EOMONTH(EDATE(Stammdaten!$B$6,7),0)),0) | W10: =IF(C10<>"",MAX(0,MIN(H10,EOMONTH(EDATE(Stammdaten!$B$6,8),0))-MAX(G10,EDATE(Stammdaten!$B$6,8))+1)/DAY(EOMONTH(EDATE(Stammdaten!$B$6,8),0)),0) | X10: =IF(C10<>"",MAX(0,MIN(H10,EOMONTH(EDATE(Stammdaten!$B$6,9),0))-MAX(G10,EDATE(Stammdaten!$B$6,9))+1)/DAY(EOMONTH(EDATE(Stammdaten!$B$6,9),0)),0) | Y10: =IF(C10<>"",MAX(0,MIN(H10,EOMONTH(EDATE(Stammdaten!$B$6,10),0))-MAX(G10,EDATE(Stammdaten!$B$6,10))+1)/DAY(EOMONTH(EDATE(Stammdaten!$B$6,10),0)),0) | Z10: =IF(C10<>"",MAX(0,MIN(H10,EOMONTH(EDATE(Stammdaten!$B$6,11),0))-MAX(G10,EDATE(Stammdaten!$B$6,11))+1)/DAY(EOMONTH(EDATE(Stammdaten!$B$6,11),0)),0)
A11: 7 | G11: =IF(C11<>"",MAX(IF(D11="",Stammdaten!$B$6,D11),Stammdaten!$B$6),"") | H11: =IF(C11<>"",MIN(IF(E11="",Stammdaten!$B$7,E11),Stammdaten!$B$7),"") | I11: =IF(C11<>"",MAX(0,H11-G11+1),0) | J11: =IF(C11<>"",I11/Stammdaten!$B$8,0) | K11: =IF(C11<>"",SUMPRODUCT(O11:Z11,$O$3:$Z$3)/Stammdaten!$E$17,0) | L11: =IF(C11<>"",IFERROR(INDEX(Stammdaten!$C$22:$C$51,MATCH(C11,Stammdaten!$A$22:$A$51,0)),0),0) | M11: =IF(C11<>"",IFERROR(INDEX(Stammdaten!$D$22:$D$51,MATCH(C11,Stammdaten!$A$22:$A$51,0)),0),0) | N11: =IF(C11<>"",IFERROR(INDEX(Stammdaten!$E$22:$E$51,MATCH(C11,Stammdaten!$A$22:$A$51,0)),0),0) | O11: =IF(C11<>"",MAX(0,MIN(H11,EOMONTH(EDATE(Stammdaten!$B$6,0),0))-MAX(G11,EDATE(Stammdaten!$B$6,0))+1)/DAY(EOMONTH(EDATE(Stammdaten!$B$6,0),0)),0) | P11: =IF(C11<>"",MAX(0,MIN(H11,EOMONTH(EDATE(Stammdaten!$B$6,1),0))-MAX(G11,EDATE(Stammdaten!$B$6,1))+1)/DAY(EOMONTH(EDATE(Stammdaten!$B$6,1),0)),0) | Q11: =IF(C11<>"",MAX(0,MIN(H11,EOMONTH(EDATE(Stammdaten!$B$6,2),0))-MAX(G11,EDATE(Stammdaten!$B$6,2))+1)/DAY(EOMONTH(EDATE(Stammdaten!$B$6,2),0)),0) | R11: =IF(C11<>"",MAX(0,MIN(H11,EOMONTH(EDATE(Stammdaten!$B$6,3),0))-MAX(G11,EDATE(Stammdaten!$B$6,3))+1)/DAY(EOMONTH(EDATE(Stammdaten!$B$6,3),0)),0) | S11: =IF(C11<>"",MAX(0,MIN(H11,EOMONTH(EDATE(Stammdaten!$B$6,4),0))-MAX(G11,EDATE(Stammdaten!$B$6,4))+1)/DAY(EOMONTH(EDATE(Stammdaten!$B$6,4),0)),0) | T11: =IF(C11<>"",MAX(0,MIN(H11,EOMONTH(EDATE(Stammdaten!$B$6,5),0))-MAX(G11,EDATE(Stammdaten!$B$6,5))+1)/DAY(EOMONTH(EDATE(Stammdaten!$B$6,5),0)),0) | U11: =IF(C11<>"",MAX(0,MIN(H11,EOMONTH(EDATE(Stammdaten!$B$6,6),0))-MAX(G11,EDATE(Stammdaten!$B$6,6))+1)/DAY(EOMONTH(EDATE(Stammdaten!$B$6,6),0)),0) | V11: =IF(C11<>"",MAX(0,MIN(H11,EOMONTH(EDATE(Stammdaten!$B$6,7),0))-MAX(G11,EDATE(Stammdaten!$B$6,7))+1)/DAY(EOMONTH(EDATE(Stammdaten!$B$6,7),0)),0) | W11: =IF(C11<>"",MAX(0,MIN(H11,EOMONTH(EDATE(Stammdaten!$B$6,8),0))-MAX(G11,EDATE(Stammdaten!$B$6,8))+1)/DAY(EOMONTH(EDATE(Stammdaten!$B$6,8),0)),0) | X11: =IF(C11<>"",MAX(0,MIN(H11,EOMONTH(EDATE(Stammdaten!$B$6,9),0))-MAX(G11,EDATE(Stammdaten!$B$6,9))+1)/DAY(EOMONTH(EDATE(Stammdaten!$B$6,9),0)),0) | Y11: =IF(C11<>"",MAX(0,MIN(H11,EOMONTH(EDATE(Stammdaten!$B$6,10),0))-MAX(G11,EDATE(Stammdaten!$B$6,10))+1)/DAY(EOMONTH(EDATE(Stammdaten!$B$6,10),0)),0) | Z11: =IF(C11<>"",MAX(0,MIN(H11,EOMONTH(EDATE(Stammdaten!$B$6,11),0))-MAX(G11,EDATE(Stammdaten!$B$6,11))+1)/DAY(EOMONTH(EDATE(Stammdaten!$B$6,11),0)),0)
A12: 8 | G12: =IF(C12<>"",MAX(IF(D12="",Stammdaten!$B$6,D12),Stammdaten!$B$6),"") | H12: =IF(C12<>"",MIN(IF(E12="",Stammdaten!$B$7,E12),Stammdaten!$B$7),"") | I12: =IF(C12<>"",MAX(0,H12-G12+1),0) | J12: =IF(C12<>"",I12/Stammdaten!$B$8,0) | K12: =IF(C12<>"",SUMPRODUCT(O12:Z12,$O$3:$Z$3)/Stammdaten!$E$17,0) | L12: =IF(C12<>"",IFERROR(INDEX(Stammdaten!$C$22:$C$51,MATCH(C12,Stammdaten!$A$22:$A$51,0)),0),0) | M12: =IF(C12<>"",IFERROR(INDEX(Stammdaten!$D$22:$D$51,MATCH(C12,Stammdaten!$A$22:$A$51,0)),0),0) | N12: =IF(C12<>"",IFERROR(INDEX(Stammdaten!$E$22:$E$51,MATCH(C12,Stammdaten!$A$22:$A$51,0)),0),0) | O12: =IF(C12<>"",MAX(0,MIN(H12,EOMONTH(EDATE(Stammdaten!$B$6,0),0))-MAX(G12,EDATE(Stammdaten!$B$6,0))+1)/DAY(EOMONTH(EDATE(Stammdaten!$B$6,0),0)),0) | P12: =IF(C12<>"",MAX(0,MIN(H12,EOMONTH(EDATE(Stammdaten!$B$6,1),0))-MAX(G12,EDATE(Stammdaten!$B$6,1))+1)/DAY(EOMONTH(EDATE(Stammdaten!$B$6,1),0)),0) | Q12: =IF(C12<>"",MAX(0,MIN(H12,EOMONTH(EDATE(Stammdaten!$B$6,2),0))-MAX(G12,EDATE(Stammdaten!$B$6,2))+1)/DAY(EOMONTH(EDATE(Stammdaten!$B$6,2),0)),0) | R12: =IF(C12<>"",MAX(0,MIN(H12,EOMONTH(EDATE(Stammdaten!$B$6,3),0))-MAX(G12,EDATE(Stammdaten!$B$6,3))+1)/DAY(EOMONTH(EDATE(Stammdaten!$B$6,3),0)),0) | S12: =IF(C12<>"",MAX(0,MIN(H12,EOMONTH(EDATE(Stammdaten!$B$6,4),0))-MAX(G12,EDATE(Stammdaten!$B$6,4))+1)/DAY(EOMONTH(EDATE(Stammdaten!$B$6,4),0)),0) | T12: =IF(C12<>"",MAX(0,MIN(H12,EOMONTH(EDATE(Stammdaten!$B$6,5),0))-MAX(G12,EDATE(Stammdaten!$B$6,5))+1)/DAY(EOMONTH(EDATE(Stammdaten!$B$6,5),0)),0) | U12: =IF(C12<>"",MAX(0,MIN(H12,EOMONTH(EDATE(Stammdaten!$B$6,6),0))-MAX(G12,EDATE(Stammdaten!$B$6,6))+1)/DAY(EOMONTH(EDATE(Stammdaten!$B$6,6),0)),0) | V12: =IF(C12<>"",MAX(0,MIN(H12,EOMONTH(EDATE(Stammdaten!$B$6,7),0))-MAX(G12,EDATE(Stammdaten!$B$6,7))+1)/DAY(EOMONTH(EDATE(Stammdaten!$B$6,7),0)),0) | W12: =IF(C12<>"",MAX(0,MIN(H12,EOMONTH(EDATE(Stammdaten!$B$6,8),0))-MAX(G12,EDATE(Stammdaten!$B$6,8))+1)/DAY(EOMONTH(EDATE(Stammdaten!$B$6,8),0)),0) | X12: =IF(C12<>"",MAX(0,MIN(H12,EOMONTH(EDATE(Stammdaten!$B$6,9),0))-MAX(G12,EDATE(Stammdaten!$B$6,9))+1)/DAY(EOMONTH(EDATE(Stammdaten!$B$6,9),0)),0) | Y12: =IF(C12<>"",MAX(0,MIN(H12,EOMONTH(EDATE(Stammdaten!$B$6,10),0))-MAX(G12,EDATE(Stammdaten!$B$6,10))+1)/DAY(EOMONTH(EDATE(Stammdaten!$B$6,10),0)),0) | Z12: =IF(C12<>"",MAX(0,MIN(H12,EOMONTH(EDATE(Stammdaten!$B$6,11),0))-MAX(G12,EDATE(Stammdaten!$B$6,11))+1)/DAY(EOMONTH(EDATE(Stammdaten!$B$6,11),0)),0)
A13: 9 | G13: =IF(C13<>"",MAX(IF(D13="",Stammdaten!$B$6,D13),Stammdaten!$B$6),"") | H13: =IF(C13<>"",MIN(IF(E13="",Stammdaten!$B$7,E13),Stammdaten!$B$7),"") | I13: =IF(C13<>"",MAX(0,H13-G13+1),0) | J13: =IF(C13<>"",I13/Stammdaten!$B$8,0) | K13: =IF(C13<>"",SUMPRODUCT(O13:Z13,$O$3:$Z$3)/Stammdaten!$E$17,0) | L13: =IF(C13<>"",IFERROR(INDEX(Stammdaten!$C$22:$C$51,MATCH(C13,Stammdaten!$A$22:$A$51,0)),0),0) | M13: =IF(C13<>"",IFERROR(INDEX(Stammdaten!$D$22:$D$51,MATCH(C13,Stammdaten!$A$22:$A$51,0)),0),0) | N13: =IF(C13<>"",IFERROR(INDEX(Stammdaten!$E$22:$E$51,MATCH(C13,Stammdaten!$A$22:$A$51,0)),0),0) | O13: =IF(C13<>"",MAX(0,MIN(H13,EOMONTH(EDATE(Stammdaten!$B$6,0),0))-MAX(G13,EDATE(Stammdaten!$B$6,0))+1)/DAY(EOMONTH(EDATE(Stammdaten!$B$6,0),0)),0) | P13: =IF(C13<>"",MAX(0,MIN(H13,EOMONTH(EDATE(Stammdaten!$B$6,1),0))-MAX(G13,EDATE(Stammdaten!$B$6,1))+1)/DAY(EOMONTH(EDATE(Stammdaten!$B$6,1),0)),0) | Q13: =IF(C13<>"",MAX(0,MIN(H13,EOMONTH(EDATE(Stammdaten!$B$6,2),0))-MAX(G13,EDATE(Stammdaten!$B$6,2))+1)/DAY(EOMONTH(EDATE(Stammdaten!$B$6,2),0)),0) | R13: =IF(C13<>"",MAX(0,MIN(H13,EOMONTH(EDATE(Stammdaten!$B$6,3),0))-MAX(G13,EDATE(Stammdaten!$B$6,3))+1)/DAY(EOMONTH(EDATE(Stammdaten!$B$6,3),0)),0) | S13: =IF(C13<>"",MAX(0,MIN(H13,EOMONTH(EDATE(Stammdaten!$B$6,4),0))-MAX(G13,EDATE(Stammdaten!$B$6,4))+1)/DAY(EOMONTH(EDATE(Stammdaten!$B$6,4),0)),0) | T13: =IF(C13<>"",MAX(0,MIN(H13,EOMONTH(EDATE(Stammdaten!$B$6,5),0))-MAX(G13,EDATE(Stammdaten!$B$6,5))+1)/DAY(EOMONTH(EDATE(Stammdaten!$B$6,5),0)),0) | U13: =IF(C13<>"",MAX(0,MIN(H13,EOMONTH(EDATE(Stammdaten!$B$6,6),0))-MAX(G13,EDATE(Stammdaten!$B$6,6))+1)/DAY(EOMONTH(EDATE(Stammdaten!$B$6,6),0)),0) | V13: =IF(C13<>"",MAX(0,MIN(H13,EOMONTH(EDATE(Stammdaten!$B$6,7),0))-MAX(G13,EDATE(Stammdaten!$B$6,7))+1)/DAY(EOMONTH(EDATE(Stammdaten!$B$6,7),0)),0) | W13: =IF(C13<>"",MAX(0,MIN(H13,EOMONTH(EDATE(Stammdaten!$B$6,8),0))-MAX(G13,EDATE(Stammdaten!$B$6,8))+1)/DAY(EOMONTH(EDATE(Stammdaten!$B$6,8),0)),0) | X13: =IF(C13<>"",MAX(0,MIN(H13,EOMONTH(EDATE(Stammdaten!$B$6,9),0))-MAX(G13,EDATE(Stammdaten!$B$6,9))+1)/DAY(EOMONTH(EDATE(Stammdaten!$B$6,9),0)),0) | Y13: =IF(C13<>"",MAX(0,MIN(H13,EOMONTH(EDATE(Stammdaten!$B$6,10),0))-MAX(G13,EDATE(Stammdaten!$B$6,10))+1)/DAY(EOMONTH(EDATE(Stammdaten!$B$6,10),0)),0) | Z13: =IF(C13<>"",MAX(0,MIN(H13,EOMONTH(EDATE(Stammdaten!$B$6,11),0))-MAX(G13,EDATE(Stammdaten!$B$6,11))+1)/DAY(EOMONTH(EDATE(Stammdaten!$B$6,11),0)),0)
A14: 10 | G14: =IF(C14<>"",MAX(IF(D14="",Stammdaten!$B$6,D14),Stammdaten!$B$6),"") | H14: =IF(C14<>"",MIN(IF(E14="",Stammdaten!$B$7,E14),Stammdaten!$B$7),"") | I14: =IF(C14<>"",MAX(0,H14-G14+1),0) | J14: =IF(C14<>"",I14/Stammdaten!$B$8,0) | K14: =IF(C14<>"",SUMPRODUCT(O14:Z14,$O$3:$Z$3)/Stammdaten!$E$17,0) | L14: =IF(C14<>"",IFERROR(INDEX(Stammdaten!$C$22:$C$51,MATCH(C14,Stammdaten!$A$22:$A$51,0)),0),0) | M14: =IF(C14<>"",IFERROR(INDEX(Stammdaten!$D$22:$D$51,MATCH(C14,Stammdaten!$A$22:$A$51,0)),0),0) | N14: =IF(C14<>"",IFERROR(INDEX(Stammdaten!$E$22:$E$51,MATCH(C14,Stammdaten!$A$22:$A$51,0)),0),0) | O14: =IF(C14<>"",MAX(0,MIN(H14,EOMONTH(EDATE(Stammdaten!$B$6,0),0))-MAX(G14,EDATE(Stammdaten!$B$6,0))+1)/DAY(EOMONTH(EDATE(Stammdaten!$B$6,0),0)),0) | P14: =IF(C14<>"",MAX(0,MIN(H14,EOMONTH(EDATE(Stammdaten!$B$6,1),0))-MAX(G14,EDATE(Stammdaten!$B$6,1))+1)/DAY(EOMONTH(EDATE(Stammdaten!$B$6,1),0)),0) | Q14: =IF(C14<>"",MAX(0,MIN(H14,EOMONTH(EDATE(Stammdaten!$B$6,2),0))-MAX(G14,EDATE(Stammdaten!$B$6,2))+1)/DAY(EOMONTH(EDATE(Stammdaten!$B$6,2),0)),0) | R14: =IF(C14<>"",MAX(0,MIN(H14,EOMONTH(EDATE(Stammdaten!$B$6,3),0))-MAX(G14,EDATE(Stammdaten!$B$6,3))+1)/DAY(EOMONTH(EDATE(Stammdaten!$B$6,3),0)),0) | S14: =IF(C14<>"",MAX(0,MIN(H14,EOMONTH(EDATE(Stammdaten!$B$6,4),0))-MAX(G14,EDATE(Stammdaten!$B$6,4))+1)/DAY(EOMONTH(EDATE(Stammdaten!$B$6,4),0)),0) | T14: =IF(C14<>"",MAX(0,MIN(H14,EOMONTH(EDATE(Stammdaten!$B$6,5),0))-MAX(G14,EDATE(Stammdaten!$B$6,5))+1)/DAY(EOMONTH(EDATE(Stammdaten!$B$6,5),0)),0) | U14: =IF(C14<>"",MAX(0,MIN(H14,EOMONTH(EDATE(Stammdaten!$B$6,6),0))-MAX(G14,EDATE(Stammdaten!$B$6,6))+1)/DAY(EOMONTH(EDATE(Stammdaten!$B$6,6),0)),0) | V14: =IF(C14<>"",MAX(0,MIN(H14,EOMONTH(EDATE(Stammdaten!$B$6,7),0))-MAX(G14,EDATE(Stammdaten!$B$6,7))+1)/DAY(EOMONTH(EDATE(Stammdaten!$B$6,7),0)),0) | W14: =IF(C14<>"",MAX(0,MIN(H14,EOMONTH(EDATE(Stammdaten!$B$6,8),0))-MAX(G14,EDATE(Stammdaten!$B$6,8))+1)/DAY(EOMONTH(EDATE(Stammdaten!$B$6,8),0)),0) | X14: =IF(C14<>"",MAX(0,MIN(H14,EOMONTH(EDATE(Stammdaten!$B$6,9),0))-MAX(G14,EDATE(Stammdaten!$B$6,9))+1)/DAY(EOMONTH(EDATE(Stammdaten!$B$6,9),0)),0) | Y14: =IF(C14<>"",MAX(0,MIN(H14,EOMONTH(EDATE(Stammdaten!$B$6,10),0))-MAX(G14,EDATE(Stammdaten!$B$6,10))+1)/DAY(EOMONTH(EDATE(Stammdaten!$B$6,10),0)),0) | Z14: =IF(C14<>"",MAX(0,MIN(H14,EOMONTH(EDATE(Stammdaten!$B$6,11),0))-MAX(G14,EDATE(Stammdaten!$B$6,11))+1)/DAY(EOMONTH(EDATE(Stammdaten!$B$6,11),0)),0)
A15: 11 | G15: =IF(C15<>"",MAX(IF(D15="",Stammdaten!$B$6,D15),Stammdaten!$B$6),"") | H15: =IF(C15<>"",MIN(IF(E15="",Stammdaten!$B$7,E15),Stammdaten!$B$7),"") | I15: =IF(C15<>"",MAX(0,H15-G15+1),0) | J15: =IF(C15<>"",I15/Stammdaten!$B$8,0) | K15: =IF(C15<>"",SUMPRODUCT(O15:Z15,$O$3:$Z$3)/Stammdaten!$E$17,0) | L15: =IF(C15<>"",IFERROR(INDEX(Stammdaten!$C$22:$C$51,MATCH(C15,Stammdaten!$A$22:$A$51,0)),0),0) | M15: =IF(C15<>"",IFERROR(INDEX(Stammdaten!$D$22:$D$51,MATCH(C15,Stammdaten!$A$22:$A$51,0)),0),0) | N15: =IF(C15<>"",IFERROR(INDEX(Stammdaten!$E$22:$E$51,MATCH(C15,Stammdaten!$A$22:$A$51,0)),0),0) | O15: =IF(C15<>"",MAX(0,MIN(H15,EOMONTH(EDATE(Stammdaten!$B$6,0),0))-MAX(G15,EDATE(Stammdaten!$B$6,0))+1)/DAY(EOMONTH(EDATE(Stammdaten!$B$6,0),0)),0) | P15: =IF(C15<>"",MAX(0,MIN(H15,EOMONTH(EDATE(Stammdaten!$B$6,1),0))-MAX(G15,EDATE(Stammdaten!$B$6,1))+1)/DAY(EOMONTH(EDATE(Stammdaten!$B$6,1),0)),0) | Q15: =IF(C15<>"",MAX(0,MIN(H15,EOMONTH(EDATE(Stammdaten!$B$6,2),0))-MAX(G15,EDATE(Stammdaten!$B$6,2))+1)/DAY(EOMONTH(EDATE(Stammdaten!$B$6,2),0)),0) | R15: =IF(C15<>"",MAX(0,MIN(H15,EOMONTH(EDATE(Stammdaten!$B$6,3),0))-MAX(G15,EDATE(Stammdaten!$B$6,3))+1)/DAY(EOMONTH(EDATE(Stammdaten!$B$6,3),0)),0) | S15: =IF(C15<>"",MAX(0,MIN(H15,EOMONTH(EDATE(Stammdaten!$B$6,4),0))-MAX(G15,EDATE(Stammdaten!$B$6,4))+1)/DAY(EOMONTH(EDATE(Stammdaten!$B$6,4),0)),0) | T15: =IF(C15<>"",MAX(0,MIN(H15,EOMONTH(EDATE(Stammdaten!$B$6,5),0))-MAX(G15,EDATE(Stammdaten!$B$6,5))+1)/DAY(EOMONTH(EDATE(Stammdaten!$B$6,5),0)),0) | U15: =IF(C15<>"",MAX(0,MIN(H15,EOMONTH(EDATE(Stammdaten!$B$6,6),0))-MAX(G15,EDATE(Stammdaten!$B$6,6))+1)/DAY(EOMONTH(EDATE(Stammdaten!$B$6,6),0)),0) | V15: =IF(C15<>"",MAX(0,MIN(H15,EOMONTH(EDATE(Stammdaten!$B$6,7),0))-MAX(G15,EDATE(Stammdaten!$B$6,7))+1)/DAY(EOMONTH(EDATE(Stammdaten!$B$6,7),0)),0) | W15: =IF(C15<>"",MAX(0,MIN(H15,EOMONTH(EDATE(Stammdaten!$B$6,8),0))-MAX(G15,EDATE(Stammdaten!$B$6,8))+1)/DAY(EOMONTH(EDATE(Stammdaten!$B$6,8),0)),0) | X15: =IF(C15<>"",MAX(0,MIN(H15,EOMONTH(EDATE(Stammdaten!$B$6,9),0))-MAX(G15,EDATE(Stammdaten!$B$6,9))+1)/DAY(EOMONTH(EDATE(Stammdaten!$B$6,9),0)),0) | Y15: =IF(C15<>"",MAX(0,MIN(H15,EOMONTH(EDATE(Stammdaten!$B$6,10),0))-MAX(G15,EDATE(Stammdaten!$B$6,10))+1)/DAY(EOMONTH(EDATE(Stammdaten!$B$6,10),0)),0) | Z15: =IF(C15<>"",MAX(0,MIN(H15,EOMONTH(EDATE(Stammdaten!$B$6,11),0))-MAX(G15,EDATE(Stammdaten!$B$6,11))+1)/DAY(EOMONTH(EDATE(Stammdaten!$B$6,11),0)),0)
A16: 12 | G16: =IF(C16<>"",MAX(IF(D16="",Stammdaten!$B$6,D16),Stammdaten!$B$6),"") | H16: =IF(C16<>"",MIN(IF(E16="",Stammdaten!$B$7,E16),Stammdaten!$B$7),"") | I16: =IF(C16<>"",MAX(0,H16-G16+1),0) | J16: =IF(C16<>"",I16/Stammdaten!$B$8,0) | K16: =IF(C16<>"",SUMPRODUCT(O16:Z16,$O$3:$Z$3)/Stammdaten!$E$17,0) | L16: =IF(C16<>"",IFERROR(INDEX(Stammdaten!$C$22:$C$51,MATCH(C16,Stammdaten!$A$22:$A$51,0)),0),0) | M16: =IF(C16<>"",IFERROR(INDEX(Stammdaten!$D$22:$D$51,MATCH(C16,Stammdaten!$A$22:$A$51,0)),0),0) | N16: =IF(C16<>"",IFERROR(INDEX(Stammdaten!$E$22:$E$51,MATCH(C16,Stammdaten!$A$22:$A$51,0)),0),0) | O16: =IF(C16<>"",MAX(0,MIN(H16,EOMONTH(EDATE(Stammdaten!$B$6,0),0))-MAX(G16,EDATE(Stammdaten!$B$6,0))+1)/DAY(EOMONTH(EDATE(Stammdaten!$B$6,0),0)),0) | P16: =IF(C16<>"",MAX(0,MIN(H16,EOMONTH(EDATE(Stammdaten!$B$6,1),0))-MAX(G16,EDATE(Stammdaten!$B$6,1))+1)/DAY(EOMONTH(EDATE(Stammdaten!$B$6,1),0)),0) | Q16: =IF(C16<>"",MAX(0,MIN(H16,EOMONTH(EDATE(Stammdaten!$B$6,2),0))-MAX(G16,EDATE(Stammdaten!$B$6,2))+1)/DAY(EOMONTH(EDATE(Stammdaten!$B$6,2),0)),0) | R16: =IF(C16<>"",MAX(0,MIN(H16,EOMONTH(EDATE(Stammdaten!$B$6,3),0))-MAX(G16,EDATE(Stammdaten!$B$6,3))+1)/DAY(EOMONTH(EDATE(Stammdaten!$B$6,3),0)),0) | S16: =IF(C16<>"",MAX(0,MIN(H16,EOMONTH(EDATE(Stammdaten!$B$6,4),0))-MAX(G16,EDATE(Stammdaten!$B$6,4))+1)/DAY(EOMONTH(EDATE(Stammdaten!$B$6,4),0)),0) | T16: =IF(C16<>"",MAX(0,MIN(H16,EOMONTH(EDATE(Stammdaten!$B$6,5),0))-MAX(G16,EDATE(Stammdaten!$B$6,5))+1)/DAY(EOMONTH(EDATE(Stammdaten!$B$6,5),0)),0) | U16: =IF(C16<>"",MAX(0,MIN(H16,EOMONTH(EDATE(Stammdaten!$B$6,6),0))-MAX(G16,EDATE(Stammdaten!$B$6,6))+1)/DAY(EOMONTH(EDATE(Stammdaten!$B$6,6),0)),0) | V16: =IF(C16<>"",MAX(0,MIN(H16,EOMONTH(EDATE(Stammdaten!$B$6,7),0))-MAX(G16,EDATE(Stammdaten!$B$6,7))+1)/DAY(EOMONTH(EDATE(Stammdaten!$B$6,7),0)),0) | W16: =IF(C16<>"",MAX(0,MIN(H16,EOMONTH(EDATE(Stammdaten!$B$6,8),0))-MAX(G16,EDATE(Stammdaten!$B$6,8))+1)/DAY(EOMONTH(EDATE(Stammdaten!$B$6,8),0)),0) | X16: =IF(C16<>"",MAX(0,MIN(H16,EOMONTH(EDATE(Stammdaten!$B$6,9),0))-MAX(G16,EDATE(Stammdaten!$B$6,9))+1)/DAY(EOMONTH(EDATE(Stammdaten!$B$6,9),0)),0) | Y16: =IF(C16<>"",MAX(0,MIN(H16,EOMONTH(EDATE(Stammdaten!$B$6,10),0))-MAX(G16,EDATE(Stammdaten!$B$6,10))+1)/DAY(EOMONTH(EDATE(Stammdaten!$B$6,10),0)),0) | Z16: =IF(C16<>"",MAX(0,MIN(H16,EOMONTH(EDATE(Stammdaten!$B$6,11),0))-MAX(G16,EDATE(Stammdaten!$B$6,11))+1)/DAY(EOMONTH(EDATE(Stammdaten!$B$6,11),0)),0)
... A44: 40 | G44: =IF(C44<>"",MAX(IF(D44="",Stammdaten!$B$6,D44),Stammdaten!$B$6),"") | H44: =IF(C44<>"",MIN(IF(E44="",Stammdaten!$B$7,E44),Stammdaten!$B$7),"") | I44: =IF(C44<>"",MAX(0,H44-G44+1),0) | J44: =IF(C44<>"",I44/Stammdaten!$B$8,0) | K44: =IF(C44<>"",SUMPRODUCT(O44:Z44,$O$3:$Z$3)/Stammdaten!$E$17,0) | L44: =IF(C44<>"",IFERROR(INDEX(Stammdaten!$C$22:$C$51,MATCH(C44,Stammdaten!$A$22:$A$51,0)),0),0) | M44: =IF(C44<>"",IFERROR(INDEX(Stammdaten!$D$22:$D$51,MATCH(C44,Stammdaten!$A$22:$A$51,0)),0),0) | N44: =IF(C44<>"",IFERROR(INDEX(Stammdaten!$E$22:$E$51,MATCH(C44,Stammdaten!$A$22:$A$51,0)),0),0) | O44: =IF(C44<>"",MAX(0,MIN(H44,EOMONTH(EDATE(Stammdaten!$B$6,0),0))-MAX(G44,EDATE(Stammdaten!$B$6,0))+1)/DAY(EOMONTH(EDATE(Stammdaten!$B$6,0),0)),0) | P44: =IF(C44<>"",MAX(0,MIN(H44,EOMONTH(EDATE(Stammdaten!$B$6,1),0))-MAX(G44,EDATE(Stammdaten!$B$6,1))+1)/DAY(EOMONTH(EDATE(Stammdaten!$B$6,1),0)),0) | Q44: =IF(C44<>"",MAX(0,MIN(H44,EOMONTH(EDATE(Stammdaten!$B$6,2),0))-MAX(G44,EDATE(Stammdaten!$B$6,2))+1)/DAY(EOMONTH(EDATE(Stammdaten!$B$6,2),0)),0) | R44: =IF(C44<>"",MAX(0,MIN(H44,EOMONTH(EDATE(Stammdaten!$B$6,3),0))-MAX(G44,EDATE(Stammdaten!$B$6,3))+1)/DAY(EOMONTH(EDATE(Stammdaten!$B$6,3),0)),0) | S44: =IF(C44<>"",MAX(0,MIN(H44,EOMONTH(EDATE(Stammdaten!$B$6,4),0))-MAX(G44,EDATE(Stammdaten!$B$6,4))+1)/DAY(EOMONTH(EDATE(Stammdaten!$B$6,4),0)),0) | T44: =IF(C44<>"",MAX(0,MIN(H44,EOMONTH(EDATE(Stammdaten!$B$6,5),0))-MAX(G44,EDATE(Stammdaten!$B$6,5))+1)/DAY(EOMONTH(EDATE(Stammdaten!$B$6,5),0)),0) | U44: =IF(C44<>"",MAX(0,MIN(H44,EOMONTH(EDATE(Stammdaten!$B$6,6),0))-MAX(G44,EDATE(Stammdaten!$B$6,6))+1)/DAY(EOMONTH(EDATE(Stammdaten!$B$6,6),0)),0) | V44: =IF(C44<>"",MAX(0,MIN(H44,EOMONTH(EDATE(Stammdaten!$B$6,7),0))-MAX(G44,EDATE(Stammdaten!$B$6,7))+1)/DAY(EOMONTH(EDATE(Stammdaten!$B$6,7),0)),0) | W44: =IF(C44<>"",MAX(0,MIN(H44,EOMONTH(EDATE(Stammdaten!$B$6,8),0))-MAX(G44,EDATE(Stammdaten!$B$6,8))+1)/DAY(EOMONTH(EDATE(Stammdaten!$B$6,8),0)),0) | X44: =IF(C44<>"",MAX(0,MIN(H44,EOMONTH(EDATE(Stammdaten!$B$6,9),0))-MAX(G44,EDATE(Stammdaten!$B$6,9))+1)/DAY(EOMONTH(EDATE(Stammdaten!$B$6,9),0)),0) | Y44: =IF(C44<>"",MAX(0,MIN(H44,EOMONTH(EDATE(Stammdaten!$B$6,10),0))-MAX(G44,EDATE(Stammdaten!$B$6,10))+1)/DAY(EOMONTH(EDATE(Stammdaten!$B$6,10),0)),0) | Z44: =IF(C44<>"",MAX(0,MIN(H44,EOMONTH(EDATE(Stammdaten!$B$6,11),0))-MAX(G44,EDATE(Stammdaten!$B$6,11))+1)/DAY(EOMONTH(EDATE(Stammdaten!$B$6,11),0)),0)

Sheet Verteilung
A1: Verteilung je Mieter und Kostenart
A2: Vollständig berechnet. Keine Eingaben nötig.
C3: =IF(Kosten!A5="","",Kosten!A5) | D3: =IF(Kosten!A6="","",Kosten!A6) | E3: =IF(Kosten!A7="","",Kosten!A7) | F3: =IF(Kosten!A8="","",Kosten!A8) | G3: =IF(Kosten!A9="","",Kosten!A9) | H3: =IF(Kosten!A10="","",Kosten!A10) | I3: =IF(Kosten!A11="","",Kosten!A11) | J3: =IF(Kosten!A12="","",Kosten!A12) | K3: =IF(Kosten!A13="","",Kosten!A13) | L3: =IF(Kosten!A14="","",Kosten!A14) | M3: =IF(Kosten!A15="","",Kosten!A15) | N3: =IF(Kosten!A16="","",Kosten!A16) | O3: =IF(Kosten!A17="","",Kosten!A17) | P3: =IF(Kosten!A18="","",Kosten!A18) | Q3: =IF(Kosten!A19="","",Kosten!A19) | R3: =IF(Kosten!A20="","",Kosten!A20) | S3: =IF(Kosten!A21="","",Kosten!A21) | T3: =IF(Kosten!A22="","",Kosten!A22) | U3: =IF(Kosten!A23="","",Kosten!A23) | V3: =IF(Kosten!A24="","",Kosten!A24) | W3: =IF(Kosten!A25="","",Kosten!A25) | X3: =IF(Kosten!A26="","",Kosten!A26) | Y3: =IF(Kosten!A27="","",Kosten!A27) | Z3: =IF(Kosten!A28="","",Kosten!A28) | AA3: =IF(Kosten!A29="","",Kosten!A29)
A4: Nr. | B4: Mieter | C4: K1 | D4: K2 | E4: K3 | F4: K4 | G4: K5 | H4: K6 | I4: K7 | J4: K8 | K4: K9 | L4: K10 | M4: K11 | N4: K12 | O4: K13 | P4: K14 | Q4: K15 | R4: K16 | S4: K17 | T4: K18 | U4: K19 | V4: K20 | W4: K21 | X4: K22 | Y4: K23 | Z4: K24 | AA4: K25 | AB4: Total | AC4: Akonto | AD4: Saldo
A5: =Mieter!A5 | B5: =IF(Mieter!C5="","",Mieter!B5) | C5: =IF(OR(Kosten!$B$5="",Kosten!$E$5=0,Mieter!$C5=""),0,Kosten!$B$5*IF(Kosten!$C$5="Fläche",Mieter!$L5,IF(Kosten!$C$5="Anteil",Mieter!$M5,Mieter!$N5))*IF(Kosten!$D$5="Heizung",Mieter!$K5,Mieter!$J5)/Kosten!$E$5) | D5: =IF(OR(Kosten!$B$6="",Kosten!$E$6=0,Mieter!$C5=""),0,Kosten!$B$6*IF(Kosten!$C$6="Fläche",Mieter!$L5,IF(Kosten!$C$6="Anteil",Mieter!$M5,Mieter!$N5))*IF(Kosten!$D$6="Heizung",Mieter!$K5,Mieter!$J5)/Kosten!$E$6) | E5: =IF(OR(Kosten!$B$7="",Kosten!$E$7=0,Mieter!$C5=""),0,Kosten!$B$7*IF(Kosten!$C$7="Fläche",Mieter!$L5,IF(Kosten!$C$7="Anteil",Mieter!$M5,Mieter!$N5))*IF(Kosten!$D$7="Heizung",Mieter!$K5,Mieter!$J5)/Kosten!$E$7) | F5: =IF(OR(Kosten!$B$8="",Kosten!$E$8=0,Mieter!$C5=""),0,Kosten!$B$8*IF(Kosten!$C$8="Fläche",Mieter!$L5,IF(Kosten!$C$8="Anteil",Mieter!$M5,Mieter!$N5))*IF(Kosten!$D$8="Heizung",Mieter!$K5,Mieter!$J5)/Kosten!$E$8) | G5: =IF(OR(Kosten!$B$9="",Kosten!$E$9=0,Mieter!$C5=""),0,Kosten!$B$9*IF(Kosten!$C$9="Fläche",Mieter!$L5,IF(Kosten!$C$9="Anteil",Mieter!$M5,Mieter!$N5))*IF(Kosten!$D$9="Heizung",Mieter!$K5,Mieter!$J5)/Kosten!$E$9) | H5: =IF(OR(Kosten!$B$10="",Kosten!$E$10=0,Mieter!$C5=""),0,Kosten!$B$10*IF(Kosten!$C$10="Fläche",Mieter!$L5,IF(Kosten!$C$10="Anteil",Mieter!$M5,Mieter!$N5))*IF(Kosten!$D$10="Heizung",Mieter!$K5,Mieter!$J5)/Kosten!$E$10) | I5: =IF(OR(Kosten!$B$11="",Kosten!$E$11=0,Mieter!$C5=""),0,Kosten!$B$11*IF(Kosten!$C$11="Fläche",Mieter!$L5,IF(Kosten!$C$11="Anteil",Mieter!$M5,Mieter!$N5))*IF(Kosten!$D$11="Heizung",Mieter!$K5,Mieter!$J5)/Kosten!$E$11) | J5: =IF(OR(Kosten!$B$12="",Kosten!$E$12=0,Mieter!$C5=""),0,Kosten!$B$12*IF(Kosten!$C$12="Fläche",Mieter!$L5,IF(Kosten!$C$12="Anteil",Mieter!$M5,Mieter!$N5))*IF(Kosten!$D$12="Heizung",Mieter!$K5,Mieter!$J5)/Kosten!$E$12) | K5: =IF(OR(Kosten!$B$13="",Kosten!$E$13=0,Mieter!$C5=""),0,Kosten!$B$13*IF(Kosten!$C$13="Fläche",Mieter!$L5,IF(Kosten!$C$13="Anteil",Mieter!$M5,Mieter!$N5))*IF(Kosten!$D$13="Heizung",Mieter!$K5,Mieter!$J5)/Kosten!$E$13) | L5: =IF(OR(Kosten!$B$14="",Kosten!$E$14=0,Mieter!$C5=""),0,Kosten!$B$14*IF(Kosten!$C$14="Fläche",Mieter!$L5,IF(Kosten!$C$14="Anteil",Mieter!$M5,Mieter!$N5))*IF(Kosten!$D$14="Heizung",Mieter!$K5,Mieter!$J5)/Kosten!$E$14) | M5: =IF(OR(Kosten!$B$15="",Kosten!$E$15=0,Mieter!$C5=""),0,Kosten!$B$15*IF(Kosten!$C$15="Fläche",Mieter!$L5,IF(Kosten!$C$15="Anteil",Mieter!$M5,Mieter!$N5))*IF(Kosten!$D$15="Heizung",Mieter!$K5,Mieter!$J5)/Kosten!$E$15) | N5: =IF(OR(Kosten!$B$16="",Kosten!$E$16=0,Mieter!$C5=""),0,Kosten!$B$16*IF(Kosten!$C$16="Fläche",Mieter!$L5,IF(Kosten!$C$16="Anteil",Mieter!$M5,Mieter!$N5))*IF(Kosten!$D$16="Heizung",Mieter!$K5,Mieter!$J5)/Kosten!$E$16) | O5: =IF(OR(Kosten!$B$17="",Kosten!$E$17=0,Mieter!$C5=""),0,Kosten!$B$17*IF(Kosten!$C$17="Fläche",Mieter!$L5,IF(Kosten!$C$17="Anteil",Mieter!$M5,Mieter!$N5))*IF(Kosten!$D$17="Heizung",Mieter!$K5,Mieter!$J5)/Kosten!$E$17) | P5: =IF(OR(Kosten!$B$18="",Kosten!$E$18=0,Mieter!$C5=""),0,Kosten!$B$18*IF(Kosten!$C$18="Fläche",Mieter!$L5,IF(Kosten!$C$18="Anteil",Mieter!$M5,Mieter!$N5))*IF(Kosten!$D$18="Heizung",Mieter!$K5,Mieter!$J5)/Kosten!$E$18) | Q5: =IF(OR(Kosten!$B$19="",Kosten!$E$19=0,Mieter!$C5=""),0,Kosten!$B$19*IF(Kosten!$C$19="Fläche",Mieter!$L5,IF(Kosten!$C$19="Anteil",Mieter!$M5,Mieter!$N5))*IF(Kosten!$D$19="Heizung",Mieter!$K5,Mieter!$J5)/Kosten!$E$19) | R5: =IF(OR(Kosten!$B$20="",Kosten!$E$20=0,Mieter!$C5=""),0,Kosten!$B$20*IF(Kosten!$C$20="Fläche",Mieter!$L5,IF(Kosten!$C$20="Anteil",Mieter!$M5,Mieter!$N5))*IF(Kosten!$D$20="Heizung",Mieter!$K5,Mieter!$J5)/Kosten!$E$20) | S5: =IF(OR(Kosten!$B$21="",Kosten!$E$21=0,Mieter!$C5=""),0,Kosten!$B$21*IF(Kosten!$C$21="Fläche",Mieter!$L5,IF(Kosten!$C$21="Anteil",Mieter!$M5,Mieter!$N5))*IF(Kosten!$D$21="Heizung",Mieter!$K5,Mieter!$J5)/Kosten!$E$21) | T5: =IF(OR(Kosten!$B$22="",Kosten!$E$22=0,Mieter!$C5=""),0,Kosten!$B$22*IF(Kosten!$C$22="Fläche",Mieter!$L5,IF(Kosten!$C$22="Anteil",Mieter!$M5,Mieter!$N5))*IF(Kosten!$D$22="Heizung",Mieter!$K5,Mieter!$J5)/Kosten!$E$22) | U5: =IF(OR(Kosten!$B$23="",Kosten!$E$23=0,Mieter!$C5=""),0,Kosten!$B$23*IF(Kosten!$C$23="Fläche",Mieter!$L5,IF(Kosten!$C$23="Anteil",Mieter!$M5,Mieter!$N5))*IF(Kosten!$D$23="Heizung",Mieter!$K5,Mieter!$J5)/Kosten!$E$23) | V5: =IF(OR(Kosten!$B$24="",Kosten!$E$24=0,Mieter!$C5=""),0,Kosten!$B$24*IF(Kosten!$C$24="Fläche",Mieter!$L5,IF(Kosten!$C$24="Anteil",Mieter!$M5,Mieter!$N5))*IF(Kosten!$D$24="Heizung",Mieter!$K5,Mieter!$J5)/Kosten!$E$24) | W5: =IF(OR(Kosten!$B$25="",Kosten!$E$25=0,Mieter!$C5=""),0,Kosten!$B$25*IF(Kosten!$C$25="Fläche",Mieter!$L5,IF(Kosten!$C$25="Anteil",Mieter!$M5,Mieter!$N5))*IF(Kosten!$D$25="Heizung",Mieter!$K5,Mieter!$J5)/Kosten!$E$25) | X5: =IF(OR(Kosten!$B$26="",Kosten!$E$26=0,Mieter!$C5=""),0,Kosten!$B$26*IF(Kosten!$C$26="Fläche",Mieter!$L5,IF(Kosten!$C$26="Anteil",Mieter!$M5,Mieter!$N5))*IF(Kosten!$D$26="Heizung",Mieter!$K5,Mieter!$J5)/Kosten!$E$26) | Y5: =IF(OR(Kosten!$B$27="",Kosten!$E$27=0,Mieter!$C5=""),0,Kosten!$B$27*IF(Kosten!$C$27="Fläche",Mieter!$L5,IF(Kosten!$C$27="Anteil",Mieter!$M5,Mieter!$N5))*IF(Kosten!$D$27="Heizung",Mieter!$K5,Mieter!$J5)/Kosten!$E$27) | Z5: =IF(OR(Kosten!$B$28="",Kosten!$E$28=0,Mieter!$C5=""),0,Kosten!$B$28*IF(Kosten!$C$28="Fläche",Mieter!$L5,IF(Kosten!$C$28="Anteil",Mieter!$M5,Mieter!$N5))*IF(Kosten!$D$28="Heizung",Mieter!$K5,Mieter!$J5)/Kosten!$E$28) | AA5: =IF(OR(Kosten!$B$29="",Kosten!$E$29=0,Mieter!$C5=""),0,Kosten!$B$29*IF(Kosten!$C$29="Fläche",Mieter!$L5,IF(Kosten!$C$29="Anteil",Mieter!$M5,Mieter!$N5))*IF(Kosten!$D$29="Heizung",Mieter!$K5,Mieter!$J5)/Kosten!$E$29) | AB5: =ROUND(SUM(C5:AA5)*20,0)/20 | AC5: =N(Mieter!F5) | AD5: =AB5-AC5
A6: =Mieter!A6 | B6: =IF(Mieter!C6="","",Mieter!B6) | C6: =IF(OR(Kosten!$B$5="",Kosten!$E$5=0,Mieter!$C6=""),0,Kosten!$B$5*IF(Kosten!$C$5="Fläche",Mieter!$L6,IF(Kosten!$C$5="Anteil",Mieter!$M6,Mieter!$N6))*IF(Kosten!$D$5="Heizung",Mieter!$K6,Mieter!$J6)/Kosten!$E$5) | D6: =IF(OR(Kosten!$B$6="",Kosten!$E$6=0,Mieter!$C6=""),0,Kosten!$B$6*IF(Kosten!$C$6="Fläche",Mieter!$L6,IF(Kosten!$C$6="Anteil",Mieter!$M6,Mieter!$N6))*IF(Kosten!$D$6="Heizung",Mieter!$K6,Mieter!$J6)/Kosten!$E$6) | E6: =IF(OR(Kosten!$B$7="",Kosten!$E$7=0,Mieter!$C6=""),0,Kosten!$B$7*IF(Kosten!$C$7="Fläche",Mieter!$L6,IF(Kosten!$C$7="Anteil",Mieter!$M6,Mieter!$N6))*IF(Kosten!$D$7="Heizung",Mieter!$K6,Mieter!$J6)/Kosten!$E$7) | F6: =IF(OR(Kosten!$B$8="",Kosten!$E$8=0,Mieter!$C6=""),0,Kosten!$B$8*IF(Kosten!$C$8="Fläche",Mieter!$L6,IF(Kosten!$C$8="Anteil",Mieter!$M6,Mieter!$N6))*IF(Kosten!$D$8="Heizung",Mieter!$K6,Mieter!$J6)/Kosten!$E$8) | G6: =IF(OR(Kosten!$B$9="",Kosten!$E$9=0,Mieter!$C6=""),0,Kosten!$B$9*IF(Kosten!$C$9="Fläche",Mieter!$L6,IF(Kosten!$C$9="Anteil",Mieter!$M6,Mieter!$N6))*IF(Kosten!$D$9="Heizung",Mieter!$K6,Mieter!$J6)/Kosten!$E$9) | H6: =IF(OR(Kosten!$B$10="",Kosten!$E$10=0,Mieter!$C6=""),0,Kosten!$B$10*IF(Kosten!$C$10="Fläche",Mieter!$L6,IF(Kosten!$C$10="Anteil",Mieter!$M6,Mieter!$N6))*IF(Kosten!$D$10="Heizung",Mieter!$K6,Mieter!$J6)/Kosten!$E$10) | I6: =IF(OR(Kosten!$B$11="",Kosten!$E$11=0,Mieter!$C6=""),0,Kosten!$B$11*IF(Kosten!$C$11="Fläche",Mieter!$L6,IF(Kosten!$C$11="Anteil",Mieter!$M6,Mieter!$N6))*IF(Kosten!$D$11="Heizung",Mieter!$K6,Mieter!$J6)/Kosten!$E$11) | J6: =IF(OR(Kosten!$B$12="",Kosten!$E$12=0,Mieter!$C6=""),0,Kosten!$B$12*IF(Kosten!$C$12="Fläche",Mieter!$L6,IF(Kosten!$C$12="Anteil",Mieter!$M6,Mieter!$N6))*IF(Kosten!$D$12="Heizung",Mieter!$K6,Mieter!$J6)/Kosten!$E$12) | K6: =IF(OR(Kosten!$B$13="",Kosten!$E$13=0,Mieter!$C6=""),0,Kosten!$B$13*IF(Kosten!$C$13="Fläche",Mieter!$L6,IF(Kosten!$C$13="Anteil",Mieter!$M6,Mieter!$N6))*IF(Kosten!$D$13="Heizung",Mieter!$K6,Mieter!$J6)/Kosten!$E$13) | L6: =IF(OR(Kosten!$B$14="",Kosten!$E$14=0,Mieter!$C6=""),0,Kosten!$B$14*IF(Kosten!$C$14="Fläche",Mieter!$L6,IF(Kosten!$C$14="Anteil",Mieter!$M6,Mieter!$N6))*IF(Kosten!$D$14="Heizung",Mieter!$K6,Mieter!$J6)/Kosten!$E$14) | M6: =IF(OR(Kosten!$B$15="",Kosten!$E$15=0,Mieter!$C6=""),0,Kosten!$B$15*IF(Kosten!$C$15="Fläche",Mieter!$L6,IF(Kosten!$C$15="Anteil",Mieter!$M6,Mieter!$N6))*IF(Kosten!$D$15="Heizung",Mieter!$K6,Mieter!$J6)/Kosten!$E$15) | N6: =IF(OR(Kosten!$B$16="",Kosten!$E$16=0,Mieter!$C6=""),0,Kosten!$B$16*IF(Kosten!$C$16="Fläche",Mieter!$L6,IF(Kosten!$C$16="Anteil",Mieter!$M6,Mieter!$N6))*IF(Kosten!$D$16="Heizung",Mieter!$K6,Mieter!$J6)/Kosten!$E$16) | O6: =IF(OR(Kosten!$B$17="",Kosten!$E$17=0,Mieter!$C6=""),0,Kosten!$B$17*IF(Kosten!$C$17="Fläche",Mieter!$L6,IF(Kosten!$C$17="Anteil",Mieter!$M6,Mieter!$N6))*IF(Kosten!$D$17="Heizung",Mieter!$K6,Mieter!$J6)/Kosten!$E$17) | P6: =IF(OR(Kosten!$B$18="",Kosten!$E$18=0,Mieter!$C6=""),0,Kosten!$B$18*IF(Kosten!$C$18="Fläche",Mieter!$L6,IF(Kosten!$C$18="Anteil",Mieter!$M6,Mieter!$N6))*IF(Kosten!$D$18="Heizung",Mieter!$K6,Mieter!$J6)/Kosten!$E$18) | Q6: =IF(OR(Kosten!$B$19="",Kosten!$E$19=0,Mieter!$C6=""),0,Kosten!$B$19*IF(Kosten!$C$19="Fläche",Mieter!$L6,IF(Kosten!$C$19="Anteil",Mieter!$M6,Mieter!$N6))*IF(Kosten!$D$19="Heizung",Mieter!$K6,Mieter!$J6)/Kosten!$E$19) | R6: =IF(OR(Kosten!$B$20="",Kosten!$E$20=0,Mieter!$C6=""),0,Kosten!$B$20*IF(Kosten!$C$20="Fläche",Mieter!$L6,IF(Kosten!$C$20="Anteil",Mieter!$M6,Mieter!$N6))*IF(Kosten!$D$20="Heizung",Mieter!$K6,Mieter!$J6)/Kosten!$E$20) | S6: =IF(OR(Kosten!$B$21="",Kosten!$E$21=0,Mieter!$C6=""),0,Kosten!$B$21*IF(Kosten!$C$21="Fläche",Mieter!$L6,IF(Kosten!$C$21="Anteil",Mieter!$M6,Mieter!$N6))*IF(Kosten!$D$21="Heizung",Mieter!$K6,Mieter!$J6)/Kosten!$E$21) | T6: =IF(OR(Kosten!$B$22="",Kosten!$E$22=0,Mieter!$C6=""),0,Kosten!$B$22*IF(Kosten!$C$22="Fläche",Mieter!$L6,IF(Kosten!$C$22="Anteil",Mieter!$M6,Mieter!$N6))*IF(Kosten!$D$22="Heizung",Mieter!$K6,Mieter!$J6)/Kosten!$E$22) | U6: =IF(OR(Kosten!$B$23="",Kosten!$E$23=0,Mieter!$C6=""),0,Kosten!$B$23*IF(Kosten!$C$23="Fläche",Mieter!$L6,IF(Kosten!$C$23="Anteil",Mieter!$M6,Mieter!$N6))*IF(Kosten!$D$23="Heizung",Mieter!$K6,Mieter!$J6)/Kosten!$E$23) | V6: =IF(OR(Kosten!$B$24="",Kosten!$E$24=0,Mieter!$C6=""),0,Kosten!$B$24*IF(Kosten!$C$24="Fläche",Mieter!$L6,IF(Kosten!$C$24="Anteil",Mieter!$M6,Mieter!$N6))*IF(Kosten!$D$24="Heizung",Mieter!$K6,Mieter!$J6)/Kosten!$E$24) | W6: =IF(OR(Kosten!$B$25="",Kosten!$E$25=0,Mieter!$C6=""),0,Kosten!$B$25*IF(Kosten!$C$25="Fläche",Mieter!$L6,IF(Kosten!$C$25="Anteil",Mieter!$M6,Mieter!$N6))*IF(Kosten!$D$25="Heizung",Mieter!$K6,Mieter!$J6)/Kosten!$E$25) | X6: =IF(OR(Kosten!$B$26="",Kosten!$E$26=0,Mieter!$C6=""),0,Kosten!$B$26*IF(Kosten!$C$26="Fläche",Mieter!$L6,IF(Kosten!$C$26="Anteil",Mieter!$M6,Mieter!$N6))*IF(Kosten!$D$26="Heizung",Mieter!$K6,Mieter!$J6)/Kosten!$E$26) | Y6: =IF(OR(Kosten!$B$27="",Kosten!$E$27=0,Mieter!$C6=""),0,Kosten!$B$27*IF(Kosten!$C$27="Fläche",Mieter!$L6,IF(Kosten!$C$27="Anteil",Mieter!$M6,Mieter!$N6))*IF(Kosten!$D$27="Heizung",Mieter!$K6,Mieter!$J6)/Kosten!$E$27) | Z6: =IF(OR(Kosten!$B$28="",Kosten!$E$28=0,Mieter!$C6=""),0,Kosten!$B$28*IF(Kosten!$C$28="Fläche",Mieter!$L6,IF(Kosten!$C$28="Anteil",Mieter!$M6,Mieter!$N6))*IF(Kosten!$D$28="Heizung",Mieter!$K6,Mieter!$J6)/Kosten!$E$28) | AA6: =IF(OR(Kosten!$B$29="",Kosten!$E$29=0,Mieter!$C6=""),0,Kosten!$B$29*IF(Kosten!$C$29="Fläche",Mieter!$L6,IF(Kosten!$C$29="Anteil",Mieter!$M6,Mieter!$N6))*IF(Kosten!$D$29="Heizung",Mieter!$K6,Mieter!$J6)/Kosten!$E$29) | AB6: =ROUND(SUM(C6:AA6)*20,0)/20 | AC6: =N(Mieter!F6) | AD6: =AB6-AC6
A7: =Mieter!A7 | B7: =IF(Mieter!C7="","",Mieter!B7) | C7: =IF(OR(Kosten!$B$5="",Kosten!$E$5=0,Mieter!$C7=""),0,Kosten!$B$5*IF(Kosten!$C$5="Fläche",Mieter!$L7,IF(Kosten!$C$5="Anteil",Mieter!$M7,Mieter!$N7))*IF(Kosten!$D$5="Heizung",Mieter!$K7,Mieter!$J7)/Kosten!$E$5) | D7: =IF(OR(Kosten!$B$6="",Kosten!$E$6=0,Mieter!$C7=""),0,Kosten!$B$6*IF(Kosten!$C$6="Fläche",Mieter!$L7,IF(Kosten!$C$6="Anteil",Mieter!$M7,Mieter!$N7))*IF(Kosten!$D$6="Heizung",Mieter!$K7,Mieter!$J7)/Kosten!$E$6) | E7: =IF(OR(Kosten!$B$7="",Kosten!$E$7=0,Mieter!$C7=""),0,Kosten!$B$7*IF(Kosten!$C$7="Fläche",Mieter!$L7,IF(Kosten!$C$7="Anteil",Mieter!$M7,Mieter!$N7))*IF(Kosten!$D$7="Heizung",Mieter!$K7,Mieter!$J7)/Kosten!$E$7) | F7: =IF(OR(Kosten!$B$8="",Kosten!$E$8=0,Mieter!$C7=""),0,Kosten!$B$8*IF(Kosten!$C$8="Fläche",Mieter!$L7,IF(Kosten!$C$8="Anteil",Mieter!$M7,Mieter!$N7))*IF(Kosten!$D$8="Heizung",Mieter!$K7,Mieter!$J7)/Kosten!$E$8) | G7: =IF(OR(Kosten!$B$9="",Kosten!$E$9=0,Mieter!$C7=""),0,Kosten!$B$9*IF(Kosten!$C$9="Fläche",Mieter!$L7,IF(Kosten!$C$9="Anteil",Mieter!$M7,Mieter!$N7))*IF(Kosten!$D$9="Heizung",Mieter!$K7,Mieter!$J7)/Kosten!$E$9) | H7: =IF(OR(Kosten!$B$10="",Kosten!$E$10=0,Mieter!$C7=""),0,Kosten!$B$10*IF(Kosten!$C$10="Fläche",Mieter!$L7,IF(Kosten!$C$10="Anteil",Mieter!$M7,Mieter!$N7))*IF(Kosten!$D$10="Heizung",Mieter!$K7,Mieter!$J7)/Kosten!$E$10) | I7: =IF(OR(Kosten!$B$11="",Kosten!$E$11=0,Mieter!$C7=""),0,Kosten!$B$11*IF(Kosten!$C$11="Fläche",Mieter!$L7,IF(Kosten!$C$11="Anteil",Mieter!$M7,Mieter!$N7))*IF(Kosten!$D$11="Heizung",Mieter!$K7,Mieter!$J7)/Kosten!$E$11) | J7: =IF(OR(Kosten!$B$12="",Kosten!$E$12=0,Mieter!$C7=""),0,Kosten!$B$12*IF(Kosten!$C$12="Fläche",Mieter!$L7,IF(Kosten!$C$12="Anteil",Mieter!$M7,Mieter!$N7))*IF(Kosten!$D$12="Heizung",Mieter!$K7,Mieter!$J7)/Kosten!$E$12) | K7: =IF(OR(Kosten!$B$13="",Kosten!$E$13=0,Mieter!$C7=""),0,Kosten!$B$13*IF(Kosten!$C$13="Fläche",Mieter!$L7,IF(Kosten!$C$13="Anteil",Mieter!$M7,Mieter!$N7))*IF(Kosten!$D$13="Heizung",Mieter!$K7,Mieter!$J7)/Kosten!$E$13) | L7: =IF(OR(Kosten!$B$14="",Kosten!$E$14=0,Mieter!$C7=""),0,Kosten!$B$14*IF(Kosten!$C$14="Fläche",Mieter!$L7,IF(Kosten!$C$14="Anteil",Mieter!$M7,Mieter!$N7))*IF(Kosten!$D$14="Heizung",Mieter!$K7,Mieter!$J7)/Kosten!$E$14) | M7: =IF(OR(Kosten!$B$15="",Kosten!$E$15=0,Mieter!$C7=""),0,Kosten!$B$15*IF(Kosten!$C$15="Fläche",Mieter!$L7,IF(Kosten!$C$15="Anteil",Mieter!$M7,Mieter!$N7))*IF(Kosten!$D$15="Heizung",Mieter!$K7,Mieter!$J7)/Kosten!$E$15) | N7: =IF(OR(Kosten!$B$16="",Kosten!$E$16=0,Mieter!$C7=""),0,Kosten!$B$16*IF(Kosten!$C$16="Fläche",Mieter!$L7,IF(Kosten!$C$16="Anteil",Mieter!$M7,Mieter!$N7))*IF(Kosten!$D$16="Heizung",Mieter!$K7,Mieter!$J7)/Kosten!$E$16) | O7: =IF(OR(Kosten!$B$17="",Kosten!$E$17=0,Mieter!$C7=""),0,Kosten!$B$17*IF(Kosten!$C$17="Fläche",Mieter!$L7,IF(Kosten!$C$17="Anteil",Mieter!$M7,Mieter!$N7))*IF(Kosten!$D$17="Heizung",Mieter!$K7,Mieter!$J7)/Kosten!$E$17) | P7: =IF(OR(Kosten!$B$18="",Kosten!$E$18=0,Mieter!$C7=""),0,Kosten!$B$18*IF(Kosten!$C$18="Fläche",Mieter!$L7,IF(Kosten!$C$18="Anteil",Mieter!$M7,Mieter!$N7))*IF(Kosten!$D$18="Heizung",Mieter!$K7,Mieter!$J7)/Kosten!$E$18) | Q7: =IF(OR(Kosten!$B$19="",Kosten!$E$19=0,Mieter!$C7=""),0,Kosten!$B$19*IF(Kosten!$C$19="Fläche",Mieter!$L7,IF(Kosten!$C$19="Anteil",Mieter!$M7,Mieter!$N7))*IF(Kosten!$D$19="Heizung",Mieter!$K7,Mieter!$J7)/Kosten!$E$19) | R7: =IF(OR(Kosten!$B$20="",Kosten!$E$20=0,Mieter!$C7=""),0,Kosten!$B$20*IF(Kosten!$C$20="Fläche",Mieter!$L7,IF(Kosten!$C$20="Anteil",Mieter!$M7,Mieter!$N7))*IF(Kosten!$D$20="Heizung",Mieter!$K7,Mieter!$J7)/Kosten!$E$20) | S7: =IF(OR(Kosten!$B$21="",Kosten!$E$21=0,Mieter!$C7=""),0,Kosten!$B$21*IF(Kosten!$C$21="Fläche",Mieter!$L7,IF(Kosten!$C$21="Anteil",Mieter!$M7,Mieter!$N7))*IF(Kosten!$D$21="Heizung",Mieter!$K7,Mieter!$J7)/Kosten!$E$21) | T7: =IF(OR(Kosten!$B$22="",Kosten!$E$22=0,Mieter!$C7=""),0,Kosten!$B$22*IF(Kosten!$C$22="Fläche",Mieter!$L7,IF(Kosten!$C$22="Anteil",Mieter!$M7,Mieter!$N7))*IF(Kosten!$D$22="Heizung",Mieter!$K7,Mieter!$J7)/Kosten!$E$22) | U7: =IF(OR(Kosten!$B$23="",Kosten!$E$23=0,Mieter!$C7=""),0,Kosten!$B$23*IF(Kosten!$C$23="Fläche",Mieter!$L7,IF(Kosten!$C$23="Anteil",Mieter!$M7,Mieter!$N7))*IF(Kosten!$D$23="Heizung",Mieter!$K7,Mieter!$J7)/Kosten!$E$23) | V7: =IF(OR(Kosten!$B$24="",Kosten!$E$24=0,Mieter!$C7=""),0,Kosten!$B$24*IF(Kosten!$C$24="Fläche",Mieter!$L7,IF(Kosten!$C$24="Anteil",Mieter!$M7,Mieter!$N7))*IF(Kosten!$D$24="Heizung",Mieter!$K7,Mieter!$J7)/Kosten!$E$24) | W7: =IF(OR(Kosten!$B$25="",Kosten!$E$25=0,Mieter!$C7=""),0,Kosten!$B$25*IF(Kosten!$C$25="Fläche",Mieter!$L7,IF(Kosten!$C$25="Anteil",Mieter!$M7,Mieter!$N7))*IF(Kosten!$D$25="Heizung",Mieter!$K7,Mieter!$J7)/Kosten!$E$25) | X7: =IF(OR(Kosten!$B$26="",Kosten!$E$26=0,Mieter!$C7=""),0,Kosten!$B$26*IF(Kosten!$C$26="Fläche",Mieter!$L7,IF(Kosten!$C$26="Anteil",Mieter!$M7,Mieter!$N7))*IF(Kosten!$D$26="Heizung",Mieter!$K7,Mieter!$J7)/Kosten!$E$26) | Y7: =IF(OR(Kosten!$B$27="",Kosten!$E$27=0,Mieter!$C7=""),0,Kosten!$B$27*IF(Kosten!$C$27="Fläche",Mieter!$L7,IF(Kosten!$C$27="Anteil",Mieter!$M7,Mieter!$N7))*IF(Kosten!$D$27="Heizung",Mieter!$K7,Mieter!$J7)/Kosten!$E$27) | Z7: =IF(OR(Kosten!$B$28="",Kosten!$E$28=0,Mieter!$C7=""),0,Kosten!$B$28*IF(Kosten!$C$28="Fläche",Mieter!$L7,IF(Kosten!$C$28="Anteil",Mieter!$M7,Mieter!$N7))*IF(Kosten!$D$28="Heizung",Mieter!$K7,Mieter!$J7)/Kosten!$E$28) | AA7: =IF(OR(Kosten!$B$29="",Kosten!$E$29=0,Mieter!$C7=""),0,Kosten!$B$29*IF(Kosten!$C$29="Fläche",Mieter!$L7,IF(Kosten!$C$29="Anteil",Mieter!$M7,Mieter!$N7))*IF(Kosten!$D$29="Heizung",Mieter!$K7,Mieter!$J7)/Kosten!$E$29) | AB7: =ROUND(SUM(C7:AA7)*20,0)/20 | AC7: =N(Mieter!F7) | AD7: =AB7-AC7
