Workbook

Sheet Übersicht
A1: Hausklar – Übersicht 5 Jahre
A2: ="Szenario: "&Annahmen!C4&" · Wechsel in Annahmen!C4"
A4: Kennzahl | C4: 2027 | D4: 2028 | E4: 2029 | F4: 2030 | G4: 2031
A5: Umsatz | C5: =Modell!C18 | D5: =Modell!D18 | E5: =Modell!E18 | F5: =Modell!F18 | G5: =Modell!G18
A6: EBITDA | C6: =Modell!C28 | D6: =Modell!D28 | E6: =Modell!E28 | F6: =Modell!F28 | G6: =Modell!G28
A7: EBITDA-Marge | C7: =Modell!C29 | D7: =Modell!D29 | E7: =Modell!E29 | F7: =Modell!F29 | G7: =Modell!G29
A8: Jahresergebnis | C8: =Modell!C34 | D8: =Modell!D34 | E8: =Modell!E34 | F8: =Modell!F34 | G8: =Modell!G34
A9: Liquide Mittel Jahresende | C9: =Modell!C54 | D9: =Modell!D54 | E9: =Modell!E54 | F9: =Modell!F54 | G9: =Modell!G54
A10: Miet-Einheiten Jahresende | C10: =Modell!C9 | D10: =Modell!D9 | E10: =Modell!E9 | F10: =Modell!F9 | G10: =Modell!G9
A11: STWE-Einheiten Jahresende | C11: =Modell!C10 | D11: =Modell!D10 | E11: =Modell!E10 | F11: =Modell!F10 | G11: =Modell!G10
A12: Mitarbeitende FTE | C12: =Modell!C59 | D12: =Modell!D59 | E12: =Modell!E59 | F12: =Modell!F59 | G12: =Modell!G59
A13: Umsatz je FTE | C13: =Modell!C58 | D13: =Modell!D58 | E13: =Modell!E58 | F13: =Modell!F58 | G13: =Modell!G58
A14: Run-Rate Jahresende | C14: =Modell!C60 | D14: =Modell!D60 | E14: =Modell!E60 | F14: =Modell!F60 | G14: =Modell!G60
A15: Nettoverschuldung / EBITDA | C15: =Modell!C55 | D15: =Modell!D55 | E15: =Modell!E55 | F15: =Modell!F55 | G15: =Modell!G55
A16: Ziel CHF 10 Mio. erreicht? | C16: =Modell!C61 | D16: =Modell!D61 | E16: =Modell!E61 | F16: =Modell!F61 | G16: =Modell!G61
A19: Lesehilfe
A20: Die Zahlen sind ein Plan, keine Prognose. Jede Zeile lässt sich über «Annahmen» nachvollziehen.
A21: Die grösste Stellschraube ist das Übernahmevolumen; die zweitgrösste die Produktivität je Bewirtschafter.

Sheet Annahmen
A1: Hausklar – Finanzmodell · Annahmen
A2: Blaue Werte sind Eingaben. Alles andere ist berechnet. Quelle/Begründung in Spalte H. Alle Beträge in CHF ohne MWST.
A4: Szenario | C4: Basis | D4: =IF(C4="Vorsichtig",0.6,IF(C4="Stark",1.3,1)) | E4: ← Faktor auf Neugeschäft und Übernahmen
A6: Markt und Preise (einmalige Werte in Spalte C) | C6: 2027 | D6: 2028 | E6: 2029 | F6: 2030 | G6: 2031
A7: Durchschnittliche Nettomiete je Wohnung | B7: CHF/Mt. | C7: 1485 | H7: BFS, Strukturerhebung 2024: Durchschnittsmiete CHF 1485 (alle Grössen).
A8: Bewirtschaftungshonorar Mietliegenschaften (Mischsatz) | B8: % Nettomiete | C8: 0.034 | H8: Markt 3–6 %, meist 4–5 % (bovita.ch, kama-plus.ch). mory.ai: 2 %. Hausklar Neukunden 2,9 %, übernommene Mandate behalten ihren Satz (~4 %) → Mischsatz 3,4 %.
A9: Honorarsatz übernommener Mandate | B9: % Nettomiete | C9: 0.04 | H9: Bestehende Verträge laufen zum Marktsatz weiter (4–5 %). Nur für den Kaufpreis verwendet; der Ertrag wird vorsichtig mit dem Mischsatz gerechnet.
A10: Honorar Stockwerkeigentum je Einheit | B10: CHF/Jahr | C10: 480 | H10: Markt CHF 350–500 je Einheit plus Grundhonorar CHF 2000–3000 je Gemeinschaft (hausinfo.ch, bawos.ch). Grundhonorar hier im Einheitenpreis enthalten.
A11: Zusatzerträge (Erstvermietung, Mieterwechsel, Bauherrenvertretung, NK-Abrechnung) | B11: % Grundhonorar | C11: 0.22 | H11: Beispielfirma CH: CHF 400k Fixhonorar + CHF 200k einmalige Erträge = 50 %. Konservativ 22 %.
A12: Kündigungsrate Mandate (Einheiten) | B12: %/Jahr | C12: 0.05 | H12: Annahme. Verwaltungsmandate sind langlebig (Kündigungsfristen, Wechselaufwand).
A14: Wachstum (Basis, wird mit Szenariofaktor multipliziert) | C14: 2027 | D14: 2028 | E14: 2029 | F14: 2030 | G14: 2031
A15: Neue Mieteinheiten organisch (Neukunden) | B15: Einheiten | C15: 250 | D15: 700 | E15: 1200 | F15: 1600 | G15: 2000 | H15: Vertriebstrichter siehe 04-vertrieb.md: Jahr 1 ≈ 12 Mandate à 20 Einheiten.
A16: Neue STWE-Einheiten organisch | B16: Einheiten | C16: 150 | D16: 450 | E16: 800 | F16: 1100 | G16: 1400 | H16: Kleine STWEG finden kaum Verwalter (NZZ, 13.11.2025). Ø 10 Einheiten je Gemeinschaft.
A17: Übernommene Mieteinheiten (Nachfolgelösungen) | B17: Einheiten | C17: 700 | D17: 1300 | E17: 1800 | F17: 2200 | G17: 2500 | H17: 90'667 KMU mit offener Nachfolge (Dun & Bradstreet, März 2025). Kleinverwaltung Ø 700–1500 Einheiten.
A18: Übernommene STWE-Einheiten | B18: Einheiten | C18: 300 | D18: 600 | E18: 900 | F18: 1100 | G18: 1300 | H18: Mit den Übernahmen mitkommend.
A19: Anteil Umsatz im Zugangsjahr | B19: % | C19: 0.5 | H19: Halbjahreskonvention: Zugang im Mittel zur Jahresmitte.
A21: Übernahmen | C21: 2027 | D21: 2028 | E21: 2029 | F21: 2030 | G21: 2031
A22: Kaufpreis in Jahresumsätzen | B22: x Umsatz | C22: 1 | H22: Implenia/Wincasa: CHF 171,6 Mio. für CHF 159 Mio. Umsatz = 1,08x (cash.ch). Kleinfirmen tiefer.
A23: davon bar bei Vollzug | B23: % | C23: 0.5 | H23: Übliche Struktur Nachfolge-Deal; Rest Verkäuferdarlehen und Earn-out.
A24: davon Verkäuferdarlehen (3 Jahre) | B24: % | C24: 0.3 | H24: Rückzahlung in 3 gleichen Raten ab Folgejahr.
A25: davon Earn-out (im Folgejahr fällig) | B25: % | C25: 0.2 | H25: Nur bei Kundenbindung >90 %.
A26: Integrationskosten | B26: % Kaufpreis | C26: 0.08 | H26: Datenmigration, Umschulung, Doppellizenzen.
A27: Abschreibungsdauer Goodwill/Kundenstamm | B27: Jahre | C27: 8 | H27: OR/Swiss GAAP FER: 5–20 Jahre.
A29: Produktivität und Personal | C29: 2027 | D29: 2028 | E29: 2029 | F29: 2030 | G29: 2031
A30: Miet-Einheiten je Bewirtschafter-FTE (inkl. KI) | B30: Einheiten | C30: 400 | D30: 440 | E30: 480 | F30: 520 | G30: 560 | H30: Klassisch ca. 400–450 (Annahme aus Praxis, zu verifizieren). KI-Ziel +40 % bis Jahr 5 (bewusst unter dem Anspruch «KI erledigt 80 %»), analog «KI erledigt 80 %» (mory.ai).
A31: STWE-Einheit entspricht Miet-Einheiten | B31: Faktor | C31: 0.6 | H31: Weniger Mieterkontakte, dafür Versammlungen.
A32: Kosten je Bewirtschafter-FTE (Vollkosten) | B32: CHF/Jahr | C32: 118000 | H32: Lohn Median CHF 84k–98k (jobs.ch, lohncheck.ch) + ca. 18 % Sozialabgaben/BVG + Weiterbildung.
A33: Assistenz/Buchhaltung je Bewirtschafter | B33: FTE | C33: 0.6 | D33: 0.55 | E33: 0.5 | F33: 0.45 | G33: 0.4 | H33: KI übernimmt Belegerfassung und Standardkorrespondenz.
A34: Kosten je Assistenz-FTE (Vollkosten) | B34: CHF/Jahr | C34: 88000 | H34: Sachbearbeitung Immobilien, lohnanalyse.ch.
A35: Geschäftsleitung und Zentrale (Gründer, Technik, Vertrieb, Finanzen) | B35: CHF/Jahr | C35: 330000 | D35: 650000 | E35: 1000000 | F35: 1350000 | G35: 1650000 | H35: J1: Gründer 140k + Technik 150k + Teilzeit 40k. Ab J3 CFO/M&A, ab J2 Vertrieb/Marketing.
A37: Sachkosten | C37: 2027 | D37: 2028 | E37: 2029 | F37: 2030 | G37: 2031
A38: Software (ERP, KI, Hosting) je verwaltete Einheit | B38: CHF/Jahr | C38: 22 | H38: ERP-Lizenz ca. CHF 10–15/Einheit (Annahme, Offerten einholen) + KI/LLM ca. CHF 8.
A39: Akquisekosten je neue organische Miet-Einheit | B39: CHF | C39: 260 | H39: Marketingplan 03: Budget ÷ Zielvolumen.
A40: Akquisekosten je neue organische STWE-Einheit | B40: CHF | C40: 160
A41: Büro/Arbeitsplatz je FTE | B41: CHF/Jahr | C41: 9000 | H41: Coworking/Büro Agglomeration Zürich, Annahme.
A42: Versicherung, Treuhand, Revision, Recht, Verbände | B42: CHF/Jahr | C42: 70000 | D42: 95000 | E42: 130000 | F42: 160000 | G42: 190000 | H42: Berufshaftpflicht, Vertrauensschaden, Revision, SVIT-Mitgliedschaft.
A43: Gewinnsteuersatz effektiv | B43: % | C43: 0.197 | H43: Kanton Zürich, Stadt Zürich, ca. 19,7 %.
A45: Finanzierung | C45: 2027 | D45: 2028 | E45: 2029 | F45: 2030 | G45: 2031
A46: Eigenkapital-Einlagen | B46: CHF | C46: 750000 | D46: 1800000 | E46: 0 | F46: 0 | G46: 0 | H46: J1: Gründer + 2–4 Business Angels. J2: Wachstumsrunde (Family Office / Search-Fund-Investoren).
A47: Akquisitionskredit Bank (neu aufgenommen) | B47: CHF | C47: 200000 | D47: 500000 | E47: 600000 | F47: 1000000 | G47: 1200000 | H47: Zielgrösse ≤ 2,5x EBITDA. Laufzeit 5 Jahre.
...

Sheet Modell
A1: Hausklar – Modell (berechnet, nicht bearbeiten)
A2: ="Szenario: "&Annahmen!C4
A4: Einheiten | C4: 2027 | D4: 2028 | E4: 2029 | F4: 2030 | G4: 2031
A5: Zugang Miet-Einheiten | C5: =ROUND((Annahmen!C15+Annahmen!C17)*Annahmen!$D$4,0) | D5: =ROUND((Annahmen!D15+Annahmen!D17)*Annahmen!$D$4,0) | E5: =ROUND((Annahmen!E15+Annahmen!E17)*Annahmen!$D$4,0) | F5: =ROUND((Annahmen!F15+Annahmen!F17)*Annahmen!$D$4,0) | G5: =ROUND((Annahmen!G15+Annahmen!G17)*Annahmen!$D$4,0)
A6: Zugang STWE-Einheiten | C6: =ROUND((Annahmen!C16+Annahmen!C18)*Annahmen!$D$4,0) | D6: =ROUND((Annahmen!D16+Annahmen!D18)*Annahmen!$D$4,0) | E6: =ROUND((Annahmen!E16+Annahmen!E18)*Annahmen!$D$4,0) | F6: =ROUND((Annahmen!F16+Annahmen!F18)*Annahmen!$D$4,0) | G6: =ROUND((Annahmen!G16+Annahmen!G18)*Annahmen!$D$4,0)
A7: Abgang Miet-Einheiten (Kündigungen) | C7: =-ROUND(0*Annahmen!$C$12,0) | D7: =-ROUND(C9*Annahmen!$C$12,0) | E7: =-ROUND(D9*Annahmen!$C$12,0) | F7: =-ROUND(E9*Annahmen!$C$12,0) | G7: =-ROUND(F9*Annahmen!$C$12,0)
A8: Abgang STWE-Einheiten | C8: =-ROUND(0*Annahmen!$C$12,0) | D8: =-ROUND(C10*Annahmen!$C$12,0) | E8: =-ROUND(D10*Annahmen!$C$12,0) | F8: =-ROUND(E10*Annahmen!$C$12,0) | G8: =-ROUND(F10*Annahmen!$C$12,0)
A9: Miet-Einheiten Jahresende | C9: =0+C5+C7 | D9: =C9+D5+D7 | E9: =D9+E5+E7 | F9: =E9+F5+F7 | G9: =F9+G5+G7
A10: STWE-Einheiten Jahresende | C10: =0+C6+C8 | D10: =C10+D6+D8 | E10: =D10+E6+E8 | F10: =E10+F6+F8 | G10: =F10+G6+G8
A11: Miet-Einheiten ertragswirksam (Ø) | C11: =0+(C5+C7)*Annahmen!$C$19 | D11: =C9+(D5+D7)*Annahmen!$C$19 | E11: =D9+(E5+E7)*Annahmen!$C$19 | F11: =E9+(F5+F7)*Annahmen!$C$19 | G11: =F9+(G5+G7)*Annahmen!$C$19
A12: STWE-Einheiten ertragswirksam (Ø) | C12: =0+(C6+C8)*Annahmen!$C$19 | D12: =C10+(D6+D8)*Annahmen!$C$19 | E12: =D10+(E6+E8)*Annahmen!$C$19 | F12: =E10+(F6+F8)*Annahmen!$C$19 | G12: =F10+(G6+G8)*Annahmen!$C$19
A14: Erfolgsrechnung (CHF) | C14: 2027 | D14: 2028 | E14: 2029 | F14: 2030 | G14: 2031
A15: Honorar Mietliegenschaften | C15: =C11*Annahmen!$C$7*12*Annahmen!$C$8 | D15: =D11*Annahmen!$C$7*12*Annahmen!$C$8 | E15: =E11*Annahmen!$C$7*12*Annahmen!$C$8 | F15: =F11*Annahmen!$C$7*12*Annahmen!$C$8 | G15: =G11*Annahmen!$C$7*12*Annahmen!$C$8
A16: Honorar Stockwerkeigentum | C16: =C12*Annahmen!$C$10 | D16: =D12*Annahmen!$C$10 | E16: =E12*Annahmen!$C$10 | F16: =F12*Annahmen!$C$10 | G16: =G12*Annahmen!$C$10
A17: Zusatzerträge | C17: =(C15+C16)*Annahmen!$C$11 | D17: =(D15+D16)*Annahmen!$C$11 | E17: =(E15+E16)*Annahmen!$C$11 | F17: =(F15+F16)*Annahmen!$C$11 | G17: =(G15+G16)*Annahmen!$C$11
A18: Umsatz | C18: =C15+C16+C17 | D18: =D15+D16+D17 | E18: =E15+E16+E17 | F18: =F15+F16+F17 | G18: =G15+G16+G17
A19: Bewirtschafter-FTE (Bedarf) | C19: =ROUNDUP((C11+C12*Annahmen!$C$31)/Annahmen!C30,1) | D19: =ROUNDUP((D11+D12*Annahmen!$C$31)/Annahmen!D30,1) | E19: =ROUNDUP((E11+E12*Annahmen!$C$31)/Annahmen!E30,1) | F19: =ROUNDUP((F11+F12*Annahmen!$C$31)/Annahmen!F30,1) | G19: =ROUNDUP((G11+G12*Annahmen!$C$31)/Annahmen!G30,1)
A20: Assistenz-FTE | C20: =ROUND(C19*Annahmen!C33,1) | D20: =ROUND(D19*Annahmen!D33,1) | E20: =ROUND(E19*Annahmen!E33,1) | F20: =ROUND(F19*Annahmen!F33,1) | G20: =ROUND(G19*Annahmen!G33,1)
A21: Personal Bewirtschaftung | C21: =-(C19*Annahmen!$C$32+C20*Annahmen!$C$34) | D21: =-(D19*Annahmen!$C$32+D20*Annahmen!$C$34) | E21: =-(E19*Annahmen!$C$32+E20*Annahmen!$C$34) | F21: =-(F19*Annahmen!$C$32+F20*Annahmen!$C$34) | G21: =-(G19*Annahmen!$C$32+G20*Annahmen!$C$34)
A22: Geschäftsleitung und Zentrale | C22: =-Annahmen!C35 | D22: =-Annahmen!D35 | E22: =-Annahmen!E35 | F22: =-Annahmen!F35 | G22: =-Annahmen!G35
A23: Software und KI | C23: =-(C11+C12)*Annahmen!$C$38 | D23: =-(D11+D12)*Annahmen!$C$38 | E23: =-(E11+E12)*Annahmen!$C$38 | F23: =-(F11+F12)*Annahmen!$C$38 | G23: =-(G11+G12)*Annahmen!$C$38
A24: Marketing und Vertrieb | C24: =-ROUND((Annahmen!C15*Annahmen!$C$39+Annahmen!C16*Annahmen!$C$40)*Annahmen!$D$4,0) | D24: =-ROUND((Annahmen!D15*Annahmen!$C$39+Annahmen!D16*Annahmen!$C$40)*Annahmen!$D$4,0) | E24: =-ROUND((Annahmen!E15*Annahmen!$C$39+Annahmen!E16*Annahmen!$C$40)*Annahmen!$D$4,0) | F24: =-ROUND((Annahmen!F15*Annahmen!$C$39+Annahmen!F16*Annahmen!$C$40)*Annahmen!$D$4,0) | G24: =-ROUND((Annahmen!G15*Annahmen!$C$39+Annahmen!G16*Annahmen!$C$40)*Annahmen!$D$4,0)
A25: Büro | C25: =-(C19+C20+ROUND(Annahmen!C35/150000,0))*Annahmen!$C$41 | D25: =-(D19+D20+ROUND(Annahmen!D35/150000,0))*Annahmen!$C$41 | E25: =-(E19+E20+ROUND(Annahmen!E35/150000,0))*Annahmen!$C$41 | F25: =-(F19+F20+ROUND(Annahmen!F35/150000,0))*Annahmen!$C$41 | G25: =-(G19+G20+ROUND(Annahmen!G35/150000,0))*Annahmen!$C$41
A26: Versicherung, Treuhand, Recht | C26: =-Annahmen!C42 | D26: =-Annahmen!D42 | E26: =-Annahmen!E42 | F26: =-Annahmen!F42 | G26: =-Annahmen!G42
A27: Integrationskosten Übernahmen | C27: =-C38*Annahmen!$C$26 | D27: =-D38*Annahmen!$C$26 | E27: =-E38*Annahmen!$C$26 | F27: =-F38*Annahmen!$C$26 | G27: =-G38*Annahmen!$C$26
A28: EBITDA | C28: =SUM(C18,C21:C27) | D28: =SUM(D18,D21:D27) | E28: =SUM(E18,E21:E27) | F28: =SUM(F18,F21:F27) | G28: =SUM(G18,G21:G27)
A29: EBITDA-Marge | C29: =IF(C18=0,0,C28/C18) | D29: =IF(D18=0,0,D28/D18) | E29: =IF(E18=0,0,E28/E18) | F29: =IF(F18=0,0,F28/F18) | G29: =IF(G18=0,0,G28/G18)
A30: Abschreibung Goodwill/Kundenstamm | C30: =-SUM($C$38:C38)/Annahmen!$C$27 | D30: =-SUM($C$38:D38)/Annahmen!$C$27 | E30: =-SUM($C$38:E38)/Annahmen!$C$27 | F30: =-SUM($C$38:F38)/Annahmen!$C$27 | G30: =-SUM($C$38:G38)/Annahmen!$C$27
A31: Zinsaufwand | C31: =-(0+0)*Annahmen!$C$48 | D31: =-(C51+C43)*Annahmen!$C$48 | E31: =-(D51+D43)*Annahmen!$C$48 | F31: =-(E51+E43)*Annahmen!$C$48 | G31: =-(F51+F43)*Annahmen!$C$48
A32: Ergebnis vor Steuern | C32: =C28+C30+C31 | D32: =D28+D30+D31 | E32: =E28+E30+E31 | F32: =F28+F30+F31 | G32: =G28+G30+G31
A33: Steuern | C33: =-MAX(0,C32)*Annahmen!$C$43 | D33: =-MAX(0,D32)*Annahmen!$C$43 | E33: =-MAX(0,E32)*Annahmen!$C$43 | F33: =-MAX(0,F32)*Annahmen!$C$43 | G33: =-MAX(0,G32)*Annahmen!$C$43
A34: Jahresergebnis | C34: =C32+C33 | D34: =D32+D33 | E34: =E32+E33 | F34: =F32+F33 | G34: =G32+G33
A36: Übernahmen (CHF) | C36: 2027 | D36: 2028 | E36: 2029 | F36: 2030 | G36: 2031
A37: Übernommener Jahresumsatz | C37: =ROUND(Annahmen!C17*Annahmen!$D$4,0)*Annahmen!$C$7*12*Annahmen!$C$9*(1+Annahmen!$C$11)+ROUND(Annahmen!C18*Annahmen!$D$4,0)*Annahmen!$C$10*(1+Annahmen!$C$11) | D37: =ROUND(Annahmen!D17*Annahmen!$D$4,0)*Annahmen!$C$7*12*Annahmen!$C$9*(1+Annahmen!$C$11)+ROUND(Annahmen!D18*Annahmen!$D$4,0)*Annahmen!$C$10*(1+Annahmen!$C$11) | E37: =ROUND(Annahmen!E17*Annahmen!$D$4,0)*Annahmen!$C$7*12*Annahmen!$C$9*(1+Annahmen!$C$11)+ROUND(Annahmen!E18*Annahmen!$D$4,0)*Annahmen!$C$10*(1+Annahmen!$C$11) | F37: =ROUND(Annahmen!F17*Annahmen!$D$4,0)*Annahmen!$C$7*12*Annahmen!$C$9*(1+Annahmen!$C$11)+ROUND(Annahmen!F18*Annahmen!$D$4,0)*Annahmen!$C$10*(1+Annahmen!$C$11) | G37: =ROUND(Annahmen!G17*Annahmen!$D$4,0)*Annahmen!$C$7*12*Annahmen!$C$9*(1+Annahmen!$C$11)+ROUND(Annahmen!G18*Annahmen!$D$4,0)*Annahmen!$C$10*(1+Annahmen!$C$11)
A38: Kaufpreis total | C38: =C37*Annahmen!$C$22 | D38: =D37*Annahmen!$C$22 | E38: =E37*Annahmen!$C$22 | F38: =F37*Annahmen!$C$22 | G38: =G37*Annahmen!$C$22
A39: davon bar bei Vollzug | C39: =C38*Annahmen!$C$23 | D39: =D38*Annahmen!$C$23 | E39: =E38*Annahmen!$C$23 | F39: =F38*Annahmen!$C$23 | G39: =G38*Annahmen!$C$23
A40: Earn-out fällig (aus Vorjahres-Deals) | C40: =0 | D40: =C38*Annahmen!$C$25 | E40: =D38*Annahmen!$C$25 | F40: =E38*Annahmen!$C$25 | G40: =F38*Annahmen!$C$25
A41: Verkäuferdarlehen neu | C41: =C38*Annahmen!$C$24 | D41: =D38*Annahmen!$C$24 | E41: =E38*Annahmen!$C$24 | F41: =F38*Annahmen!$C$24 | G41: =G38*Annahmen!$C$24
A42: Tilgung Verkäuferdarlehen | C42: =0 | D42: =(C41)/3 | E42: =(C41+D41)/3 | F42: =(C41+D41+E41)/3 | G42: =(D41+E41+F41)/3
A43: Verkäuferdarlehen Bestand Jahresende | C43: =0+C41-C42 | D43: =C43+D41-D42 | E43: =D43+E41-E42 | F43: =E43+F41-F42 | G43: =F43+G41-G42
...
